Sun, 08 Apr 2018 11:23:37 PngImagePlugin.py[line:137] DEBUG STREAM b'IHDR' 16 13
Sun, 08 Apr 2018 11:23:37 PngImagePlugin.py[line:137] DEBUG STREAM b'IDAT' 41 65536
Sun, 08 Apr 2018 11:23:38 PngImagePlugin.py[line:137] DEBUG STREAM b'IHDR' 16 13
Sun, 08 Apr 2018 11:23:38 PngImagePlugin.py[line:137] DEBUG STREAM b'IDAT' 41 65536
Sun, 08 Apr 2018 11:23:38 app_thread.py[line:127] ERROR 刷新失败
Sun, 08 Apr 2018 11:23:38 app_thread.py[line:128] ERROR this is an exception message
Traceback (most recent call last):
  File "E:\hupai\component\app_thread.py", line 125, in run
    findrefresh()
  File "E:\hupai\component\imgcut.py", line 383, in findrefresh
    img = cv2.cvtColor(sc, cv2.COLOR_BGR2GRAY)  # 转灰度图
cv2.error: C:\projects\opencv-python\opencv\modules\imgproc\src\color.cpp:11073: error: (-215) depth == 0 || depth == 2 || depth == 5 in function cv::cvtColor

Sun, 08 Apr 2018 11:23:38 imgcut.py[line:368] ERROR cut_img 这里出错
Sun, 08 Apr 2018 11:23:38 imgcut.py[line:369] ERROR this is an exception message
Traceback (most recent call last):
  File "E:\hupai\component\imgcut.py", line 361, in cut_img
    set_val('imgpos_lowestprice', img[use_area[0][1]:use_area[0][3], use_area[0][0]:use_area[0][2]])  # ok
IndexError: list index out of range
Sun, 08 Apr 2018 11:23:38 app_thread.py[line:127] ERROR 刷新失败
Sun, 08 Apr 2018 11:23:38 app_thread.py[line:128] ERROR this is an exception message
Traceback (most recent call last):
  File "E:\hupai\component\app_thread.py", line 125, in run
    findrefresh()
  File "E:\hupai\component\imgcut.py", line 383, in findrefresh
    img = cv2.cvtColor(sc, cv2.COLOR_BGR2GRAY)  # 转灰度图
cv2.error: C:\projects\opencv-python\opencv\modules\imgproc\src\color.cpp:11073: error: (-215) depth == 0 || depth == 2 || depth == 5 in function cv::cvtColor

Sun, 08 Apr 2018 11:23:38 app_thread.py[line:127] ERROR 刷新失败
Sun, 08 Apr 2018 11:23:38 app_thread.py[line:128] ERROR this is an exception message
Traceback (most recent call last):
  File "E:\hupai\component\app_thread.py", line 125, in run
    findrefresh()
  File "E:\hupai\component\imgcut.py", line 383, in findrefresh
    img = cv2.cvtColor(sc, cv2.COLOR_BGR2GRAY)  # 转灰度图
cv2.error: C:\projects\opencv-python\opencv\modules\imgproc\src\color.cpp:11073: error: (-215) depth == 0 || depth == 2 || depth == 5 in function cv::cvtColor

Sun, 08 Apr 2018 11:23:38 imgcut.py[line:368] ERROR cut_img 这里出错
Sun, 08 Apr 2018 11:23:38 imgcut.py[line:369] ERROR this is an exception message
Traceback (most recent call last):
  File "E:\hupai\component\imgcut.py", line 361, in cut_img
    set_val('imgpos_lowestprice', img[use_area[0][1]:use_area[0][3], use_area[0][0]:use_area[0][2]])  # ok
IndexError: list index out of range
Sun, 08 Apr 2018 11:23:38 app_thread.py[line:127] ERROR 刷新失败
Sun, 08 Apr 2018 11:23:38 app_thread.py[line:128] ERROR this is an exception message
Traceback (most recent call last):
  File "E:\hupai\component\app_thread.py", line 125, in run
    findrefresh()
  File "E:\hupai\component\imgcut.py", line 383, in findrefresh
    img = cv2.cvtColor(sc, cv2.COLOR_BGR2GRAY)  # 转灰度图
cv2.error: C:\projects\opencv-python\opencv\modules\imgproc\src\color.cpp:11073: error: (-215) depth == 0 || depth == 2 || depth == 5 in function cv::cvtColor

Sun, 08 Apr 2018 11:23:38 app_thread.py[line:127] ERROR 刷新失败
Sun, 08 Apr 2018 11:23:38 app_thread.py[line:128] ERROR this is an exception message
Traceback (most recent call last):
  File "E:\hupai\component\app_thread.py", line 125, in run
    findrefresh()
  File "E:\hupai\component\imgcut.py", line 383, in findrefresh
    img = cv2.cvtColor(sc, cv2.COLOR_BGR2GRAY)  # 转灰度图
cv2.error: C:\projects\opencv-python\opencv\modules\imgproc\src\color.cpp:11073: error: (-215) depth == 0 || depth == 2 || depth == 5 in function cv::cvtColor

Sun, 08 Apr 2018 11:23:38 imgcut.py[line:368] ERROR cut_img 这里出错
Sun, 08 Apr 2018 11:23:38 imgcut.py[line:369] ERROR this is an exception message
Traceback (most recent call last):
  File "E:\hupai\component\imgcut.py", line 361, in cut_img
    set_val('imgpos_lowestprice', img[use_area[0][1]:use_area[0][3], use_area[0][0]:use_area[0][2]])  # ok
IndexError: list index out of range
Sun, 08 Apr 2018 11:23:38 app_thread.py[line:127] ERROR 刷新失败
Sun, 08 Apr 2018 11:23:38 app_thread.py[line:128] ERROR this is an exception message
Traceback (most recent call last):
  File "E:\hupai\component\app_thread.py", line 125, in run
    findrefresh()
  File "E:\hupai\component\imgcut.py", line 383, in findrefresh
    img = cv2.cvtColor(sc, cv2.COLOR_BGR2GRAY)  # 转灰度图
cv2.error: C:\projects\opencv-python\opencv\modules\imgproc\src\color.cpp:11073: error: (-215) depth == 0 || depth == 2 || depth == 5 in function cv::cvtColor

Sun, 08 Apr 2018 11:23:38 imgcut.py[line:368] ERROR cut_img 这里出错
Sun, 08 Apr 2018 11:23:38 imgcut.py[line:369] ERROR this is an exception message
Traceback (most recent call last):
  File "E:\hupai\component\imgcut.py", line 361, in cut_img
    set_val('imgpos_lowestprice', img[use_area[0][1]:use_area[0][3], use_area[0][0]:use_area[0][2]])  # ok
IndexError: list index out of range
Sun, 08 Apr 2018 11:23:38 app_thread.py[line:127] ERROR 刷新失败
Sun, 08 Apr 2018 11:23:38 app_thread.py[line:128] ERROR this is an exception message
Traceback (most recent call last):
  File "E:\hupai\component\app_thread.py", line 125, in run
    findrefresh()
  File "E:\hupai\component\imgcut.py", line 383, in findrefresh
    img = cv2.cvtColor(sc, cv2.COLOR_BGR2GRAY)  # 转灰度图
cv2.error: C:\projects\opencv-python\opencv\modules\imgproc\src\color.cpp:11073: error: (-215) depth == 0 || depth == 2 || depth == 5 in function cv::cvtColor

Sun, 08 Apr 2018 11:23:38 imgcut.py[line:368] ERROR cut_img 这里出错
Sun, 08 Apr 2018 11:23:38 imgcut.py[line:369] ERROR this is an exception message
Traceback (most recent call last):
  File "E:\hupai\component\imgcut.py", line 361, in cut_img
    set_val('imgpos_lowestprice', img[use_area[0][1]:use_area[0][3], use_area[0][0]:use_area[0][2]])  # ok
IndexError: list index out of range
Sun, 08 Apr 2018 11:23:38 app_thread.py[line:127] ERROR 刷新失败
Sun, 08 Apr 2018 11:23:38 app_thread.py[line:128] ERROR this is an exception message
Traceback (most recent call last):
  File "E:\hupai\component\app_thread.py", line 125, in run
    findrefresh()
  File "E:\hupai\component\imgcut.py", line 383, in findrefresh
    img = cv2.cvtColor(sc, cv2.COLOR_BGR2GRAY)  # 转灰度图
cv2.error: C:\projects\opencv-python\opencv\modules\imgproc\src\color.cpp:11073: error: (-215) depth == 0 || depth == 2 || depth == 5 in function cv::cvtColor

Sun, 08 Apr 2018 11:23:38 app_thread.py[line:127] ERROR 刷新失败
Sun, 08 Apr 2018 11:23:38 imgcut.py[line:368] ERROR cut_img 这里出错
Sun, 08 Apr 2018 11:23:38 app_thread.py[line:128] ERROR this is an exception message
Traceback (most recent call last):
  File "E:\hupai\component\app_thread.py", line 125, in run
    findrefresh()
  File "E:\hupai\component\imgcut.py", line 383, in findrefresh
    img = cv2.cvtColor(sc, cv2.COLOR_BGR2GRAY)  # 转灰度图
cv2.error: C:\projects\opencv-python\opencv\modules\imgproc\src\color.cpp:11073: error: (-215) depth == 0 || depth == 2 || depth == 5 in function cv::cvtColor

Sun, 08 Apr 2018 11:23:38 imgcut.py[line:369] ERROR this is an exception message
Traceback (most recent call last):
  File "E:\hupai\component\imgcut.py", line 361, in cut_img
    set_val('imgpos_lowestprice', img[use_area[0][1]:use_area[0][3], use_area[0][0]:use_area[0][2]])  # ok
IndexError: list index out of range
Sun, 08 Apr 2018 11:23:38 app_thread.py[line:127] ERROR 刷新失败
Sun, 08 Apr 2018 11:23:38 app_thread.py[line:128] ERROR this is an exception message
Traceback (most recent call last):
  File "E:\hupai\component\app_thread.py", line 125, in run
    findrefresh()
  File "E:\hupai\component\imgcut.py", line 383, in findrefresh
    img = cv2.cvtColor(sc, cv2.COLOR_BGR2GRAY)  # 转灰度图
cv2.error: C:\projects\opencv-python\opencv\modules\imgproc\src\color.cpp:11073: error: (-215) depth == 0 || depth == 2 || depth == 5 in function cv::cvtColor

Sun, 08 Apr 2018 11:23:38 imgcut.py[line:368] ERROR cut_img 这里出错
Sun, 08 Apr 2018 11:23:38 imgcut.py[line:369] ERROR this is an exception message
Traceback (most recent call last):
  File "E:\hupai\component\imgcut.py", line 361, in cut_img
    set_val('imgpos_lowestprice', img[use_area[0][1]:use_area[0][3], use_area[0][0]:use_area[0][2]])  # ok
IndexError: list index out of range
Sun, 08 Apr 2018 11:23:38 app_thread.py[line:127] ERROR 刷新失败
Sun, 08 Apr 2018 11:23:38 app_thread.py[line:128] ERROR this is an exception message
Traceback (most recent call last):
  File "E:\hupai\component\app_thread.py", line 125, in run
    findrefresh()
  File "E:\hupai\component\imgcut.py", line 383, in findrefresh
    img = cv2.cvtColor(sc, cv2.COLOR_BGR2GRAY)  # 转灰度图
cv2.error: C:\projects\opencv-python\opencv\modules\imgproc\src\color.cpp:11073: error: (-215) depth == 0 || depth == 2 || depth == 5 in function cv::cvtColor

Sun, 08 Apr 2018 11:23:38 imgcut.py[line:368] ERROR cut_img 这里出错
Sun, 08 Apr 2018 11:23:38 imgcut.py[line:369] ERROR this is an exception message
Traceback (most recent call last):
  File "E:\hupai\component\imgcut.py", line 361, in cut_img
    set_val('imgpos_lowestprice', img[use_area[0][1]:use_area[0][3], use_area[0][0]:use_area[0][2]])  # ok
IndexError: list index out of range
Sun, 08 Apr 2018 11:23:38 app_thread.py[line:127] ERROR 刷新失败
Sun, 08 Apr 2018 11:23:38 app_thread.py[line:128] ERROR this is an exception message
Traceback (most recent call last):
  File "E:\hupai\component\app_thread.py", line 125, in run
    findrefresh()
  File "E:\hupai\component\imgcut.py", line 383, in findrefresh
    img = cv2.cvtColor(sc, cv2.COLOR_BGR2GRAY)  # 转灰度图
cv2.error: C:\projects\opencv-python\opencv\modules\imgproc\src\color.cpp:11073: error: (-215) depth == 0 || depth == 2 || depth == 5 in function cv::cvtColor

Sun, 08 Apr 2018 11:23:38 imgcut.py[line:368] ERROR cut_img 这里出错
Sun, 08 Apr 2018 11:23:38 imgcut.py[line:369] ERROR this is an exception message
Traceback (most recent call last):
  File "E:\hupai\component\imgcut.py", line 361, in cut_img
    set_val('imgpos_lowestprice', img[use_area[0][1]:use_area[0][3], use_area[0][0]:use_area[0][2]])  # ok
IndexError: list index out of range
Sun, 08 Apr 2018 11:23:39 app_thread.py[line:127] ERROR 刷新失败
Sun, 08 Apr 2018 11:23:39 app_thread.py[line:128] ERROR this is an exception message
Traceback (most recent call last):
  File "E:\hupai\component\app_thread.py", line 125, in run
    findrefresh()
  File "E:\hupai\component\imgcut.py", line 383, in findrefresh
    img = cv2.cvtColor(sc, cv2.COLOR_BGR2GRAY)  # 转灰度图
cv2.error: C:\projects\opencv-python\opencv\modules\imgproc\src\color.cpp:11073: error: (-215) depth == 0 || depth == 2 || depth == 5 in function cv::cvtColor

Sun, 08 Apr 2018 11:23:39 imgcut.py[line:368] ERROR cut_img 这里出错
Sun, 08 Apr 2018 11:23:39 imgcut.py[line:369] ERROR this is an exception message
Traceback (most recent call last):
  File "E:\hupai\component\imgcut.py", line 361, in cut_img
    set_val('imgpos_lowestprice', img[use_area[0][1]:use_area[0][3], use_area[0][0]:use_area[0][2]])  # ok
IndexError: list index out of range
Sun, 08 Apr 2018 11:23:39 app_thread.py[line:127] ERROR 刷新失败
Sun, 08 Apr 2018 11:23:39 app_thread.py[line:128] ERROR this is an exception message
Traceback (most recent call last):
  File "E:\hupai\component\app_thread.py", line 125, in run
    findrefresh()
  File "E:\hupai\component\imgcut.py", line 383, in findrefresh
    img = cv2.cvtColor(sc, cv2.COLOR_BGR2GRAY)  # 转灰度图
cv2.error: C:\projects\opencv-python\opencv\modules\imgproc\src\color.cpp:11073: error: (-215) depth == 0 || depth == 2 || depth == 5 in function cv::cvtColor

Sun, 08 Apr 2018 11:23:39 imgcut.py[line:368] ERROR cut_img 这里出错
Sun, 08 Apr 2018 11:23:39 imgcut.py[line:369] ERROR this is an exception message
Traceback (most recent call last):
  File "E:\hupai\component\imgcut.py", line 361, in cut_img
    set_val('imgpos_lowestprice', img[use_area[0][1]:use_area[0][3], use_area[0][0]:use_area[0][2]])  # ok
IndexError: list index out of range
Sun, 08 Apr 2018 11:23:39 app_thread.py[line:127] ERROR 刷新失败
Sun, 08 Apr 2018 11:23:39 app_thread.py[line:128] ERROR this is an exception message
Traceback (most recent call last):
  File "E:\hupai\component\app_thread.py", line 125, in run
    findrefresh()
  File "E:\hupai\component\imgcut.py", line 383, in findrefresh
    img = cv2.cvtColor(sc, cv2.COLOR_BGR2GRAY)  # 转灰度图
cv2.error: C:\projects\opencv-python\opencv\modules\imgproc\src\color.cpp:11073: error: (-215) depth == 0 || depth == 2 || depth == 5 in function cv::cvtColor

Sun, 08 Apr 2018 11:23:39 imgcut.py[line:368] ERROR cut_img 这里出错
Sun, 08 Apr 2018 11:23:39 imgcut.py[line:369] ERROR this is an exception message
Traceback (most recent call last):
  File "E:\hupai\component\imgcut.py", line 361, in cut_img
    set_val('imgpos_lowestprice', img[use_area[0][1]:use_area[0][3], use_area[0][0]:use_area[0][2]])  # ok
IndexError: list index out of range
Sun, 08 Apr 2018 11:23:39 app_thread.py[line:127] ERROR 刷新失败
Sun, 08 Apr 2018 11:23:39 app_thread.py[line:128] ERROR this is an exception message
Traceback (most recent call last):
  File "E:\hupai\component\app_thread.py", line 125, in run
    findrefresh()
  File "E:\hupai\component\imgcut.py", line 383, in findrefresh
    img = cv2.cvtColor(sc, cv2.COLOR_BGR2GRAY)  # 转灰度图
cv2.error: C:\projects\opencv-python\opencv\modules\imgproc\src\color.cpp:11073: error: (-215) depth == 0 || depth == 2 || depth == 5 in function cv::cvtColor

Sun, 08 Apr 2018 11:23:39 imgcut.py[line:368] ERROR cut_img 这里出错
Sun, 08 Apr 2018 11:23:39 imgcut.py[line:369] ERROR this is an exception message
Traceback (most recent call last):
  File "E:\hupai\component\imgcut.py", line 361, in cut_img
    set_val('imgpos_lowestprice', img[use_area[0][1]:use_area[0][3], use_area[0][0]:use_area[0][2]])  # ok
IndexError: list index out of range
Sun, 08 Apr 2018 11:23:39 app_thread.py[line:127] ERROR 刷新失败
Sun, 08 Apr 2018 11:23:39 app_thread.py[line:128] ERROR this is an exception message
Traceback (most recent call last):
  File "E:\hupai\component\app_thread.py", line 125, in run
    findrefresh()
  File "E:\hupai\component\imgcut.py", line 383, in findrefresh
    img = cv2.cvtColor(sc, cv2.COLOR_BGR2GRAY)  # 转灰度图
cv2.error: C:\projects\opencv-python\opencv\modules\imgproc\src\color.cpp:11073: error: (-215) depth == 0 || depth == 2 || depth == 5 in function cv::cvtColor

Sun, 08 Apr 2018 11:23:39 imgcut.py[line:368] ERROR cut_img 这里出错
Sun, 08 Apr 2018 11:23:39 imgcut.py[line:369] ERROR this is an exception message
Traceback (most recent call last):
  File "E:\hupai\component\imgcut.py", line 361, in cut_img
    set_val('imgpos_lowestprice', img[use_area[0][1]:use_area[0][3], use_area[0][0]:use_area[0][2]])  # ok
IndexError: list index out of range
Sun, 08 Apr 2018 11:23:39 app_thread.py[line:127] ERROR 刷新失败
Sun, 08 Apr 2018 11:23:39 app_thread.py[line:128] ERROR this is an exception message
Traceback (most recent call last):
  File "E:\hupai\component\app_thread.py", line 125, in run
    findrefresh()
  File "E:\hupai\component\imgcut.py", line 383, in findrefresh
    img = cv2.cvtColor(sc, cv2.COLOR_BGR2GRAY)  # 转灰度图
cv2.error: C:\projects\opencv-python\opencv\modules\imgproc\src\color.cpp:11073: error: (-215) depth == 0 || depth == 2 || depth == 5 in function cv::cvtColor

Sun, 08 Apr 2018 11:23:39 imgcut.py[line:368] ERROR cut_img 这里出错
Sun, 08 Apr 2018 11:23:39 imgcut.py[line:369] ERROR this is an exception message
Traceback (most recent call last):
  File "E:\hupai\component\imgcut.py", line 361, in cut_img
    set_val('imgpos_lowestprice', img[use_area[0][1]:use_area[0][3], use_area[0][0]:use_area[0][2]])  # ok
IndexError: list index out of range
Sun, 08 Apr 2018 11:23:39 app_thread.py[line:127] ERROR 刷新失败
Sun, 08 Apr 2018 11:23:39 app_thread.py[line:128] ERROR this is an exception message
Traceback (most recent call last):
  File "E:\hupai\component\app_thread.py", line 125, in run
    findrefresh()
  File "E:\hupai\component\imgcut.py", line 383, in findrefresh
    img = cv2.cvtColor(sc, cv2.COLOR_BGR2GRAY)  # 转灰度图
cv2.error: C:\projects\opencv-python\opencv\modules\imgproc\src\color.cpp:11073: error: (-215) depth == 0 || depth == 2 || depth == 5 in function cv::cvtColor

Sun, 08 Apr 2018 11:23:39 imgcut.py[line:368] ERROR cut_img 这里出错
Sun, 08 Apr 2018 11:23:39 imgcut.py[line:369] ERROR this is an exception message
Traceback (most recent call last):
  File "E:\hupai\component\imgcut.py", line 361, in cut_img
    set_val('imgpos_lowestprice', img[use_area[0][1]:use_area[0][3], use_area[0][0]:use_area[0][2]])  # ok
IndexError: list index out of range
Sun, 08 Apr 2018 11:23:39 app_thread.py[line:127] ERROR 刷新失败
Sun, 08 Apr 2018 11:23:39 app_thread.py[line:128] ERROR this is an exception message
Traceback (most recent call last):
  File "E:\hupai\component\app_thread.py", line 125, in run
    findrefresh()
  File "E:\hupai\component\imgcut.py", line 383, in findrefresh
    img = cv2.cvtColor(sc, cv2.COLOR_BGR2GRAY)  # 转灰度图
cv2.error: C:\projects\opencv-python\opencv\modules\imgproc\src\color.cpp:11073: error: (-215) depth == 0 || depth == 2 || depth == 5 in function cv::cvtColor

Sun, 08 Apr 2018 11:23:39 imgcut.py[line:368] ERROR cut_img 这里出错
Sun, 08 Apr 2018 11:23:39 imgcut.py[line:369] ERROR this is an exception message
Traceback (most recent call last):
  File "E:\hupai\component\imgcut.py", line 361, in cut_img
    set_val('imgpos_lowestprice', img[use_area[0][1]:use_area[0][3], use_area[0][0]:use_area[0][2]])  # ok
IndexError: list index out of range
Sun, 08 Apr 2018 11:23:39 app_thread.py[line:127] ERROR 刷新失败
Sun, 08 Apr 2018 11:23:39 app_thread.py[line:128] ERROR this is an exception message
Traceback (most recent call last):
  File "E:\hupai\component\app_thread.py", line 125, in run
    findrefresh()
  File "E:\hupai\component\imgcut.py", line 383, in findrefresh
    img = cv2.cvtColor(sc, cv2.COLOR_BGR2GRAY)  # 转灰度图
cv2.error: C:\projects\opencv-python\opencv\modules\imgproc\src\color.cpp:11073: error: (-215) depth == 0 || depth == 2 || depth == 5 in function cv::cvtColor

Sun, 08 Apr 2018 11:23:39 imgcut.py[line:368] ERROR cut_img 这里出错
Sun, 08 Apr 2018 11:23:39 imgcut.py[line:369] ERROR this is an exception message
Traceback (most recent call last):
  File "E:\hupai\component\imgcut.py", line 361, in cut_img
    set_val('imgpos_lowestprice', img[use_area[0][1]:use_area[0][3], use_area[0][0]:use_area[0][2]])  # ok
IndexError: list index out of range
Sun, 08 Apr 2018 11:23:39 app_thread.py[line:127] ERROR 刷新失败
Sun, 08 Apr 2018 11:23:39 app_thread.py[line:128] ERROR this is an exception message
Traceback (most recent call last):
  File "E:\hupai\component\app_thread.py", line 125, in run
    findrefresh()
  File "E:\hupai\component\imgcut.py", line 383, in findrefresh
    img = cv2.cvtColor(sc, cv2.COLOR_BGR2GRAY)  # 转灰度图
cv2.error: C:\projects\opencv-python\opencv\modules\imgproc\src\color.cpp:11073: error: (-215) depth == 0 || depth == 2 || depth == 5 in function cv::cvtColor

Sun, 08 Apr 2018 11:23:39 imgcut.py[line:368] ERROR cut_img 这里出错
Sun, 08 Apr 2018 11:23:39 imgcut.py[line:369] ERROR this is an exception message
Traceback (most recent call last):
  File "E:\hupai\component\imgcut.py", line 361, in cut_img
    set_val('imgpos_lowestprice', img[use_area[0][1]:use_area[0][3], use_area[0][0]:use_area[0][2]])  # ok
IndexError: list index out of range
Sun, 08 Apr 2018 11:23:39 app_thread.py[line:127] ERROR 刷新失败
Sun, 08 Apr 2018 11:23:39 app_thread.py[line:128] ERROR this is an exception message
Traceback (most recent call last):
  File "E:\hupai\component\app_thread.py", line 125, in run
    findrefresh()
  File "E:\hupai\component\imgcut.py", line 383, in findrefresh
    img = cv2.cvtColor(sc, cv2.COLOR_BGR2GRAY)  # 转灰度图
cv2.error: C:\projects\opencv-python\opencv\modules\imgproc\src\color.cpp:11073: error: (-215) depth == 0 || depth == 2 || depth == 5 in function cv::cvtColor

Sun, 08 Apr 2018 11:23:39 imgcut.py[line:368] ERROR cut_img 这里出错
Sun, 08 Apr 2018 11:23:39 imgcut.py[line:369] ERROR this is an exception message
Traceback (most recent call last):
  File "E:\hupai\component\imgcut.py", line 361, in cut_img
    set_val('imgpos_lowestprice', img[use_area[0][1]:use_area[0][3], use_area[0][0]:use_area[0][2]])  # ok
IndexError: list index out of range
Sun, 08 Apr 2018 11:23:39 app_thread.py[line:127] ERROR 刷新失败
Sun, 08 Apr 2018 11:23:39 app_thread.py[line:128] ERROR this is an exception message
Traceback (most recent call last):
  File "E:\hupai\component\app_thread.py", line 125, in run
    findrefresh()
  File "E:\hupai\component\imgcut.py", line 383, in findrefresh
    img = cv2.cvtColor(sc, cv2.COLOR_BGR2GRAY)  # 转灰度图
cv2.error: C:\projects\opencv-python\opencv\modules\imgproc\src\color.cpp:11073: error: (-215) depth == 0 || depth == 2 || depth == 5 in function cv::cvtColor

Sun, 08 Apr 2018 11:23:39 imgcut.py[line:368] ERROR cut_img 这里出错
Sun, 08 Apr 2018 11:23:39 imgcut.py[line:369] ERROR this is an exception message
Traceback (most recent call last):
  File "E:\hupai\component\imgcut.py", line 361, in cut_img
    set_val('imgpos_lowestprice', img[use_area[0][1]:use_area[0][3], use_area[0][0]:use_area[0][2]])  # ok
IndexError: list index out of range
Sun, 08 Apr 2018 11:23:39 app_thread.py[line:127] ERROR 刷新失败
Sun, 08 Apr 2018 11:23:39 app_thread.py[line:128] ERROR this is an exception message
Traceback (most recent call last):
  File "E:\hupai\component\app_thread.py", line 125, in run
    findrefresh()
  File "E:\hupai\component\imgcut.py", line 383, in findrefresh
    img = cv2.cvtColor(sc, cv2.COLOR_BGR2GRAY)  # 转灰度图
cv2.error: C:\projects\opencv-python\opencv\modules\imgproc\src\color.cpp:11073: error: (-215) depth == 0 || depth == 2 || depth == 5 in function cv::cvtColor

Sun, 08 Apr 2018 11:23:39 imgcut.py[line:368] ERROR cut_img 这里出错
Sun, 08 Apr 2018 11:23:39 imgcut.py[line:369] ERROR this is an exception message
Traceback (most recent call last):
  File "E:\hupai\component\imgcut.py", line 361, in cut_img
    set_val('imgpos_lowestprice', img[use_area[0][1]:use_area[0][3], use_area[0][0]:use_area[0][2]])  # ok
IndexError: list index out of range
Sun, 08 Apr 2018 11:23:39 app_thread.py[line:127] ERROR 刷新失败
Sun, 08 Apr 2018 11:23:39 app_thread.py[line:128] ERROR this is an exception message
Traceback (most recent call last):
  File "E:\hupai\component\app_thread.py", line 125, in run
    findrefresh()
  File "E:\hupai\component\imgcut.py", line 383, in findrefresh
    img = cv2.cvtColor(sc, cv2.COLOR_BGR2GRAY)  # 转灰度图
cv2.error: C:\projects\opencv-python\opencv\modules\imgproc\src\color.cpp:11073: error: (-215) depth == 0 || depth == 2 || depth == 5 in function cv::cvtColor

Sun, 08 Apr 2018 11:23:39 app_thread.py[line:127] ERROR 刷新失败
Sun, 08 Apr 2018 11:23:39 app_thread.py[line:128] ERROR this is an exception message
Traceback (most recent call last):
  File "E:\hupai\component\app_thread.py", line 125, in run
    findrefresh()
  File "E:\hupai\component\imgcut.py", line 383, in findrefresh
    img = cv2.cvtColor(sc, cv2.COLOR_BGR2GRAY)  # 转灰度图
cv2.error: C:\projects\opencv-python\opencv\modules\imgproc\src\color.cpp:11073: error: (-215) depth == 0 || depth == 2 || depth == 5 in function cv::cvtColor

Sun, 08 Apr 2018 11:23:39 imgcut.py[line:368] ERROR cut_img 这里出错
Sun, 08 Apr 2018 11:23:39 imgcut.py[line:369] ERROR this is an exception message
Traceback (most recent call last):
  File "E:\hupai\component\imgcut.py", line 361, in cut_img
    set_val('imgpos_lowestprice', img[use_area[0][1]:use_area[0][3], use_area[0][0]:use_area[0][2]])  # ok
IndexError: list index out of range
Sun, 08 Apr 2018 11:23:39 app_thread.py[line:127] ERROR 刷新失败
Sun, 08 Apr 2018 11:23:39 app_thread.py[line:128] ERROR this is an exception message
Traceback (most recent call last):
  File "E:\hupai\component\app_thread.py", line 125, in run
    findrefresh()
  File "E:\hupai\component\imgcut.py", line 383, in findrefresh
    img = cv2.cvtColor(sc, cv2.COLOR_BGR2GRAY)  # 转灰度图
cv2.error: C:\projects\opencv-python\opencv\modules\imgproc\src\color.cpp:11073: error: (-215) depth == 0 || depth == 2 || depth == 5 in function cv::cvtColor

Sun, 08 Apr 2018 11:23:39 imgcut.py[line:368] ERROR cut_img 这里出错
Sun, 08 Apr 2018 11:23:39 imgcut.py[line:369] ERROR this is an exception message
Traceback (most recent call last):
  File "E:\hupai\component\imgcut.py", line 361, in cut_img
    set_val('imgpos_lowestprice', img[use_area[0][1]:use_area[0][3], use_area[0][0]:use_area[0][2]])  # ok
IndexError: list index out of range
Sun, 08 Apr 2018 11:23:40 app_thread.py[line:127] ERROR 刷新失败
Sun, 08 Apr 2018 11:23:40 app_thread.py[line:128] ERROR this is an exception message
Traceback (most recent call last):
  File "E:\hupai\component\app_thread.py", line 125, in run
    findrefresh()
  File "E:\hupai\component\imgcut.py", line 383, in findrefresh
    img = cv2.cvtColor(sc, cv2.COLOR_BGR2GRAY)  # 转灰度图
cv2.error: C:\projects\opencv-python\opencv\modules\imgproc\src\color.cpp:11073: error: (-215) depth == 0 || depth == 2 || depth == 5 in function cv::cvtColor

Sun, 08 Apr 2018 11:23:40 imgcut.py[line:368] ERROR cut_img 这里出错
Sun, 08 Apr 2018 11:23:40 imgcut.py[line:369] ERROR this is an exception message
Traceback (most recent call last):
  File "E:\hupai\component\imgcut.py", line 361, in cut_img
    set_val('imgpos_lowestprice', img[use_area[0][1]:use_area[0][3], use_area[0][0]:use_area[0][2]])  # ok
IndexError: list index out of range
Sun, 08 Apr 2018 11:23:40 app_thread.py[line:127] ERROR 刷新失败
Sun, 08 Apr 2018 11:23:40 app_thread.py[line:128] ERROR this is an exception message
Traceback (most recent call last):
  File "E:\hupai\component\app_thread.py", line 125, in run
    findrefresh()
  File "E:\hupai\component\imgcut.py", line 383, in findrefresh
    img = cv2.cvtColor(sc, cv2.COLOR_BGR2GRAY)  # 转灰度图
cv2.error: C:\projects\opencv-python\opencv\modules\imgproc\src\color.cpp:11073: error: (-215) depth == 0 || depth == 2 || depth == 5 in function cv::cvtColor

Sun, 08 Apr 2018 11:23:40 imgcut.py[line:368] ERROR cut_img 这里出错
Sun, 08 Apr 2018 11:23:40 imgcut.py[line:369] ERROR this is an exception message
Traceback (most recent call last):
  File "E:\hupai\component\imgcut.py", line 361, in cut_img
    set_val('imgpos_lowestprice', img[use_area[0][1]:use_area[0][3], use_area[0][0]:use_area[0][2]])  # ok
IndexError: list index out of range
Sun, 08 Apr 2018 11:23:40 app_thread.py[line:127] ERROR 刷新失败
Sun, 08 Apr 2018 11:23:40 app_thread.py[line:128] ERROR this is an exception message
Traceback (most recent call last):
  File "E:\hupai\component\app_thread.py", line 125, in run
    findrefresh()
  File "E:\hupai\component\imgcut.py", line 383, in findrefresh
    img = cv2.cvtColor(sc, cv2.COLOR_BGR2GRAY)  # 转灰度图
cv2.error: C:\projects\opencv-python\opencv\modules\imgproc\src\color.cpp:11073: error: (-215) depth == 0 || depth == 2 || depth == 5 in function cv::cvtColor

Sun, 08 Apr 2018 11:23:40 imgcut.py[line:368] ERROR cut_img 这里出错
Sun, 08 Apr 2018 11:23:40 imgcut.py[line:369] ERROR this is an exception message
Traceback (most recent call last):
  File "E:\hupai\component\imgcut.py", line 361, in cut_img
    set_val('imgpos_lowestprice', img[use_area[0][1]:use_area[0][3], use_area[0][0]:use_area[0][2]])  # ok
IndexError: list index out of range
Sun, 08 Apr 2018 11:23:40 app_thread.py[line:127] ERROR 刷新失败
Sun, 08 Apr 2018 11:23:40 app_thread.py[line:128] ERROR this is an exception message
Traceback (most recent call last):
  File "E:\hupai\component\app_thread.py", line 125, in run
    findrefresh()
  File "E:\hupai\component\imgcut.py", line 383, in findrefresh
    img = cv2.cvtColor(sc, cv2.COLOR_BGR2GRAY)  # 转灰度图
cv2.error: C:\projects\opencv-python\opencv\modules\imgproc\src\color.cpp:11073: error: (-215) depth == 0 || depth == 2 || depth == 5 in function cv::cvtColor

Sun, 08 Apr 2018 11:23:40 imgcut.py[line:368] ERROR cut_img 这里出错
Sun, 08 Apr 2018 11:23:40 imgcut.py[line:369] ERROR this is an exception message
Traceback (most recent call last):
  File "E:\hupai\component\imgcut.py", line 361, in cut_img
    set_val('imgpos_lowestprice', img[use_area[0][1]:use_area[0][3], use_area[0][0]:use_area[0][2]])  # ok
IndexError: list index out of range
Sun, 08 Apr 2018 11:23:40 app_thread.py[line:127] ERROR 刷新失败
Sun, 08 Apr 2018 11:23:40 app_thread.py[line:128] ERROR this is an exception message
Traceback (most recent call last):
  File "E:\hupai\component\app_thread.py", line 125, in run
    findrefresh()
  File "E:\hupai\component\imgcut.py", line 383, in findrefresh
    img = cv2.cvtColor(sc, cv2.COLOR_BGR2GRAY)  # 转灰度图
cv2.error: C:\projects\opencv-python\opencv\modules\imgproc\src\color.cpp:11073: error: (-215) depth == 0 || depth == 2 || depth == 5 in function cv::cvtColor

Sun, 08 Apr 2018 11:23:40 imgcut.py[line:368] ERROR cut_img 这里出错
Sun, 08 Apr 2018 11:23:40 imgcut.py[line:369] ERROR this is an exception message
Traceback (most recent call last):
  File "E:\hupai\component\imgcut.py", line 361, in cut_img
    set_val('imgpos_lowestprice', img[use_area[0][1]:use_area[0][3], use_area[0][0]:use_area[0][2]])  # ok
IndexError: list index out of range
Sun, 08 Apr 2018 11:23:40 app_thread.py[line:127] ERROR 刷新失败
Sun, 08 Apr 2018 11:23:40 app_thread.py[line:128] ERROR this is an exception message
Traceback (most recent call last):
  File "E:\hupai\component\app_thread.py", line 125, in run
    findrefresh()
  File "E:\hupai\component\imgcut.py", line 383, in findrefresh
    img = cv2.cvtColor(sc, cv2.COLOR_BGR2GRAY)  # 转灰度图
cv2.error: C:\projects\opencv-python\opencv\modules\imgproc\src\color.cpp:11073: error: (-215) depth == 0 || depth == 2 || depth == 5 in function cv::cvtColor

Sun, 08 Apr 2018 11:23:40 imgcut.py[line:368] ERROR cut_img 这里出错
Sun, 08 Apr 2018 11:23:40 imgcut.py[line:369] ERROR this is an exception message
Traceback (most recent call last):
  File "E:\hupai\component\imgcut.py", line 361, in cut_img
    set_val('imgpos_lowestprice', img[use_area[0][1]:use_area[0][3], use_area[0][0]:use_area[0][2]])  # ok
IndexError: list index out of range
Sun, 08 Apr 2018 11:23:40 app_thread.py[line:127] ERROR 刷新失败
Sun, 08 Apr 2018 11:23:40 app_thread.py[line:128] ERROR this is an exception message
Traceback (most recent call last):
  File "E:\hupai\component\app_thread.py", line 125, in run
    findrefresh()
  File "E:\hupai\component\imgcut.py", line 383, in findrefresh
    img = cv2.cvtColor(sc, cv2.COLOR_BGR2GRAY)  # 转灰度图
cv2.error: C:\projects\opencv-python\opencv\modules\imgproc\src\color.cpp:11073: error: (-215) depth == 0 || depth == 2 || depth == 5 in function cv::cvtColor

Sun, 08 Apr 2018 11:23:40 imgcut.py[line:368] ERROR cut_img 这里出错
Sun, 08 Apr 2018 11:23:40 imgcut.py[line:369] ERROR this is an exception message
Traceback (most recent call last):
  File "E:\hupai\component\imgcut.py", line 361, in cut_img
    set_val('imgpos_lowestprice', img[use_area[0][1]:use_area[0][3], use_area[0][0]:use_area[0][2]])  # ok
IndexError: list index out of range
Sun, 08 Apr 2018 11:23:40 app_thread.py[line:127] ERROR 刷新失败
Sun, 08 Apr 2018 11:23:40 app_thread.py[line:128] ERROR this is an exception message
Traceback (most recent call last):
  File "E:\hupai\component\app_thread.py", line 125, in run
    findrefresh()
  File "E:\hupai\component\imgcut.py", line 383, in findrefresh
    img = cv2.cvtColor(sc, cv2.COLOR_BGR2GRAY)  # 转灰度图
cv2.error: C:\projects\opencv-python\opencv\modules\imgproc\src\color.cpp:11073: error: (-215) depth == 0 || depth == 2 || depth == 5 in function cv::cvtColor

Sun, 08 Apr 2018 11:23:40 app_thread.py[line:127] ERROR 刷新失败
Sun, 08 Apr 2018 11:23:40 app_thread.py[line:128] ERROR this is an exception message
Traceback (most recent call last):
  File "E:\hupai\component\app_thread.py", line 125, in run
    findrefresh()
  File "E:\hupai\component\imgcut.py", line 383, in findrefresh
    img = cv2.cvtColor(sc, cv2.COLOR_BGR2GRAY)  # 转灰度图
cv2.error: C:\projects\opencv-python\opencv\modules\imgproc\src\color.cpp:11073: error: (-215) depth == 0 || depth == 2 || depth == 5 in function cv::cvtColor

Sun, 08 Apr 2018 11:23:40 imgcut.py[line:368] ERROR cut_img 这里出错
Sun, 08 Apr 2018 11:23:40 imgcut.py[line:369] ERROR this is an exception message
Traceback (most recent call last):
  File "E:\hupai\component\imgcut.py", line 361, in cut_img
    set_val('imgpos_lowestprice', img[use_area[0][1]:use_area[0][3], use_area[0][0]:use_area[0][2]])  # ok
IndexError: list index out of range
Sun, 08 Apr 2018 11:23:40 app_thread.py[line:127] ERROR 刷新失败
Sun, 08 Apr 2018 11:23:40 app_thread.py[line:128] ERROR this is an exception message
Traceback (most recent call last):
  File "E:\hupai\component\app_thread.py", line 125, in run
    findrefresh()
  File "E:\hupai\component\imgcut.py", line 383, in findrefresh
    img = cv2.cvtColor(sc, cv2.COLOR_BGR2GRAY)  # 转灰度图
cv2.error: C:\projects\opencv-python\opencv\modules\imgproc\src\color.cpp:11073: error: (-215) depth == 0 || depth == 2 || depth == 5 in function cv::cvtColor

Sun, 08 Apr 2018 11:23:40 imgcut.py[line:368] ERROR cut_img 这里出错
Sun, 08 Apr 2018 11:23:40 imgcut.py[line:369] ERROR this is an exception message
Traceback (most recent call last):
  File "E:\hupai\component\imgcut.py", line 361, in cut_img
    set_val('imgpos_lowestprice', img[use_area[0][1]:use_area[0][3], use_area[0][0]:use_area[0][2]])  # ok
IndexError: list index out of range
Sun, 08 Apr 2018 11:23:40 app_thread.py[line:127] ERROR 刷新失败
Sun, 08 Apr 2018 11:23:40 app_thread.py[line:128] ERROR this is an exception message
Traceback (most recent call last):
  File "E:\hupai\component\app_thread.py", line 125, in run
    findrefresh()
  File "E:\hupai\component\imgcut.py", line 383, in findrefresh
    img = cv2.cvtColor(sc, cv2.COLOR_BGR2GRAY)  # 转灰度图
cv2.error: C:\projects\opencv-python\opencv\modules\imgproc\src\color.cpp:11073: error: (-215) depth == 0 || depth == 2 || depth == 5 in function cv::cvtColor

Sun, 08 Apr 2018 11:23:40 imgcut.py[line:368] ERROR cut_img 这里出错
Sun, 08 Apr 2018 11:23:40 imgcut.py[line:369] ERROR this is an exception message
Traceback (most recent call last):
  File "E:\hupai\component\imgcut.py", line 361, in cut_img
    set_val('imgpos_lowestprice', img[use_area[0][1]:use_area[0][3], use_area[0][0]:use_area[0][2]])  # ok
IndexError: list index out of range
Sun, 08 Apr 2018 11:23:40 app_thread.py[line:127] ERROR 刷新失败
Sun, 08 Apr 2018 11:23:40 app_thread.py[line:128] ERROR this is an exception message
Traceback (most recent call last):
  File "E:\hupai\component\app_thread.py", line 125, in run
    findrefresh()
  File "E:\hupai\component\imgcut.py", line 383, in findrefresh
    img = cv2.cvtColor(sc, cv2.COLOR_BGR2GRAY)  # 转灰度图
cv2.error: C:\projects\opencv-python\opencv\modules\imgproc\src\color.cpp:11073: error: (-215) depth == 0 || depth == 2 || depth == 5 in function cv::cvtColor

Sun, 08 Apr 2018 11:23:40 app_thread.py[line:127] ERROR 刷新失败
Sun, 08 Apr 2018 11:23:40 app_thread.py[line:128] ERROR this is an exception message
Traceback (most recent call last):
  File "E:\hupai\component\app_thread.py", line 125, in run
    findrefresh()
  File "E:\hupai\component\imgcut.py", line 383, in findrefresh
    img = cv2.cvtColor(sc, cv2.COLOR_BGR2GRAY)  # 转灰度图
cv2.error: C:\projects\opencv-python\opencv\modules\imgproc\src\color.cpp:11073: error: (-215) depth == 0 || depth == 2 || depth == 5 in function cv::cvtColor

Sun, 08 Apr 2018 11:23:40 imgcut.py[line:368] ERROR cut_img 这里出错
Sun, 08 Apr 2018 11:23:40 imgcut.py[line:369] ERROR this is an exception message
Traceback (most recent call last):
  File "E:\hupai\component\imgcut.py", line 361, in cut_img
    set_val('imgpos_lowestprice', img[use_area[0][1]:use_area[0][3], use_area[0][0]:use_area[0][2]])  # ok
IndexError: list index out of range
Sun, 08 Apr 2018 11:23:40 app_thread.py[line:127] ERROR 刷新失败
Sun, 08 Apr 2018 11:23:40 app_thread.py[line:128] ERROR this is an exception message
Traceback (most recent call last):
  File "E:\hupai\component\app_thread.py", line 125, in run
    findrefresh()
  File "E:\hupai\component\imgcut.py", line 383, in findrefresh
    img = cv2.cvtColor(sc, cv2.COLOR_BGR2GRAY)  # 转灰度图
cv2.error: C:\projects\opencv-python\opencv\modules\imgproc\src\color.cpp:11073: error: (-215) depth == 0 || depth == 2 || depth == 5 in function cv::cvtColor

Sun, 08 Apr 2018 11:23:40 app_thread.py[line:127] ERROR 刷新失败
Sun, 08 Apr 2018 11:23:40 app_thread.py[line:128] ERROR this is an exception message
Traceback (most recent call last):
  File "E:\hupai\component\app_thread.py", line 125, in run
    findrefresh()
  File "E:\hupai\component\imgcut.py", line 383, in findrefresh
    img = cv2.cvtColor(sc, cv2.COLOR_BGR2GRAY)  # 转灰度图
cv2.error: C:\projects\opencv-python\opencv\modules\imgproc\src\color.cpp:11073: error: (-215) depth == 0 || depth == 2 || depth == 5 in function cv::cvtColor

Sun, 08 Apr 2018 11:23:40 imgcut.py[line:368] ERROR cut_img 这里出错
Sun, 08 Apr 2018 11:23:40 imgcut.py[line:369] ERROR this is an exception message
Traceback (most recent call last):
  File "E:\hupai\component\imgcut.py", line 361, in cut_img
    set_val('imgpos_lowestprice', img[use_area[0][1]:use_area[0][3], use_area[0][0]:use_area[0][2]])  # ok
IndexError: list index out of range
Sun, 08 Apr 2018 11:23:40 app_thread.py[line:127] ERROR 刷新失败
Sun, 08 Apr 2018 11:23:40 app_thread.py[line:128] ERROR this is an exception message
Traceback (most recent call last):
  File "E:\hupai\component\app_thread.py", line 125, in run
    findrefresh()
  File "E:\hupai\component\imgcut.py", line 383, in findrefresh
    img = cv2.cvtColor(sc, cv2.COLOR_BGR2GRAY)  # 转灰度图
cv2.error: C:\projects\opencv-python\opencv\modules\imgproc\src\color.cpp:11073: error: (-215) depth == 0 || depth == 2 || depth == 5 in function cv::cvtColor

Sun, 08 Apr 2018 11:23:40 imgcut.py[line:368] ERROR cut_img 这里出错
Sun, 08 Apr 2018 11:23:40 imgcut.py[line:369] ERROR this is an exception message
Traceback (most recent call last):
  File "E:\hupai\component\imgcut.py", line 361, in cut_img
    set_val('imgpos_lowestprice', img[use_area[0][1]:use_area[0][3], use_area[0][0]:use_area[0][2]])  # ok
IndexError: list index out of range
Sun, 08 Apr 2018 11:23:41 app_thread.py[line:127] ERROR 刷新失败
Sun, 08 Apr 2018 11:23:41 app_thread.py[line:128] ERROR this is an exception message
Traceback (most recent call last):
  File "E:\hupai\component\app_thread.py", line 125, in run
    findrefresh()
  File "E:\hupai\component\imgcut.py", line 383, in findrefresh
    img = cv2.cvtColor(sc, cv2.COLOR_BGR2GRAY)  # 转灰度图
cv2.error: C:\projects\opencv-python\opencv\modules\imgproc\src\color.cpp:11073: error: (-215) depth == 0 || depth == 2 || depth == 5 in function cv::cvtColor

Sun, 08 Apr 2018 11:23:41 imgcut.py[line:368] ERROR cut_img 这里出错
Sun, 08 Apr 2018 11:23:41 imgcut.py[line:369] ERROR this is an exception message
Traceback (most recent call last):
  File "E:\hupai\component\imgcut.py", line 361, in cut_img
    set_val('imgpos_lowestprice', img[use_area[0][1]:use_area[0][3], use_area[0][0]:use_area[0][2]])  # ok
IndexError: list index out of range
Sun, 08 Apr 2018 11:23:41 app_thread.py[line:127] ERROR 刷新失败
Sun, 08 Apr 2018 11:23:41 app_thread.py[line:128] ERROR this is an exception message
Traceback (most recent call last):
  File "E:\hupai\component\app_thread.py", line 125, in run
    findrefresh()
  File "E:\hupai\component\imgcut.py", line 383, in findrefresh
    img = cv2.cvtColor(sc, cv2.COLOR_BGR2GRAY)  # 转灰度图
cv2.error: C:\projects\opencv-python\opencv\modules\imgproc\src\color.cpp:11073: error: (-215) depth == 0 || depth == 2 || depth == 5 in function cv::cvtColor

Sun, 08 Apr 2018 11:23:41 imgcut.py[line:368] ERROR cut_img 这里出错
Sun, 08 Apr 2018 11:23:41 imgcut.py[line:369] ERROR this is an exception message
Traceback (most recent call last):
  File "E:\hupai\component\imgcut.py", line 361, in cut_img
    set_val('imgpos_lowestprice', img[use_area[0][1]:use_area[0][3], use_area[0][0]:use_area[0][2]])  # ok
IndexError: list index out of range
Sun, 08 Apr 2018 11:23:41 app_thread.py[line:127] ERROR 刷新失败
Sun, 08 Apr 2018 11:23:41 app_thread.py[line:128] ERROR this is an exception message
Traceback (most recent call last):
  File "E:\hupai\component\app_thread.py", line 125, in run
    findrefresh()
  File "E:\hupai\component\imgcut.py", line 383, in findrefresh
    img = cv2.cvtColor(sc, cv2.COLOR_BGR2GRAY)  # 转灰度图
cv2.error: C:\projects\opencv-python\opencv\modules\imgproc\src\color.cpp:11073: error: (-215) depth == 0 || depth == 2 || depth == 5 in function cv::cvtColor

Sun, 08 Apr 2018 11:23:41 imgcut.py[line:368] ERROR cut_img 这里出错
Sun, 08 Apr 2018 11:23:41 imgcut.py[line:369] ERROR this is an exception message
Traceback (most recent call last):
  File "E:\hupai\component\imgcut.py", line 361, in cut_img
    set_val('imgpos_lowestprice', img[use_area[0][1]:use_area[0][3], use_area[0][0]:use_area[0][2]])  # ok
IndexError: list index out of range
Sun, 08 Apr 2018 11:23:41 app_thread.py[line:127] ERROR 刷新失败
Sun, 08 Apr 2018 11:23:41 app_thread.py[line:128] ERROR this is an exception message
Traceback (most recent call last):
  File "E:\hupai\component\app_thread.py", line 125, in run
    findrefresh()
  File "E:\hupai\component\imgcut.py", line 383, in findrefresh
    img = cv2.cvtColor(sc, cv2.COLOR_BGR2GRAY)  # 转灰度图
cv2.error: C:\projects\opencv-python\opencv\modules\imgproc\src\color.cpp:11073: error: (-215) depth == 0 || depth == 2 || depth == 5 in function cv::cvtColor

Sun, 08 Apr 2018 11:23:41 imgcut.py[line:368] ERROR cut_img 这里出错
Sun, 08 Apr 2018 11:23:41 imgcut.py[line:369] ERROR this is an exception message
Traceback (most recent call last):
  File "E:\hupai\component\imgcut.py", line 361, in cut_img
    set_val('imgpos_lowestprice', img[use_area[0][1]:use_area[0][3], use_area[0][0]:use_area[0][2]])  # ok
IndexError: list index out of range
Sun, 08 Apr 2018 11:23:41 app_thread.py[line:127] ERROR 刷新失败
Sun, 08 Apr 2018 11:23:41 app_thread.py[line:128] ERROR this is an exception message
Traceback (most recent call last):
  File "E:\hupai\component\app_thread.py", line 125, in run
    findrefresh()
  File "E:\hupai\component\imgcut.py", line 383, in findrefresh
    img = cv2.cvtColor(sc, cv2.COLOR_BGR2GRAY)  # 转灰度图
cv2.error: C:\projects\opencv-python\opencv\modules\imgproc\src\color.cpp:11073: error: (-215) depth == 0 || depth == 2 || depth == 5 in function cv::cvtColor

Sun, 08 Apr 2018 11:23:41 imgcut.py[line:368] ERROR cut_img 这里出错
Sun, 08 Apr 2018 11:23:41 imgcut.py[line:369] ERROR this is an exception message
Traceback (most recent call last):
  File "E:\hupai\component\imgcut.py", line 361, in cut_img
    set_val('imgpos_lowestprice', img[use_area[0][1]:use_area[0][3], use_area[0][0]:use_area[0][2]])  # ok
IndexError: list index out of range
Sun, 08 Apr 2018 11:23:41 app_thread.py[line:127] ERROR 刷新失败
Sun, 08 Apr 2018 11:23:41 app_thread.py[line:128] ERROR this is an exception message
Traceback (most recent call last):
  File "E:\hupai\component\app_thread.py", line 125, in run
    findrefresh()
  File "E:\hupai\component\imgcut.py", line 383, in findrefresh
    img = cv2.cvtColor(sc, cv2.COLOR_BGR2GRAY)  # 转灰度图
cv2.error: C:\projects\opencv-python\opencv\modules\imgproc\src\color.cpp:11073: error: (-215) depth == 0 || depth == 2 || depth == 5 in function cv::cvtColor

Sun, 08 Apr 2018 11:23:41 app_thread.py[line:127] ERROR 刷新失败
Sun, 08 Apr 2018 11:23:41 app_thread.py[line:128] ERROR this is an exception message
Traceback (most recent call last):
  File "E:\hupai\component\app_thread.py", line 125, in run
    findrefresh()
  File "E:\hupai\component\imgcut.py", line 383, in findrefresh
    img = cv2.cvtColor(sc, cv2.COLOR_BGR2GRAY)  # 转灰度图
cv2.error: C:\projects\opencv-python\opencv\modules\imgproc\src\color.cpp:11073: error: (-215) depth == 0 || depth == 2 || depth == 5 in function cv::cvtColor

Sun, 08 Apr 2018 11:23:41 imgcut.py[line:368] ERROR cut_img 这里出错
Sun, 08 Apr 2018 11:23:41 imgcut.py[line:369] ERROR this is an exception message
Traceback (most recent call last):
  File "E:\hupai\component\imgcut.py", line 361, in cut_img
    set_val('imgpos_lowestprice', img[use_area[0][1]:use_area[0][3], use_area[0][0]:use_area[0][2]])  # ok
IndexError: list index out of range
Sun, 08 Apr 2018 11:23:41 app_thread.py[line:127] ERROR 刷新失败
Sun, 08 Apr 2018 11:23:41 app_thread.py[line:128] ERROR this is an exception message
Traceback (most recent call last):
  File "E:\hupai\component\app_thread.py", line 125, in run
    findrefresh()
  File "E:\hupai\component\imgcut.py", line 383, in findrefresh
    img = cv2.cvtColor(sc, cv2.COLOR_BGR2GRAY)  # 转灰度图
cv2.error: C:\projects\opencv-python\opencv\modules\imgproc\src\color.cpp:11073: error: (-215) depth == 0 || depth == 2 || depth == 5 in function cv::cvtColor

Sun, 08 Apr 2018 11:23:41 imgcut.py[line:368] ERROR cut_img 这里出错
Sun, 08 Apr 2018 11:23:41 imgcut.py[line:369] ERROR this is an exception message
Traceback (most recent call last):
  File "E:\hupai\component\imgcut.py", line 361, in cut_img
    set_val('imgpos_lowestprice', img[use_area[0][1]:use_area[0][3], use_area[0][0]:use_area[0][2]])  # ok
IndexError: list index out of range
Sun, 08 Apr 2018 11:23:41 app_thread.py[line:127] ERROR 刷新失败
Sun, 08 Apr 2018 11:23:41 app_thread.py[line:128] ERROR this is an exception message
Traceback (most recent call last):
  File "E:\hupai\component\app_thread.py", line 125, in run
    findrefresh()
  File "E:\hupai\component\imgcut.py", line 383, in findrefresh
    img = cv2.cvtColor(sc, cv2.COLOR_BGR2GRAY)  # 转灰度图
cv2.error: C:\projects\opencv-python\opencv\modules\imgproc\src\color.cpp:11073: error: (-215) depth == 0 || depth == 2 || depth == 5 in function cv::cvtColor

Sun, 08 Apr 2018 11:23:41 imgcut.py[line:368] ERROR cut_img 这里出错
Sun, 08 Apr 2018 11:23:41 imgcut.py[line:369] ERROR this is an exception message
Traceback (most recent call last):
  File "E:\hupai\component\imgcut.py", line 361, in cut_img
    set_val('imgpos_lowestprice', img[use_area[0][1]:use_area[0][3], use_area[0][0]:use_area[0][2]])  # ok
IndexError: list index out of range
Sun, 08 Apr 2018 11:23:41 app_thread.py[line:127] ERROR 刷新失败
Sun, 08 Apr 2018 11:23:41 app_thread.py[line:128] ERROR this is an exception message
Traceback (most recent call last):
  File "E:\hupai\component\app_thread.py", line 125, in run
    findrefresh()
  File "E:\hupai\component\imgcut.py", line 383, in findrefresh
    img = cv2.cvtColor(sc, cv2.COLOR_BGR2GRAY)  # 转灰度图
cv2.error: C:\projects\opencv-python\opencv\modules\imgproc\src\color.cpp:11073: error: (-215) depth == 0 || depth == 2 || depth == 5 in function cv::cvtColor

Sun, 08 Apr 2018 11:23:41 imgcut.py[line:368] ERROR cut_img 这里出错
Sun, 08 Apr 2018 11:23:41 app_thread.py[line:127] ERROR 刷新失败
Sun, 08 Apr 2018 11:23:41 imgcut.py[line:369] ERROR this is an exception message
Traceback (most recent call last):
  File "E:\hupai\component\imgcut.py", line 361, in cut_img
    set_val('imgpos_lowestprice', img[use_area[0][1]:use_area[0][3], use_area[0][0]:use_area[0][2]])  # ok
IndexError: list index out of range
Sun, 08 Apr 2018 11:23:41 app_thread.py[line:128] ERROR this is an exception message
Traceback (most recent call last):
  File "E:\hupai\component\app_thread.py", line 125, in run
    findrefresh()
  File "E:\hupai\component\imgcut.py", line 383, in findrefresh
    img = cv2.cvtColor(sc, cv2.COLOR_BGR2GRAY)  # 转灰度图
cv2.error: C:\projects\opencv-python\opencv\modules\imgproc\src\color.cpp:11073: error: (-215) depth == 0 || depth == 2 || depth == 5 in function cv::cvtColor

Sun, 08 Apr 2018 11:23:41 app_thread.py[line:127] ERROR 刷新失败
Sun, 08 Apr 2018 11:23:41 app_thread.py[line:128] ERROR this is an exception message
Traceback (most recent call last):
  File "E:\hupai\component\app_thread.py", line 125, in run
    findrefresh()
  File "E:\hupai\component\imgcut.py", line 383, in findrefresh
    img = cv2.cvtColor(sc, cv2.COLOR_BGR2GRAY)  # 转灰度图
cv2.error: C:\projects\opencv-python\opencv\modules\imgproc\src\color.cpp:11073: error: (-215) depth == 0 || depth == 2 || depth == 5 in function cv::cvtColor

Sun, 08 Apr 2018 11:23:41 imgcut.py[line:368] ERROR cut_img 这里出错
Sun, 08 Apr 2018 11:23:41 imgcut.py[line:369] ERROR this is an exception message
Traceback (most recent call last):
  File "E:\hupai\component\imgcut.py", line 361, in cut_img
    set_val('imgpos_lowestprice', img[use_area[0][1]:use_area[0][3], use_area[0][0]:use_area[0][2]])  # ok
IndexError: list index out of range
Sun, 08 Apr 2018 11:23:41 app_thread.py[line:127] ERROR 刷新失败
Sun, 08 Apr 2018 11:23:41 app_thread.py[line:128] ERROR this is an exception message
Traceback (most recent call last):
  File "E:\hupai\component\app_thread.py", line 125, in run
    findrefresh()
  File "E:\hupai\component\imgcut.py", line 383, in findrefresh
    img = cv2.cvtColor(sc, cv2.COLOR_BGR2GRAY)  # 转灰度图
cv2.error: C:\projects\opencv-python\opencv\modules\imgproc\src\color.cpp:11073: error: (-215) depth == 0 || depth == 2 || depth == 5 in function cv::cvtColor

Sun, 08 Apr 2018 11:23:41 imgcut.py[line:368] ERROR cut_img 这里出错
Sun, 08 Apr 2018 11:23:41 imgcut.py[line:369] ERROR this is an exception message
Traceback (most recent call last):
  File "E:\hupai\component\imgcut.py", line 361, in cut_img
    set_val('imgpos_lowestprice', img[use_area[0][1]:use_area[0][3], use_area[0][0]:use_area[0][2]])  # ok
IndexError: list index out of range
Sun, 08 Apr 2018 11:23:41 app_thread.py[line:127] ERROR 刷新失败
Sun, 08 Apr 2018 11:23:41 app_thread.py[line:128] ERROR this is an exception message
Traceback (most recent call last):
  File "E:\hupai\component\app_thread.py", line 125, in run
    findrefresh()
  File "E:\hupai\component\imgcut.py", line 383, in findrefresh
    img = cv2.cvtColor(sc, cv2.COLOR_BGR2GRAY)  # 转灰度图
cv2.error: C:\projects\opencv-python\opencv\modules\imgproc\src\color.cpp:11073: error: (-215) depth == 0 || depth == 2 || depth == 5 in function cv::cvtColor

Sun, 08 Apr 2018 11:23:41 imgcut.py[line:368] ERROR cut_img 这里出错
Sun, 08 Apr 2018 11:23:41 imgcut.py[line:369] ERROR this is an exception message
Traceback (most recent call last):
  File "E:\hupai\component\imgcut.py", line 361, in cut_img
    set_val('imgpos_lowestprice', img[use_area[0][1]:use_area[0][3], use_area[0][0]:use_area[0][2]])  # ok
IndexError: list index out of range
Sun, 08 Apr 2018 11:23:41 app_thread.py[line:127] ERROR 刷新失败
Sun, 08 Apr 2018 11:23:41 app_thread.py[line:128] ERROR this is an exception message
Traceback (most recent call last):
  File "E:\hupai\component\app_thread.py", line 125, in run
    findrefresh()
  File "E:\hupai\component\imgcut.py", line 383, in findrefresh
    img = cv2.cvtColor(sc, cv2.COLOR_BGR2GRAY)  # 转灰度图
cv2.error: C:\projects\opencv-python\opencv\modules\imgproc\src\color.cpp:11073: error: (-215) depth == 0 || depth == 2 || depth == 5 in function cv::cvtColor

Sun, 08 Apr 2018 11:23:41 imgcut.py[line:368] ERROR cut_img 这里出错
Sun, 08 Apr 2018 11:23:41 imgcut.py[line:369] ERROR this is an exception message
Traceback (most recent call last):
  File "E:\hupai\component\imgcut.py", line 361, in cut_img
    set_val('imgpos_lowestprice', img[use_area[0][1]:use_area[0][3], use_area[0][0]:use_area[0][2]])  # ok
IndexError: list index out of range
Sun, 08 Apr 2018 11:23:41 app_thread.py[line:127] ERROR 刷新失败
Sun, 08 Apr 2018 11:23:41 app_thread.py[line:128] ERROR this is an exception message
Traceback (most recent call last):
  File "E:\hupai\component\app_thread.py", line 125, in run
    findrefresh()
  File "E:\hupai\component\imgcut.py", line 383, in findrefresh
    img = cv2.cvtColor(sc, cv2.COLOR_BGR2GRAY)  # 转灰度图
cv2.error: C:\projects\opencv-python\opencv\modules\imgproc\src\color.cpp:11073: error: (-215) depth == 0 || depth == 2 || depth == 5 in function cv::cvtColor

Sun, 08 Apr 2018 11:23:42 app_thread.py[line:127] ERROR 刷新失败
Sun, 08 Apr 2018 11:23:42 app_thread.py[line:128] ERROR this is an exception message
Traceback (most recent call last):
  File "E:\hupai\component\app_thread.py", line 125, in run
    findrefresh()
  File "E:\hupai\component\imgcut.py", line 383, in findrefresh
    img = cv2.cvtColor(sc, cv2.COLOR_BGR2GRAY)  # 转灰度图
cv2.error: C:\projects\opencv-python\opencv\modules\imgproc\src\color.cpp:11073: error: (-215) depth == 0 || depth == 2 || depth == 5 in function cv::cvtColor

Sun, 08 Apr 2018 11:23:42 imgcut.py[line:368] ERROR cut_img 这里出错
Sun, 08 Apr 2018 11:23:42 imgcut.py[line:369] ERROR this is an exception message
Traceback (most recent call last):
  File "E:\hupai\component\imgcut.py", line 361, in cut_img
    set_val('imgpos_lowestprice', img[use_area[0][1]:use_area[0][3], use_area[0][0]:use_area[0][2]])  # ok
IndexError: list index out of range
Sun, 08 Apr 2018 11:23:42 app_thread.py[line:127] ERROR 刷新失败
Sun, 08 Apr 2018 11:23:42 app_thread.py[line:128] ERROR this is an exception message
Traceback (most recent call last):
  File "E:\hupai\component\app_thread.py", line 125, in run
    findrefresh()
  File "E:\hupai\component\imgcut.py", line 383, in findrefresh
    img = cv2.cvtColor(sc, cv2.COLOR_BGR2GRAY)  # 转灰度图
cv2.error: C:\projects\opencv-python\opencv\modules\imgproc\src\color.cpp:11073: error: (-215) depth == 0 || depth == 2 || depth == 5 in function cv::cvtColor

Sun, 08 Apr 2018 11:23:42 imgcut.py[line:368] ERROR cut_img 这里出错
Sun, 08 Apr 2018 11:23:42 imgcut.py[line:369] ERROR this is an exception message
Traceback (most recent call last):
  File "E:\hupai\component\imgcut.py", line 361, in cut_img
    set_val('imgpos_lowestprice', img[use_area[0][1]:use_area[0][3], use_area[0][0]:use_area[0][2]])  # ok
IndexError: list index out of range
Sun, 08 Apr 2018 11:23:42 app_thread.py[line:127] ERROR 刷新失败
Sun, 08 Apr 2018 11:23:42 app_thread.py[line:128] ERROR this is an exception message
Traceback (most recent call last):
  File "E:\hupai\component\app_thread.py", line 125, in run
    findrefresh()
  File "E:\hupai\component\imgcut.py", line 383, in findrefresh
    img = cv2.cvtColor(sc, cv2.COLOR_BGR2GRAY)  # 转灰度图
cv2.error: C:\projects\opencv-python\opencv\modules\imgproc\src\color.cpp:11073: error: (-215) depth == 0 || depth == 2 || depth == 5 in function cv::cvtColor

Sun, 08 Apr 2018 11:23:42 imgcut.py[line:368] ERROR cut_img 这里出错
Sun, 08 Apr 2018 11:23:42 imgcut.py[line:369] ERROR this is an exception message
Traceback (most recent call last):
  File "E:\hupai\component\imgcut.py", line 361, in cut_img
    set_val('imgpos_lowestprice', img[use_area[0][1]:use_area[0][3], use_area[0][0]:use_area[0][2]])  # ok
IndexError: list index out of range
Sun, 08 Apr 2018 11:23:42 app_thread.py[line:127] ERROR 刷新失败
Sun, 08 Apr 2018 11:23:42 app_thread.py[line:128] ERROR this is an exception message
Traceback (most recent call last):
  File "E:\hupai\component\app_thread.py", line 125, in run
    findrefresh()
  File "E:\hupai\component\imgcut.py", line 383, in findrefresh
    img = cv2.cvtColor(sc, cv2.COLOR_BGR2GRAY)  # 转灰度图
cv2.error: C:\projects\opencv-python\opencv\modules\imgproc\src\color.cpp:11073: error: (-215) depth == 0 || depth == 2 || depth == 5 in function cv::cvtColor

Sun, 08 Apr 2018 11:23:42 imgcut.py[line:368] ERROR cut_img 这里出错
Sun, 08 Apr 2018 11:23:42 imgcut.py[line:369] ERROR this is an exception message
Traceback (most recent call last):
  File "E:\hupai\component\imgcut.py", line 361, in cut_img
    set_val('imgpos_lowestprice', img[use_area[0][1]:use_area[0][3], use_area[0][0]:use_area[0][2]])  # ok
IndexError: list index out of range
Sun, 08 Apr 2018 11:23:42 app_thread.py[line:127] ERROR 刷新失败
Sun, 08 Apr 2018 11:23:42 app_thread.py[line:128] ERROR this is an exception message
Traceback (most recent call last):
  File "E:\hupai\component\app_thread.py", line 125, in run
    findrefresh()
  File "E:\hupai\component\imgcut.py", line 383, in findrefresh
    img = cv2.cvtColor(sc, cv2.COLOR_BGR2GRAY)  # 转灰度图
cv2.error: C:\projects\opencv-python\opencv\modules\imgproc\src\color.cpp:11073: error: (-215) depth == 0 || depth == 2 || depth == 5 in function cv::cvtColor

Sun, 08 Apr 2018 11:23:42 imgcut.py[line:368] ERROR cut_img 这里出错
Sun, 08 Apr 2018 11:23:42 imgcut.py[line:369] ERROR this is an exception message
Traceback (most recent call last):
  File "E:\hupai\component\imgcut.py", line 361, in cut_img
    set_val('imgpos_lowestprice', img[use_area[0][1]:use_area[0][3], use_area[0][0]:use_area[0][2]])  # ok
IndexError: list index out of range
Sun, 08 Apr 2018 11:23:42 app_thread.py[line:127] ERROR 刷新失败
Sun, 08 Apr 2018 11:23:42 app_thread.py[line:128] ERROR this is an exception message
Traceback (most recent call last):
  File "E:\hupai\component\app_thread.py", line 125, in run
    findrefresh()
  File "E:\hupai\component\imgcut.py", line 383, in findrefresh
    img = cv2.cvtColor(sc, cv2.COLOR_BGR2GRAY)  # 转灰度图
cv2.error: C:\projects\opencv-python\opencv\modules\imgproc\src\color.cpp:11073: error: (-215) depth == 0 || depth == 2 || depth == 5 in function cv::cvtColor

Sun, 08 Apr 2018 11:23:42 imgcut.py[line:368] ERROR cut_img 这里出错
Sun, 08 Apr 2018 11:23:42 imgcut.py[line:369] ERROR this is an exception message
Traceback (most recent call last):
  File "E:\hupai\component\imgcut.py", line 361, in cut_img
    set_val('imgpos_lowestprice', img[use_area[0][1]:use_area[0][3], use_area[0][0]:use_area[0][2]])  # ok
IndexError: list index out of range
Sun, 08 Apr 2018 11:23:42 app_thread.py[line:127] ERROR 刷新失败
Sun, 08 Apr 2018 11:23:42 app_thread.py[line:128] ERROR this is an exception message
Traceback (most recent call last):
  File "E:\hupai\component\app_thread.py", line 125, in run
    findrefresh()
  File "E:\hupai\component\imgcut.py", line 383, in findrefresh
    img = cv2.cvtColor(sc, cv2.COLOR_BGR2GRAY)  # 转灰度图
cv2.error: C:\projects\opencv-python\opencv\modules\imgproc\src\color.cpp:11073: error: (-215) depth == 0 || depth == 2 || depth == 5 in function cv::cvtColor

Sun, 08 Apr 2018 11:23:42 imgcut.py[line:368] ERROR cut_img 这里出错
Sun, 08 Apr 2018 11:23:42 imgcut.py[line:369] ERROR this is an exception message
Traceback (most recent call last):
  File "E:\hupai\component\imgcut.py", line 361, in cut_img
    set_val('imgpos_lowestprice', img[use_area[0][1]:use_area[0][3], use_area[0][0]:use_area[0][2]])  # ok
IndexError: list index out of range
Sun, 08 Apr 2018 11:23:42 app_thread.py[line:127] ERROR 刷新失败
Sun, 08 Apr 2018 11:23:42 app_thread.py[line:128] ERROR this is an exception message
Traceback (most recent call last):
  File "E:\hupai\component\app_thread.py", line 125, in run
    findrefresh()
  File "E:\hupai\component\imgcut.py", line 383, in findrefresh
    img = cv2.cvtColor(sc, cv2.COLOR_BGR2GRAY)  # 转灰度图
cv2.error: C:\projects\opencv-python\opencv\modules\imgproc\src\color.cpp:11073: error: (-215) depth == 0 || depth == 2 || depth == 5 in function cv::cvtColor

Sun, 08 Apr 2018 11:23:42 imgcut.py[line:368] ERROR cut_img 这里出错
Sun, 08 Apr 2018 11:23:42 imgcut.py[line:369] ERROR this is an exception message
Traceback (most recent call last):
  File "E:\hupai\component\imgcut.py", line 361, in cut_img
    set_val('imgpos_lowestprice', img[use_area[0][1]:use_area[0][3], use_area[0][0]:use_area[0][2]])  # ok
IndexError: list index out of range
Sun, 08 Apr 2018 11:23:42 app_thread.py[line:127] ERROR 刷新失败
Sun, 08 Apr 2018 11:23:42 app_thread.py[line:128] ERROR this is an exception message
Traceback (most recent call last):
  File "E:\hupai\component\app_thread.py", line 125, in run
    findrefresh()
  File "E:\hupai\component\imgcut.py", line 383, in findrefresh
    img = cv2.cvtColor(sc, cv2.COLOR_BGR2GRAY)  # 转灰度图
cv2.error: C:\projects\opencv-python\opencv\modules\imgproc\src\color.cpp:11073: error: (-215) depth == 0 || depth == 2 || depth == 5 in function cv::cvtColor

Sun, 08 Apr 2018 11:23:42 imgcut.py[line:368] ERROR cut_img 这里出错
Sun, 08 Apr 2018 11:23:42 imgcut.py[line:369] ERROR this is an exception message
Traceback (most recent call last):
  File "E:\hupai\component\imgcut.py", line 361, in cut_img
    set_val('imgpos_lowestprice', img[use_area[0][1]:use_area[0][3], use_area[0][0]:use_area[0][2]])  # ok
IndexError: list index out of range
Sun, 08 Apr 2018 11:23:42 app_thread.py[line:127] ERROR 刷新失败
Sun, 08 Apr 2018 11:23:42 app_thread.py[line:128] ERROR this is an exception message
Traceback (most recent call last):
  File "E:\hupai\component\app_thread.py", line 125, in run
    findrefresh()
  File "E:\hupai\component\imgcut.py", line 383, in findrefresh
    img = cv2.cvtColor(sc, cv2.COLOR_BGR2GRAY)  # 转灰度图
cv2.error: C:\projects\opencv-python\opencv\modules\imgproc\src\color.cpp:11073: error: (-215) depth == 0 || depth == 2 || depth == 5 in function cv::cvtColor

Sun, 08 Apr 2018 11:23:42 imgcut.py[line:368] ERROR cut_img 这里出错
Sun, 08 Apr 2018 11:23:42 imgcut.py[line:369] ERROR this is an exception message
Traceback (most recent call last):
  File "E:\hupai\component\imgcut.py", line 361, in cut_img
    set_val('imgpos_lowestprice', img[use_area[0][1]:use_area[0][3], use_area[0][0]:use_area[0][2]])  # ok
IndexError: list index out of range
Sun, 08 Apr 2018 11:23:42 app_thread.py[line:127] ERROR 刷新失败
Sun, 08 Apr 2018 11:23:42 app_thread.py[line:128] ERROR this is an exception message
Traceback (most recent call last):
  File "E:\hupai\component\app_thread.py", line 125, in run
    findrefresh()
  File "E:\hupai\component\imgcut.py", line 383, in findrefresh
    img = cv2.cvtColor(sc, cv2.COLOR_BGR2GRAY)  # 转灰度图
cv2.error: C:\projects\opencv-python\opencv\modules\imgproc\src\color.cpp:11073: error: (-215) depth == 0 || depth == 2 || depth == 5 in function cv::cvtColor

Sun, 08 Apr 2018 11:23:42 imgcut.py[line:368] ERROR cut_img 这里出错
Sun, 08 Apr 2018 11:23:42 imgcut.py[line:369] ERROR this is an exception message
Traceback (most recent call last):
  File "E:\hupai\component\imgcut.py", line 361, in cut_img
    set_val('imgpos_lowestprice', img[use_area[0][1]:use_area[0][3], use_area[0][0]:use_area[0][2]])  # ok
IndexError: list index out of range
Sun, 08 Apr 2018 11:23:42 app_thread.py[line:127] ERROR 刷新失败
Sun, 08 Apr 2018 11:23:42 app_thread.py[line:128] ERROR this is an exception message
Traceback (most recent call last):
  File "E:\hupai\component\app_thread.py", line 125, in run
    findrefresh()
  File "E:\hupai\component\imgcut.py", line 383, in findrefresh
    img = cv2.cvtColor(sc, cv2.COLOR_BGR2GRAY)  # 转灰度图
cv2.error: C:\projects\opencv-python\opencv\modules\imgproc\src\color.cpp:11073: error: (-215) depth == 0 || depth == 2 || depth == 5 in function cv::cvtColor

Sun, 08 Apr 2018 11:23:42 imgcut.py[line:368] ERROR cut_img 这里出错
Sun, 08 Apr 2018 11:23:42 imgcut.py[line:369] ERROR this is an exception message
Traceback (most recent call last):
  File "E:\hupai\component\imgcut.py", line 361, in cut_img
    set_val('imgpos_lowestprice', img[use_area[0][1]:use_area[0][3], use_area[0][0]:use_area[0][2]])  # ok
IndexError: list index out of range
Sun, 08 Apr 2018 11:23:42 app_thread.py[line:127] ERROR 刷新失败
Sun, 08 Apr 2018 11:23:42 app_thread.py[line:128] ERROR this is an exception message
Traceback (most recent call last):
  File "E:\hupai\component\app_thread.py", line 125, in run
    findrefresh()
  File "E:\hupai\component\imgcut.py", line 383, in findrefresh
    img = cv2.cvtColor(sc, cv2.COLOR_BGR2GRAY)  # 转灰度图
cv2.error: C:\projects\opencv-python\opencv\modules\imgproc\src\color.cpp:11073: error: (-215) depth == 0 || depth == 2 || depth == 5 in function cv::cvtColor

Sun, 08 Apr 2018 11:23:42 imgcut.py[line:368] ERROR cut_img 这里出错
Sun, 08 Apr 2018 11:23:42 imgcut.py[line:369] ERROR this is an exception message
Traceback (most recent call last):
  File "E:\hupai\component\imgcut.py", line 361, in cut_img
    set_val('imgpos_lowestprice', img[use_area[0][1]:use_area[0][3], use_area[0][0]:use_area[0][2]])  # ok
IndexError: list index out of range
Sun, 08 Apr 2018 11:23:42 app_thread.py[line:127] ERROR 刷新失败
Sun, 08 Apr 2018 11:23:42 app_thread.py[line:128] ERROR this is an exception message
Traceback (most recent call last):
  File "E:\hupai\component\app_thread.py", line 125, in run
    findrefresh()
  File "E:\hupai\component\imgcut.py", line 383, in findrefresh
    img = cv2.cvtColor(sc, cv2.COLOR_BGR2GRAY)  # 转灰度图
cv2.error: C:\projects\opencv-python\opencv\modules\imgproc\src\color.cpp:11073: error: (-215) depth == 0 || depth == 2 || depth == 5 in function cv::cvtColor

Sun, 08 Apr 2018 11:23:42 app_thread.py[line:127] ERROR 刷新失败
Sun, 08 Apr 2018 11:23:42 app_thread.py[line:128] ERROR this is an exception message
Traceback (most recent call last):
  File "E:\hupai\component\app_thread.py", line 125, in run
    findrefresh()
  File "E:\hupai\component\imgcut.py", line 383, in findrefresh
    img = cv2.cvtColor(sc, cv2.COLOR_BGR2GRAY)  # 转灰度图
cv2.error: C:\projects\opencv-python\opencv\modules\imgproc\src\color.cpp:11073: error: (-215) depth == 0 || depth == 2 || depth == 5 in function cv::cvtColor

Sun, 08 Apr 2018 11:23:42 imgcut.py[line:368] ERROR cut_img 这里出错
Sun, 08 Apr 2018 11:23:42 imgcut.py[line:369] ERROR this is an exception message
Traceback (most recent call last):
  File "E:\hupai\component\imgcut.py", line 361, in cut_img
    set_val('imgpos_lowestprice', img[use_area[0][1]:use_area[0][3], use_area[0][0]:use_area[0][2]])  # ok
IndexError: list index out of range
Sun, 08 Apr 2018 11:23:42 app_thread.py[line:127] ERROR 刷新失败
Sun, 08 Apr 2018 11:23:42 app_thread.py[line:128] ERROR this is an exception message
Traceback (most recent call last):
  File "E:\hupai\component\app_thread.py", line 125, in run
    findrefresh()
  File "E:\hupai\component\imgcut.py", line 383, in findrefresh
    img = cv2.cvtColor(sc, cv2.COLOR_BGR2GRAY)  # 转灰度图
cv2.error: C:\projects\opencv-python\opencv\modules\imgproc\src\color.cpp:11073: error: (-215) depth == 0 || depth == 2 || depth == 5 in function cv::cvtColor

Sun, 08 Apr 2018 11:23:43 imgcut.py[line:368] ERROR cut_img 这里出错
Sun, 08 Apr 2018 11:23:43 imgcut.py[line:369] ERROR this is an exception message
Traceback (most recent call last):
  File "E:\hupai\component\imgcut.py", line 361, in cut_img
    set_val('imgpos_lowestprice', img[use_area[0][1]:use_area[0][3], use_area[0][0]:use_area[0][2]])  # ok
IndexError: list index out of range
Sun, 08 Apr 2018 11:23:43 app_thread.py[line:127] ERROR 刷新失败
Sun, 08 Apr 2018 11:23:43 app_thread.py[line:128] ERROR this is an exception message
Traceback (most recent call last):
  File "E:\hupai\component\app_thread.py", line 125, in run
    findrefresh()
  File "E:\hupai\component\imgcut.py", line 383, in findrefresh
    img = cv2.cvtColor(sc, cv2.COLOR_BGR2GRAY)  # 转灰度图
cv2.error: C:\projects\opencv-python\opencv\modules\imgproc\src\color.cpp:11073: error: (-215) depth == 0 || depth == 2 || depth == 5 in function cv::cvtColor

Sun, 08 Apr 2018 11:23:43 imgcut.py[line:368] ERROR cut_img 这里出错
Sun, 08 Apr 2018 11:23:43 imgcut.py[line:369] ERROR this is an exception message
Traceback (most recent call last):
  File "E:\hupai\component\imgcut.py", line 361, in cut_img
    set_val('imgpos_lowestprice', img[use_area[0][1]:use_area[0][3], use_area[0][0]:use_area[0][2]])  # ok
IndexError: list index out of range
Sun, 08 Apr 2018 11:23:43 app_thread.py[line:127] ERROR 刷新失败
Sun, 08 Apr 2018 11:23:43 app_thread.py[line:128] ERROR this is an exception message
Traceback (most recent call last):
  File "E:\hupai\component\app_thread.py", line 125, in run
    findrefresh()
  File "E:\hupai\component\imgcut.py", line 383, in findrefresh
    img = cv2.cvtColor(sc, cv2.COLOR_BGR2GRAY)  # 转灰度图
cv2.error: C:\projects\opencv-python\opencv\modules\imgproc\src\color.cpp:11073: error: (-215) depth == 0 || depth == 2 || depth == 5 in function cv::cvtColor

Sun, 08 Apr 2018 11:23:43 imgcut.py[line:368] ERROR cut_img 这里出错
Sun, 08 Apr 2018 11:23:43 imgcut.py[line:369] ERROR this is an exception message
Traceback (most recent call last):
  File "E:\hupai\component\imgcut.py", line 361, in cut_img
    set_val('imgpos_lowestprice', img[use_area[0][1]:use_area[0][3], use_area[0][0]:use_area[0][2]])  # ok
IndexError: list index out of range
Sun, 08 Apr 2018 11:23:43 app_thread.py[line:127] ERROR 刷新失败
Sun, 08 Apr 2018 11:23:43 app_thread.py[line:128] ERROR this is an exception message
Traceback (most recent call last):
  File "E:\hupai\component\app_thread.py", line 125, in run
    findrefresh()
  File "E:\hupai\component\imgcut.py", line 383, in findrefresh
    img = cv2.cvtColor(sc, cv2.COLOR_BGR2GRAY)  # 转灰度图
cv2.error: C:\projects\opencv-python\opencv\modules\imgproc\src\color.cpp:11073: error: (-215) depth == 0 || depth == 2 || depth == 5 in function cv::cvtColor

Sun, 08 Apr 2018 11:23:43 imgcut.py[line:368] ERROR cut_img 这里出错
Sun, 08 Apr 2018 11:23:43 imgcut.py[line:369] ERROR this is an exception message
Traceback (most recent call last):
  File "E:\hupai\component\imgcut.py", line 361, in cut_img
    set_val('imgpos_lowestprice', img[use_area[0][1]:use_area[0][3], use_area[0][0]:use_area[0][2]])  # ok
IndexError: list index out of range
Sun, 08 Apr 2018 11:23:43 app_thread.py[line:127] ERROR 刷新失败
Sun, 08 Apr 2018 11:23:43 app_thread.py[line:128] ERROR this is an exception message
Traceback (most recent call last):
  File "E:\hupai\component\app_thread.py", line 125, in run
    findrefresh()
  File "E:\hupai\component\imgcut.py", line 383, in findrefresh
    img = cv2.cvtColor(sc, cv2.COLOR_BGR2GRAY)  # 转灰度图
cv2.error: C:\projects\opencv-python\opencv\modules\imgproc\src\color.cpp:11073: error: (-215) depth == 0 || depth == 2 || depth == 5 in function cv::cvtColor

Sun, 08 Apr 2018 11:23:43 imgcut.py[line:368] ERROR cut_img 这里出错
Sun, 08 Apr 2018 11:23:43 imgcut.py[line:369] ERROR this is an exception message
Traceback (most recent call last):
  File "E:\hupai\component\imgcut.py", line 361, in cut_img
    set_val('imgpos_lowestprice', img[use_area[0][1]:use_area[0][3], use_area[0][0]:use_area[0][2]])  # ok
IndexError: list index out of range
Sun, 08 Apr 2018 11:23:43 app_thread.py[line:127] ERROR 刷新失败
Sun, 08 Apr 2018 11:23:43 app_thread.py[line:128] ERROR this is an exception message
Traceback (most recent call last):
  File "E:\hupai\component\app_thread.py", line 125, in run
    findrefresh()
  File "E:\hupai\component\imgcut.py", line 383, in findrefresh
    img = cv2.cvtColor(sc, cv2.COLOR_BGR2GRAY)  # 转灰度图
cv2.error: C:\projects\opencv-python\opencv\modules\imgproc\src\color.cpp:11073: error: (-215) depth == 0 || depth == 2 || depth == 5 in function cv::cvtColor

Sun, 08 Apr 2018 11:23:43 imgcut.py[line:368] ERROR cut_img 这里出错
Sun, 08 Apr 2018 11:23:43 imgcut.py[line:369] ERROR this is an exception message
Traceback (most recent call last):
  File "E:\hupai\component\imgcut.py", line 361, in cut_img
    set_val('imgpos_lowestprice', img[use_area[0][1]:use_area[0][3], use_area[0][0]:use_area[0][2]])  # ok
IndexError: list index out of range
Sun, 08 Apr 2018 11:23:43 app_thread.py[line:127] ERROR 刷新失败
Sun, 08 Apr 2018 11:23:43 app_thread.py[line:128] ERROR this is an exception message
Traceback (most recent call last):
  File "E:\hupai\component\app_thread.py", line 125, in run
    findrefresh()
  File "E:\hupai\component\imgcut.py", line 383, in findrefresh
    img = cv2.cvtColor(sc, cv2.COLOR_BGR2GRAY)  # 转灰度图
cv2.error: C:\projects\opencv-python\opencv\modules\imgproc\src\color.cpp:11073: error: (-215) depth == 0 || depth == 2 || depth == 5 in function cv::cvtColor

Sun, 08 Apr 2018 11:23:43 app_thread.py[line:127] ERROR 刷新失败
Sun, 08 Apr 2018 11:23:43 app_thread.py[line:128] ERROR this is an exception message
Traceback (most recent call last):
  File "E:\hupai\component\app_thread.py", line 125, in run
    findrefresh()
  File "E:\hupai\component\imgcut.py", line 383, in findrefresh
    img = cv2.cvtColor(sc, cv2.COLOR_BGR2GRAY)  # 转灰度图
cv2.error: C:\projects\opencv-python\opencv\modules\imgproc\src\color.cpp:11073: error: (-215) depth == 0 || depth == 2 || depth == 5 in function cv::cvtColor

Sun, 08 Apr 2018 11:23:43 imgcut.py[line:368] ERROR cut_img 这里出错
Sun, 08 Apr 2018 11:23:43 imgcut.py[line:369] ERROR this is an exception message
Traceback (most recent call last):
  File "E:\hupai\component\imgcut.py", line 361, in cut_img
    set_val('imgpos_lowestprice', img[use_area[0][1]:use_area[0][3], use_area[0][0]:use_area[0][2]])  # ok
IndexError: list index out of range
Sun, 08 Apr 2018 11:23:43 app_thread.py[line:127] ERROR 刷新失败
Sun, 08 Apr 2018 11:23:43 app_thread.py[line:128] ERROR this is an exception message
Traceback (most recent call last):
  File "E:\hupai\component\app_thread.py", line 125, in run
    findrefresh()
  File "E:\hupai\component\imgcut.py", line 383, in findrefresh
    img = cv2.cvtColor(sc, cv2.COLOR_BGR2GRAY)  # 转灰度图
cv2.error: C:\projects\opencv-python\opencv\modules\imgproc\src\color.cpp:11073: error: (-215) depth == 0 || depth == 2 || depth == 5 in function cv::cvtColor

Sun, 08 Apr 2018 11:23:43 imgcut.py[line:368] ERROR cut_img 这里出错
Sun, 08 Apr 2018 11:23:43 imgcut.py[line:369] ERROR this is an exception message
Traceback (most recent call last):
  File "E:\hupai\component\imgcut.py", line 361, in cut_img
    set_val('imgpos_lowestprice', img[use_area[0][1]:use_area[0][3], use_area[0][0]:use_area[0][2]])  # ok
IndexError: list index out of range
Sun, 08 Apr 2018 11:23:43 app_thread.py[line:127] ERROR 刷新失败
Sun, 08 Apr 2018 11:23:43 app_thread.py[line:128] ERROR this is an exception message
Traceback (most recent call last):
  File "E:\hupai\component\app_thread.py", line 125, in run
    findrefresh()
  File "E:\hupai\component\imgcut.py", line 383, in findrefresh
    img = cv2.cvtColor(sc, cv2.COLOR_BGR2GRAY)  # 转灰度图
cv2.error: C:\projects\opencv-python\opencv\modules\imgproc\src\color.cpp:11073: error: (-215) depth == 0 || depth == 2 || depth == 5 in function cv::cvtColor

Sun, 08 Apr 2018 11:23:43 imgcut.py[line:368] ERROR cut_img 这里出错
Sun, 08 Apr 2018 11:23:43 imgcut.py[line:369] ERROR this is an exception message
Traceback (most recent call last):
  File "E:\hupai\component\imgcut.py", line 361, in cut_img
    set_val('imgpos_lowestprice', img[use_area[0][1]:use_area[0][3], use_area[0][0]:use_area[0][2]])  # ok
IndexError: list index out of range
Sun, 08 Apr 2018 11:23:43 app_thread.py[line:127] ERROR 刷新失败
Sun, 08 Apr 2018 11:23:43 app_thread.py[line:128] ERROR this is an exception message
Traceback (most recent call last):
  File "E:\hupai\component\app_thread.py", line 125, in run
    findrefresh()
  File "E:\hupai\component\imgcut.py", line 383, in findrefresh
    img = cv2.cvtColor(sc, cv2.COLOR_BGR2GRAY)  # 转灰度图
cv2.error: C:\projects\opencv-python\opencv\modules\imgproc\src\color.cpp:11073: error: (-215) depth == 0 || depth == 2 || depth == 5 in function cv::cvtColor

Sun, 08 Apr 2018 11:23:43 imgcut.py[line:368] ERROR cut_img 这里出错
Sun, 08 Apr 2018 11:23:43 imgcut.py[line:369] ERROR this is an exception message
Traceback (most recent call last):
  File "E:\hupai\component\imgcut.py", line 361, in cut_img
    set_val('imgpos_lowestprice', img[use_area[0][1]:use_area[0][3], use_area[0][0]:use_area[0][2]])  # ok
IndexError: list index out of range
Sun, 08 Apr 2018 11:23:43 app_thread.py[line:127] ERROR 刷新失败
Sun, 08 Apr 2018 11:23:43 app_thread.py[line:128] ERROR this is an exception message
Traceback (most recent call last):
  File "E:\hupai\component\app_thread.py", line 125, in run
    findrefresh()
  File "E:\hupai\component\imgcut.py", line 383, in findrefresh
    img = cv2.cvtColor(sc, cv2.COLOR_BGR2GRAY)  # 转灰度图
cv2.error: C:\projects\opencv-python\opencv\modules\imgproc\src\color.cpp:11073: error: (-215) depth == 0 || depth == 2 || depth == 5 in function cv::cvtColor

Sun, 08 Apr 2018 11:23:43 imgcut.py[line:368] ERROR cut_img 这里出错
Sun, 08 Apr 2018 11:23:43 imgcut.py[line:369] ERROR this is an exception message
Traceback (most recent call last):
  File "E:\hupai\component\imgcut.py", line 361, in cut_img
    set_val('imgpos_lowestprice', img[use_area[0][1]:use_area[0][3], use_area[0][0]:use_area[0][2]])  # ok
IndexError: list index out of range
Sun, 08 Apr 2018 11:23:43 app_thread.py[line:127] ERROR 刷新失败
Sun, 08 Apr 2018 11:23:43 app_thread.py[line:128] ERROR this is an exception message
Traceback (most recent call last):
  File "E:\hupai\component\app_thread.py", line 125, in run
    findrefresh()
  File "E:\hupai\component\imgcut.py", line 383, in findrefresh
    img = cv2.cvtColor(sc, cv2.COLOR_BGR2GRAY)  # 转灰度图
cv2.error: C:\projects\opencv-python\opencv\modules\imgproc\src\color.cpp:11073: error: (-215) depth == 0 || depth == 2 || depth == 5 in function cv::cvtColor

Sun, 08 Apr 2018 11:23:43 app_thread.py[line:127] ERROR 刷新失败
Sun, 08 Apr 2018 11:23:43 app_thread.py[line:128] ERROR this is an exception message
Traceback (most recent call last):
  File "E:\hupai\component\app_thread.py", line 125, in run
    findrefresh()
  File "E:\hupai\component\imgcut.py", line 383, in findrefresh
    img = cv2.cvtColor(sc, cv2.COLOR_BGR2GRAY)  # 转灰度图
cv2.error: C:\projects\opencv-python\opencv\modules\imgproc\src\color.cpp:11073: error: (-215) depth == 0 || depth == 2 || depth == 5 in function cv::cvtColor

Sun, 08 Apr 2018 11:23:43 imgcut.py[line:368] ERROR cut_img 这里出错
Sun, 08 Apr 2018 11:23:43 imgcut.py[line:369] ERROR this is an exception message
Traceback (most recent call last):
  File "E:\hupai\component\imgcut.py", line 361, in cut_img
    set_val('imgpos_lowestprice', img[use_area[0][1]:use_area[0][3], use_area[0][0]:use_area[0][2]])  # ok
IndexError: list index out of range
Sun, 08 Apr 2018 11:23:43 app_thread.py[line:127] ERROR 刷新失败
Sun, 08 Apr 2018 11:23:43 app_thread.py[line:128] ERROR this is an exception message
Traceback (most recent call last):
  File "E:\hupai\component\app_thread.py", line 125, in run
    findrefresh()
  File "E:\hupai\component\imgcut.py", line 383, in findrefresh
    img = cv2.cvtColor(sc, cv2.COLOR_BGR2GRAY)  # 转灰度图
cv2.error: C:\projects\opencv-python\opencv\modules\imgproc\src\color.cpp:11073: error: (-215) depth == 0 || depth == 2 || depth == 5 in function cv::cvtColor

Sun, 08 Apr 2018 11:23:43 imgcut.py[line:368] ERROR cut_img 这里出错
Sun, 08 Apr 2018 11:23:43 imgcut.py[line:369] ERROR this is an exception message
Traceback (most recent call last):
  File "E:\hupai\component\imgcut.py", line 361, in cut_img
    set_val('imgpos_lowestprice', img[use_area[0][1]:use_area[0][3], use_area[0][0]:use_area[0][2]])  # ok
IndexError: list index out of range
Sun, 08 Apr 2018 11:23:43 app_thread.py[line:127] ERROR 刷新失败
Sun, 08 Apr 2018 11:23:43 app_thread.py[line:128] ERROR this is an exception message
Traceback (most recent call last):
  File "E:\hupai\component\app_thread.py", line 125, in run
    findrefresh()
  File "E:\hupai\component\imgcut.py", line 383, in findrefresh
    img = cv2.cvtColor(sc, cv2.COLOR_BGR2GRAY)  # 转灰度图
cv2.error: C:\projects\opencv-python\opencv\modules\imgproc\src\color.cpp:11073: error: (-215) depth == 0 || depth == 2 || depth == 5 in function cv::cvtColor

Sun, 08 Apr 2018 11:23:43 imgcut.py[line:368] ERROR cut_img 这里出错
Sun, 08 Apr 2018 11:23:43 imgcut.py[line:369] ERROR this is an exception message
Traceback (most recent call last):
  File "E:\hupai\component\imgcut.py", line 361, in cut_img
    set_val('imgpos_lowestprice', img[use_area[0][1]:use_area[0][3], use_area[0][0]:use_area[0][2]])  # ok
IndexError: list index out of range
Sun, 08 Apr 2018 11:23:44 app_thread.py[line:127] ERROR 刷新失败
Sun, 08 Apr 2018 11:23:44 app_thread.py[line:128] ERROR this is an exception message
Traceback (most recent call last):
  File "E:\hupai\component\app_thread.py", line 125, in run
    findrefresh()
  File "E:\hupai\component\imgcut.py", line 383, in findrefresh
    img = cv2.cvtColor(sc, cv2.COLOR_BGR2GRAY)  # 转灰度图
cv2.error: C:\projects\opencv-python\opencv\modules\imgproc\src\color.cpp:11073: error: (-215) depth == 0 || depth == 2 || depth == 5 in function cv::cvtColor

Sun, 08 Apr 2018 11:23:44 imgcut.py[line:368] ERROR cut_img 这里出错
Sun, 08 Apr 2018 11:23:44 imgcut.py[line:369] ERROR this is an exception message
Traceback (most recent call last):
  File "E:\hupai\component\imgcut.py", line 361, in cut_img
    set_val('imgpos_lowestprice', img[use_area[0][1]:use_area[0][3], use_area[0][0]:use_area[0][2]])  # ok
IndexError: list index out of range
Sun, 08 Apr 2018 11:23:44 app_thread.py[line:127] ERROR 刷新失败
Sun, 08 Apr 2018 11:23:44 app_thread.py[line:128] ERROR this is an exception message
Traceback (most recent call last):
  File "E:\hupai\component\app_thread.py", line 125, in run
    findrefresh()
  File "E:\hupai\component\imgcut.py", line 383, in findrefresh
    img = cv2.cvtColor(sc, cv2.COLOR_BGR2GRAY)  # 转灰度图
cv2.error: C:\projects\opencv-python\opencv\modules\imgproc\src\color.cpp:11073: error: (-215) depth == 0 || depth == 2 || depth == 5 in function cv::cvtColor

Sun, 08 Apr 2018 11:23:44 imgcut.py[line:368] ERROR cut_img 这里出错
Sun, 08 Apr 2018 11:23:44 imgcut.py[line:369] ERROR this is an exception message
Traceback (most recent call last):
  File "E:\hupai\component\imgcut.py", line 361, in cut_img
    set_val('imgpos_lowestprice', img[use_area[0][1]:use_area[0][3], use_area[0][0]:use_area[0][2]])  # ok
IndexError: list index out of range
Sun, 08 Apr 2018 11:23:44 app_thread.py[line:127] ERROR 刷新失败
Sun, 08 Apr 2018 11:23:44 app_thread.py[line:128] ERROR this is an exception message
Traceback (most recent call last):
  File "E:\hupai\component\app_thread.py", line 125, in run
    findrefresh()
  File "E:\hupai\component\imgcut.py", line 383, in findrefresh
    img = cv2.cvtColor(sc, cv2.COLOR_BGR2GRAY)  # 转灰度图
cv2.error: C:\projects\opencv-python\opencv\modules\imgproc\src\color.cpp:11073: error: (-215) depth == 0 || depth == 2 || depth == 5 in function cv::cvtColor

Sun, 08 Apr 2018 11:23:44 imgcut.py[line:368] ERROR cut_img 这里出错
Sun, 08 Apr 2018 11:23:44 imgcut.py[line:369] ERROR this is an exception message
Traceback (most recent call last):
  File "E:\hupai\component\imgcut.py", line 361, in cut_img
    set_val('imgpos_lowestprice', img[use_area[0][1]:use_area[0][3], use_area[0][0]:use_area[0][2]])  # ok
IndexError: list index out of range
Sun, 08 Apr 2018 11:23:44 app_thread.py[line:127] ERROR 刷新失败
Sun, 08 Apr 2018 11:23:44 app_thread.py[line:128] ERROR this is an exception message
Traceback (most recent call last):
  File "E:\hupai\component\app_thread.py", line 125, in run
    findrefresh()
  File "E:\hupai\component\imgcut.py", line 383, in findrefresh
    img = cv2.cvtColor(sc, cv2.COLOR_BGR2GRAY)  # 转灰度图
cv2.error: C:\projects\opencv-python\opencv\modules\imgproc\src\color.cpp:11073: error: (-215) depth == 0 || depth == 2 || depth == 5 in function cv::cvtColor

Sun, 08 Apr 2018 11:23:44 imgcut.py[line:368] ERROR cut_img 这里出错
Sun, 08 Apr 2018 11:23:44 imgcut.py[line:369] ERROR this is an exception message
Traceback (most recent call last):
  File "E:\hupai\component\imgcut.py", line 361, in cut_img
    set_val('imgpos_lowestprice', img[use_area[0][1]:use_area[0][3], use_area[0][0]:use_area[0][2]])  # ok
IndexError: list index out of range
Sun, 08 Apr 2018 11:23:44 app_thread.py[line:127] ERROR 刷新失败
Sun, 08 Apr 2018 11:23:44 app_thread.py[line:128] ERROR this is an exception message
Traceback (most recent call last):
  File "E:\hupai\component\app_thread.py", line 125, in run
    findrefresh()
  File "E:\hupai\component\imgcut.py", line 383, in findrefresh
    img = cv2.cvtColor(sc, cv2.COLOR_BGR2GRAY)  # 转灰度图
cv2.error: C:\projects\opencv-python\opencv\modules\imgproc\src\color.cpp:11073: error: (-215) depth == 0 || depth == 2 || depth == 5 in function cv::cvtColor

Sun, 08 Apr 2018 11:23:44 app_thread.py[line:127] ERROR 刷新失败
Sun, 08 Apr 2018 11:23:44 app_thread.py[line:128] ERROR this is an exception message
Traceback (most recent call last):
  File "E:\hupai\component\app_thread.py", line 125, in run
    findrefresh()
  File "E:\hupai\component\imgcut.py", line 383, in findrefresh
    img = cv2.cvtColor(sc, cv2.COLOR_BGR2GRAY)  # 转灰度图
cv2.error: C:\projects\opencv-python\opencv\modules\imgproc\src\color.cpp:11073: error: (-215) depth == 0 || depth == 2 || depth == 5 in function cv::cvtColor

Sun, 08 Apr 2018 11:23:44 imgcut.py[line:368] ERROR cut_img 这里出错
Sun, 08 Apr 2018 11:23:44 imgcut.py[line:369] ERROR this is an exception message
Traceback (most recent call last):
  File "E:\hupai\component\imgcut.py", line 361, in cut_img
    set_val('imgpos_lowestprice', img[use_area[0][1]:use_area[0][3], use_area[0][0]:use_area[0][2]])  # ok
IndexError: list index out of range
Sun, 08 Apr 2018 11:23:44 app_thread.py[line:127] ERROR 刷新失败
Sun, 08 Apr 2018 11:23:44 app_thread.py[line:128] ERROR this is an exception message
Traceback (most recent call last):
  File "E:\hupai\component\app_thread.py", line 125, in run
    findrefresh()
  File "E:\hupai\component\imgcut.py", line 383, in findrefresh
    img = cv2.cvtColor(sc, cv2.COLOR_BGR2GRAY)  # 转灰度图
cv2.error: C:\projects\opencv-python\opencv\modules\imgproc\src\color.cpp:11073: error: (-215) depth == 0 || depth == 2 || depth == 5 in function cv::cvtColor

Sun, 08 Apr 2018 11:23:44 imgcut.py[line:368] ERROR cut_img 这里出错
Sun, 08 Apr 2018 11:23:44 imgcut.py[line:369] ERROR this is an exception message
Traceback (most recent call last):
  File "E:\hupai\component\imgcut.py", line 361, in cut_img
    set_val('imgpos_lowestprice', img[use_area[0][1]:use_area[0][3], use_area[0][0]:use_area[0][2]])  # ok
IndexError: list index out of range
Sun, 08 Apr 2018 11:23:44 app_thread.py[line:127] ERROR 刷新失败
Sun, 08 Apr 2018 11:23:44 app_thread.py[line:128] ERROR this is an exception message
Traceback (most recent call last):
  File "E:\hupai\component\app_thread.py", line 125, in run
    findrefresh()
  File "E:\hupai\component\imgcut.py", line 383, in findrefresh
    img = cv2.cvtColor(sc, cv2.COLOR_BGR2GRAY)  # 转灰度图
cv2.error: C:\projects\opencv-python\opencv\modules\imgproc\src\color.cpp:11073: error: (-215) depth == 0 || depth == 2 || depth == 5 in function cv::cvtColor

Sun, 08 Apr 2018 11:23:44 imgcut.py[line:368] ERROR cut_img 这里出错
Sun, 08 Apr 2018 11:23:44 imgcut.py[line:369] ERROR this is an exception message
Traceback (most recent call last):
  File "E:\hupai\component\imgcut.py", line 361, in cut_img
    set_val('imgpos_lowestprice', img[use_area[0][1]:use_area[0][3], use_area[0][0]:use_area[0][2]])  # ok
IndexError: list index out of range
Sun, 08 Apr 2018 11:23:44 app_thread.py[line:127] ERROR 刷新失败
Sun, 08 Apr 2018 11:23:44 app_thread.py[line:128] ERROR this is an exception message
Traceback (most recent call last):
  File "E:\hupai\component\app_thread.py", line 125, in run
    findrefresh()
  File "E:\hupai\component\imgcut.py", line 383, in findrefresh
    img = cv2.cvtColor(sc, cv2.COLOR_BGR2GRAY)  # 转灰度图
cv2.error: C:\projects\opencv-python\opencv\modules\imgproc\src\color.cpp:11073: error: (-215) depth == 0 || depth == 2 || depth == 5 in function cv::cvtColor

Sun, 08 Apr 2018 11:23:44 imgcut.py[line:368] ERROR cut_img 这里出错
Sun, 08 Apr 2018 11:23:44 imgcut.py[line:369] ERROR this is an exception message
Traceback (most recent call last):
  File "E:\hupai\component\imgcut.py", line 361, in cut_img
    set_val('imgpos_lowestprice', img[use_area[0][1]:use_area[0][3], use_area[0][0]:use_area[0][2]])  # ok
IndexError: list index out of range
Sun, 08 Apr 2018 11:23:44 app_thread.py[line:127] ERROR 刷新失败
Sun, 08 Apr 2018 11:23:44 app_thread.py[line:128] ERROR this is an exception message
Traceback (most recent call last):
  File "E:\hupai\component\app_thread.py", line 125, in run
    findrefresh()
  File "E:\hupai\component\imgcut.py", line 383, in findrefresh
    img = cv2.cvtColor(sc, cv2.COLOR_BGR2GRAY)  # 转灰度图
cv2.error: C:\projects\opencv-python\opencv\modules\imgproc\src\color.cpp:11073: error: (-215) depth == 0 || depth == 2 || depth == 5 in function cv::cvtColor

Sun, 08 Apr 2018 11:23:44 imgcut.py[line:368] ERROR cut_img 这里出错
Sun, 08 Apr 2018 11:23:44 imgcut.py[line:369] ERROR this is an exception message
Traceback (most recent call last):
  File "E:\hupai\component\imgcut.py", line 361, in cut_img
    set_val('imgpos_lowestprice', img[use_area[0][1]:use_area[0][3], use_area[0][0]:use_area[0][2]])  # ok
IndexError: list index out of range
Sun, 08 Apr 2018 11:23:44 app_thread.py[line:127] ERROR 刷新失败
Sun, 08 Apr 2018 11:23:44 app_thread.py[line:128] ERROR this is an exception message
Traceback (most recent call last):
  File "E:\hupai\component\app_thread.py", line 125, in run
    findrefresh()
  File "E:\hupai\component\imgcut.py", line 383, in findrefresh
    img = cv2.cvtColor(sc, cv2.COLOR_BGR2GRAY)  # 转灰度图
cv2.error: C:\projects\opencv-python\opencv\modules\imgproc\src\color.cpp:11073: error: (-215) depth == 0 || depth == 2 || depth == 5 in function cv::cvtColor

Sun, 08 Apr 2018 11:23:44 imgcut.py[line:368] ERROR cut_img 这里出错
Sun, 08 Apr 2018 11:23:44 imgcut.py[line:369] ERROR this is an exception message
Traceback (most recent call last):
  File "E:\hupai\component\imgcut.py", line 361, in cut_img
    set_val('imgpos_lowestprice', img[use_area[0][1]:use_area[0][3], use_area[0][0]:use_area[0][2]])  # ok
IndexError: list index out of range
Sun, 08 Apr 2018 11:23:44 app_thread.py[line:127] ERROR 刷新失败
Sun, 08 Apr 2018 11:23:44 app_thread.py[line:128] ERROR this is an exception message
Traceback (most recent call last):
  File "E:\hupai\component\app_thread.py", line 125, in run
    findrefresh()
  File "E:\hupai\component\imgcut.py", line 383, in findrefresh
    img = cv2.cvtColor(sc, cv2.COLOR_BGR2GRAY)  # 转灰度图
cv2.error: C:\projects\opencv-python\opencv\modules\imgproc\src\color.cpp:11073: error: (-215) depth == 0 || depth == 2 || depth == 5 in function cv::cvtColor

Sun, 08 Apr 2018 11:23:44 imgcut.py[line:368] ERROR cut_img 这里出错
Sun, 08 Apr 2018 11:23:44 imgcut.py[line:369] ERROR this is an exception message
Traceback (most recent call last):
  File "E:\hupai\component\imgcut.py", line 361, in cut_img
    set_val('imgpos_lowestprice', img[use_area[0][1]:use_area[0][3], use_area[0][0]:use_area[0][2]])  # ok
IndexError: list index out of range
Sun, 08 Apr 2018 11:23:44 app_thread.py[line:127] ERROR 刷新失败
Sun, 08 Apr 2018 11:23:44 app_thread.py[line:128] ERROR this is an exception message
Traceback (most recent call last):
  File "E:\hupai\component\app_thread.py", line 125, in run
    findrefresh()
  File "E:\hupai\component\imgcut.py", line 383, in findrefresh
    img = cv2.cvtColor(sc, cv2.COLOR_BGR2GRAY)  # 转灰度图
cv2.error: C:\projects\opencv-python\opencv\modules\imgproc\src\color.cpp:11073: error: (-215) depth == 0 || depth == 2 || depth == 5 in function cv::cvtColor

Sun, 08 Apr 2018 11:23:44 imgcut.py[line:368] ERROR cut_img 这里出错
Sun, 08 Apr 2018 11:23:44 imgcut.py[line:369] ERROR this is an exception message
Traceback (most recent call last):
  File "E:\hupai\component\imgcut.py", line 361, in cut_img
    set_val('imgpos_lowestprice', img[use_area[0][1]:use_area[0][3], use_area[0][0]:use_area[0][2]])  # ok
IndexError: list index out of range
Sun, 08 Apr 2018 11:23:44 app_thread.py[line:127] ERROR 刷新失败
Sun, 08 Apr 2018 11:23:44 app_thread.py[line:128] ERROR this is an exception message
Traceback (most recent call last):
  File "E:\hupai\component\app_thread.py", line 125, in run
    findrefresh()
  File "E:\hupai\component\imgcut.py", line 383, in findrefresh
    img = cv2.cvtColor(sc, cv2.COLOR_BGR2GRAY)  # 转灰度图
cv2.error: C:\projects\opencv-python\opencv\modules\imgproc\src\color.cpp:11073: error: (-215) depth == 0 || depth == 2 || depth == 5 in function cv::cvtColor

Sun, 08 Apr 2018 11:23:44 imgcut.py[line:368] ERROR cut_img 这里出错
Sun, 08 Apr 2018 11:23:44 imgcut.py[line:369] ERROR this is an exception message
Traceback (most recent call last):
  File "E:\hupai\component\imgcut.py", line 361, in cut_img
    set_val('imgpos_lowestprice', img[use_area[0][1]:use_area[0][3], use_area[0][0]:use_area[0][2]])  # ok
IndexError: list index out of range
Sun, 08 Apr 2018 11:23:44 app_thread.py[line:127] ERROR 刷新失败
Sun, 08 Apr 2018 11:23:44 app_thread.py[line:128] ERROR this is an exception message
Traceback (most recent call last):
  File "E:\hupai\component\app_thread.py", line 125, in run
    findrefresh()
  File "E:\hupai\component\imgcut.py", line 383, in findrefresh
    img = cv2.cvtColor(sc, cv2.COLOR_BGR2GRAY)  # 转灰度图
cv2.error: C:\projects\opencv-python\opencv\modules\imgproc\src\color.cpp:11073: error: (-215) depth == 0 || depth == 2 || depth == 5 in function cv::cvtColor

Sun, 08 Apr 2018 11:23:44 imgcut.py[line:368] ERROR cut_img 这里出错
Sun, 08 Apr 2018 11:23:44 imgcut.py[line:369] ERROR this is an exception message
Traceback (most recent call last):
  File "E:\hupai\component\imgcut.py", line 361, in cut_img
    set_val('imgpos_lowestprice', img[use_area[0][1]:use_area[0][3], use_area[0][0]:use_area[0][2]])  # ok
IndexError: list index out of range
Sun, 08 Apr 2018 11:23:44 app_thread.py[line:127] ERROR 刷新失败
Sun, 08 Apr 2018 11:23:44 app_thread.py[line:128] ERROR this is an exception message
Traceback (most recent call last):
  File "E:\hupai\component\app_thread.py", line 125, in run
    findrefresh()
  File "E:\hupai\component\imgcut.py", line 383, in findrefresh
    img = cv2.cvtColor(sc, cv2.COLOR_BGR2GRAY)  # 转灰度图
cv2.error: C:\projects\opencv-python\opencv\modules\imgproc\src\color.cpp:11073: error: (-215) depth == 0 || depth == 2 || depth == 5 in function cv::cvtColor

Sun, 08 Apr 2018 11:23:44 imgcut.py[line:368] ERROR cut_img 这里出错
Sun, 08 Apr 2018 11:23:44 imgcut.py[line:369] ERROR this is an exception message
Traceback (most recent call last):
  File "E:\hupai\component\imgcut.py", line 361, in cut_img
    set_val('imgpos_lowestprice', img[use_area[0][1]:use_area[0][3], use_area[0][0]:use_area[0][2]])  # ok
IndexError: list index out of range
Sun, 08 Apr 2018 11:23:44 app_thread.py[line:127] ERROR 刷新失败
Sun, 08 Apr 2018 11:23:45 app_thread.py[line:128] ERROR this is an exception message
Traceback (most recent call last):
  File "E:\hupai\component\app_thread.py", line 125, in run
    findrefresh()
  File "E:\hupai\component\imgcut.py", line 383, in findrefresh
    img = cv2.cvtColor(sc, cv2.COLOR_BGR2GRAY)  # 转灰度图
cv2.error: C:\projects\opencv-python\opencv\modules\imgproc\src\color.cpp:11073: error: (-215) depth == 0 || depth == 2 || depth == 5 in function cv::cvtColor

Sun, 08 Apr 2018 11:23:45 app_thread.py[line:127] ERROR 刷新失败
Sun, 08 Apr 2018 11:23:45 app_thread.py[line:128] ERROR this is an exception message
Traceback (most recent call last):
  File "E:\hupai\component\app_thread.py", line 125, in run
    findrefresh()
  File "E:\hupai\component\imgcut.py", line 383, in findrefresh
    img = cv2.cvtColor(sc, cv2.COLOR_BGR2GRAY)  # 转灰度图
cv2.error: C:\projects\opencv-python\opencv\modules\imgproc\src\color.cpp:11073: error: (-215) depth == 0 || depth == 2 || depth == 5 in function cv::cvtColor

Sun, 08 Apr 2018 11:23:45 imgcut.py[line:368] ERROR cut_img 这里出错
Sun, 08 Apr 2018 11:23:45 imgcut.py[line:369] ERROR this is an exception message
Traceback (most recent call last):
  File "E:\hupai\component\imgcut.py", line 361, in cut_img
    set_val('imgpos_lowestprice', img[use_area[0][1]:use_area[0][3], use_area[0][0]:use_area[0][2]])  # ok
IndexError: list index out of range
Sun, 08 Apr 2018 11:23:45 app_thread.py[line:127] ERROR 刷新失败
Sun, 08 Apr 2018 11:23:45 app_thread.py[line:128] ERROR this is an exception message
Traceback (most recent call last):
  File "E:\hupai\component\app_thread.py", line 125, in run
    findrefresh()
  File "E:\hupai\component\imgcut.py", line 383, in findrefresh
    img = cv2.cvtColor(sc, cv2.COLOR_BGR2GRAY)  # 转灰度图
cv2.error: C:\projects\opencv-python\opencv\modules\imgproc\src\color.cpp:11073: error: (-215) depth == 0 || depth == 2 || depth == 5 in function cv::cvtColor

Sun, 08 Apr 2018 11:23:45 imgcut.py[line:368] ERROR cut_img 这里出错
Sun, 08 Apr 2018 11:23:45 imgcut.py[line:369] ERROR this is an exception message
Traceback (most recent call last):
  File "E:\hupai\component\imgcut.py", line 361, in cut_img
    set_val('imgpos_lowestprice', img[use_area[0][1]:use_area[0][3], use_area[0][0]:use_area[0][2]])  # ok
IndexError: list index out of range
Sun, 08 Apr 2018 11:23:45 app_thread.py[line:127] ERROR 刷新失败
Sun, 08 Apr 2018 11:23:45 app_thread.py[line:128] ERROR this is an exception message
Traceback (most recent call last):
  File "E:\hupai\component\app_thread.py", line 125, in run
    findrefresh()
  File "E:\hupai\component\imgcut.py", line 383, in findrefresh
    img = cv2.cvtColor(sc, cv2.COLOR_BGR2GRAY)  # 转灰度图
cv2.error: C:\projects\opencv-python\opencv\modules\imgproc\src\color.cpp:11073: error: (-215) depth == 0 || depth == 2 || depth == 5 in function cv::cvtColor

Sun, 08 Apr 2018 11:23:45 imgcut.py[line:368] ERROR cut_img 这里出错
Sun, 08 Apr 2018 11:23:45 imgcut.py[line:369] ERROR this is an exception message
Traceback (most recent call last):
  File "E:\hupai\component\imgcut.py", line 361, in cut_img
    set_val('imgpos_lowestprice', img[use_area[0][1]:use_area[0][3], use_area[0][0]:use_area[0][2]])  # ok
IndexError: list index out of range
Sun, 08 Apr 2018 11:23:45 app_thread.py[line:127] ERROR 刷新失败
Sun, 08 Apr 2018 11:23:45 app_thread.py[line:128] ERROR this is an exception message
Traceback (most recent call last):
  File "E:\hupai\component\app_thread.py", line 125, in run
    findrefresh()
  File "E:\hupai\component\imgcut.py", line 383, in findrefresh
    img = cv2.cvtColor(sc, cv2.COLOR_BGR2GRAY)  # 转灰度图
cv2.error: C:\projects\opencv-python\opencv\modules\imgproc\src\color.cpp:11073: error: (-215) depth == 0 || depth == 2 || depth == 5 in function cv::cvtColor

Sun, 08 Apr 2018 11:23:45 imgcut.py[line:368] ERROR cut_img 这里出错
Sun, 08 Apr 2018 11:23:45 imgcut.py[line:369] ERROR this is an exception message
Traceback (most recent call last):
  File "E:\hupai\component\imgcut.py", line 361, in cut_img
    set_val('imgpos_lowestprice', img[use_area[0][1]:use_area[0][3], use_area[0][0]:use_area[0][2]])  # ok
IndexError: list index out of range
Sun, 08 Apr 2018 11:23:45 app_thread.py[line:127] ERROR 刷新失败
Sun, 08 Apr 2018 11:23:45 app_thread.py[line:128] ERROR this is an exception message
Traceback (most recent call last):
  File "E:\hupai\component\app_thread.py", line 125, in run
    findrefresh()
  File "E:\hupai\component\imgcut.py", line 383, in findrefresh
    img = cv2.cvtColor(sc, cv2.COLOR_BGR2GRAY)  # 转灰度图
cv2.error: C:\projects\opencv-python\opencv\modules\imgproc\src\color.cpp:11073: error: (-215) depth == 0 || depth == 2 || depth == 5 in function cv::cvtColor

Sun, 08 Apr 2018 11:23:45 app_thread.py[line:127] ERROR 刷新失败
Sun, 08 Apr 2018 11:23:45 app_thread.py[line:128] ERROR this is an exception message
Traceback (most recent call last):
  File "E:\hupai\component\app_thread.py", line 125, in run
    findrefresh()
  File "E:\hupai\component\imgcut.py", line 383, in findrefresh
    img = cv2.cvtColor(sc, cv2.COLOR_BGR2GRAY)  # 转灰度图
cv2.error: C:\projects\opencv-python\opencv\modules\imgproc\src\color.cpp:11073: error: (-215) depth == 0 || depth == 2 || depth == 5 in function cv::cvtColor

Sun, 08 Apr 2018 11:23:45 imgcut.py[line:368] ERROR cut_img 这里出错
Sun, 08 Apr 2018 11:23:45 imgcut.py[line:369] ERROR this is an exception message
Traceback (most recent call last):
  File "E:\hupai\component\imgcut.py", line 361, in cut_img
    set_val('imgpos_lowestprice', img[use_area[0][1]:use_area[0][3], use_area[0][0]:use_area[0][2]])  # ok
IndexError: list index out of range
Sun, 08 Apr 2018 11:23:45 app_thread.py[line:127] ERROR 刷新失败
Sun, 08 Apr 2018 11:23:45 app_thread.py[line:128] ERROR this is an exception message
Traceback (most recent call last):
  File "E:\hupai\component\app_thread.py", line 125, in run
    findrefresh()
  File "E:\hupai\component\imgcut.py", line 383, in findrefresh
    img = cv2.cvtColor(sc, cv2.COLOR_BGR2GRAY)  # 转灰度图
cv2.error: C:\projects\opencv-python\opencv\modules\imgproc\src\color.cpp:11073: error: (-215) depth == 0 || depth == 2 || depth == 5 in function cv::cvtColor

Sun, 08 Apr 2018 11:23:45 imgcut.py[line:368] ERROR cut_img 这里出错
Sun, 08 Apr 2018 11:23:45 imgcut.py[line:369] ERROR this is an exception message
Traceback (most recent call last):
  File "E:\hupai\component\imgcut.py", line 361, in cut_img
    set_val('imgpos_lowestprice', img[use_area[0][1]:use_area[0][3], use_area[0][0]:use_area[0][2]])  # ok
IndexError: list index out of range
Sun, 08 Apr 2018 11:23:45 app_thread.py[line:127] ERROR 刷新失败
Sun, 08 Apr 2018 11:23:45 app_thread.py[line:128] ERROR this is an exception message
Traceback (most recent call last):
  File "E:\hupai\component\app_thread.py", line 125, in run
    findrefresh()
  File "E:\hupai\component\imgcut.py", line 383, in findrefresh
    img = cv2.cvtColor(sc, cv2.COLOR_BGR2GRAY)  # 转灰度图
cv2.error: C:\projects\opencv-python\opencv\modules\imgproc\src\color.cpp:11073: error: (-215) depth == 0 || depth == 2 || depth == 5 in function cv::cvtColor

Sun, 08 Apr 2018 11:23:45 app_thread.py[line:127] ERROR 刷新失败
Sun, 08 Apr 2018 11:23:45 app_thread.py[line:128] ERROR this is an exception message
Traceback (most recent call last):
  File "E:\hupai\component\app_thread.py", line 125, in run
    findrefresh()
  File "E:\hupai\component\imgcut.py", line 383, in findrefresh
    img = cv2.cvtColor(sc, cv2.COLOR_BGR2GRAY)  # 转灰度图
cv2.error: C:\projects\opencv-python\opencv\modules\imgproc\src\color.cpp:11073: error: (-215) depth == 0 || depth == 2 || depth == 5 in function cv::cvtColor

Sun, 08 Apr 2018 11:23:45 imgcut.py[line:368] ERROR cut_img 这里出错
Sun, 08 Apr 2018 11:23:45 imgcut.py[line:369] ERROR this is an exception message
Traceback (most recent call last):
  File "E:\hupai\component\imgcut.py", line 361, in cut_img
    set_val('imgpos_lowestprice', img[use_area[0][1]:use_area[0][3], use_area[0][0]:use_area[0][2]])  # ok
IndexError: list index out of range
Sun, 08 Apr 2018 11:23:45 app_thread.py[line:127] ERROR 刷新失败
Sun, 08 Apr 2018 11:23:45 app_thread.py[line:128] ERROR this is an exception message
Traceback (most recent call last):
  File "E:\hupai\component\app_thread.py", line 125, in run
    findrefresh()
  File "E:\hupai\component\imgcut.py", line 383, in findrefresh
    img = cv2.cvtColor(sc, cv2.COLOR_BGR2GRAY)  # 转灰度图
cv2.error: C:\projects\opencv-python\opencv\modules\imgproc\src\color.cpp:11073: error: (-215) depth == 0 || depth == 2 || depth == 5 in function cv::cvtColor

Sun, 08 Apr 2018 11:23:45 imgcut.py[line:368] ERROR cut_img 这里出错
Sun, 08 Apr 2018 11:23:45 imgcut.py[line:369] ERROR this is an exception message
Traceback (most recent call last):
  File "E:\hupai\component\imgcut.py", line 361, in cut_img
    set_val('imgpos_lowestprice', img[use_area[0][1]:use_area[0][3], use_area[0][0]:use_area[0][2]])  # ok
IndexError: list index out of range
Sun, 08 Apr 2018 11:23:45 app_thread.py[line:127] ERROR 刷新失败
Sun, 08 Apr 2018 11:23:45 app_thread.py[line:128] ERROR this is an exception message
Traceback (most recent call last):
  File "E:\hupai\component\app_thread.py", line 125, in run
    findrefresh()
  File "E:\hupai\component\imgcut.py", line 383, in findrefresh
    img = cv2.cvtColor(sc, cv2.COLOR_BGR2GRAY)  # 转灰度图
cv2.error: C:\projects\opencv-python\opencv\modules\imgproc\src\color.cpp:11073: error: (-215) depth == 0 || depth == 2 || depth == 5 in function cv::cvtColor

Sun, 08 Apr 2018 11:23:45 imgcut.py[line:368] ERROR cut_img 这里出错
Sun, 08 Apr 2018 11:23:45 imgcut.py[line:369] ERROR this is an exception message
Traceback (most recent call last):
  File "E:\hupai\component\imgcut.py", line 361, in cut_img
    set_val('imgpos_lowestprice', img[use_area[0][1]:use_area[0][3], use_area[0][0]:use_area[0][2]])  # ok
IndexError: list index out of range
Sun, 08 Apr 2018 11:23:45 app_thread.py[line:127] ERROR 刷新失败
Sun, 08 Apr 2018 11:23:45 app_thread.py[line:128] ERROR this is an exception message
Traceback (most recent call last):
  File "E:\hupai\component\app_thread.py", line 125, in run
    findrefresh()
  File "E:\hupai\component\imgcut.py", line 383, in findrefresh
    img = cv2.cvtColor(sc, cv2.COLOR_BGR2GRAY)  # 转灰度图
cv2.error: C:\projects\opencv-python\opencv\modules\imgproc\src\color.cpp:11073: error: (-215) depth == 0 || depth == 2 || depth == 5 in function cv::cvtColor

Sun, 08 Apr 2018 11:23:45 app_thread.py[line:127] ERROR 刷新失败
Sun, 08 Apr 2018 11:23:45 imgcut.py[line:368] ERROR cut_img 这里出错
Sun, 08 Apr 2018 11:23:45 app_thread.py[line:128] ERROR this is an exception message
Traceback (most recent call last):
  File "E:\hupai\component\app_thread.py", line 125, in run
    findrefresh()
  File "E:\hupai\component\imgcut.py", line 383, in findrefresh
    img = cv2.cvtColor(sc, cv2.COLOR_BGR2GRAY)  # 转灰度图
cv2.error: C:\projects\opencv-python\opencv\modules\imgproc\src\color.cpp:11073: error: (-215) depth == 0 || depth == 2 || depth == 5 in function cv::cvtColor

Sun, 08 Apr 2018 11:23:45 imgcut.py[line:369] ERROR this is an exception message
Traceback (most recent call last):
  File "E:\hupai\component\imgcut.py", line 361, in cut_img
    set_val('imgpos_lowestprice', img[use_area[0][1]:use_area[0][3], use_area[0][0]:use_area[0][2]])  # ok
IndexError: list index out of range
Sun, 08 Apr 2018 11:23:45 app_thread.py[line:127] ERROR 刷新失败
Sun, 08 Apr 2018 11:23:45 app_thread.py[line:128] ERROR this is an exception message
Traceback (most recent call last):
  File "E:\hupai\component\app_thread.py", line 125, in run
    findrefresh()
  File "E:\hupai\component\imgcut.py", line 383, in findrefresh
    img = cv2.cvtColor(sc, cv2.COLOR_BGR2GRAY)  # 转灰度图
cv2.error: C:\projects\opencv-python\opencv\modules\imgproc\src\color.cpp:11073: error: (-215) depth == 0 || depth == 2 || depth == 5 in function cv::cvtColor

Sun, 08 Apr 2018 11:23:46 imgcut.py[line:368] ERROR cut_img 这里出错
Sun, 08 Apr 2018 11:23:46 imgcut.py[line:369] ERROR this is an exception message
Traceback (most recent call last):
  File "E:\hupai\component\imgcut.py", line 361, in cut_img
    set_val('imgpos_lowestprice', img[use_area[0][1]:use_area[0][3], use_area[0][0]:use_area[0][2]])  # ok
IndexError: list index out of range
Sun, 08 Apr 2018 11:23:46 app_thread.py[line:127] ERROR 刷新失败
Sun, 08 Apr 2018 11:23:46 app_thread.py[line:128] ERROR this is an exception message
Traceback (most recent call last):
  File "E:\hupai\component\app_thread.py", line 125, in run
    findrefresh()
  File "E:\hupai\component\imgcut.py", line 383, in findrefresh
    img = cv2.cvtColor(sc, cv2.COLOR_BGR2GRAY)  # 转灰度图
cv2.error: C:\projects\opencv-python\opencv\modules\imgproc\src\color.cpp:11073: error: (-215) depth == 0 || depth == 2 || depth == 5 in function cv::cvtColor

Sun, 08 Apr 2018 11:23:46 imgcut.py[line:368] ERROR cut_img 这里出错
Sun, 08 Apr 2018 11:23:46 imgcut.py[line:369] ERROR this is an exception message
Traceback (most recent call last):
  File "E:\hupai\component\imgcut.py", line 361, in cut_img
    set_val('imgpos_lowestprice', img[use_area[0][1]:use_area[0][3], use_area[0][0]:use_area[0][2]])  # ok
IndexError: list index out of range
Sun, 08 Apr 2018 11:23:46 app_thread.py[line:127] ERROR 刷新失败
Sun, 08 Apr 2018 11:23:46 app_thread.py[line:128] ERROR this is an exception message
Traceback (most recent call last):
  File "E:\hupai\component\app_thread.py", line 125, in run
    findrefresh()
  File "E:\hupai\component\imgcut.py", line 383, in findrefresh
    img = cv2.cvtColor(sc, cv2.COLOR_BGR2GRAY)  # 转灰度图
cv2.error: C:\projects\opencv-python\opencv\modules\imgproc\src\color.cpp:11073: error: (-215) depth == 0 || depth == 2 || depth == 5 in function cv::cvtColor

Sun, 08 Apr 2018 11:23:46 app_thread.py[line:127] ERROR 刷新失败
Sun, 08 Apr 2018 11:23:46 app_thread.py[line:128] ERROR this is an exception message
Traceback (most recent call last):
  File "E:\hupai\component\app_thread.py", line 125, in run
    findrefresh()
  File "E:\hupai\component\imgcut.py", line 383, in findrefresh
    img = cv2.cvtColor(sc, cv2.COLOR_BGR2GRAY)  # 转灰度图
cv2.error: C:\projects\opencv-python\opencv\modules\imgproc\src\color.cpp:11073: error: (-215) depth == 0 || depth == 2 || depth == 5 in function cv::cvtColor

Sun, 08 Apr 2018 11:23:46 imgcut.py[line:368] ERROR cut_img 这里出错
Sun, 08 Apr 2018 11:23:46 imgcut.py[line:369] ERROR this is an exception message
Traceback (most recent call last):
  File "E:\hupai\component\imgcut.py", line 361, in cut_img
    set_val('imgpos_lowestprice', img[use_area[0][1]:use_area[0][3], use_area[0][0]:use_area[0][2]])  # ok
IndexError: list index out of range
Sun, 08 Apr 2018 11:23:46 app_thread.py[line:127] ERROR 刷新失败
Sun, 08 Apr 2018 11:23:46 app_thread.py[line:128] ERROR this is an exception message
Traceback (most recent call last):
  File "E:\hupai\component\app_thread.py", line 125, in run
    findrefresh()
  File "E:\hupai\component\imgcut.py", line 383, in findrefresh
    img = cv2.cvtColor(sc, cv2.COLOR_BGR2GRAY)  # 转灰度图
cv2.error: C:\projects\opencv-python\opencv\modules\imgproc\src\color.cpp:11073: error: (-215) depth == 0 || depth == 2 || depth == 5 in function cv::cvtColor

Sun, 08 Apr 2018 11:23:46 imgcut.py[line:368] ERROR cut_img 这里出错
Sun, 08 Apr 2018 11:23:46 imgcut.py[line:369] ERROR this is an exception message
Traceback (most recent call last):
  File "E:\hupai\component\imgcut.py", line 361, in cut_img
    set_val('imgpos_lowestprice', img[use_area[0][1]:use_area[0][3], use_area[0][0]:use_area[0][2]])  # ok
IndexError: list index out of range
Sun, 08 Apr 2018 11:23:46 app_thread.py[line:127] ERROR 刷新失败
Sun, 08 Apr 2018 11:23:46 app_thread.py[line:128] ERROR this is an exception message
Traceback (most recent call last):
  File "E:\hupai\component\app_thread.py", line 125, in run
    findrefresh()
  File "E:\hupai\component\imgcut.py", line 383, in findrefresh
    img = cv2.cvtColor(sc, cv2.COLOR_BGR2GRAY)  # 转灰度图
cv2.error: C:\projects\opencv-python\opencv\modules\imgproc\src\color.cpp:11073: error: (-215) depth == 0 || depth == 2 || depth == 5 in function cv::cvtColor

Sun, 08 Apr 2018 11:23:46 imgcut.py[line:368] ERROR cut_img 这里出错
Sun, 08 Apr 2018 11:23:46 imgcut.py[line:369] ERROR this is an exception message
Traceback (most recent call last):
  File "E:\hupai\component\imgcut.py", line 361, in cut_img
    set_val('imgpos_lowestprice', img[use_area[0][1]:use_area[0][3], use_area[0][0]:use_area[0][2]])  # ok
IndexError: list index out of range
Sun, 08 Apr 2018 11:23:46 app_thread.py[line:127] ERROR 刷新失败
Sun, 08 Apr 2018 11:23:46 app_thread.py[line:128] ERROR this is an exception message
Traceback (most recent call last):
  File "E:\hupai\component\app_thread.py", line 125, in run
    findrefresh()
  File "E:\hupai\component\imgcut.py", line 383, in findrefresh
    img = cv2.cvtColor(sc, cv2.COLOR_BGR2GRAY)  # 转灰度图
cv2.error: C:\projects\opencv-python\opencv\modules\imgproc\src\color.cpp:11073: error: (-215) depth == 0 || depth == 2 || depth == 5 in function cv::cvtColor

Sun, 08 Apr 2018 11:23:46 app_thread.py[line:127] ERROR 刷新失败
Sun, 08 Apr 2018 11:23:46 app_thread.py[line:128] ERROR this is an exception message
Traceback (most recent call last):
  File "E:\hupai\component\app_thread.py", line 125, in run
    findrefresh()
  File "E:\hupai\component\imgcut.py", line 383, in findrefresh
    img = cv2.cvtColor(sc, cv2.COLOR_BGR2GRAY)  # 转灰度图
cv2.error: C:\projects\opencv-python\opencv\modules\imgproc\src\color.cpp:11073: error: (-215) depth == 0 || depth == 2 || depth == 5 in function cv::cvtColor

Sun, 08 Apr 2018 11:23:46 imgcut.py[line:368] ERROR cut_img 这里出错
Sun, 08 Apr 2018 11:23:46 imgcut.py[line:369] ERROR this is an exception message
Traceback (most recent call last):
  File "E:\hupai\component\imgcut.py", line 361, in cut_img
    set_val('imgpos_lowestprice', img[use_area[0][1]:use_area[0][3], use_area[0][0]:use_area[0][2]])  # ok
IndexError: list index out of range
Sun, 08 Apr 2018 11:23:46 app_thread.py[line:127] ERROR 刷新失败
Sun, 08 Apr 2018 11:23:46 app_thread.py[line:128] ERROR this is an exception message
Traceback (most recent call last):
  File "E:\hupai\component\app_thread.py", line 125, in run
    findrefresh()
  File "E:\hupai\component\imgcut.py", line 383, in findrefresh
    img = cv2.cvtColor(sc, cv2.COLOR_BGR2GRAY)  # 转灰度图
cv2.error: C:\projects\opencv-python\opencv\modules\imgproc\src\color.cpp:11073: error: (-215) depth == 0 || depth == 2 || depth == 5 in function cv::cvtColor

Sun, 08 Apr 2018 11:23:46 imgcut.py[line:368] ERROR cut_img 这里出错
Sun, 08 Apr 2018 11:23:46 imgcut.py[line:369] ERROR this is an exception message
Traceback (most recent call last):
  File "E:\hupai\component\imgcut.py", line 361, in cut_img
    set_val('imgpos_lowestprice', img[use_area[0][1]:use_area[0][3], use_area[0][0]:use_area[0][2]])  # ok
IndexError: list index out of range
Sun, 08 Apr 2018 11:23:46 app_thread.py[line:127] ERROR 刷新失败
Sun, 08 Apr 2018 11:23:46 app_thread.py[line:128] ERROR this is an exception message
Traceback (most recent call last):
  File "E:\hupai\component\app_thread.py", line 125, in run
    findrefresh()
  File "E:\hupai\component\imgcut.py", line 383, in findrefresh
    img = cv2.cvtColor(sc, cv2.COLOR_BGR2GRAY)  # 转灰度图
cv2.error: C:\projects\opencv-python\opencv\modules\imgproc\src\color.cpp:11073: error: (-215) depth == 0 || depth == 2 || depth == 5 in function cv::cvtColor

Sun, 08 Apr 2018 11:23:46 imgcut.py[line:368] ERROR cut_img 这里出错
Sun, 08 Apr 2018 11:23:46 imgcut.py[line:369] ERROR this is an exception message
Traceback (most recent call last):
  File "E:\hupai\component\imgcut.py", line 361, in cut_img
    set_val('imgpos_lowestprice', img[use_area[0][1]:use_area[0][3], use_area[0][0]:use_area[0][2]])  # ok
IndexError: list index out of range
Sun, 08 Apr 2018 11:23:46 app_thread.py[line:127] ERROR 刷新失败
Sun, 08 Apr 2018 11:23:46 app_thread.py[line:128] ERROR this is an exception message
Traceback (most recent call last):
  File "E:\hupai\component\app_thread.py", line 125, in run
    findrefresh()
  File "E:\hupai\component\imgcut.py", line 383, in findrefresh
    img = cv2.cvtColor(sc, cv2.COLOR_BGR2GRAY)  # 转灰度图
cv2.error: C:\projects\opencv-python\opencv\modules\imgproc\src\color.cpp:11073: error: (-215) depth == 0 || depth == 2 || depth == 5 in function cv::cvtColor

Sun, 08 Apr 2018 11:23:46 app_thread.py[line:127] ERROR 刷新失败
Sun, 08 Apr 2018 11:23:46 app_thread.py[line:128] ERROR this is an exception message
Traceback (most recent call last):
  File "E:\hupai\component\app_thread.py", line 125, in run
    findrefresh()
  File "E:\hupai\component\imgcut.py", line 383, in findrefresh
    img = cv2.cvtColor(sc, cv2.COLOR_BGR2GRAY)  # 转灰度图
cv2.error: C:\projects\opencv-python\opencv\modules\imgproc\src\color.cpp:11073: error: (-215) depth == 0 || depth == 2 || depth == 5 in function cv::cvtColor

Sun, 08 Apr 2018 11:23:46 imgcut.py[line:368] ERROR cut_img 这里出错
Sun, 08 Apr 2018 11:23:46 imgcut.py[line:369] ERROR this is an exception message
Traceback (most recent call last):
  File "E:\hupai\component\imgcut.py", line 361, in cut_img
    set_val('imgpos_lowestprice', img[use_area[0][1]:use_area[0][3], use_area[0][0]:use_area[0][2]])  # ok
IndexError: list index out of range
Sun, 08 Apr 2018 11:23:46 app_thread.py[line:127] ERROR 刷新失败
Sun, 08 Apr 2018 11:23:46 app_thread.py[line:128] ERROR this is an exception message
Traceback (most recent call last):
  File "E:\hupai\component\app_thread.py", line 125, in run
    findrefresh()
  File "E:\hupai\component\imgcut.py", line 383, in findrefresh
    img = cv2.cvtColor(sc, cv2.COLOR_BGR2GRAY)  # 转灰度图
cv2.error: C:\projects\opencv-python\opencv\modules\imgproc\src\color.cpp:11073: error: (-215) depth == 0 || depth == 2 || depth == 5 in function cv::cvtColor

Sun, 08 Apr 2018 11:23:46 app_thread.py[line:127] ERROR 刷新失败
Sun, 08 Apr 2018 11:23:46 app_thread.py[line:128] ERROR this is an exception message
Traceback (most recent call last):
  File "E:\hupai\component\app_thread.py", line 125, in run
    findrefresh()
  File "E:\hupai\component\imgcut.py", line 383, in findrefresh
    img = cv2.cvtColor(sc, cv2.COLOR_BGR2GRAY)  # 转灰度图
cv2.error: C:\projects\opencv-python\opencv\modules\imgproc\src\color.cpp:11073: error: (-215) depth == 0 || depth == 2 || depth == 5 in function cv::cvtColor

Sun, 08 Apr 2018 11:23:46 app_thread.py[line:127] ERROR 刷新失败
Sun, 08 Apr 2018 11:23:46 imgcut.py[line:368] ERROR cut_img 这里出错
Sun, 08 Apr 2018 11:23:47 app_thread.py[line:128] ERROR this is an exception message
Traceback (most recent call last):
  File "E:\hupai\component\app_thread.py", line 125, in run
    findrefresh()
  File "E:\hupai\component\imgcut.py", line 383, in findrefresh
    img = cv2.cvtColor(sc, cv2.COLOR_BGR2GRAY)  # 转灰度图
cv2.error: C:\projects\opencv-python\opencv\modules\imgproc\src\color.cpp:11073: error: (-215) depth == 0 || depth == 2 || depth == 5 in function cv::cvtColor

Sun, 08 Apr 2018 11:23:47 imgcut.py[line:369] ERROR this is an exception message
Traceback (most recent call last):
  File "E:\hupai\component\imgcut.py", line 361, in cut_img
    set_val('imgpos_lowestprice', img[use_area[0][1]:use_area[0][3], use_area[0][0]:use_area[0][2]])  # ok
IndexError: list index out of range
Sun, 08 Apr 2018 11:23:47 app_thread.py[line:127] ERROR 刷新失败
Sun, 08 Apr 2018 11:23:47 app_thread.py[line:128] ERROR this is an exception message
Traceback (most recent call last):
  File "E:\hupai\component\app_thread.py", line 125, in run
    findrefresh()
  File "E:\hupai\component\imgcut.py", line 383, in findrefresh
    img = cv2.cvtColor(sc, cv2.COLOR_BGR2GRAY)  # 转灰度图
cv2.error: C:\projects\opencv-python\opencv\modules\imgproc\src\color.cpp:11073: error: (-215) depth == 0 || depth == 2 || depth == 5 in function cv::cvtColor

Sun, 08 Apr 2018 11:23:47 imgcut.py[line:368] ERROR cut_img 这里出错
Sun, 08 Apr 2018 11:23:47 imgcut.py[line:369] ERROR this is an exception message
Traceback (most recent call last):
  File "E:\hupai\component\imgcut.py", line 361, in cut_img
    set_val('imgpos_lowestprice', img[use_area[0][1]:use_area[0][3], use_area[0][0]:use_area[0][2]])  # ok
IndexError: list index out of range
Sun, 08 Apr 2018 11:23:47 app_thread.py[line:127] ERROR 刷新失败
Sun, 08 Apr 2018 11:23:47 app_thread.py[line:128] ERROR this is an exception message
Traceback (most recent call last):
  File "E:\hupai\component\app_thread.py", line 125, in run
    findrefresh()
  File "E:\hupai\component\imgcut.py", line 383, in findrefresh
    img = cv2.cvtColor(sc, cv2.COLOR_BGR2GRAY)  # 转灰度图
cv2.error: C:\projects\opencv-python\opencv\modules\imgproc\src\color.cpp:11073: error: (-215) depth == 0 || depth == 2 || depth == 5 in function cv::cvtColor

Sun, 08 Apr 2018 11:23:47 app_thread.py[line:127] ERROR 刷新失败
Sun, 08 Apr 2018 11:23:47 app_thread.py[line:128] ERROR this is an exception message
Traceback (most recent call last):
  File "E:\hupai\component\app_thread.py", line 125, in run
    findrefresh()
  File "E:\hupai\component\imgcut.py", line 383, in findrefresh
    img = cv2.cvtColor(sc, cv2.COLOR_BGR2GRAY)  # 转灰度图
cv2.error: C:\projects\opencv-python\opencv\modules\imgproc\src\color.cpp:11073: error: (-215) depth == 0 || depth == 2 || depth == 5 in function cv::cvtColor

Sun, 08 Apr 2018 11:23:47 imgcut.py[line:368] ERROR cut_img 这里出错
Sun, 08 Apr 2018 11:23:47 imgcut.py[line:369] ERROR this is an exception message
Traceback (most recent call last):
  File "E:\hupai\component\imgcut.py", line 361, in cut_img
    set_val('imgpos_lowestprice', img[use_area[0][1]:use_area[0][3], use_area[0][0]:use_area[0][2]])  # ok
IndexError: list index out of range
Sun, 08 Apr 2018 11:23:47 app_thread.py[line:127] ERROR 刷新失败
Sun, 08 Apr 2018 11:23:47 app_thread.py[line:128] ERROR this is an exception message
Traceback (most recent call last):
  File "E:\hupai\component\app_thread.py", line 125, in run
    findrefresh()
  File "E:\hupai\component\imgcut.py", line 383, in findrefresh
    img = cv2.cvtColor(sc, cv2.COLOR_BGR2GRAY)  # 转灰度图
cv2.error: C:\projects\opencv-python\opencv\modules\imgproc\src\color.cpp:11073: error: (-215) depth == 0 || depth == 2 || depth == 5 in function cv::cvtColor

Sun, 08 Apr 2018 11:23:47 app_thread.py[line:127] ERROR 刷新失败
Sun, 08 Apr 2018 11:23:47 app_thread.py[line:128] ERROR this is an exception message
Traceback (most recent call last):
  File "E:\hupai\component\app_thread.py", line 125, in run
    findrefresh()
  File "E:\hupai\component\imgcut.py", line 383, in findrefresh
    img = cv2.cvtColor(sc, cv2.COLOR_BGR2GRAY)  # 转灰度图
cv2.error: C:\projects\opencv-python\opencv\modules\imgproc\src\color.cpp:11073: error: (-215) depth == 0 || depth == 2 || depth == 5 in function cv::cvtColor

Sun, 08 Apr 2018 11:23:47 imgcut.py[line:368] ERROR cut_img 这里出错
Sun, 08 Apr 2018 11:23:47 imgcut.py[line:369] ERROR this is an exception message
Traceback (most recent call last):
  File "E:\hupai\component\imgcut.py", line 361, in cut_img
    set_val('imgpos_lowestprice', img[use_area[0][1]:use_area[0][3], use_area[0][0]:use_area[0][2]])  # ok
IndexError: list index out of range
Sun, 08 Apr 2018 11:23:47 app_thread.py[line:127] ERROR 刷新失败
Sun, 08 Apr 2018 11:23:47 app_thread.py[line:128] ERROR this is an exception message
Traceback (most recent call last):
  File "E:\hupai\component\app_thread.py", line 125, in run
    findrefresh()
  File "E:\hupai\component\imgcut.py", line 383, in findrefresh
    img = cv2.cvtColor(sc, cv2.COLOR_BGR2GRAY)  # 转灰度图
cv2.error: C:\projects\opencv-python\opencv\modules\imgproc\src\color.cpp:11073: error: (-215) depth == 0 || depth == 2 || depth == 5 in function cv::cvtColor

Sun, 08 Apr 2018 11:23:47 app_thread.py[line:127] ERROR 刷新失败
Sun, 08 Apr 2018 11:23:47 app_thread.py[line:128] ERROR this is an exception message
Traceback (most recent call last):
  File "E:\hupai\component\app_thread.py", line 125, in run
    findrefresh()
  File "E:\hupai\component\imgcut.py", line 383, in findrefresh
    img = cv2.cvtColor(sc, cv2.COLOR_BGR2GRAY)  # 转灰度图
cv2.error: C:\projects\opencv-python\opencv\modules\imgproc\src\color.cpp:11073: error: (-215) depth == 0 || depth == 2 || depth == 5 in function cv::cvtColor

Sun, 08 Apr 2018 11:23:47 imgcut.py[line:368] ERROR cut_img 这里出错
Sun, 08 Apr 2018 11:23:47 imgcut.py[line:369] ERROR this is an exception message
Traceback (most recent call last):
  File "E:\hupai\component\imgcut.py", line 361, in cut_img
    set_val('imgpos_lowestprice', img[use_area[0][1]:use_area[0][3], use_area[0][0]:use_area[0][2]])  # ok
IndexError: list index out of range
Sun, 08 Apr 2018 11:23:47 app_thread.py[line:127] ERROR 刷新失败
Sun, 08 Apr 2018 11:23:47 app_thread.py[line:128] ERROR this is an exception message
Traceback (most recent call last):
  File "E:\hupai\component\app_thread.py", line 125, in run
    findrefresh()
  File "E:\hupai\component\imgcut.py", line 383, in findrefresh
    img = cv2.cvtColor(sc, cv2.COLOR_BGR2GRAY)  # 转灰度图
cv2.error: C:\projects\opencv-python\opencv\modules\imgproc\src\color.cpp:11073: error: (-215) depth == 0 || depth == 2 || depth == 5 in function cv::cvtColor

Sun, 08 Apr 2018 11:23:47 imgcut.py[line:368] ERROR cut_img 这里出错
Sun, 08 Apr 2018 11:23:47 imgcut.py[line:369] ERROR this is an exception message
Traceback (most recent call last):
  File "E:\hupai\component\imgcut.py", line 361, in cut_img
    set_val('imgpos_lowestprice', img[use_area[0][1]:use_area[0][3], use_area[0][0]:use_area[0][2]])  # ok
IndexError: list index out of range
Sun, 08 Apr 2018 11:23:47 app_thread.py[line:127] ERROR 刷新失败
Sun, 08 Apr 2018 11:23:47 app_thread.py[line:128] ERROR this is an exception message
Traceback (most recent call last):
  File "E:\hupai\component\app_thread.py", line 125, in run
    findrefresh()
  File "E:\hupai\component\imgcut.py", line 383, in findrefresh
    img = cv2.cvtColor(sc, cv2.COLOR_BGR2GRAY)  # 转灰度图
cv2.error: C:\projects\opencv-python\opencv\modules\imgproc\src\color.cpp:11073: error: (-215) depth == 0 || depth == 2 || depth == 5 in function cv::cvtColor

Sun, 08 Apr 2018 11:23:47 imgcut.py[line:368] ERROR cut_img 这里出错
Sun, 08 Apr 2018 11:23:47 imgcut.py[line:369] ERROR this is an exception message
Traceback (most recent call last):
  File "E:\hupai\component\imgcut.py", line 361, in cut_img
    set_val('imgpos_lowestprice', img[use_area[0][1]:use_area[0][3], use_area[0][0]:use_area[0][2]])  # ok
IndexError: list index out of range
Sun, 08 Apr 2018 11:23:47 app_thread.py[line:127] ERROR 刷新失败
Sun, 08 Apr 2018 11:23:47 app_thread.py[line:128] ERROR this is an exception message
Traceback (most recent call last):
  File "E:\hupai\component\app_thread.py", line 125, in run
    findrefresh()
  File "E:\hupai\component\imgcut.py", line 383, in findrefresh
    img = cv2.cvtColor(sc, cv2.COLOR_BGR2GRAY)  # 转灰度图
cv2.error: C:\projects\opencv-python\opencv\modules\imgproc\src\color.cpp:11073: error: (-215) depth == 0 || depth == 2 || depth == 5 in function cv::cvtColor

Sun, 08 Apr 2018 11:23:47 imgcut.py[line:368] ERROR cut_img 这里出错
Sun, 08 Apr 2018 11:23:47 imgcut.py[line:369] ERROR this is an exception message
Traceback (most recent call last):
  File "E:\hupai\component\imgcut.py", line 361, in cut_img
    set_val('imgpos_lowestprice', img[use_area[0][1]:use_area[0][3], use_area[0][0]:use_area[0][2]])  # ok
IndexError: list index out of range
Sun, 08 Apr 2018 11:23:47 app_thread.py[line:127] ERROR 刷新失败
Sun, 08 Apr 2018 11:23:47 app_thread.py[line:128] ERROR this is an exception message
Traceback (most recent call last):
  File "E:\hupai\component\app_thread.py", line 125, in run
    findrefresh()
  File "E:\hupai\component\imgcut.py", line 383, in findrefresh
    img = cv2.cvtColor(sc, cv2.COLOR_BGR2GRAY)  # 转灰度图
cv2.error: C:\projects\opencv-python\opencv\modules\imgproc\src\color.cpp:11073: error: (-215) depth == 0 || depth == 2 || depth == 5 in function cv::cvtColor

Sun, 08 Apr 2018 11:23:47 imgcut.py[line:368] ERROR cut_img 这里出错
Sun, 08 Apr 2018 11:23:47 imgcut.py[line:369] ERROR this is an exception message
Traceback (most recent call last):
  File "E:\hupai\component\imgcut.py", line 361, in cut_img
    set_val('imgpos_lowestprice', img[use_area[0][1]:use_area[0][3], use_area[0][0]:use_area[0][2]])  # ok
IndexError: list index out of range
Sun, 08 Apr 2018 11:23:47 app_thread.py[line:127] ERROR 刷新失败
Sun, 08 Apr 2018 11:23:47 app_thread.py[line:128] ERROR this is an exception message
Traceback (most recent call last):
  File "E:\hupai\component\app_thread.py", line 125, in run
    findrefresh()
  File "E:\hupai\component\imgcut.py", line 383, in findrefresh
    img = cv2.cvtColor(sc, cv2.COLOR_BGR2GRAY)  # 转灰度图
cv2.error: C:\projects\opencv-python\opencv\modules\imgproc\src\color.cpp:11073: error: (-215) depth == 0 || depth == 2 || depth == 5 in function cv::cvtColor

Sun, 08 Apr 2018 11:23:47 app_thread.py[line:127] ERROR 刷新失败
Sun, 08 Apr 2018 11:23:47 app_thread.py[line:128] ERROR this is an exception message
Traceback (most recent call last):
  File "E:\hupai\component\app_thread.py", line 125, in run
    findrefresh()
  File "E:\hupai\component\imgcut.py", line 383, in findrefresh
    img = cv2.cvtColor(sc, cv2.COLOR_BGR2GRAY)  # 转灰度图
cv2.error: C:\projects\opencv-python\opencv\modules\imgproc\src\color.cpp:11073: error: (-215) depth == 0 || depth == 2 || depth == 5 in function cv::cvtColor

Sun, 08 Apr 2018 11:23:47 imgcut.py[line:368] ERROR cut_img 这里出错
Sun, 08 Apr 2018 11:23:47 imgcut.py[line:369] ERROR this is an exception message
Traceback (most recent call last):
  File "E:\hupai\component\imgcut.py", line 361, in cut_img
    set_val('imgpos_lowestprice', img[use_area[0][1]:use_area[0][3], use_area[0][0]:use_area[0][2]])  # ok
IndexError: list index out of range
Sun, 08 Apr 2018 11:23:48 app_thread.py[line:127] ERROR 刷新失败
Sun, 08 Apr 2018 11:23:48 app_thread.py[line:128] ERROR this is an exception message
Traceback (most recent call last):
  File "E:\hupai\component\app_thread.py", line 125, in run
    findrefresh()
  File "E:\hupai\component\imgcut.py", line 383, in findrefresh
    img = cv2.cvtColor(sc, cv2.COLOR_BGR2GRAY)  # 转灰度图
cv2.error: C:\projects\opencv-python\opencv\modules\imgproc\src\color.cpp:11073: error: (-215) depth == 0 || depth == 2 || depth == 5 in function cv::cvtColor

Sun, 08 Apr 2018 11:23:48 imgcut.py[line:368] ERROR cut_img 这里出错
Sun, 08 Apr 2018 11:23:48 imgcut.py[line:369] ERROR this is an exception message
Traceback (most recent call last):
  File "E:\hupai\component\imgcut.py", line 361, in cut_img
    set_val('imgpos_lowestprice', img[use_area[0][1]:use_area[0][3], use_area[0][0]:use_area[0][2]])  # ok
IndexError: list index out of range
Sun, 08 Apr 2018 11:23:48 app_thread.py[line:127] ERROR 刷新失败
Sun, 08 Apr 2018 11:23:48 app_thread.py[line:128] ERROR this is an exception message
Traceback (most recent call last):
  File "E:\hupai\component\app_thread.py", line 125, in run
    findrefresh()
  File "E:\hupai\component\imgcut.py", line 383, in findrefresh
    img = cv2.cvtColor(sc, cv2.COLOR_BGR2GRAY)  # 转灰度图
cv2.error: C:\projects\opencv-python\opencv\modules\imgproc\src\color.cpp:11073: error: (-215) depth == 0 || depth == 2 || depth == 5 in function cv::cvtColor

Sun, 08 Apr 2018 11:23:48 imgcut.py[line:368] ERROR cut_img 这里出错
Sun, 08 Apr 2018 11:23:48 imgcut.py[line:369] ERROR this is an exception message
Traceback (most recent call last):
  File "E:\hupai\component\imgcut.py", line 361, in cut_img
    set_val('imgpos_lowestprice', img[use_area[0][1]:use_area[0][3], use_area[0][0]:use_area[0][2]])  # ok
IndexError: list index out of range
Sun, 08 Apr 2018 11:23:48 app_thread.py[line:127] ERROR 刷新失败
Sun, 08 Apr 2018 11:23:48 app_thread.py[line:128] ERROR this is an exception message
Traceback (most recent call last):
  File "E:\hupai\component\app_thread.py", line 125, in run
    findrefresh()
  File "E:\hupai\component\imgcut.py", line 383, in findrefresh
    img = cv2.cvtColor(sc, cv2.COLOR_BGR2GRAY)  # 转灰度图
cv2.error: C:\projects\opencv-python\opencv\modules\imgproc\src\color.cpp:11073: error: (-215) depth == 0 || depth == 2 || depth == 5 in function cv::cvtColor

Sun, 08 Apr 2018 11:23:48 app_thread.py[line:127] ERROR 刷新失败
Sun, 08 Apr 2018 11:23:48 app_thread.py[line:128] ERROR this is an exception message
Traceback (most recent call last):
  File "E:\hupai\component\app_thread.py", line 125, in run
    findrefresh()
  File "E:\hupai\component\imgcut.py", line 383, in findrefresh
    img = cv2.cvtColor(sc, cv2.COLOR_BGR2GRAY)  # 转灰度图
cv2.error: C:\projects\opencv-python\opencv\modules\imgproc\src\color.cpp:11073: error: (-215) depth == 0 || depth == 2 || depth == 5 in function cv::cvtColor

Sun, 08 Apr 2018 11:23:48 imgcut.py[line:368] ERROR cut_img 这里出错
Sun, 08 Apr 2018 11:23:48 imgcut.py[line:369] ERROR this is an exception message
Traceback (most recent call last):
  File "E:\hupai\component\imgcut.py", line 361, in cut_img
    set_val('imgpos_lowestprice', img[use_area[0][1]:use_area[0][3], use_area[0][0]:use_area[0][2]])  # ok
IndexError: list index out of range
Sun, 08 Apr 2018 11:23:48 app_thread.py[line:127] ERROR 刷新失败
Sun, 08 Apr 2018 11:23:48 app_thread.py[line:128] ERROR this is an exception message
Traceback (most recent call last):
  File "E:\hupai\component\app_thread.py", line 125, in run
    findrefresh()
  File "E:\hupai\component\imgcut.py", line 383, in findrefresh
    img = cv2.cvtColor(sc, cv2.COLOR_BGR2GRAY)  # 转灰度图
cv2.error: C:\projects\opencv-python\opencv\modules\imgproc\src\color.cpp:11073: error: (-215) depth == 0 || depth == 2 || depth == 5 in function cv::cvtColor

Sun, 08 Apr 2018 11:23:48 app_thread.py[line:127] ERROR 刷新失败
Sun, 08 Apr 2018 11:23:48 imgcut.py[line:368] ERROR cut_img 这里出错
Sun, 08 Apr 2018 11:23:48 app_thread.py[line:128] ERROR this is an exception message
Traceback (most recent call last):
  File "E:\hupai\component\app_thread.py", line 125, in run
    findrefresh()
  File "E:\hupai\component\imgcut.py", line 383, in findrefresh
    img = cv2.cvtColor(sc, cv2.COLOR_BGR2GRAY)  # 转灰度图
cv2.error: C:\projects\opencv-python\opencv\modules\imgproc\src\color.cpp:11073: error: (-215) depth == 0 || depth == 2 || depth == 5 in function cv::cvtColor

Sun, 08 Apr 2018 11:23:48 imgcut.py[line:369] ERROR this is an exception message
Traceback (most recent call last):
  File "E:\hupai\component\imgcut.py", line 361, in cut_img
    set_val('imgpos_lowestprice', img[use_area[0][1]:use_area[0][3], use_area[0][0]:use_area[0][2]])  # ok
IndexError: list index out of range
Sun, 08 Apr 2018 11:23:48 app_thread.py[line:127] ERROR 刷新失败
Sun, 08 Apr 2018 11:23:48 app_thread.py[line:128] ERROR this is an exception message
Traceback (most recent call last):
  File "E:\hupai\component\app_thread.py", line 125, in run
    findrefresh()
  File "E:\hupai\component\imgcut.py", line 383, in findrefresh
    img = cv2.cvtColor(sc, cv2.COLOR_BGR2GRAY)  # 转灰度图
cv2.error: C:\projects\opencv-python\opencv\modules\imgproc\src\color.cpp:11073: error: (-215) depth == 0 || depth == 2 || depth == 5 in function cv::cvtColor

Sun, 08 Apr 2018 11:23:48 imgcut.py[line:368] ERROR cut_img 这里出错
Sun, 08 Apr 2018 11:23:48 imgcut.py[line:369] ERROR this is an exception message
Traceback (most recent call last):
  File "E:\hupai\component\imgcut.py", line 361, in cut_img
    set_val('imgpos_lowestprice', img[use_area[0][1]:use_area[0][3], use_area[0][0]:use_area[0][2]])  # ok
IndexError: list index out of range
Sun, 08 Apr 2018 11:23:48 app_thread.py[line:127] ERROR 刷新失败
Sun, 08 Apr 2018 11:23:48 app_thread.py[line:128] ERROR this is an exception message
Traceback (most recent call last):
  File "E:\hupai\component\app_thread.py", line 125, in run
    findrefresh()
  File "E:\hupai\component\imgcut.py", line 383, in findrefresh
    img = cv2.cvtColor(sc, cv2.COLOR_BGR2GRAY)  # 转灰度图
cv2.error: C:\projects\opencv-python\opencv\modules\imgproc\src\color.cpp:11073: error: (-215) depth == 0 || depth == 2 || depth == 5 in function cv::cvtColor

Sun, 08 Apr 2018 11:23:48 imgcut.py[line:368] ERROR cut_img 这里出错
Sun, 08 Apr 2018 11:23:48 imgcut.py[line:369] ERROR this is an exception message
Traceback (most recent call last):
  File "E:\hupai\component\imgcut.py", line 361, in cut_img
    set_val('imgpos_lowestprice', img[use_area[0][1]:use_area[0][3], use_area[0][0]:use_area[0][2]])  # ok
IndexError: list index out of range
Sun, 08 Apr 2018 11:23:48 app_thread.py[line:127] ERROR 刷新失败
Sun, 08 Apr 2018 11:23:48 app_thread.py[line:128] ERROR this is an exception message
Traceback (most recent call last):
  File "E:\hupai\component\app_thread.py", line 125, in run
    findrefresh()
  File "E:\hupai\component\imgcut.py", line 383, in findrefresh
    img = cv2.cvtColor(sc, cv2.COLOR_BGR2GRAY)  # 转灰度图
cv2.error: C:\projects\opencv-python\opencv\modules\imgproc\src\color.cpp:11073: error: (-215) depth == 0 || depth == 2 || depth == 5 in function cv::cvtColor

Sun, 08 Apr 2018 11:23:48 imgcut.py[line:368] ERROR cut_img 这里出错
Sun, 08 Apr 2018 11:23:48 imgcut.py[line:369] ERROR this is an exception message
Traceback (most recent call last):
  File "E:\hupai\component\imgcut.py", line 361, in cut_img
    set_val('imgpos_lowestprice', img[use_area[0][1]:use_area[0][3], use_area[0][0]:use_area[0][2]])  # ok
IndexError: list index out of range
Sun, 08 Apr 2018 11:23:48 app_thread.py[line:127] ERROR 刷新失败
Sun, 08 Apr 2018 11:23:48 app_thread.py[line:128] ERROR this is an exception message
Traceback (most recent call last):
  File "E:\hupai\component\app_thread.py", line 125, in run
    findrefresh()
  File "E:\hupai\component\imgcut.py", line 383, in findrefresh
    img = cv2.cvtColor(sc, cv2.COLOR_BGR2GRAY)  # 转灰度图
cv2.error: C:\projects\opencv-python\opencv\modules\imgproc\src\color.cpp:11073: error: (-215) depth == 0 || depth == 2 || depth == 5 in function cv::cvtColor

Sun, 08 Apr 2018 11:23:48 imgcut.py[line:368] ERROR cut_img 这里出错
Sun, 08 Apr 2018 11:23:48 imgcut.py[line:369] ERROR this is an exception message
Traceback (most recent call last):
  File "E:\hupai\component\imgcut.py", line 361, in cut_img
    set_val('imgpos_lowestprice', img[use_area[0][1]:use_area[0][3], use_area[0][0]:use_area[0][2]])  # ok
IndexError: list index out of range
Sun, 08 Apr 2018 11:23:48 app_thread.py[line:127] ERROR 刷新失败
Sun, 08 Apr 2018 11:23:48 app_thread.py[line:128] ERROR this is an exception message
Traceback (most recent call last):
  File "E:\hupai\component\app_thread.py", line 125, in run
    findrefresh()
  File "E:\hupai\component\imgcut.py", line 383, in findrefresh
    img = cv2.cvtColor(sc, cv2.COLOR_BGR2GRAY)  # 转灰度图
cv2.error: C:\projects\opencv-python\opencv\modules\imgproc\src\color.cpp:11073: error: (-215) depth == 0 || depth == 2 || depth == 5 in function cv::cvtColor

Sun, 08 Apr 2018 11:23:48 app_thread.py[line:127] ERROR 刷新失败
Sun, 08 Apr 2018 11:23:48 app_thread.py[line:128] ERROR this is an exception message
Traceback (most recent call last):
  File "E:\hupai\component\app_thread.py", line 125, in run
    findrefresh()
  File "E:\hupai\component\imgcut.py", line 383, in findrefresh
    img = cv2.cvtColor(sc, cv2.COLOR_BGR2GRAY)  # 转灰度图
cv2.error: C:\projects\opencv-python\opencv\modules\imgproc\src\color.cpp:11073: error: (-215) depth == 0 || depth == 2 || depth == 5 in function cv::cvtColor

Sun, 08 Apr 2018 11:23:48 imgcut.py[line:368] ERROR cut_img 这里出错
Sun, 08 Apr 2018 11:23:48 imgcut.py[line:369] ERROR this is an exception message
Traceback (most recent call last):
  File "E:\hupai\component\imgcut.py", line 361, in cut_img
    set_val('imgpos_lowestprice', img[use_area[0][1]:use_area[0][3], use_area[0][0]:use_area[0][2]])  # ok
IndexError: list index out of range
Sun, 08 Apr 2018 11:23:48 app_thread.py[line:127] ERROR 刷新失败
Sun, 08 Apr 2018 11:23:48 app_thread.py[line:128] ERROR this is an exception message
Traceback (most recent call last):
  File "E:\hupai\component\app_thread.py", line 125, in run
    findrefresh()
  File "E:\hupai\component\imgcut.py", line 383, in findrefresh
    img = cv2.cvtColor(sc, cv2.COLOR_BGR2GRAY)  # 转灰度图
cv2.error: C:\projects\opencv-python\opencv\modules\imgproc\src\color.cpp:11073: error: (-215) depth == 0 || depth == 2 || depth == 5 in function cv::cvtColor

Sun, 08 Apr 2018 11:23:48 imgcut.py[line:368] ERROR cut_img 这里出错
Sun, 08 Apr 2018 11:23:48 imgcut.py[line:369] ERROR this is an exception message
Traceback (most recent call last):
  File "E:\hupai\component\imgcut.py", line 361, in cut_img
    set_val('imgpos_lowestprice', img[use_area[0][1]:use_area[0][3], use_area[0][0]:use_area[0][2]])  # ok
IndexError: list index out of range
Sun, 08 Apr 2018 11:23:48 app_thread.py[line:127] ERROR 刷新失败
Sun, 08 Apr 2018 11:23:48 app_thread.py[line:128] ERROR this is an exception message
Traceback (most recent call last):
  File "E:\hupai\component\app_thread.py", line 125, in run
    findrefresh()
  File "E:\hupai\component\imgcut.py", line 383, in findrefresh
    img = cv2.cvtColor(sc, cv2.COLOR_BGR2GRAY)  # 转灰度图
cv2.error: C:\projects\opencv-python\opencv\modules\imgproc\src\color.cpp:11073: error: (-215) depth == 0 || depth == 2 || depth == 5 in function cv::cvtColor

Sun, 08 Apr 2018 11:23:48 imgcut.py[line:368] ERROR cut_img 这里出错
Sun, 08 Apr 2018 11:23:48 imgcut.py[line:369] ERROR this is an exception message
Traceback (most recent call last):
  File "E:\hupai\component\imgcut.py", line 361, in cut_img
    set_val('imgpos_lowestprice', img[use_area[0][1]:use_area[0][3], use_area[0][0]:use_area[0][2]])  # ok
IndexError: list index out of range
Sun, 08 Apr 2018 11:23:48 app_thread.py[line:127] ERROR 刷新失败
Sun, 08 Apr 2018 11:23:48 app_thread.py[line:128] ERROR this is an exception message
Traceback (most recent call last):
  File "E:\hupai\component\app_thread.py", line 125, in run
    findrefresh()
  File "E:\hupai\component\imgcut.py", line 383, in findrefresh
    img = cv2.cvtColor(sc, cv2.COLOR_BGR2GRAY)  # 转灰度图
cv2.error: C:\projects\opencv-python\opencv\modules\imgproc\src\color.cpp:11073: error: (-215) depth == 0 || depth == 2 || depth == 5 in function cv::cvtColor

Sun, 08 Apr 2018 11:23:49 imgcut.py[line:368] ERROR cut_img 这里出错
Sun, 08 Apr 2018 11:23:49 imgcut.py[line:369] ERROR this is an exception message
Traceback (most recent call last):
  File "E:\hupai\component\imgcut.py", line 361, in cut_img
    set_val('imgpos_lowestprice', img[use_area[0][1]:use_area[0][3], use_area[0][0]:use_area[0][2]])  # ok
IndexError: list index out of range
Sun, 08 Apr 2018 11:23:49 app_thread.py[line:127] ERROR 刷新失败
Sun, 08 Apr 2018 11:23:49 app_thread.py[line:128] ERROR this is an exception message
Traceback (most recent call last):
  File "E:\hupai\component\app_thread.py", line 125, in run
    findrefresh()
  File "E:\hupai\component\imgcut.py", line 383, in findrefresh
    img = cv2.cvtColor(sc, cv2.COLOR_BGR2GRAY)  # 转灰度图
cv2.error: C:\projects\opencv-python\opencv\modules\imgproc\src\color.cpp:11073: error: (-215) depth == 0 || depth == 2 || depth == 5 in function cv::cvtColor

Sun, 08 Apr 2018 11:23:49 imgcut.py[line:368] ERROR cut_img 这里出错
Sun, 08 Apr 2018 11:23:49 imgcut.py[line:369] ERROR this is an exception message
Traceback (most recent call last):
  File "E:\hupai\component\imgcut.py", line 361, in cut_img
    set_val('imgpos_lowestprice', img[use_area[0][1]:use_area[0][3], use_area[0][0]:use_area[0][2]])  # ok
IndexError: list index out of range
Sun, 08 Apr 2018 11:23:49 app_thread.py[line:127] ERROR 刷新失败
Sun, 08 Apr 2018 11:23:49 app_thread.py[line:128] ERROR this is an exception message
Traceback (most recent call last):
  File "E:\hupai\component\app_thread.py", line 125, in run
    findrefresh()
  File "E:\hupai\component\imgcut.py", line 383, in findrefresh
    img = cv2.cvtColor(sc, cv2.COLOR_BGR2GRAY)  # 转灰度图
cv2.error: C:\projects\opencv-python\opencv\modules\imgproc\src\color.cpp:11073: error: (-215) depth == 0 || depth == 2 || depth == 5 in function cv::cvtColor

Sun, 08 Apr 2018 11:23:49 app_thread.py[line:127] ERROR 刷新失败
Sun, 08 Apr 2018 11:23:49 app_thread.py[line:128] ERROR this is an exception message
Traceback (most recent call last):
  File "E:\hupai\component\app_thread.py", line 125, in run
    findrefresh()
  File "E:\hupai\component\imgcut.py", line 383, in findrefresh
    img = cv2.cvtColor(sc, cv2.COLOR_BGR2GRAY)  # 转灰度图
cv2.error: C:\projects\opencv-python\opencv\modules\imgproc\src\color.cpp:11073: error: (-215) depth == 0 || depth == 2 || depth == 5 in function cv::cvtColor

Sun, 08 Apr 2018 11:23:49 imgcut.py[line:368] ERROR cut_img 这里出错
Sun, 08 Apr 2018 11:23:49 imgcut.py[line:369] ERROR this is an exception message
Traceback (most recent call last):
  File "E:\hupai\component\imgcut.py", line 361, in cut_img
    set_val('imgpos_lowestprice', img[use_area[0][1]:use_area[0][3], use_area[0][0]:use_area[0][2]])  # ok
IndexError: list index out of range
Sun, 08 Apr 2018 11:23:49 app_thread.py[line:127] ERROR 刷新失败
Sun, 08 Apr 2018 11:23:49 app_thread.py[line:128] ERROR this is an exception message
Traceback (most recent call last):
  File "E:\hupai\component\app_thread.py", line 125, in run
    findrefresh()
  File "E:\hupai\component\imgcut.py", line 383, in findrefresh
    img = cv2.cvtColor(sc, cv2.COLOR_BGR2GRAY)  # 转灰度图
cv2.error: C:\projects\opencv-python\opencv\modules\imgproc\src\color.cpp:11073: error: (-215) depth == 0 || depth == 2 || depth == 5 in function cv::cvtColor

Sun, 08 Apr 2018 11:23:49 imgcut.py[line:368] ERROR cut_img 这里出错
Sun, 08 Apr 2018 11:23:49 imgcut.py[line:369] ERROR this is an exception message
Traceback (most recent call last):
  File "E:\hupai\component\imgcut.py", line 361, in cut_img
    set_val('imgpos_lowestprice', img[use_area[0][1]:use_area[0][3], use_area[0][0]:use_area[0][2]])  # ok
IndexError: list index out of range
Sun, 08 Apr 2018 11:23:49 app_thread.py[line:127] ERROR 刷新失败
Sun, 08 Apr 2018 11:23:49 app_thread.py[line:128] ERROR this is an exception message
Traceback (most recent call last):
  File "E:\hupai\component\app_thread.py", line 125, in run
    findrefresh()
  File "E:\hupai\component\imgcut.py", line 383, in findrefresh
    img = cv2.cvtColor(sc, cv2.COLOR_BGR2GRAY)  # 转灰度图
cv2.error: C:\projects\opencv-python\opencv\modules\imgproc\src\color.cpp:11073: error: (-215) depth == 0 || depth == 2 || depth == 5 in function cv::cvtColor

Sun, 08 Apr 2018 11:23:49 imgcut.py[line:368] ERROR cut_img 这里出错
Sun, 08 Apr 2018 11:23:49 imgcut.py[line:369] ERROR this is an exception message
Traceback (most recent call last):
  File "E:\hupai\component\imgcut.py", line 361, in cut_img
    set_val('imgpos_lowestprice', img[use_area[0][1]:use_area[0][3], use_area[0][0]:use_area[0][2]])  # ok
IndexError: list index out of range
Sun, 08 Apr 2018 11:23:49 app_thread.py[line:127] ERROR 刷新失败
Sun, 08 Apr 2018 11:23:49 app_thread.py[line:128] ERROR this is an exception message
Traceback (most recent call last):
  File "E:\hupai\component\app_thread.py", line 125, in run
    findrefresh()
  File "E:\hupai\component\imgcut.py", line 383, in findrefresh
    img = cv2.cvtColor(sc, cv2.COLOR_BGR2GRAY)  # 转灰度图
cv2.error: C:\projects\opencv-python\opencv\modules\imgproc\src\color.cpp:11073: error: (-215) depth == 0 || depth == 2 || depth == 5 in function cv::cvtColor

Sun, 08 Apr 2018 11:23:49 imgcut.py[line:368] ERROR cut_img 这里出错
Sun, 08 Apr 2018 11:23:49 imgcut.py[line:369] ERROR this is an exception message
Traceback (most recent call last):
  File "E:\hupai\component\imgcut.py", line 361, in cut_img
    set_val('imgpos_lowestprice', img[use_area[0][1]:use_area[0][3], use_area[0][0]:use_area[0][2]])  # ok
IndexError: list index out of range
Sun, 08 Apr 2018 11:23:49 app_thread.py[line:127] ERROR 刷新失败
Sun, 08 Apr 2018 11:23:49 app_thread.py[line:128] ERROR this is an exception message
Traceback (most recent call last):
  File "E:\hupai\component\app_thread.py", line 125, in run
    findrefresh()
  File "E:\hupai\component\imgcut.py", line 383, in findrefresh
    img = cv2.cvtColor(sc, cv2.COLOR_BGR2GRAY)  # 转灰度图
cv2.error: C:\projects\opencv-python\opencv\modules\imgproc\src\color.cpp:11073: error: (-215) depth == 0 || depth == 2 || depth == 5 in function cv::cvtColor

Sun, 08 Apr 2018 11:23:49 imgcut.py[line:368] ERROR cut_img 这里出错
Sun, 08 Apr 2018 11:23:49 imgcut.py[line:369] ERROR this is an exception message
Traceback (most recent call last):
  File "E:\hupai\component\imgcut.py", line 361, in cut_img
    set_val('imgpos_lowestprice', img[use_area[0][1]:use_area[0][3], use_area[0][0]:use_area[0][2]])  # ok
IndexError: list index out of range
Sun, 08 Apr 2018 11:23:49 app_thread.py[line:127] ERROR 刷新失败
Sun, 08 Apr 2018 11:23:49 app_thread.py[line:128] ERROR this is an exception message
Traceback (most recent call last):
  File "E:\hupai\component\app_thread.py", line 125, in run
    findrefresh()
  File "E:\hupai\component\imgcut.py", line 383, in findrefresh
    img = cv2.cvtColor(sc, cv2.COLOR_BGR2GRAY)  # 转灰度图
cv2.error: C:\projects\opencv-python\opencv\modules\imgproc\src\color.cpp:11073: error: (-215) depth == 0 || depth == 2 || depth == 5 in function cv::cvtColor

Sun, 08 Apr 2018 11:23:49 imgcut.py[line:368] ERROR cut_img 这里出错
Sun, 08 Apr 2018 11:23:49 imgcut.py[line:369] ERROR this is an exception message
Traceback (most recent call last):
  File "E:\hupai\component\imgcut.py", line 361, in cut_img
    set_val('imgpos_lowestprice', img[use_area[0][1]:use_area[0][3], use_area[0][0]:use_area[0][2]])  # ok
IndexError: list index out of range
Sun, 08 Apr 2018 11:23:49 app_thread.py[line:127] ERROR 刷新失败
Sun, 08 Apr 2018 11:23:49 app_thread.py[line:128] ERROR this is an exception message
Traceback (most recent call last):
  File "E:\hupai\component\app_thread.py", line 125, in run
    findrefresh()
  File "E:\hupai\component\imgcut.py", line 383, in findrefresh
    img = cv2.cvtColor(sc, cv2.COLOR_BGR2GRAY)  # 转灰度图
cv2.error: C:\projects\opencv-python\opencv\modules\imgproc\src\color.cpp:11073: error: (-215) depth == 0 || depth == 2 || depth == 5 in function cv::cvtColor

Sun, 08 Apr 2018 11:23:49 imgcut.py[line:368] ERROR cut_img 这里出错
Sun, 08 Apr 2018 11:23:49 imgcut.py[line:369] ERROR this is an exception message
Traceback (most recent call last):
  File "E:\hupai\component\imgcut.py", line 361, in cut_img
    set_val('imgpos_lowestprice', img[use_area[0][1]:use_area[0][3], use_area[0][0]:use_area[0][2]])  # ok
IndexError: list index out of range
Sun, 08 Apr 2018 11:23:49 app_thread.py[line:127] ERROR 刷新失败
Sun, 08 Apr 2018 11:23:49 app_thread.py[line:128] ERROR this is an exception message
Traceback (most recent call last):
  File "E:\hupai\component\app_thread.py", line 125, in run
    findrefresh()
  File "E:\hupai\component\imgcut.py", line 383, in findrefresh
    img = cv2.cvtColor(sc, cv2.COLOR_BGR2GRAY)  # 转灰度图
cv2.error: C:\projects\opencv-python\opencv\modules\imgproc\src\color.cpp:11073: error: (-215) depth == 0 || depth == 2 || depth == 5 in function cv::cvtColor

Sun, 08 Apr 2018 11:23:49 imgcut.py[line:368] ERROR cut_img 这里出错
Sun, 08 Apr 2018 11:23:49 imgcut.py[line:369] ERROR this is an exception message
Traceback (most recent call last):
  File "E:\hupai\component\imgcut.py", line 361, in cut_img
    set_val('imgpos_lowestprice', img[use_area[0][1]:use_area[0][3], use_area[0][0]:use_area[0][2]])  # ok
IndexError: list index out of range
Sun, 08 Apr 2018 11:23:49 app_thread.py[line:127] ERROR 刷新失败
Sun, 08 Apr 2018 11:23:49 app_thread.py[line:128] ERROR this is an exception message
Traceback (most recent call last):
  File "E:\hupai\component\app_thread.py", line 125, in run
    findrefresh()
  File "E:\hupai\component\imgcut.py", line 383, in findrefresh
    img = cv2.cvtColor(sc, cv2.COLOR_BGR2GRAY)  # 转灰度图
cv2.error: C:\projects\opencv-python\opencv\modules\imgproc\src\color.cpp:11073: error: (-215) depth == 0 || depth == 2 || depth == 5 in function cv::cvtColor

Sun, 08 Apr 2018 11:23:49 imgcut.py[line:368] ERROR cut_img 这里出错
Sun, 08 Apr 2018 11:23:49 imgcut.py[line:369] ERROR this is an exception message
Traceback (most recent call last):
  File "E:\hupai\component\imgcut.py", line 361, in cut_img
    set_val('imgpos_lowestprice', img[use_area[0][1]:use_area[0][3], use_area[0][0]:use_area[0][2]])  # ok
IndexError: list index out of range
Sun, 08 Apr 2018 11:23:49 app_thread.py[line:127] ERROR 刷新失败
Sun, 08 Apr 2018 11:23:49 app_thread.py[line:128] ERROR this is an exception message
Traceback (most recent call last):
  File "E:\hupai\component\app_thread.py", line 125, in run
    findrefresh()
  File "E:\hupai\component\imgcut.py", line 383, in findrefresh
    img = cv2.cvtColor(sc, cv2.COLOR_BGR2GRAY)  # 转灰度图
cv2.error: C:\projects\opencv-python\opencv\modules\imgproc\src\color.cpp:11073: error: (-215) depth == 0 || depth == 2 || depth == 5 in function cv::cvtColor

Sun, 08 Apr 2018 11:23:49 app_thread.py[line:127] ERROR 刷新失败
Sun, 08 Apr 2018 11:23:49 app_thread.py[line:128] ERROR this is an exception message
Traceback (most recent call last):
  File "E:\hupai\component\app_thread.py", line 125, in run
    findrefresh()
  File "E:\hupai\component\imgcut.py", line 383, in findrefresh
    img = cv2.cvtColor(sc, cv2.COLOR_BGR2GRAY)  # 转灰度图
cv2.error: C:\projects\opencv-python\opencv\modules\imgproc\src\color.cpp:11073: error: (-215) depth == 0 || depth == 2 || depth == 5 in function cv::cvtColor

Sun, 08 Apr 2018 11:23:49 imgcut.py[line:368] ERROR cut_img 这里出错
Sun, 08 Apr 2018 11:23:49 imgcut.py[line:369] ERROR this is an exception message
Traceback (most recent call last):
  File "E:\hupai\component\imgcut.py", line 361, in cut_img
    set_val('imgpos_lowestprice', img[use_area[0][1]:use_area[0][3], use_area[0][0]:use_area[0][2]])  # ok
IndexError: list index out of range
Sun, 08 Apr 2018 11:23:49 app_thread.py[line:127] ERROR 刷新失败
Sun, 08 Apr 2018 11:23:49 app_thread.py[line:128] ERROR this is an exception message
Traceback (most recent call last):
  File "E:\hupai\component\app_thread.py", line 125, in run
    findrefresh()
  File "E:\hupai\component\imgcut.py", line 383, in findrefresh
    img = cv2.cvtColor(sc, cv2.COLOR_BGR2GRAY)  # 转灰度图
cv2.error: C:\projects\opencv-python\opencv\modules\imgproc\src\color.cpp:11073: error: (-215) depth == 0 || depth == 2 || depth == 5 in function cv::cvtColor

Sun, 08 Apr 2018 11:23:49 imgcut.py[line:368] ERROR cut_img 这里出错
Sun, 08 Apr 2018 11:23:49 imgcut.py[line:369] ERROR this is an exception message
Traceback (most recent call last):
  File "E:\hupai\component\imgcut.py", line 361, in cut_img
    set_val('imgpos_lowestprice', img[use_area[0][1]:use_area[0][3], use_area[0][0]:use_area[0][2]])  # ok
IndexError: list index out of range
Sun, 08 Apr 2018 11:23:49 app_thread.py[line:127] ERROR 刷新失败
Sun, 08 Apr 2018 11:23:49 app_thread.py[line:128] ERROR this is an exception message
Traceback (most recent call last):
  File "E:\hupai\component\app_thread.py", line 125, in run
    findrefresh()
  File "E:\hupai\component\imgcut.py", line 383, in findrefresh
    img = cv2.cvtColor(sc, cv2.COLOR_BGR2GRAY)  # 转灰度图
cv2.error: C:\projects\opencv-python\opencv\modules\imgproc\src\color.cpp:11073: error: (-215) depth == 0 || depth == 2 || depth == 5 in function cv::cvtColor

Sun, 08 Apr 2018 11:23:50 imgcut.py[line:368] ERROR cut_img 这里出错
Sun, 08 Apr 2018 11:23:50 imgcut.py[line:369] ERROR this is an exception message
Traceback (most recent call last):
  File "E:\hupai\component\imgcut.py", line 361, in cut_img
    set_val('imgpos_lowestprice', img[use_area[0][1]:use_area[0][3], use_area[0][0]:use_area[0][2]])  # ok
IndexError: list index out of range
Sun, 08 Apr 2018 11:23:50 app_thread.py[line:127] ERROR 刷新失败
Sun, 08 Apr 2018 11:23:50 app_thread.py[line:128] ERROR this is an exception message
Traceback (most recent call last):
  File "E:\hupai\component\app_thread.py", line 125, in run
    findrefresh()
  File "E:\hupai\component\imgcut.py", line 383, in findrefresh
    img = cv2.cvtColor(sc, cv2.COLOR_BGR2GRAY)  # 转灰度图
cv2.error: C:\projects\opencv-python\opencv\modules\imgproc\src\color.cpp:11073: error: (-215) depth == 0 || depth == 2 || depth == 5 in function cv::cvtColor

Sun, 08 Apr 2018 11:23:50 imgcut.py[line:368] ERROR cut_img 这里出错
Sun, 08 Apr 2018 11:23:50 imgcut.py[line:369] ERROR this is an exception message
Traceback (most recent call last):
  File "E:\hupai\component\imgcut.py", line 361, in cut_img
    set_val('imgpos_lowestprice', img[use_area[0][1]:use_area[0][3], use_area[0][0]:use_area[0][2]])  # ok
IndexError: list index out of range
Sun, 08 Apr 2018 11:23:50 app_thread.py[line:127] ERROR 刷新失败
Sun, 08 Apr 2018 11:23:50 app_thread.py[line:128] ERROR this is an exception message
Traceback (most recent call last):
  File "E:\hupai\component\app_thread.py", line 125, in run
    findrefresh()
  File "E:\hupai\component\imgcut.py", line 383, in findrefresh
    img = cv2.cvtColor(sc, cv2.COLOR_BGR2GRAY)  # 转灰度图
cv2.error: C:\projects\opencv-python\opencv\modules\imgproc\src\color.cpp:11073: error: (-215) depth == 0 || depth == 2 || depth == 5 in function cv::cvtColor

Sun, 08 Apr 2018 11:23:50 imgcut.py[line:368] ERROR cut_img 这里出错
Sun, 08 Apr 2018 11:23:50 imgcut.py[line:369] ERROR this is an exception message
Traceback (most recent call last):
  File "E:\hupai\component\imgcut.py", line 361, in cut_img
    set_val('imgpos_lowestprice', img[use_area[0][1]:use_area[0][3], use_area[0][0]:use_area[0][2]])  # ok
IndexError: list index out of range
Sun, 08 Apr 2018 11:23:50 app_thread.py[line:127] ERROR 刷新失败
Sun, 08 Apr 2018 11:23:50 app_thread.py[line:128] ERROR this is an exception message
Traceback (most recent call last):
  File "E:\hupai\component\app_thread.py", line 125, in run
    findrefresh()
  File "E:\hupai\component\imgcut.py", line 383, in findrefresh
    img = cv2.cvtColor(sc, cv2.COLOR_BGR2GRAY)  # 转灰度图
cv2.error: C:\projects\opencv-python\opencv\modules\imgproc\src\color.cpp:11073: error: (-215) depth == 0 || depth == 2 || depth == 5 in function cv::cvtColor

Sun, 08 Apr 2018 11:23:50 imgcut.py[line:368] ERROR cut_img 这里出错
Sun, 08 Apr 2018 11:23:50 app_thread.py[line:127] ERROR 刷新失败
Sun, 08 Apr 2018 11:23:50 imgcut.py[line:369] ERROR this is an exception message
Traceback (most recent call last):
  File "E:\hupai\component\imgcut.py", line 361, in cut_img
    set_val('imgpos_lowestprice', img[use_area[0][1]:use_area[0][3], use_area[0][0]:use_area[0][2]])  # ok
IndexError: list index out of range
Sun, 08 Apr 2018 11:23:50 app_thread.py[line:128] ERROR this is an exception message
Traceback (most recent call last):
  File "E:\hupai\component\app_thread.py", line 125, in run
    findrefresh()
  File "E:\hupai\component\imgcut.py", line 383, in findrefresh
    img = cv2.cvtColor(sc, cv2.COLOR_BGR2GRAY)  # 转灰度图
cv2.error: C:\projects\opencv-python\opencv\modules\imgproc\src\color.cpp:11073: error: (-215) depth == 0 || depth == 2 || depth == 5 in function cv::cvtColor

Sun, 08 Apr 2018 11:23:50 app_thread.py[line:127] ERROR 刷新失败
Sun, 08 Apr 2018 11:23:50 app_thread.py[line:128] ERROR this is an exception message
Traceback (most recent call last):
  File "E:\hupai\component\app_thread.py", line 125, in run
    findrefresh()
  File "E:\hupai\component\imgcut.py", line 383, in findrefresh
    img = cv2.cvtColor(sc, cv2.COLOR_BGR2GRAY)  # 转灰度图
cv2.error: C:\projects\opencv-python\opencv\modules\imgproc\src\color.cpp:11073: error: (-215) depth == 0 || depth == 2 || depth == 5 in function cv::cvtColor

Sun, 08 Apr 2018 11:23:50 imgcut.py[line:368] ERROR cut_img 这里出错
Sun, 08 Apr 2018 11:23:50 imgcut.py[line:369] ERROR this is an exception message
Traceback (most recent call last):
  File "E:\hupai\component\imgcut.py", line 361, in cut_img
    set_val('imgpos_lowestprice', img[use_area[0][1]:use_area[0][3], use_area[0][0]:use_area[0][2]])  # ok
IndexError: list index out of range
Sun, 08 Apr 2018 11:23:50 app_thread.py[line:127] ERROR 刷新失败
Sun, 08 Apr 2018 11:23:50 app_thread.py[line:128] ERROR this is an exception message
Traceback (most recent call last):
  File "E:\hupai\component\app_thread.py", line 125, in run
    findrefresh()
  File "E:\hupai\component\imgcut.py", line 383, in findrefresh
    img = cv2.cvtColor(sc, cv2.COLOR_BGR2GRAY)  # 转灰度图
cv2.error: C:\projects\opencv-python\opencv\modules\imgproc\src\color.cpp:11073: error: (-215) depth == 0 || depth == 2 || depth == 5 in function cv::cvtColor

Sun, 08 Apr 2018 11:23:50 imgcut.py[line:368] ERROR cut_img 这里出错
Sun, 08 Apr 2018 11:23:50 imgcut.py[line:369] ERROR this is an exception message
Traceback (most recent call last):
  File "E:\hupai\component\imgcut.py", line 361, in cut_img
    set_val('imgpos_lowestprice', img[use_area[0][1]:use_area[0][3], use_area[0][0]:use_area[0][2]])  # ok
IndexError: list index out of range
Sun, 08 Apr 2018 11:23:50 app_thread.py[line:127] ERROR 刷新失败
Sun, 08 Apr 2018 11:23:50 app_thread.py[line:128] ERROR this is an exception message
Traceback (most recent call last):
  File "E:\hupai\component\app_thread.py", line 125, in run
    findrefresh()
  File "E:\hupai\component\imgcut.py", line 383, in findrefresh
    img = cv2.cvtColor(sc, cv2.COLOR_BGR2GRAY)  # 转灰度图
cv2.error: C:\projects\opencv-python\opencv\modules\imgproc\src\color.cpp:11073: error: (-215) depth == 0 || depth == 2 || depth == 5 in function cv::cvtColor

Sun, 08 Apr 2018 11:23:50 app_thread.py[line:127] ERROR 刷新失败
Sun, 08 Apr 2018 11:23:50 app_thread.py[line:128] ERROR this is an exception message
Traceback (most recent call last):
  File "E:\hupai\component\app_thread.py", line 125, in run
    findrefresh()
  File "E:\hupai\component\imgcut.py", line 383, in findrefresh
    img = cv2.cvtColor(sc, cv2.COLOR_BGR2GRAY)  # 转灰度图
cv2.error: C:\projects\opencv-python\opencv\modules\imgproc\src\color.cpp:11073: error: (-215) depth == 0 || depth == 2 || depth == 5 in function cv::cvtColor

Sun, 08 Apr 2018 11:23:50 imgcut.py[line:368] ERROR cut_img 这里出错
Sun, 08 Apr 2018 11:23:50 imgcut.py[line:369] ERROR this is an exception message
Traceback (most recent call last):
  File "E:\hupai\component\imgcut.py", line 361, in cut_img
    set_val('imgpos_lowestprice', img[use_area[0][1]:use_area[0][3], use_area[0][0]:use_area[0][2]])  # ok
IndexError: list index out of range
Sun, 08 Apr 2018 11:23:50 app_thread.py[line:127] ERROR 刷新失败
Sun, 08 Apr 2018 11:23:50 app_thread.py[line:128] ERROR this is an exception message
Traceback (most recent call last):
  File "E:\hupai\component\app_thread.py", line 125, in run
    findrefresh()
  File "E:\hupai\component\imgcut.py", line 383, in findrefresh
    img = cv2.cvtColor(sc, cv2.COLOR_BGR2GRAY)  # 转灰度图
cv2.error: C:\projects\opencv-python\opencv\modules\imgproc\src\color.cpp:11073: error: (-215) depth == 0 || depth == 2 || depth == 5 in function cv::cvtColor

Sun, 08 Apr 2018 11:23:50 imgcut.py[line:368] ERROR cut_img 这里出错
Sun, 08 Apr 2018 11:23:50 imgcut.py[line:369] ERROR this is an exception message
Traceback (most recent call last):
  File "E:\hupai\component\imgcut.py", line 361, in cut_img
    set_val('imgpos_lowestprice', img[use_area[0][1]:use_area[0][3], use_area[0][0]:use_area[0][2]])  # ok
IndexError: list index out of range
Sun, 08 Apr 2018 11:23:50 app_thread.py[line:127] ERROR 刷新失败
Sun, 08 Apr 2018 11:23:50 app_thread.py[line:128] ERROR this is an exception message
Traceback (most recent call last):
  File "E:\hupai\component\app_thread.py", line 125, in run
    findrefresh()
  File "E:\hupai\component\imgcut.py", line 383, in findrefresh
    img = cv2.cvtColor(sc, cv2.COLOR_BGR2GRAY)  # 转灰度图
cv2.error: C:\projects\opencv-python\opencv\modules\imgproc\src\color.cpp:11073: error: (-215) depth == 0 || depth == 2 || depth == 5 in function cv::cvtColor

Sun, 08 Apr 2018 11:23:50 imgcut.py[line:368] ERROR cut_img 这里出错
Sun, 08 Apr 2018 11:23:50 imgcut.py[line:369] ERROR this is an exception message
Traceback (most recent call last):
  File "E:\hupai\component\imgcut.py", line 361, in cut_img
    set_val('imgpos_lowestprice', img[use_area[0][1]:use_area[0][3], use_area[0][0]:use_area[0][2]])  # ok
IndexError: list index out of range
Sun, 08 Apr 2018 11:23:50 app_thread.py[line:127] ERROR 刷新失败
Sun, 08 Apr 2018 11:23:50 app_thread.py[line:128] ERROR this is an exception message
Traceback (most recent call last):
  File "E:\hupai\component\app_thread.py", line 125, in run
    findrefresh()
  File "E:\hupai\component\imgcut.py", line 383, in findrefresh
    img = cv2.cvtColor(sc, cv2.COLOR_BGR2GRAY)  # 转灰度图
cv2.error: C:\projects\opencv-python\opencv\modules\imgproc\src\color.cpp:11073: error: (-215) depth == 0 || depth == 2 || depth == 5 in function cv::cvtColor

Sun, 08 Apr 2018 11:23:50 app_thread.py[line:127] ERROR 刷新失败
Sun, 08 Apr 2018 11:23:50 imgcut.py[line:368] ERROR cut_img 这里出错
Sun, 08 Apr 2018 11:23:50 app_thread.py[line:128] ERROR this is an exception message
Traceback (most recent call last):
  File "E:\hupai\component\app_thread.py", line 125, in run
    findrefresh()
  File "E:\hupai\component\imgcut.py", line 383, in findrefresh
    img = cv2.cvtColor(sc, cv2.COLOR_BGR2GRAY)  # 转灰度图
cv2.error: C:\projects\opencv-python\opencv\modules\imgproc\src\color.cpp:11073: error: (-215) depth == 0 || depth == 2 || depth == 5 in function cv::cvtColor

Sun, 08 Apr 2018 11:23:50 imgcut.py[line:369] ERROR this is an exception message
Traceback (most recent call last):
  File "E:\hupai\component\imgcut.py", line 361, in cut_img
    set_val('imgpos_lowestprice', img[use_area[0][1]:use_area[0][3], use_area[0][0]:use_area[0][2]])  # ok
IndexError: list index out of range
Sun, 08 Apr 2018 11:23:50 app_thread.py[line:127] ERROR 刷新失败
Sun, 08 Apr 2018 11:23:50 app_thread.py[line:128] ERROR this is an exception message
Traceback (most recent call last):
  File "E:\hupai\component\app_thread.py", line 125, in run
    findrefresh()
  File "E:\hupai\component\imgcut.py", line 383, in findrefresh
    img = cv2.cvtColor(sc, cv2.COLOR_BGR2GRAY)  # 转灰度图
cv2.error: C:\projects\opencv-python\opencv\modules\imgproc\src\color.cpp:11073: error: (-215) depth == 0 || depth == 2 || depth == 5 in function cv::cvtColor

Sun, 08 Apr 2018 11:23:50 imgcut.py[line:368] ERROR cut_img 这里出错
Sun, 08 Apr 2018 11:23:50 imgcut.py[line:369] ERROR this is an exception message
Traceback (most recent call last):
  File "E:\hupai\component\imgcut.py", line 361, in cut_img
    set_val('imgpos_lowestprice', img[use_area[0][1]:use_area[0][3], use_area[0][0]:use_area[0][2]])  # ok
IndexError: list index out of range
Sun, 08 Apr 2018 11:23:50 app_thread.py[line:127] ERROR 刷新失败
Sun, 08 Apr 2018 11:23:50 app_thread.py[line:128] ERROR this is an exception message
Traceback (most recent call last):
  File "E:\hupai\component\app_thread.py", line 125, in run
    findrefresh()
  File "E:\hupai\component\imgcut.py", line 383, in findrefresh
    img = cv2.cvtColor(sc, cv2.COLOR_BGR2GRAY)  # 转灰度图
cv2.error: C:\projects\opencv-python\opencv\modules\imgproc\src\color.cpp:11073: error: (-215) depth == 0 || depth == 2 || depth == 5 in function cv::cvtColor

Sun, 08 Apr 2018 11:23:50 imgcut.py[line:368] ERROR cut_img 这里出错
Sun, 08 Apr 2018 11:23:50 imgcut.py[line:369] ERROR this is an exception message
Traceback (most recent call last):
  File "E:\hupai\component\imgcut.py", line 361, in cut_img
    set_val('imgpos_lowestprice', img[use_area[0][1]:use_area[0][3], use_area[0][0]:use_area[0][2]])  # ok
IndexError: list index out of range
Sun, 08 Apr 2018 11:23:50 app_thread.py[line:127] ERROR 刷新失败
Sun, 08 Apr 2018 11:23:50 app_thread.py[line:128] ERROR this is an exception message
Traceback (most recent call last):
  File "E:\hupai\component\app_thread.py", line 125, in run
    findrefresh()
  File "E:\hupai\component\imgcut.py", line 383, in findrefresh
    img = cv2.cvtColor(sc, cv2.COLOR_BGR2GRAY)  # 转灰度图
cv2.error: C:\projects\opencv-python\opencv\modules\imgproc\src\color.cpp:11073: error: (-215) depth == 0 || depth == 2 || depth == 5 in function cv::cvtColor

Sun, 08 Apr 2018 11:23:51 imgcut.py[line:368] ERROR cut_img 这里出错
Sun, 08 Apr 2018 11:23:51 imgcut.py[line:369] ERROR this is an exception message
Traceback (most recent call last):
  File "E:\hupai\component\imgcut.py", line 361, in cut_img
    set_val('imgpos_lowestprice', img[use_area[0][1]:use_area[0][3], use_area[0][0]:use_area[0][2]])  # ok
IndexError: list index out of range
Sun, 08 Apr 2018 11:23:51 app_thread.py[line:127] ERROR 刷新失败
Sun, 08 Apr 2018 11:23:51 app_thread.py[line:128] ERROR this is an exception message
Traceback (most recent call last):
  File "E:\hupai\component\app_thread.py", line 125, in run
    findrefresh()
  File "E:\hupai\component\imgcut.py", line 383, in findrefresh
    img = cv2.cvtColor(sc, cv2.COLOR_BGR2GRAY)  # 转灰度图
cv2.error: C:\projects\opencv-python\opencv\modules\imgproc\src\color.cpp:11073: error: (-215) depth == 0 || depth == 2 || depth == 5 in function cv::cvtColor

Sun, 08 Apr 2018 11:23:51 app_thread.py[line:127] ERROR 刷新失败
Sun, 08 Apr 2018 11:23:51 app_thread.py[line:128] ERROR this is an exception message
Traceback (most recent call last):
  File "E:\hupai\component\app_thread.py", line 125, in run
    findrefresh()
  File "E:\hupai\component\imgcut.py", line 383, in findrefresh
    img = cv2.cvtColor(sc, cv2.COLOR_BGR2GRAY)  # 转灰度图
cv2.error: C:\projects\opencv-python\opencv\modules\imgproc\src\color.cpp:11073: error: (-215) depth == 0 || depth == 2 || depth == 5 in function cv::cvtColor

Sun, 08 Apr 2018 11:23:51 imgcut.py[line:368] ERROR cut_img 这里出错
Sun, 08 Apr 2018 11:23:51 imgcut.py[line:369] ERROR this is an exception message
Traceback (most recent call last):
  File "E:\hupai\component\imgcut.py", line 361, in cut_img
    set_val('imgpos_lowestprice', img[use_area[0][1]:use_area[0][3], use_area[0][0]:use_area[0][2]])  # ok
IndexError: list index out of range
Sun, 08 Apr 2018 11:23:51 app_thread.py[line:127] ERROR 刷新失败
Sun, 08 Apr 2018 11:23:51 app_thread.py[line:128] ERROR this is an exception message
Traceback (most recent call last):
  File "E:\hupai\component\app_thread.py", line 125, in run
    findrefresh()
  File "E:\hupai\component\imgcut.py", line 383, in findrefresh
    img = cv2.cvtColor(sc, cv2.COLOR_BGR2GRAY)  # 转灰度图
cv2.error: C:\projects\opencv-python\opencv\modules\imgproc\src\color.cpp:11073: error: (-215) depth == 0 || depth == 2 || depth == 5 in function cv::cvtColor

Sun, 08 Apr 2018 11:23:51 imgcut.py[line:368] ERROR cut_img 这里出错
Sun, 08 Apr 2018 11:23:51 imgcut.py[line:369] ERROR this is an exception message
Traceback (most recent call last):
  File "E:\hupai\component\imgcut.py", line 361, in cut_img
    set_val('imgpos_lowestprice', img[use_area[0][1]:use_area[0][3], use_area[0][0]:use_area[0][2]])  # ok
IndexError: list index out of range
Sun, 08 Apr 2018 11:23:51 app_thread.py[line:127] ERROR 刷新失败
Sun, 08 Apr 2018 11:23:51 app_thread.py[line:128] ERROR this is an exception message
Traceback (most recent call last):
  File "E:\hupai\component\app_thread.py", line 125, in run
    findrefresh()
  File "E:\hupai\component\imgcut.py", line 383, in findrefresh
    img = cv2.cvtColor(sc, cv2.COLOR_BGR2GRAY)  # 转灰度图
cv2.error: C:\projects\opencv-python\opencv\modules\imgproc\src\color.cpp:11073: error: (-215) depth == 0 || depth == 2 || depth == 5 in function cv::cvtColor

Sun, 08 Apr 2018 11:23:51 app_thread.py[line:127] ERROR 刷新失败
Sun, 08 Apr 2018 11:23:51 app_thread.py[line:128] ERROR this is an exception message
Traceback (most recent call last):
  File "E:\hupai\component\app_thread.py", line 125, in run
    findrefresh()
  File "E:\hupai\component\imgcut.py", line 383, in findrefresh
    img = cv2.cvtColor(sc, cv2.COLOR_BGR2GRAY)  # 转灰度图
cv2.error: C:\projects\opencv-python\opencv\modules\imgproc\src\color.cpp:11073: error: (-215) depth == 0 || depth == 2 || depth == 5 in function cv::cvtColor

Sun, 08 Apr 2018 11:23:51 imgcut.py[line:368] ERROR cut_img 这里出错
Sun, 08 Apr 2018 11:23:51 imgcut.py[line:369] ERROR this is an exception message
Traceback (most recent call last):
  File "E:\hupai\component\imgcut.py", line 361, in cut_img
    set_val('imgpos_lowestprice', img[use_area[0][1]:use_area[0][3], use_area[0][0]:use_area[0][2]])  # ok
IndexError: list index out of range
Sun, 08 Apr 2018 11:23:51 app_thread.py[line:127] ERROR 刷新失败
Sun, 08 Apr 2018 11:23:51 app_thread.py[line:128] ERROR this is an exception message
Traceback (most recent call last):
  File "E:\hupai\component\app_thread.py", line 125, in run
    findrefresh()
  File "E:\hupai\component\imgcut.py", line 383, in findrefresh
    img = cv2.cvtColor(sc, cv2.COLOR_BGR2GRAY)  # 转灰度图
cv2.error: C:\projects\opencv-python\opencv\modules\imgproc\src\color.cpp:11073: error: (-215) depth == 0 || depth == 2 || depth == 5 in function cv::cvtColor

Sun, 08 Apr 2018 11:23:51 imgcut.py[line:368] ERROR cut_img 这里出错
Sun, 08 Apr 2018 11:23:51 imgcut.py[line:369] ERROR this is an exception message
Traceback (most recent call last):
  File "E:\hupai\component\imgcut.py", line 361, in cut_img
    set_val('imgpos_lowestprice', img[use_area[0][1]:use_area[0][3], use_area[0][0]:use_area[0][2]])  # ok
IndexError: list index out of range
Sun, 08 Apr 2018 11:23:51 app_thread.py[line:127] ERROR 刷新失败
Sun, 08 Apr 2018 11:23:51 app_thread.py[line:128] ERROR this is an exception message
Traceback (most recent call last):
  File "E:\hupai\component\app_thread.py", line 125, in run
    findrefresh()
  File "E:\hupai\component\imgcut.py", line 383, in findrefresh
    img = cv2.cvtColor(sc, cv2.COLOR_BGR2GRAY)  # 转灰度图
cv2.error: C:\projects\opencv-python\opencv\modules\imgproc\src\color.cpp:11073: error: (-215) depth == 0 || depth == 2 || depth == 5 in function cv::cvtColor

Sun, 08 Apr 2018 11:23:51 imgcut.py[line:368] ERROR cut_img 这里出错
Sun, 08 Apr 2018 11:23:51 imgcut.py[line:369] ERROR this is an exception message
Traceback (most recent call last):
  File "E:\hupai\component\imgcut.py", line 361, in cut_img
    set_val('imgpos_lowestprice', img[use_area[0][1]:use_area[0][3], use_area[0][0]:use_area[0][2]])  # ok
IndexError: list index out of range
Sun, 08 Apr 2018 11:23:51 app_thread.py[line:127] ERROR 刷新失败
Sun, 08 Apr 2018 11:23:51 app_thread.py[line:128] ERROR this is an exception message
Traceback (most recent call last):
  File "E:\hupai\component\app_thread.py", line 125, in run
    findrefresh()
  File "E:\hupai\component\imgcut.py", line 383, in findrefresh
    img = cv2.cvtColor(sc, cv2.COLOR_BGR2GRAY)  # 转灰度图
cv2.error: C:\projects\opencv-python\opencv\modules\imgproc\src\color.cpp:11073: error: (-215) depth == 0 || depth == 2 || depth == 5 in function cv::cvtColor

Sun, 08 Apr 2018 11:23:51 imgcut.py[line:368] ERROR cut_img 这里出错
Sun, 08 Apr 2018 11:23:51 imgcut.py[line:369] ERROR this is an exception message
Traceback (most recent call last):
  File "E:\hupai\component\imgcut.py", line 361, in cut_img
    set_val('imgpos_lowestprice', img[use_area[0][1]:use_area[0][3], use_area[0][0]:use_area[0][2]])  # ok
IndexError: list index out of range
Sun, 08 Apr 2018 11:23:51 app_thread.py[line:127] ERROR 刷新失败
Sun, 08 Apr 2018 11:23:51 app_thread.py[line:128] ERROR this is an exception message
Traceback (most recent call last):
  File "E:\hupai\component\app_thread.py", line 125, in run
    findrefresh()
  File "E:\hupai\component\imgcut.py", line 383, in findrefresh
    img = cv2.cvtColor(sc, cv2.COLOR_BGR2GRAY)  # 转灰度图
cv2.error: C:\projects\opencv-python\opencv\modules\imgproc\src\color.cpp:11073: error: (-215) depth == 0 || depth == 2 || depth == 5 in function cv::cvtColor

Sun, 08 Apr 2018 11:23:51 app_thread.py[line:127] ERROR 刷新失败
Sun, 08 Apr 2018 11:23:51 app_thread.py[line:128] ERROR this is an exception message
Traceback (most recent call last):
  File "E:\hupai\component\app_thread.py", line 125, in run
    findrefresh()
  File "E:\hupai\component\imgcut.py", line 383, in findrefresh
    img = cv2.cvtColor(sc, cv2.COLOR_BGR2GRAY)  # 转灰度图
cv2.error: C:\projects\opencv-python\opencv\modules\imgproc\src\color.cpp:11073: error: (-215) depth == 0 || depth == 2 || depth == 5 in function cv::cvtColor

Sun, 08 Apr 2018 11:23:51 imgcut.py[line:368] ERROR cut_img 这里出错
Sun, 08 Apr 2018 11:23:51 imgcut.py[line:369] ERROR this is an exception message
Traceback (most recent call last):
  File "E:\hupai\component\imgcut.py", line 361, in cut_img
    set_val('imgpos_lowestprice', img[use_area[0][1]:use_area[0][3], use_area[0][0]:use_area[0][2]])  # ok
IndexError: list index out of range
Sun, 08 Apr 2018 11:23:51 app_thread.py[line:127] ERROR 刷新失败
Sun, 08 Apr 2018 11:23:51 app_thread.py[line:128] ERROR this is an exception message
Traceback (most recent call last):
  File "E:\hupai\component\app_thread.py", line 125, in run
    findrefresh()
  File "E:\hupai\component\imgcut.py", line 383, in findrefresh
    img = cv2.cvtColor(sc, cv2.COLOR_BGR2GRAY)  # 转灰度图
cv2.error: C:\projects\opencv-python\opencv\modules\imgproc\src\color.cpp:11073: error: (-215) depth == 0 || depth == 2 || depth == 5 in function cv::cvtColor

Sun, 08 Apr 2018 11:23:51 imgcut.py[line:368] ERROR cut_img 这里出错
Sun, 08 Apr 2018 11:23:51 imgcut.py[line:369] ERROR this is an exception message
Traceback (most recent call last):
  File "E:\hupai\component\imgcut.py", line 361, in cut_img
    set_val('imgpos_lowestprice', img[use_area[0][1]:use_area[0][3], use_area[0][0]:use_area[0][2]])  # ok
IndexError: list index out of range
Sun, 08 Apr 2018 11:23:51 app_thread.py[line:127] ERROR 刷新失败
Sun, 08 Apr 2018 11:23:51 app_thread.py[line:128] ERROR this is an exception message
Traceback (most recent call last):
  File "E:\hupai\component\app_thread.py", line 125, in run
    findrefresh()
  File "E:\hupai\component\imgcut.py", line 383, in findrefresh
    img = cv2.cvtColor(sc, cv2.COLOR_BGR2GRAY)  # 转灰度图
cv2.error: C:\projects\opencv-python\opencv\modules\imgproc\src\color.cpp:11073: error: (-215) depth == 0 || depth == 2 || depth == 5 in function cv::cvtColor

Sun, 08 Apr 2018 11:23:51 imgcut.py[line:368] ERROR cut_img 这里出错
Sun, 08 Apr 2018 11:23:51 imgcut.py[line:369] ERROR this is an exception message
Traceback (most recent call last):
  File "E:\hupai\component\imgcut.py", line 361, in cut_img
    set_val('imgpos_lowestprice', img[use_area[0][1]:use_area[0][3], use_area[0][0]:use_area[0][2]])  # ok
IndexError: list index out of range
Sun, 08 Apr 2018 11:23:51 app_thread.py[line:127] ERROR 刷新失败
Sun, 08 Apr 2018 11:23:51 app_thread.py[line:128] ERROR this is an exception message
Traceback (most recent call last):
  File "E:\hupai\component\app_thread.py", line 125, in run
    findrefresh()
  File "E:\hupai\component\imgcut.py", line 383, in findrefresh
    img = cv2.cvtColor(sc, cv2.COLOR_BGR2GRAY)  # 转灰度图
cv2.error: C:\projects\opencv-python\opencv\modules\imgproc\src\color.cpp:11073: error: (-215) depth == 0 || depth == 2 || depth == 5 in function cv::cvtColor

Sun, 08 Apr 2018 11:23:51 imgcut.py[line:368] ERROR cut_img 这里出错
Sun, 08 Apr 2018 11:23:51 imgcut.py[line:369] ERROR this is an exception message
Traceback (most recent call last):
  File "E:\hupai\component\imgcut.py", line 361, in cut_img
    set_val('imgpos_lowestprice', img[use_area[0][1]:use_area[0][3], use_area[0][0]:use_area[0][2]])  # ok
IndexError: list index out of range
Sun, 08 Apr 2018 11:23:51 app_thread.py[line:127] ERROR 刷新失败
Sun, 08 Apr 2018 11:23:51 app_thread.py[line:128] ERROR this is an exception message
Traceback (most recent call last):
  File "E:\hupai\component\app_thread.py", line 125, in run
    findrefresh()
  File "E:\hupai\component\imgcut.py", line 383, in findrefresh
    img = cv2.cvtColor(sc, cv2.COLOR_BGR2GRAY)  # 转灰度图
cv2.error: C:\projects\opencv-python\opencv\modules\imgproc\src\color.cpp:11073: error: (-215) depth == 0 || depth == 2 || depth == 5 in function cv::cvtColor

Sun, 08 Apr 2018 11:23:52 app_thread.py[line:127] ERROR 刷新失败
Sun, 08 Apr 2018 11:23:52 app_thread.py[line:128] ERROR this is an exception message
Traceback (most recent call last):
  File "E:\hupai\component\app_thread.py", line 125, in run
    findrefresh()
  File "E:\hupai\component\imgcut.py", line 383, in findrefresh
    img = cv2.cvtColor(sc, cv2.COLOR_BGR2GRAY)  # 转灰度图
cv2.error: C:\projects\opencv-python\opencv\modules\imgproc\src\color.cpp:11073: error: (-215) depth == 0 || depth == 2 || depth == 5 in function cv::cvtColor

Sun, 08 Apr 2018 11:23:52 imgcut.py[line:368] ERROR cut_img 这里出错
Sun, 08 Apr 2018 11:23:52 imgcut.py[line:369] ERROR this is an exception message
Traceback (most recent call last):
  File "E:\hupai\component\imgcut.py", line 361, in cut_img
    set_val('imgpos_lowestprice', img[use_area[0][1]:use_area[0][3], use_area[0][0]:use_area[0][2]])  # ok
IndexError: list index out of range
Sun, 08 Apr 2018 11:23:52 app_thread.py[line:127] ERROR 刷新失败
Sun, 08 Apr 2018 11:23:52 app_thread.py[line:128] ERROR this is an exception message
Traceback (most recent call last):
  File "E:\hupai\component\app_thread.py", line 125, in run
    findrefresh()
  File "E:\hupai\component\imgcut.py", line 383, in findrefresh
    img = cv2.cvtColor(sc, cv2.COLOR_BGR2GRAY)  # 转灰度图
cv2.error: C:\projects\opencv-python\opencv\modules\imgproc\src\color.cpp:11073: error: (-215) depth == 0 || depth == 2 || depth == 5 in function cv::cvtColor

Sun, 08 Apr 2018 11:23:52 imgcut.py[line:368] ERROR cut_img 这里出错
Sun, 08 Apr 2018 11:23:52 imgcut.py[line:369] ERROR this is an exception message
Traceback (most recent call last):
  File "E:\hupai\component\imgcut.py", line 361, in cut_img
    set_val('imgpos_lowestprice', img[use_area[0][1]:use_area[0][3], use_area[0][0]:use_area[0][2]])  # ok
IndexError: list index out of range
Sun, 08 Apr 2018 11:23:52 app_thread.py[line:127] ERROR 刷新失败
Sun, 08 Apr 2018 11:23:52 app_thread.py[line:128] ERROR this is an exception message
Traceback (most recent call last):
  File "E:\hupai\component\app_thread.py", line 125, in run
    findrefresh()
  File "E:\hupai\component\imgcut.py", line 383, in findrefresh
    img = cv2.cvtColor(sc, cv2.COLOR_BGR2GRAY)  # 转灰度图
cv2.error: C:\projects\opencv-python\opencv\modules\imgproc\src\color.cpp:11073: error: (-215) depth == 0 || depth == 2 || depth == 5 in function cv::cvtColor

Sun, 08 Apr 2018 11:23:52 imgcut.py[line:368] ERROR cut_img 这里出错
Sun, 08 Apr 2018 11:23:52 imgcut.py[line:369] ERROR this is an exception message
Traceback (most recent call last):
  File "E:\hupai\component\imgcut.py", line 361, in cut_img
    set_val('imgpos_lowestprice', img[use_area[0][1]:use_area[0][3], use_area[0][0]:use_area[0][2]])  # ok
IndexError: list index out of range
Sun, 08 Apr 2018 11:23:52 app_thread.py[line:127] ERROR 刷新失败
Sun, 08 Apr 2018 11:23:52 app_thread.py[line:128] ERROR this is an exception message
Traceback (most recent call last):
  File "E:\hupai\component\app_thread.py", line 125, in run
    findrefresh()
  File "E:\hupai\component\imgcut.py", line 383, in findrefresh
    img = cv2.cvtColor(sc, cv2.COLOR_BGR2GRAY)  # 转灰度图
cv2.error: C:\projects\opencv-python\opencv\modules\imgproc\src\color.cpp:11073: error: (-215) depth == 0 || depth == 2 || depth == 5 in function cv::cvtColor

