Mon, 26 Mar 2018 22:19:37 PngImagePlugin.py[line:137] DEBUG STREAM b'IHDR' 16 13
Mon, 26 Mar 2018 22:19:37 PngImagePlugin.py[line:137] DEBUG STREAM b'IDAT' 41 8192
Mon, 26 Mar 2018 22:19:37 PngImagePlugin.py[line:137] DEBUG STREAM b'IHDR' 16 13
Mon, 26 Mar 2018 22:19:37 PngImagePlugin.py[line:137] DEBUG STREAM b'IDAT' 41 65536
Mon, 26 Mar 2018 22:19:37 app_thread.py[line:125] ERROR 刷新失败
Mon, 26 Mar 2018 22:19:37 app_thread.py[line:126] ERROR this is an exception message
Traceback (most recent call last):
  File "E:/hupai\component\app_thread.py", line 123, in run
    findrefresh()
  File "E:/hupai\component\imgcut.py", line 324, in findrefresh
    img = cv2.cvtColor(sc, cv2.COLOR_BGR2GRAY)  # 转灰度图
cv2.error: C:\projects\opencv-python\opencv\modules\imgproc\src\color.cpp:11073: error: (-215) depth == 0 || depth == 2 || depth == 5 in function cv::cvtColor

Mon, 26 Mar 2018 22:19:37 app_thread.py[line:125] ERROR 刷新失败
Mon, 26 Mar 2018 22:19:37 app_thread.py[line:126] ERROR this is an exception message
Traceback (most recent call last):
  File "E:/hupai\component\app_thread.py", line 123, in run
    findrefresh()
  File "E:/hupai\component\imgcut.py", line 324, in findrefresh
    img = cv2.cvtColor(sc, cv2.COLOR_BGR2GRAY)  # 转灰度图
cv2.error: C:\projects\opencv-python\opencv\modules\imgproc\src\color.cpp:11073: error: (-215) depth == 0 || depth == 2 || depth == 5 in function cv::cvtColor

Mon, 26 Mar 2018 22:19:37 imgcut.py[line:309] ERROR cut_img 这里出错
Mon, 26 Mar 2018 22:19:37 imgcut.py[line:310] ERROR this is an exception message
Traceback (most recent call last):
  File "E:/hupai\component\imgcut.py", line 302, in cut_img
    set_val('imgpos_lowestprice', img[use_area[0][1]:use_area[0][3], use_area[0][0]:use_area[0][2]])  # ok
IndexError: list index out of range
Mon, 26 Mar 2018 22:19:37 app_thread.py[line:125] ERROR 刷新失败
Mon, 26 Mar 2018 22:19:37 app_thread.py[line:126] ERROR this is an exception message
Traceback (most recent call last):
  File "E:/hupai\component\app_thread.py", line 123, in run
    findrefresh()
  File "E:/hupai\component\imgcut.py", line 324, in findrefresh
    img = cv2.cvtColor(sc, cv2.COLOR_BGR2GRAY)  # 转灰度图
cv2.error: C:\projects\opencv-python\opencv\modules\imgproc\src\color.cpp:11073: error: (-215) depth == 0 || depth == 2 || depth == 5 in function cv::cvtColor

Mon, 26 Mar 2018 22:19:37 app_thread.py[line:125] ERROR 刷新失败
Mon, 26 Mar 2018 22:19:37 app_thread.py[line:126] ERROR this is an exception message
Traceback (most recent call last):
  File "E:/hupai\component\app_thread.py", line 123, in run
    findrefresh()
  File "E:/hupai\component\imgcut.py", line 324, in findrefresh
    img = cv2.cvtColor(sc, cv2.COLOR_BGR2GRAY)  # 转灰度图
cv2.error: C:\projects\opencv-python\opencv\modules\imgproc\src\color.cpp:11073: error: (-215) depth == 0 || depth == 2 || depth == 5 in function cv::cvtColor

Mon, 26 Mar 2018 22:19:37 imgcut.py[line:309] ERROR cut_img 这里出错
Mon, 26 Mar 2018 22:19:37 imgcut.py[line:310] ERROR this is an exception message
Traceback (most recent call last):
  File "E:/hupai\component\imgcut.py", line 302, in cut_img
    set_val('imgpos_lowestprice', img[use_area[0][1]:use_area[0][3], use_area[0][0]:use_area[0][2]])  # ok
IndexError: list index out of range
Mon, 26 Mar 2018 22:19:37 app_thread.py[line:125] ERROR 刷新失败
Mon, 26 Mar 2018 22:19:37 app_thread.py[line:126] ERROR this is an exception message
Traceback (most recent call last):
  File "E:/hupai\component\app_thread.py", line 123, in run
    findrefresh()
  File "E:/hupai\component\imgcut.py", line 324, in findrefresh
    img = cv2.cvtColor(sc, cv2.COLOR_BGR2GRAY)  # 转灰度图
cv2.error: C:\projects\opencv-python\opencv\modules\imgproc\src\color.cpp:11073: error: (-215) depth == 0 || depth == 2 || depth == 5 in function cv::cvtColor

Mon, 26 Mar 2018 22:19:37 imgcut.py[line:309] ERROR cut_img 这里出错
Mon, 26 Mar 2018 22:19:37 imgcut.py[line:310] ERROR this is an exception message
Traceback (most recent call last):
  File "E:/hupai\component\imgcut.py", line 302, in cut_img
    set_val('imgpos_lowestprice', img[use_area[0][1]:use_area[0][3], use_area[0][0]:use_area[0][2]])  # ok
IndexError: list index out of range
Mon, 26 Mar 2018 22:19:37 app_thread.py[line:125] ERROR 刷新失败
Mon, 26 Mar 2018 22:19:37 app_thread.py[line:126] ERROR this is an exception message
Traceback (most recent call last):
  File "E:/hupai\component\app_thread.py", line 123, in run
    findrefresh()
  File "E:/hupai\component\imgcut.py", line 324, in findrefresh
    img = cv2.cvtColor(sc, cv2.COLOR_BGR2GRAY)  # 转灰度图
cv2.error: C:\projects\opencv-python\opencv\modules\imgproc\src\color.cpp:11073: error: (-215) depth == 0 || depth == 2 || depth == 5 in function cv::cvtColor

Mon, 26 Mar 2018 22:19:38 app_thread.py[line:125] ERROR 刷新失败
Mon, 26 Mar 2018 22:19:38 app_thread.py[line:126] ERROR this is an exception message
Traceback (most recent call last):
  File "E:/hupai\component\app_thread.py", line 123, in run
    findrefresh()
  File "E:/hupai\component\imgcut.py", line 324, in findrefresh
    img = cv2.cvtColor(sc, cv2.COLOR_BGR2GRAY)  # 转灰度图
cv2.error: C:\projects\opencv-python\opencv\modules\imgproc\src\color.cpp:11073: error: (-215) depth == 0 || depth == 2 || depth == 5 in function cv::cvtColor

Mon, 26 Mar 2018 22:19:38 imgcut.py[line:309] ERROR cut_img 这里出错
Mon, 26 Mar 2018 22:19:38 imgcut.py[line:310] ERROR this is an exception message
Traceback (most recent call last):
  File "E:/hupai\component\imgcut.py", line 302, in cut_img
    set_val('imgpos_lowestprice', img[use_area[0][1]:use_area[0][3], use_area[0][0]:use_area[0][2]])  # ok
IndexError: list index out of range
Mon, 26 Mar 2018 22:19:38 app_thread.py[line:125] ERROR 刷新失败
Mon, 26 Mar 2018 22:19:38 app_thread.py[line:126] ERROR this is an exception message
Traceback (most recent call last):
  File "E:/hupai\component\app_thread.py", line 123, in run
    findrefresh()
  File "E:/hupai\component\imgcut.py", line 324, in findrefresh
    img = cv2.cvtColor(sc, cv2.COLOR_BGR2GRAY)  # 转灰度图
cv2.error: C:\projects\opencv-python\opencv\modules\imgproc\src\color.cpp:11073: error: (-215) depth == 0 || depth == 2 || depth == 5 in function cv::cvtColor

Mon, 26 Mar 2018 22:19:38 app_thread.py[line:125] ERROR 刷新失败
Mon, 26 Mar 2018 22:19:38 app_thread.py[line:126] ERROR this is an exception message
Traceback (most recent call last):
  File "E:/hupai\component\app_thread.py", line 123, in run
    findrefresh()
  File "E:/hupai\component\imgcut.py", line 324, in findrefresh
    img = cv2.cvtColor(sc, cv2.COLOR_BGR2GRAY)  # 转灰度图
cv2.error: C:\projects\opencv-python\opencv\modules\imgproc\src\color.cpp:11073: error: (-215) depth == 0 || depth == 2 || depth == 5 in function cv::cvtColor

Mon, 26 Mar 2018 22:19:38 imgcut.py[line:309] ERROR cut_img 这里出错
Mon, 26 Mar 2018 22:19:38 imgcut.py[line:310] ERROR this is an exception message
Traceback (most recent call last):
  File "E:/hupai\component\imgcut.py", line 302, in cut_img
    set_val('imgpos_lowestprice', img[use_area[0][1]:use_area[0][3], use_area[0][0]:use_area[0][2]])  # ok
IndexError: list index out of range
Mon, 26 Mar 2018 22:19:38 app_thread.py[line:125] ERROR 刷新失败
Mon, 26 Mar 2018 22:19:38 app_thread.py[line:126] ERROR this is an exception message
Traceback (most recent call last):
  File "E:/hupai\component\app_thread.py", line 123, in run
    findrefresh()
  File "E:/hupai\component\imgcut.py", line 324, in findrefresh
    img = cv2.cvtColor(sc, cv2.COLOR_BGR2GRAY)  # 转灰度图
cv2.error: C:\projects\opencv-python\opencv\modules\imgproc\src\color.cpp:11073: error: (-215) depth == 0 || depth == 2 || depth == 5 in function cv::cvtColor

Mon, 26 Mar 2018 22:19:38 imgcut.py[line:309] ERROR cut_img 这里出错
Mon, 26 Mar 2018 22:19:38 imgcut.py[line:310] ERROR this is an exception message
Traceback (most recent call last):
  File "E:/hupai\component\imgcut.py", line 302, in cut_img
    set_val('imgpos_lowestprice', img[use_area[0][1]:use_area[0][3], use_area[0][0]:use_area[0][2]])  # ok
IndexError: list index out of range
Mon, 26 Mar 2018 22:19:38 app_thread.py[line:125] ERROR 刷新失败
Mon, 26 Mar 2018 22:19:38 app_thread.py[line:126] ERROR this is an exception message
Traceback (most recent call last):
  File "E:/hupai\component\app_thread.py", line 123, in run
    findrefresh()
  File "E:/hupai\component\imgcut.py", line 324, in findrefresh
    img = cv2.cvtColor(sc, cv2.COLOR_BGR2GRAY)  # 转灰度图
cv2.error: C:\projects\opencv-python\opencv\modules\imgproc\src\color.cpp:11073: error: (-215) depth == 0 || depth == 2 || depth == 5 in function cv::cvtColor

Mon, 26 Mar 2018 22:19:38 app_thread.py[line:125] ERROR 刷新失败
Mon, 26 Mar 2018 22:19:38 app_thread.py[line:126] ERROR this is an exception message
Traceback (most recent call last):
  File "E:/hupai\component\app_thread.py", line 123, in run
    findrefresh()
  File "E:/hupai\component\imgcut.py", line 324, in findrefresh
    img = cv2.cvtColor(sc, cv2.COLOR_BGR2GRAY)  # 转灰度图
cv2.error: C:\projects\opencv-python\opencv\modules\imgproc\src\color.cpp:11073: error: (-215) depth == 0 || depth == 2 || depth == 5 in function cv::cvtColor

Mon, 26 Mar 2018 22:19:38 imgcut.py[line:309] ERROR cut_img 这里出错
Mon, 26 Mar 2018 22:19:38 imgcut.py[line:310] ERROR this is an exception message
Traceback (most recent call last):
  File "E:/hupai\component\imgcut.py", line 302, in cut_img
    set_val('imgpos_lowestprice', img[use_area[0][1]:use_area[0][3], use_area[0][0]:use_area[0][2]])  # ok
IndexError: list index out of range
Mon, 26 Mar 2018 22:19:38 app_thread.py[line:125] ERROR 刷新失败
Mon, 26 Mar 2018 22:19:38 app_thread.py[line:126] ERROR this is an exception message
Traceback (most recent call last):
  File "E:/hupai\component\app_thread.py", line 123, in run
    findrefresh()
  File "E:/hupai\component\imgcut.py", line 324, in findrefresh
    img = cv2.cvtColor(sc, cv2.COLOR_BGR2GRAY)  # 转灰度图
cv2.error: C:\projects\opencv-python\opencv\modules\imgproc\src\color.cpp:11073: error: (-215) depth == 0 || depth == 2 || depth == 5 in function cv::cvtColor

Mon, 26 Mar 2018 22:19:38 imgcut.py[line:309] ERROR cut_img 这里出错
Mon, 26 Mar 2018 22:19:38 imgcut.py[line:310] ERROR this is an exception message
Traceback (most recent call last):
  File "E:/hupai\component\imgcut.py", line 302, in cut_img
    set_val('imgpos_lowestprice', img[use_area[0][1]:use_area[0][3], use_area[0][0]:use_area[0][2]])  # ok
IndexError: list index out of range
Mon, 26 Mar 2018 22:19:38 app_thread.py[line:125] ERROR 刷新失败
Mon, 26 Mar 2018 22:19:38 app_thread.py[line:126] ERROR this is an exception message
Traceback (most recent call last):
  File "E:/hupai\component\app_thread.py", line 123, in run
    findrefresh()
  File "E:/hupai\component\imgcut.py", line 324, in findrefresh
    img = cv2.cvtColor(sc, cv2.COLOR_BGR2GRAY)  # 转灰度图
cv2.error: C:\projects\opencv-python\opencv\modules\imgproc\src\color.cpp:11073: error: (-215) depth == 0 || depth == 2 || depth == 5 in function cv::cvtColor

Mon, 26 Mar 2018 22:19:38 app_thread.py[line:125] ERROR 刷新失败
Mon, 26 Mar 2018 22:19:38 app_thread.py[line:126] ERROR this is an exception message
Traceback (most recent call last):
  File "E:/hupai\component\app_thread.py", line 123, in run
    findrefresh()
  File "E:/hupai\component\imgcut.py", line 324, in findrefresh
    img = cv2.cvtColor(sc, cv2.COLOR_BGR2GRAY)  # 转灰度图
cv2.error: C:\projects\opencv-python\opencv\modules\imgproc\src\color.cpp:11073: error: (-215) depth == 0 || depth == 2 || depth == 5 in function cv::cvtColor

Mon, 26 Mar 2018 22:19:38 imgcut.py[line:309] ERROR cut_img 这里出错
Mon, 26 Mar 2018 22:19:38 imgcut.py[line:310] ERROR this is an exception message
Traceback (most recent call last):
  File "E:/hupai\component\imgcut.py", line 302, in cut_img
    set_val('imgpos_lowestprice', img[use_area[0][1]:use_area[0][3], use_area[0][0]:use_area[0][2]])  # ok
IndexError: list index out of range
Mon, 26 Mar 2018 22:19:38 app_thread.py[line:125] ERROR 刷新失败
Mon, 26 Mar 2018 22:19:38 app_thread.py[line:126] ERROR this is an exception message
Traceback (most recent call last):
  File "E:/hupai\component\app_thread.py", line 123, in run
    findrefresh()
  File "E:/hupai\component\imgcut.py", line 324, in findrefresh
    img = cv2.cvtColor(sc, cv2.COLOR_BGR2GRAY)  # 转灰度图
cv2.error: C:\projects\opencv-python\opencv\modules\imgproc\src\color.cpp:11073: error: (-215) depth == 0 || depth == 2 || depth == 5 in function cv::cvtColor

Mon, 26 Mar 2018 22:19:38 app_thread.py[line:125] ERROR 刷新失败
Mon, 26 Mar 2018 22:19:38 app_thread.py[line:126] ERROR this is an exception message
Traceback (most recent call last):
  File "E:/hupai\component\app_thread.py", line 123, in run
    findrefresh()
  File "E:/hupai\component\imgcut.py", line 324, in findrefresh
    img = cv2.cvtColor(sc, cv2.COLOR_BGR2GRAY)  # 转灰度图
cv2.error: C:\projects\opencv-python\opencv\modules\imgproc\src\color.cpp:11073: error: (-215) depth == 0 || depth == 2 || depth == 5 in function cv::cvtColor

Mon, 26 Mar 2018 22:19:38 imgcut.py[line:309] ERROR cut_img 这里出错
Mon, 26 Mar 2018 22:19:38 imgcut.py[line:310] ERROR this is an exception message
Traceback (most recent call last):
  File "E:/hupai\component\imgcut.py", line 302, in cut_img
    set_val('imgpos_lowestprice', img[use_area[0][1]:use_area[0][3], use_area[0][0]:use_area[0][2]])  # ok
IndexError: list index out of range
Mon, 26 Mar 2018 22:19:38 app_thread.py[line:125] ERROR 刷新失败
Mon, 26 Mar 2018 22:19:38 app_thread.py[line:126] ERROR this is an exception message
Traceback (most recent call last):
  File "E:/hupai\component\app_thread.py", line 123, in run
    findrefresh()
  File "E:/hupai\component\imgcut.py", line 324, in findrefresh
    img = cv2.cvtColor(sc, cv2.COLOR_BGR2GRAY)  # 转灰度图
cv2.error: C:\projects\opencv-python\opencv\modules\imgproc\src\color.cpp:11073: error: (-215) depth == 0 || depth == 2 || depth == 5 in function cv::cvtColor

Mon, 26 Mar 2018 22:19:38 imgcut.py[line:309] ERROR cut_img 这里出错
Mon, 26 Mar 2018 22:19:38 imgcut.py[line:310] ERROR this is an exception message
Traceback (most recent call last):
  File "E:/hupai\component\imgcut.py", line 302, in cut_img
    set_val('imgpos_lowestprice', img[use_area[0][1]:use_area[0][3], use_area[0][0]:use_area[0][2]])  # ok
IndexError: list index out of range
Mon, 26 Mar 2018 22:19:38 app_thread.py[line:125] ERROR 刷新失败
Mon, 26 Mar 2018 22:19:38 app_thread.py[line:126] ERROR this is an exception message
Traceback (most recent call last):
  File "E:/hupai\component\app_thread.py", line 123, in run
    findrefresh()
  File "E:/hupai\component\imgcut.py", line 324, in findrefresh
    img = cv2.cvtColor(sc, cv2.COLOR_BGR2GRAY)  # 转灰度图
cv2.error: C:\projects\opencv-python\opencv\modules\imgproc\src\color.cpp:11073: error: (-215) depth == 0 || depth == 2 || depth == 5 in function cv::cvtColor

Mon, 26 Mar 2018 22:19:38 imgcut.py[line:309] ERROR cut_img 这里出错
Mon, 26 Mar 2018 22:19:38 imgcut.py[line:310] ERROR this is an exception message
Traceback (most recent call last):
  File "E:/hupai\component\imgcut.py", line 302, in cut_img
    set_val('imgpos_lowestprice', img[use_area[0][1]:use_area[0][3], use_area[0][0]:use_area[0][2]])  # ok
IndexError: list index out of range
Mon, 26 Mar 2018 22:19:38 app_thread.py[line:125] ERROR 刷新失败
Mon, 26 Mar 2018 22:19:38 app_thread.py[line:126] ERROR this is an exception message
Traceback (most recent call last):
  File "E:/hupai\component\app_thread.py", line 123, in run
    findrefresh()
  File "E:/hupai\component\imgcut.py", line 324, in findrefresh
    img = cv2.cvtColor(sc, cv2.COLOR_BGR2GRAY)  # 转灰度图
cv2.error: C:\projects\opencv-python\opencv\modules\imgproc\src\color.cpp:11073: error: (-215) depth == 0 || depth == 2 || depth == 5 in function cv::cvtColor

Mon, 26 Mar 2018 22:19:39 imgcut.py[line:309] ERROR cut_img 这里出错
Mon, 26 Mar 2018 22:19:39 imgcut.py[line:310] ERROR this is an exception message
Traceback (most recent call last):
  File "E:/hupai\component\imgcut.py", line 302, in cut_img
    set_val('imgpos_lowestprice', img[use_area[0][1]:use_area[0][3], use_area[0][0]:use_area[0][2]])  # ok
IndexError: list index out of range
Mon, 26 Mar 2018 22:19:39 app_thread.py[line:125] ERROR 刷新失败
Mon, 26 Mar 2018 22:19:39 app_thread.py[line:126] ERROR this is an exception message
Traceback (most recent call last):
  File "E:/hupai\component\app_thread.py", line 123, in run
    findrefresh()
  File "E:/hupai\component\imgcut.py", line 324, in findrefresh
    img = cv2.cvtColor(sc, cv2.COLOR_BGR2GRAY)  # 转灰度图
cv2.error: C:\projects\opencv-python\opencv\modules\imgproc\src\color.cpp:11073: error: (-215) depth == 0 || depth == 2 || depth == 5 in function cv::cvtColor

Mon, 26 Mar 2018 22:19:39 imgcut.py[line:309] ERROR cut_img 这里出错
Mon, 26 Mar 2018 22:19:39 imgcut.py[line:310] ERROR this is an exception message
Traceback (most recent call last):
  File "E:/hupai\component\imgcut.py", line 302, in cut_img
    set_val('imgpos_lowestprice', img[use_area[0][1]:use_area[0][3], use_area[0][0]:use_area[0][2]])  # ok
IndexError: list index out of range
Mon, 26 Mar 2018 22:19:39 app_thread.py[line:125] ERROR 刷新失败
Mon, 26 Mar 2018 22:19:39 app_thread.py[line:126] ERROR this is an exception message
Traceback (most recent call last):
  File "E:/hupai\component\app_thread.py", line 123, in run
    findrefresh()
  File "E:/hupai\component\imgcut.py", line 324, in findrefresh
    img = cv2.cvtColor(sc, cv2.COLOR_BGR2GRAY)  # 转灰度图
cv2.error: C:\projects\opencv-python\opencv\modules\imgproc\src\color.cpp:11073: error: (-215) depth == 0 || depth == 2 || depth == 5 in function cv::cvtColor

Mon, 26 Mar 2018 22:19:39 app_thread.py[line:125] ERROR 刷新失败
Mon, 26 Mar 2018 22:19:39 app_thread.py[line:126] ERROR this is an exception message
Traceback (most recent call last):
  File "E:/hupai\component\app_thread.py", line 123, in run
    findrefresh()
  File "E:/hupai\component\imgcut.py", line 324, in findrefresh
    img = cv2.cvtColor(sc, cv2.COLOR_BGR2GRAY)  # 转灰度图
cv2.error: C:\projects\opencv-python\opencv\modules\imgproc\src\color.cpp:11073: error: (-215) depth == 0 || depth == 2 || depth == 5 in function cv::cvtColor

Mon, 26 Mar 2018 22:19:39 imgcut.py[line:309] ERROR cut_img 这里出错
Mon, 26 Mar 2018 22:19:39 imgcut.py[line:310] ERROR this is an exception message
Traceback (most recent call last):
  File "E:/hupai\component\imgcut.py", line 302, in cut_img
    set_val('imgpos_lowestprice', img[use_area[0][1]:use_area[0][3], use_area[0][0]:use_area[0][2]])  # ok
IndexError: list index out of range
Mon, 26 Mar 2018 22:19:39 app_thread.py[line:125] ERROR 刷新失败
Mon, 26 Mar 2018 22:19:39 app_thread.py[line:126] ERROR this is an exception message
Traceback (most recent call last):
  File "E:/hupai\component\app_thread.py", line 123, in run
    findrefresh()
  File "E:/hupai\component\imgcut.py", line 324, in findrefresh
    img = cv2.cvtColor(sc, cv2.COLOR_BGR2GRAY)  # 转灰度图
cv2.error: C:\projects\opencv-python\opencv\modules\imgproc\src\color.cpp:11073: error: (-215) depth == 0 || depth == 2 || depth == 5 in function cv::cvtColor

Mon, 26 Mar 2018 22:19:39 imgcut.py[line:309] ERROR cut_img 这里出错
Mon, 26 Mar 2018 22:19:39 imgcut.py[line:310] ERROR this is an exception message
Traceback (most recent call last):
  File "E:/hupai\component\imgcut.py", line 302, in cut_img
    set_val('imgpos_lowestprice', img[use_area[0][1]:use_area[0][3], use_area[0][0]:use_area[0][2]])  # ok
IndexError: list index out of range
Mon, 26 Mar 2018 22:19:39 app_thread.py[line:125] ERROR 刷新失败
Mon, 26 Mar 2018 22:19:39 app_thread.py[line:126] ERROR this is an exception message
Traceback (most recent call last):
  File "E:/hupai\component\app_thread.py", line 123, in run
    findrefresh()
  File "E:/hupai\component\imgcut.py", line 324, in findrefresh
    img = cv2.cvtColor(sc, cv2.COLOR_BGR2GRAY)  # 转灰度图
cv2.error: C:\projects\opencv-python\opencv\modules\imgproc\src\color.cpp:11073: error: (-215) depth == 0 || depth == 2 || depth == 5 in function cv::cvtColor

Mon, 26 Mar 2018 22:19:39 imgcut.py[line:309] ERROR cut_img 这里出错
Mon, 26 Mar 2018 22:19:39 imgcut.py[line:310] ERROR this is an exception message
Traceback (most recent call last):
  File "E:/hupai\component\imgcut.py", line 302, in cut_img
    set_val('imgpos_lowestprice', img[use_area[0][1]:use_area[0][3], use_area[0][0]:use_area[0][2]])  # ok
IndexError: list index out of range
Mon, 26 Mar 2018 22:19:39 app_thread.py[line:125] ERROR 刷新失败
Mon, 26 Mar 2018 22:19:39 app_thread.py[line:126] ERROR this is an exception message
Traceback (most recent call last):
  File "E:/hupai\component\app_thread.py", line 123, in run
    findrefresh()
  File "E:/hupai\component\imgcut.py", line 324, in findrefresh
    img = cv2.cvtColor(sc, cv2.COLOR_BGR2GRAY)  # 转灰度图
cv2.error: C:\projects\opencv-python\opencv\modules\imgproc\src\color.cpp:11073: error: (-215) depth == 0 || depth == 2 || depth == 5 in function cv::cvtColor

Mon, 26 Mar 2018 22:19:39 imgcut.py[line:309] ERROR cut_img 这里出错
Mon, 26 Mar 2018 22:19:39 app_thread.py[line:125] ERROR 刷新失败
Mon, 26 Mar 2018 22:19:39 imgcut.py[line:310] ERROR this is an exception message
Traceback (most recent call last):
  File "E:/hupai\component\imgcut.py", line 302, in cut_img
    set_val('imgpos_lowestprice', img[use_area[0][1]:use_area[0][3], use_area[0][0]:use_area[0][2]])  # ok
IndexError: list index out of range
Mon, 26 Mar 2018 22:19:39 app_thread.py[line:126] ERROR this is an exception message
Traceback (most recent call last):
  File "E:/hupai\component\app_thread.py", line 123, in run
    findrefresh()
  File "E:/hupai\component\imgcut.py", line 324, in findrefresh
    img = cv2.cvtColor(sc, cv2.COLOR_BGR2GRAY)  # 转灰度图
cv2.error: C:\projects\opencv-python\opencv\modules\imgproc\src\color.cpp:11073: error: (-215) depth == 0 || depth == 2 || depth == 5 in function cv::cvtColor

Mon, 26 Mar 2018 22:19:39 app_thread.py[line:125] ERROR 刷新失败
Mon, 26 Mar 2018 22:19:39 app_thread.py[line:126] ERROR this is an exception message
Traceback (most recent call last):
  File "E:/hupai\component\app_thread.py", line 123, in run
    findrefresh()
  File "E:/hupai\component\imgcut.py", line 324, in findrefresh
    img = cv2.cvtColor(sc, cv2.COLOR_BGR2GRAY)  # 转灰度图
cv2.error: C:\projects\opencv-python\opencv\modules\imgproc\src\color.cpp:11073: error: (-215) depth == 0 || depth == 2 || depth == 5 in function cv::cvtColor

Mon, 26 Mar 2018 22:19:39 app_thread.py[line:125] ERROR 刷新失败
Mon, 26 Mar 2018 22:19:39 app_thread.py[line:126] ERROR this is an exception message
Traceback (most recent call last):
  File "E:/hupai\component\app_thread.py", line 123, in run
    findrefresh()
  File "E:/hupai\component\imgcut.py", line 324, in findrefresh
    img = cv2.cvtColor(sc, cv2.COLOR_BGR2GRAY)  # 转灰度图
cv2.error: C:\projects\opencv-python\opencv\modules\imgproc\src\color.cpp:11073: error: (-215) depth == 0 || depth == 2 || depth == 5 in function cv::cvtColor

Mon, 26 Mar 2018 22:19:39 imgcut.py[line:309] ERROR cut_img 这里出错
Mon, 26 Mar 2018 22:19:39 imgcut.py[line:310] ERROR this is an exception message
Traceback (most recent call last):
  File "E:/hupai\component\imgcut.py", line 302, in cut_img
    set_val('imgpos_lowestprice', img[use_area[0][1]:use_area[0][3], use_area[0][0]:use_area[0][2]])  # ok
IndexError: list index out of range
Mon, 26 Mar 2018 22:19:39 app_thread.py[line:125] ERROR 刷新失败
Mon, 26 Mar 2018 22:19:39 app_thread.py[line:126] ERROR this is an exception message
Traceback (most recent call last):
  File "E:/hupai\component\app_thread.py", line 123, in run
    findrefresh()
  File "E:/hupai\component\imgcut.py", line 324, in findrefresh
    img = cv2.cvtColor(sc, cv2.COLOR_BGR2GRAY)  # 转灰度图
cv2.error: C:\projects\opencv-python\opencv\modules\imgproc\src\color.cpp:11073: error: (-215) depth == 0 || depth == 2 || depth == 5 in function cv::cvtColor

Mon, 26 Mar 2018 22:19:39 app_thread.py[line:125] ERROR 刷新失败
Mon, 26 Mar 2018 22:19:39 app_thread.py[line:126] ERROR this is an exception message
Traceback (most recent call last):
  File "E:/hupai\component\app_thread.py", line 123, in run
    findrefresh()
  File "E:/hupai\component\imgcut.py", line 324, in findrefresh
    img = cv2.cvtColor(sc, cv2.COLOR_BGR2GRAY)  # 转灰度图
cv2.error: C:\projects\opencv-python\opencv\modules\imgproc\src\color.cpp:11073: error: (-215) depth == 0 || depth == 2 || depth == 5 in function cv::cvtColor

Mon, 26 Mar 2018 22:19:39 imgcut.py[line:309] ERROR cut_img 这里出错
Mon, 26 Mar 2018 22:19:39 imgcut.py[line:310] ERROR this is an exception message
Traceback (most recent call last):
  File "E:/hupai\component\imgcut.py", line 302, in cut_img
    set_val('imgpos_lowestprice', img[use_area[0][1]:use_area[0][3], use_area[0][0]:use_area[0][2]])  # ok
IndexError: list index out of range
Mon, 26 Mar 2018 22:19:39 app_thread.py[line:125] ERROR 刷新失败
Mon, 26 Mar 2018 22:19:39 app_thread.py[line:126] ERROR this is an exception message
Traceback (most recent call last):
  File "E:/hupai\component\app_thread.py", line 123, in run
    findrefresh()
  File "E:/hupai\component\imgcut.py", line 324, in findrefresh
    img = cv2.cvtColor(sc, cv2.COLOR_BGR2GRAY)  # 转灰度图
cv2.error: C:\projects\opencv-python\opencv\modules\imgproc\src\color.cpp:11073: error: (-215) depth == 0 || depth == 2 || depth == 5 in function cv::cvtColor

Mon, 26 Mar 2018 22:19:39 imgcut.py[line:309] ERROR cut_img 这里出错
Mon, 26 Mar 2018 22:19:39 imgcut.py[line:310] ERROR this is an exception message
Traceback (most recent call last):
  File "E:/hupai\component\imgcut.py", line 302, in cut_img
    set_val('imgpos_lowestprice', img[use_area[0][1]:use_area[0][3], use_area[0][0]:use_area[0][2]])  # ok
IndexError: list index out of range
Mon, 26 Mar 2018 22:19:39 app_thread.py[line:125] ERROR 刷新失败
Mon, 26 Mar 2018 22:19:39 app_thread.py[line:126] ERROR this is an exception message
Traceback (most recent call last):
  File "E:/hupai\component\app_thread.py", line 123, in run
    findrefresh()
  File "E:/hupai\component\imgcut.py", line 324, in findrefresh
    img = cv2.cvtColor(sc, cv2.COLOR_BGR2GRAY)  # 转灰度图
cv2.error: C:\projects\opencv-python\opencv\modules\imgproc\src\color.cpp:11073: error: (-215) depth == 0 || depth == 2 || depth == 5 in function cv::cvtColor

Mon, 26 Mar 2018 22:19:39 imgcut.py[line:309] ERROR cut_img 这里出错
Mon, 26 Mar 2018 22:19:39 imgcut.py[line:310] ERROR this is an exception message
Traceback (most recent call last):
  File "E:/hupai\component\imgcut.py", line 302, in cut_img
    set_val('imgpos_lowestprice', img[use_area[0][1]:use_area[0][3], use_area[0][0]:use_area[0][2]])  # ok
IndexError: list index out of range
Mon, 26 Mar 2018 22:19:39 app_thread.py[line:125] ERROR 刷新失败
Mon, 26 Mar 2018 22:19:39 app_thread.py[line:126] ERROR this is an exception message
Traceback (most recent call last):
  File "E:/hupai\component\app_thread.py", line 123, in run
    findrefresh()
  File "E:/hupai\component\imgcut.py", line 324, in findrefresh
    img = cv2.cvtColor(sc, cv2.COLOR_BGR2GRAY)  # 转灰度图
cv2.error: C:\projects\opencv-python\opencv\modules\imgproc\src\color.cpp:11073: error: (-215) depth == 0 || depth == 2 || depth == 5 in function cv::cvtColor

Mon, 26 Mar 2018 22:19:39 imgcut.py[line:309] ERROR cut_img 这里出错
Mon, 26 Mar 2018 22:19:39 imgcut.py[line:310] ERROR this is an exception message
Traceback (most recent call last):
  File "E:/hupai\component\imgcut.py", line 302, in cut_img
    set_val('imgpos_lowestprice', img[use_area[0][1]:use_area[0][3], use_area[0][0]:use_area[0][2]])  # ok
IndexError: list index out of range
Mon, 26 Mar 2018 22:19:40 app_thread.py[line:125] ERROR 刷新失败
Mon, 26 Mar 2018 22:19:40 app_thread.py[line:126] ERROR this is an exception message
Traceback (most recent call last):
  File "E:/hupai\component\app_thread.py", line 123, in run
    findrefresh()
  File "E:/hupai\component\imgcut.py", line 324, in findrefresh
    img = cv2.cvtColor(sc, cv2.COLOR_BGR2GRAY)  # 转灰度图
cv2.error: C:\projects\opencv-python\opencv\modules\imgproc\src\color.cpp:11073: error: (-215) depth == 0 || depth == 2 || depth == 5 in function cv::cvtColor

Mon, 26 Mar 2018 22:19:40 imgcut.py[line:309] ERROR cut_img 这里出错
Mon, 26 Mar 2018 22:19:40 imgcut.py[line:310] ERROR this is an exception message
Traceback (most recent call last):
  File "E:/hupai\component\imgcut.py", line 302, in cut_img
    set_val('imgpos_lowestprice', img[use_area[0][1]:use_area[0][3], use_area[0][0]:use_area[0][2]])  # ok
IndexError: list index out of range
Mon, 26 Mar 2018 22:19:40 app_thread.py[line:125] ERROR 刷新失败
Mon, 26 Mar 2018 22:19:40 app_thread.py[line:126] ERROR this is an exception message
Traceback (most recent call last):
  File "E:/hupai\component\app_thread.py", line 123, in run
    findrefresh()
  File "E:/hupai\component\imgcut.py", line 324, in findrefresh
    img = cv2.cvtColor(sc, cv2.COLOR_BGR2GRAY)  # 转灰度图
cv2.error: C:\projects\opencv-python\opencv\modules\imgproc\src\color.cpp:11073: error: (-215) depth == 0 || depth == 2 || depth == 5 in function cv::cvtColor

Mon, 26 Mar 2018 22:19:40 imgcut.py[line:309] ERROR cut_img 这里出错
Mon, 26 Mar 2018 22:19:40 imgcut.py[line:310] ERROR this is an exception message
Traceback (most recent call last):
  File "E:/hupai\component\imgcut.py", line 302, in cut_img
    set_val('imgpos_lowestprice', img[use_area[0][1]:use_area[0][3], use_area[0][0]:use_area[0][2]])  # ok
IndexError: list index out of range
Mon, 26 Mar 2018 22:19:40 app_thread.py[line:125] ERROR 刷新失败
Mon, 26 Mar 2018 22:19:40 app_thread.py[line:126] ERROR this is an exception message
Traceback (most recent call last):
  File "E:/hupai\component\app_thread.py", line 123, in run
    findrefresh()
  File "E:/hupai\component\imgcut.py", line 324, in findrefresh
    img = cv2.cvtColor(sc, cv2.COLOR_BGR2GRAY)  # 转灰度图
cv2.error: C:\projects\opencv-python\opencv\modules\imgproc\src\color.cpp:11073: error: (-215) depth == 0 || depth == 2 || depth == 5 in function cv::cvtColor

Mon, 26 Mar 2018 22:19:40 app_thread.py[line:125] ERROR 刷新失败
Mon, 26 Mar 2018 22:19:40 app_thread.py[line:126] ERROR this is an exception message
Traceback (most recent call last):
  File "E:/hupai\component\app_thread.py", line 123, in run
    findrefresh()
  File "E:/hupai\component\imgcut.py", line 324, in findrefresh
    img = cv2.cvtColor(sc, cv2.COLOR_BGR2GRAY)  # 转灰度图
cv2.error: C:\projects\opencv-python\opencv\modules\imgproc\src\color.cpp:11073: error: (-215) depth == 0 || depth == 2 || depth == 5 in function cv::cvtColor

Mon, 26 Mar 2018 22:19:40 imgcut.py[line:309] ERROR cut_img 这里出错
Mon, 26 Mar 2018 22:19:40 imgcut.py[line:310] ERROR this is an exception message
Traceback (most recent call last):
  File "E:/hupai\component\imgcut.py", line 302, in cut_img
    set_val('imgpos_lowestprice', img[use_area[0][1]:use_area[0][3], use_area[0][0]:use_area[0][2]])  # ok
IndexError: list index out of range
Mon, 26 Mar 2018 22:19:40 app_thread.py[line:125] ERROR 刷新失败
Mon, 26 Mar 2018 22:19:40 app_thread.py[line:126] ERROR this is an exception message
Traceback (most recent call last):
  File "E:/hupai\component\app_thread.py", line 123, in run
    findrefresh()
  File "E:/hupai\component\imgcut.py", line 324, in findrefresh
    img = cv2.cvtColor(sc, cv2.COLOR_BGR2GRAY)  # 转灰度图
cv2.error: C:\projects\opencv-python\opencv\modules\imgproc\src\color.cpp:11073: error: (-215) depth == 0 || depth == 2 || depth == 5 in function cv::cvtColor

Mon, 26 Mar 2018 22:19:40 app_thread.py[line:125] ERROR 刷新失败
Mon, 26 Mar 2018 22:19:40 app_thread.py[line:126] ERROR this is an exception message
Traceback (most recent call last):
  File "E:/hupai\component\app_thread.py", line 123, in run
    findrefresh()
  File "E:/hupai\component\imgcut.py", line 324, in findrefresh
    img = cv2.cvtColor(sc, cv2.COLOR_BGR2GRAY)  # 转灰度图
cv2.error: C:\projects\opencv-python\opencv\modules\imgproc\src\color.cpp:11073: error: (-215) depth == 0 || depth == 2 || depth == 5 in function cv::cvtColor

Mon, 26 Mar 2018 22:19:40 imgcut.py[line:309] ERROR cut_img 这里出错
Mon, 26 Mar 2018 22:19:40 imgcut.py[line:310] ERROR this is an exception message
Traceback (most recent call last):
  File "E:/hupai\component\imgcut.py", line 302, in cut_img
    set_val('imgpos_lowestprice', img[use_area[0][1]:use_area[0][3], use_area[0][0]:use_area[0][2]])  # ok
IndexError: list index out of range
Mon, 26 Mar 2018 22:19:40 app_thread.py[line:125] ERROR 刷新失败
Mon, 26 Mar 2018 22:19:40 app_thread.py[line:126] ERROR this is an exception message
Traceback (most recent call last):
  File "E:/hupai\component\app_thread.py", line 123, in run
    findrefresh()
  File "E:/hupai\component\imgcut.py", line 324, in findrefresh
    img = cv2.cvtColor(sc, cv2.COLOR_BGR2GRAY)  # 转灰度图
cv2.error: C:\projects\opencv-python\opencv\modules\imgproc\src\color.cpp:11073: error: (-215) depth == 0 || depth == 2 || depth == 5 in function cv::cvtColor

Mon, 26 Mar 2018 22:19:40 imgcut.py[line:309] ERROR cut_img 这里出错
Mon, 26 Mar 2018 22:19:40 imgcut.py[line:310] ERROR this is an exception message
Traceback (most recent call last):
  File "E:/hupai\component\imgcut.py", line 302, in cut_img
    set_val('imgpos_lowestprice', img[use_area[0][1]:use_area[0][3], use_area[0][0]:use_area[0][2]])  # ok
IndexError: list index out of range
Mon, 26 Mar 2018 22:19:40 app_thread.py[line:125] ERROR 刷新失败
Mon, 26 Mar 2018 22:19:40 app_thread.py[line:126] ERROR this is an exception message
Traceback (most recent call last):
  File "E:/hupai\component\app_thread.py", line 123, in run
    findrefresh()
  File "E:/hupai\component\imgcut.py", line 324, in findrefresh
    img = cv2.cvtColor(sc, cv2.COLOR_BGR2GRAY)  # 转灰度图
cv2.error: C:\projects\opencv-python\opencv\modules\imgproc\src\color.cpp:11073: error: (-215) depth == 0 || depth == 2 || depth == 5 in function cv::cvtColor

Mon, 26 Mar 2018 22:19:40 app_thread.py[line:125] ERROR 刷新失败
Mon, 26 Mar 2018 22:19:40 app_thread.py[line:126] ERROR this is an exception message
Traceback (most recent call last):
  File "E:/hupai\component\app_thread.py", line 123, in run
    findrefresh()
  File "E:/hupai\component\imgcut.py", line 324, in findrefresh
    img = cv2.cvtColor(sc, cv2.COLOR_BGR2GRAY)  # 转灰度图
cv2.error: C:\projects\opencv-python\opencv\modules\imgproc\src\color.cpp:11073: error: (-215) depth == 0 || depth == 2 || depth == 5 in function cv::cvtColor

Mon, 26 Mar 2018 22:19:40 app_thread.py[line:125] ERROR 刷新失败
Mon, 26 Mar 2018 22:19:40 app_thread.py[line:126] ERROR this is an exception message
Traceback (most recent call last):
  File "E:/hupai\component\app_thread.py", line 123, in run
    findrefresh()
  File "E:/hupai\component\imgcut.py", line 324, in findrefresh
    img = cv2.cvtColor(sc, cv2.COLOR_BGR2GRAY)  # 转灰度图
cv2.error: C:\projects\opencv-python\opencv\modules\imgproc\src\color.cpp:11073: error: (-215) depth == 0 || depth == 2 || depth == 5 in function cv::cvtColor

Mon, 26 Mar 2018 22:19:40 imgcut.py[line:309] ERROR cut_img 这里出错
Mon, 26 Mar 2018 22:19:40 imgcut.py[line:310] ERROR this is an exception message
Traceback (most recent call last):
  File "E:/hupai\component\imgcut.py", line 302, in cut_img
    set_val('imgpos_lowestprice', img[use_area[0][1]:use_area[0][3], use_area[0][0]:use_area[0][2]])  # ok
IndexError: list index out of range
Mon, 26 Mar 2018 22:19:40 app_thread.py[line:125] ERROR 刷新失败
Mon, 26 Mar 2018 22:19:40 app_thread.py[line:126] ERROR this is an exception message
Traceback (most recent call last):
  File "E:/hupai\component\app_thread.py", line 123, in run
    findrefresh()
  File "E:/hupai\component\imgcut.py", line 324, in findrefresh
    img = cv2.cvtColor(sc, cv2.COLOR_BGR2GRAY)  # 转灰度图
cv2.error: C:\projects\opencv-python\opencv\modules\imgproc\src\color.cpp:11073: error: (-215) depth == 0 || depth == 2 || depth == 5 in function cv::cvtColor

Mon, 26 Mar 2018 22:19:40 app_thread.py[line:125] ERROR 刷新失败
Mon, 26 Mar 2018 22:19:40 app_thread.py[line:126] ERROR this is an exception message
Traceback (most recent call last):
  File "E:/hupai\component\app_thread.py", line 123, in run
    findrefresh()
  File "E:/hupai\component\imgcut.py", line 324, in findrefresh
    img = cv2.cvtColor(sc, cv2.COLOR_BGR2GRAY)  # 转灰度图
cv2.error: C:\projects\opencv-python\opencv\modules\imgproc\src\color.cpp:11073: error: (-215) depth == 0 || depth == 2 || depth == 5 in function cv::cvtColor

Mon, 26 Mar 2018 22:19:40 imgcut.py[line:309] ERROR cut_img 这里出错
Mon, 26 Mar 2018 22:19:40 imgcut.py[line:310] ERROR this is an exception message
Traceback (most recent call last):
  File "E:/hupai\component\imgcut.py", line 302, in cut_img
    set_val('imgpos_lowestprice', img[use_area[0][1]:use_area[0][3], use_area[0][0]:use_area[0][2]])  # ok
IndexError: list index out of range
Mon, 26 Mar 2018 22:19:40 app_thread.py[line:125] ERROR 刷新失败
Mon, 26 Mar 2018 22:19:40 app_thread.py[line:126] ERROR this is an exception message
Traceback (most recent call last):
  File "E:/hupai\component\app_thread.py", line 123, in run
    findrefresh()
  File "E:/hupai\component\imgcut.py", line 324, in findrefresh
    img = cv2.cvtColor(sc, cv2.COLOR_BGR2GRAY)  # 转灰度图
cv2.error: C:\projects\opencv-python\opencv\modules\imgproc\src\color.cpp:11073: error: (-215) depth == 0 || depth == 2 || depth == 5 in function cv::cvtColor

Mon, 26 Mar 2018 22:19:40 app_thread.py[line:125] ERROR 刷新失败
Mon, 26 Mar 2018 22:19:40 app_thread.py[line:126] ERROR this is an exception message
Traceback (most recent call last):
  File "E:/hupai\component\app_thread.py", line 123, in run
    findrefresh()
  File "E:/hupai\component\imgcut.py", line 324, in findrefresh
    img = cv2.cvtColor(sc, cv2.COLOR_BGR2GRAY)  # 转灰度图
cv2.error: C:\projects\opencv-python\opencv\modules\imgproc\src\color.cpp:11073: error: (-215) depth == 0 || depth == 2 || depth == 5 in function cv::cvtColor

Mon, 26 Mar 2018 22:19:40 imgcut.py[line:309] ERROR cut_img 这里出错
Mon, 26 Mar 2018 22:19:40 imgcut.py[line:310] ERROR this is an exception message
Traceback (most recent call last):
  File "E:/hupai\component\imgcut.py", line 302, in cut_img
    set_val('imgpos_lowestprice', img[use_area[0][1]:use_area[0][3], use_area[0][0]:use_area[0][2]])  # ok
IndexError: list index out of range
Mon, 26 Mar 2018 22:19:41 app_thread.py[line:125] ERROR 刷新失败
Mon, 26 Mar 2018 22:19:41 app_thread.py[line:126] ERROR this is an exception message
Traceback (most recent call last):
  File "E:/hupai\component\app_thread.py", line 123, in run
    findrefresh()
  File "E:/hupai\component\imgcut.py", line 324, in findrefresh
    img = cv2.cvtColor(sc, cv2.COLOR_BGR2GRAY)  # 转灰度图
cv2.error: C:\projects\opencv-python\opencv\modules\imgproc\src\color.cpp:11073: error: (-215) depth == 0 || depth == 2 || depth == 5 in function cv::cvtColor

Mon, 26 Mar 2018 22:19:41 imgcut.py[line:309] ERROR cut_img 这里出错
Mon, 26 Mar 2018 22:19:41 imgcut.py[line:310] ERROR this is an exception message
Traceback (most recent call last):
  File "E:/hupai\component\imgcut.py", line 302, in cut_img
    set_val('imgpos_lowestprice', img[use_area[0][1]:use_area[0][3], use_area[0][0]:use_area[0][2]])  # ok
IndexError: list index out of range
Mon, 26 Mar 2018 22:19:41 app_thread.py[line:125] ERROR 刷新失败
Mon, 26 Mar 2018 22:19:41 app_thread.py[line:126] ERROR this is an exception message
Traceback (most recent call last):
  File "E:/hupai\component\app_thread.py", line 123, in run
    findrefresh()
  File "E:/hupai\component\imgcut.py", line 324, in findrefresh
    img = cv2.cvtColor(sc, cv2.COLOR_BGR2GRAY)  # 转灰度图
cv2.error: C:\projects\opencv-python\opencv\modules\imgproc\src\color.cpp:11073: error: (-215) depth == 0 || depth == 2 || depth == 5 in function cv::cvtColor

Mon, 26 Mar 2018 22:19:41 app_thread.py[line:125] ERROR 刷新失败
Mon, 26 Mar 2018 22:19:41 app_thread.py[line:126] ERROR this is an exception message
Traceback (most recent call last):
  File "E:/hupai\component\app_thread.py", line 123, in run
    findrefresh()
  File "E:/hupai\component\imgcut.py", line 324, in findrefresh
    img = cv2.cvtColor(sc, cv2.COLOR_BGR2GRAY)  # 转灰度图
cv2.error: C:\projects\opencv-python\opencv\modules\imgproc\src\color.cpp:11073: error: (-215) depth == 0 || depth == 2 || depth == 5 in function cv::cvtColor

Mon, 26 Mar 2018 22:19:41 imgcut.py[line:309] ERROR cut_img 这里出错
Mon, 26 Mar 2018 22:19:41 imgcut.py[line:310] ERROR this is an exception message
Traceback (most recent call last):
  File "E:/hupai\component\imgcut.py", line 302, in cut_img
    set_val('imgpos_lowestprice', img[use_area[0][1]:use_area[0][3], use_area[0][0]:use_area[0][2]])  # ok
IndexError: list index out of range
Mon, 26 Mar 2018 22:19:41 app_thread.py[line:125] ERROR 刷新失败
Mon, 26 Mar 2018 22:19:41 app_thread.py[line:126] ERROR this is an exception message
Traceback (most recent call last):
  File "E:/hupai\component\app_thread.py", line 123, in run
    findrefresh()
  File "E:/hupai\component\imgcut.py", line 324, in findrefresh
    img = cv2.cvtColor(sc, cv2.COLOR_BGR2GRAY)  # 转灰度图
cv2.error: C:\projects\opencv-python\opencv\modules\imgproc\src\color.cpp:11073: error: (-215) depth == 0 || depth == 2 || depth == 5 in function cv::cvtColor

Mon, 26 Mar 2018 22:19:41 app_thread.py[line:125] ERROR 刷新失败
Mon, 26 Mar 2018 22:19:41 app_thread.py[line:126] ERROR this is an exception message
Traceback (most recent call last):
  File "E:/hupai\component\app_thread.py", line 123, in run
    findrefresh()
  File "E:/hupai\component\imgcut.py", line 324, in findrefresh
    img = cv2.cvtColor(sc, cv2.COLOR_BGR2GRAY)  # 转灰度图
cv2.error: C:\projects\opencv-python\opencv\modules\imgproc\src\color.cpp:11073: error: (-215) depth == 0 || depth == 2 || depth == 5 in function cv::cvtColor

Mon, 26 Mar 2018 22:19:41 imgcut.py[line:309] ERROR cut_img 这里出错
Mon, 26 Mar 2018 22:19:41 imgcut.py[line:310] ERROR this is an exception message
Traceback (most recent call last):
  File "E:/hupai\component\imgcut.py", line 302, in cut_img
    set_val('imgpos_lowestprice', img[use_area[0][1]:use_area[0][3], use_area[0][0]:use_area[0][2]])  # ok
IndexError: list index out of range
Mon, 26 Mar 2018 22:19:41 app_thread.py[line:125] ERROR 刷新失败
Mon, 26 Mar 2018 22:19:41 app_thread.py[line:126] ERROR this is an exception message
Traceback (most recent call last):
  File "E:/hupai\component\app_thread.py", line 123, in run
    findrefresh()
  File "E:/hupai\component\imgcut.py", line 324, in findrefresh
    img = cv2.cvtColor(sc, cv2.COLOR_BGR2GRAY)  # 转灰度图
cv2.error: C:\projects\opencv-python\opencv\modules\imgproc\src\color.cpp:11073: error: (-215) depth == 0 || depth == 2 || depth == 5 in function cv::cvtColor

Mon, 26 Mar 2018 22:19:41 app_thread.py[line:125] ERROR 刷新失败
Mon, 26 Mar 2018 22:19:41 app_thread.py[line:126] ERROR this is an exception message
Traceback (most recent call last):
  File "E:/hupai\component\app_thread.py", line 123, in run
    findrefresh()
  File "E:/hupai\component\imgcut.py", line 324, in findrefresh
    img = cv2.cvtColor(sc, cv2.COLOR_BGR2GRAY)  # 转灰度图
cv2.error: C:\projects\opencv-python\opencv\modules\imgproc\src\color.cpp:11073: error: (-215) depth == 0 || depth == 2 || depth == 5 in function cv::cvtColor

Mon, 26 Mar 2018 22:19:41 imgcut.py[line:309] ERROR cut_img 这里出错
Mon, 26 Mar 2018 22:19:41 imgcut.py[line:310] ERROR this is an exception message
Traceback (most recent call last):
  File "E:/hupai\component\imgcut.py", line 302, in cut_img
    set_val('imgpos_lowestprice', img[use_area[0][1]:use_area[0][3], use_area[0][0]:use_area[0][2]])  # ok
IndexError: list index out of range
Mon, 26 Mar 2018 22:19:41 app_thread.py[line:125] ERROR 刷新失败
Mon, 26 Mar 2018 22:19:41 app_thread.py[line:126] ERROR this is an exception message
Traceback (most recent call last):
  File "E:/hupai\component\app_thread.py", line 123, in run
    findrefresh()
  File "E:/hupai\component\imgcut.py", line 324, in findrefresh
    img = cv2.cvtColor(sc, cv2.COLOR_BGR2GRAY)  # 转灰度图
cv2.error: C:\projects\opencv-python\opencv\modules\imgproc\src\color.cpp:11073: error: (-215) depth == 0 || depth == 2 || depth == 5 in function cv::cvtColor

Mon, 26 Mar 2018 22:19:41 imgcut.py[line:309] ERROR cut_img 这里出错
Mon, 26 Mar 2018 22:19:41 imgcut.py[line:310] ERROR this is an exception message
Traceback (most recent call last):
  File "E:/hupai\component\imgcut.py", line 302, in cut_img
    set_val('imgpos_lowestprice', img[use_area[0][1]:use_area[0][3], use_area[0][0]:use_area[0][2]])  # ok
IndexError: list index out of range
Mon, 26 Mar 2018 22:19:41 app_thread.py[line:125] ERROR 刷新失败
Mon, 26 Mar 2018 22:19:41 app_thread.py[line:126] ERROR this is an exception message
Traceback (most recent call last):
  File "E:/hupai\component\app_thread.py", line 123, in run
    findrefresh()
  File "E:/hupai\component\imgcut.py", line 324, in findrefresh
    img = cv2.cvtColor(sc, cv2.COLOR_BGR2GRAY)  # 转灰度图
cv2.error: C:\projects\opencv-python\opencv\modules\imgproc\src\color.cpp:11073: error: (-215) depth == 0 || depth == 2 || depth == 5 in function cv::cvtColor

Mon, 26 Mar 2018 22:19:41 app_thread.py[line:125] ERROR 刷新失败
Mon, 26 Mar 2018 22:19:41 app_thread.py[line:126] ERROR this is an exception message
Traceback (most recent call last):
  File "E:/hupai\component\app_thread.py", line 123, in run
    findrefresh()
  File "E:/hupai\component\imgcut.py", line 324, in findrefresh
    img = cv2.cvtColor(sc, cv2.COLOR_BGR2GRAY)  # 转灰度图
cv2.error: C:\projects\opencv-python\opencv\modules\imgproc\src\color.cpp:11073: error: (-215) depth == 0 || depth == 2 || depth == 5 in function cv::cvtColor

Mon, 26 Mar 2018 22:19:41 imgcut.py[line:309] ERROR cut_img 这里出错
Mon, 26 Mar 2018 22:19:41 imgcut.py[line:310] ERROR this is an exception message
Traceback (most recent call last):
  File "E:/hupai\component\imgcut.py", line 302, in cut_img
    set_val('imgpos_lowestprice', img[use_area[0][1]:use_area[0][3], use_area[0][0]:use_area[0][2]])  # ok
IndexError: list index out of range
Mon, 26 Mar 2018 22:19:41 app_thread.py[line:125] ERROR 刷新失败
Mon, 26 Mar 2018 22:19:41 app_thread.py[line:126] ERROR this is an exception message
Traceback (most recent call last):
  File "E:/hupai\component\app_thread.py", line 123, in run
    findrefresh()
  File "E:/hupai\component\imgcut.py", line 324, in findrefresh
    img = cv2.cvtColor(sc, cv2.COLOR_BGR2GRAY)  # 转灰度图
cv2.error: C:\projects\opencv-python\opencv\modules\imgproc\src\color.cpp:11073: error: (-215) depth == 0 || depth == 2 || depth == 5 in function cv::cvtColor

Mon, 26 Mar 2018 22:19:41 app_thread.py[line:125] ERROR 刷新失败
Mon, 26 Mar 2018 22:19:41 app_thread.py[line:126] ERROR this is an exception message
Traceback (most recent call last):
  File "E:/hupai\component\app_thread.py", line 123, in run
    findrefresh()
  File "E:/hupai\component\imgcut.py", line 324, in findrefresh
    img = cv2.cvtColor(sc, cv2.COLOR_BGR2GRAY)  # 转灰度图
cv2.error: C:\projects\opencv-python\opencv\modules\imgproc\src\color.cpp:11073: error: (-215) depth == 0 || depth == 2 || depth == 5 in function cv::cvtColor

Mon, 26 Mar 2018 22:19:41 imgcut.py[line:309] ERROR cut_img 这里出错
Mon, 26 Mar 2018 22:19:41 imgcut.py[line:310] ERROR this is an exception message
Traceback (most recent call last):
  File "E:/hupai\component\imgcut.py", line 302, in cut_img
    set_val('imgpos_lowestprice', img[use_area[0][1]:use_area[0][3], use_area[0][0]:use_area[0][2]])  # ok
IndexError: list index out of range
Mon, 26 Mar 2018 22:19:42 app_thread.py[line:125] ERROR 刷新失败
Mon, 26 Mar 2018 22:19:42 app_thread.py[line:126] ERROR this is an exception message
Traceback (most recent call last):
  File "E:/hupai\component\app_thread.py", line 123, in run
    findrefresh()
  File "E:/hupai\component\imgcut.py", line 324, in findrefresh
    img = cv2.cvtColor(sc, cv2.COLOR_BGR2GRAY)  # 转灰度图
cv2.error: C:\projects\opencv-python\opencv\modules\imgproc\src\color.cpp:11073: error: (-215) depth == 0 || depth == 2 || depth == 5 in function cv::cvtColor

Mon, 26 Mar 2018 22:19:42 app_thread.py[line:125] ERROR 刷新失败
Mon, 26 Mar 2018 22:19:42 app_thread.py[line:126] ERROR this is an exception message
Traceback (most recent call last):
  File "E:/hupai\component\app_thread.py", line 123, in run
    findrefresh()
  File "E:/hupai\component\imgcut.py", line 324, in findrefresh
    img = cv2.cvtColor(sc, cv2.COLOR_BGR2GRAY)  # 转灰度图
cv2.error: C:\projects\opencv-python\opencv\modules\imgproc\src\color.cpp:11073: error: (-215) depth == 0 || depth == 2 || depth == 5 in function cv::cvtColor

Mon, 26 Mar 2018 22:19:42 imgcut.py[line:309] ERROR cut_img 这里出错
Mon, 26 Mar 2018 22:19:42 imgcut.py[line:310] ERROR this is an exception message
Traceback (most recent call last):
  File "E:/hupai\component\imgcut.py", line 302, in cut_img
    set_val('imgpos_lowestprice', img[use_area[0][1]:use_area[0][3], use_area[0][0]:use_area[0][2]])  # ok
IndexError: list index out of range
Mon, 26 Mar 2018 22:19:42 app_thread.py[line:125] ERROR 刷新失败
Mon, 26 Mar 2018 22:19:42 app_thread.py[line:126] ERROR this is an exception message
Traceback (most recent call last):
  File "E:/hupai\component\app_thread.py", line 123, in run
    findrefresh()
  File "E:/hupai\component\imgcut.py", line 324, in findrefresh
    img = cv2.cvtColor(sc, cv2.COLOR_BGR2GRAY)  # 转灰度图
cv2.error: C:\projects\opencv-python\opencv\modules\imgproc\src\color.cpp:11073: error: (-215) depth == 0 || depth == 2 || depth == 5 in function cv::cvtColor

Mon, 26 Mar 2018 22:19:42 app_thread.py[line:125] ERROR 刷新失败
Mon, 26 Mar 2018 22:19:42 app_thread.py[line:126] ERROR this is an exception message
Traceback (most recent call last):
  File "E:/hupai\component\app_thread.py", line 123, in run
    findrefresh()
  File "E:/hupai\component\imgcut.py", line 324, in findrefresh
    img = cv2.cvtColor(sc, cv2.COLOR_BGR2GRAY)  # 转灰度图
cv2.error: C:\projects\opencv-python\opencv\modules\imgproc\src\color.cpp:11073: error: (-215) depth == 0 || depth == 2 || depth == 5 in function cv::cvtColor

Mon, 26 Mar 2018 22:19:42 imgcut.py[line:309] ERROR cut_img 这里出错
Mon, 26 Mar 2018 22:19:42 imgcut.py[line:310] ERROR this is an exception message
Traceback (most recent call last):
  File "E:/hupai\component\imgcut.py", line 302, in cut_img
    set_val('imgpos_lowestprice', img[use_area[0][1]:use_area[0][3], use_area[0][0]:use_area[0][2]])  # ok
IndexError: list index out of range
Mon, 26 Mar 2018 22:19:42 app_thread.py[line:125] ERROR 刷新失败
Mon, 26 Mar 2018 22:19:42 app_thread.py[line:126] ERROR this is an exception message
Traceback (most recent call last):
  File "E:/hupai\component\app_thread.py", line 123, in run
    findrefresh()
  File "E:/hupai\component\imgcut.py", line 324, in findrefresh
    img = cv2.cvtColor(sc, cv2.COLOR_BGR2GRAY)  # 转灰度图
cv2.error: C:\projects\opencv-python\opencv\modules\imgproc\src\color.cpp:11073: error: (-215) depth == 0 || depth == 2 || depth == 5 in function cv::cvtColor

Mon, 26 Mar 2018 22:19:42 imgcut.py[line:309] ERROR cut_img 这里出错
Mon, 26 Mar 2018 22:19:42 imgcut.py[line:310] ERROR this is an exception message
Traceback (most recent call last):
  File "E:/hupai\component\imgcut.py", line 302, in cut_img
    set_val('imgpos_lowestprice', img[use_area[0][1]:use_area[0][3], use_area[0][0]:use_area[0][2]])  # ok
IndexError: list index out of range
Mon, 26 Mar 2018 22:19:42 app_thread.py[line:125] ERROR 刷新失败
Mon, 26 Mar 2018 22:19:42 app_thread.py[line:126] ERROR this is an exception message
Traceback (most recent call last):
  File "E:/hupai\component\app_thread.py", line 123, in run
    findrefresh()
  File "E:/hupai\component\imgcut.py", line 324, in findrefresh
    img = cv2.cvtColor(sc, cv2.COLOR_BGR2GRAY)  # 转灰度图
cv2.error: C:\projects\opencv-python\opencv\modules\imgproc\src\color.cpp:11073: error: (-215) depth == 0 || depth == 2 || depth == 5 in function cv::cvtColor

Mon, 26 Mar 2018 22:19:42 imgcut.py[line:309] ERROR cut_img 这里出错
Mon, 26 Mar 2018 22:19:42 imgcut.py[line:310] ERROR this is an exception message
Traceback (most recent call last):
  File "E:/hupai\component\imgcut.py", line 302, in cut_img
    set_val('imgpos_lowestprice', img[use_area[0][1]:use_area[0][3], use_area[0][0]:use_area[0][2]])  # ok
IndexError: list index out of range
Mon, 26 Mar 2018 22:19:42 app_thread.py[line:125] ERROR 刷新失败
Mon, 26 Mar 2018 22:19:42 app_thread.py[line:126] ERROR this is an exception message
Traceback (most recent call last):
  File "E:/hupai\component\app_thread.py", line 123, in run
    findrefresh()
  File "E:/hupai\component\imgcut.py", line 324, in findrefresh
    img = cv2.cvtColor(sc, cv2.COLOR_BGR2GRAY)  # 转灰度图
cv2.error: C:\projects\opencv-python\opencv\modules\imgproc\src\color.cpp:11073: error: (-215) depth == 0 || depth == 2 || depth == 5 in function cv::cvtColor

Mon, 26 Mar 2018 22:19:42 app_thread.py[line:125] ERROR 刷新失败
Mon, 26 Mar 2018 22:19:42 app_thread.py[line:126] ERROR this is an exception message
Traceback (most recent call last):
  File "E:/hupai\component\app_thread.py", line 123, in run
    findrefresh()
  File "E:/hupai\component\imgcut.py", line 324, in findrefresh
    img = cv2.cvtColor(sc, cv2.COLOR_BGR2GRAY)  # 转灰度图
cv2.error: C:\projects\opencv-python\opencv\modules\imgproc\src\color.cpp:11073: error: (-215) depth == 0 || depth == 2 || depth == 5 in function cv::cvtColor

Mon, 26 Mar 2018 22:19:42 app_thread.py[line:125] ERROR 刷新失败
Mon, 26 Mar 2018 22:19:42 app_thread.py[line:126] ERROR this is an exception message
Traceback (most recent call last):
  File "E:/hupai\component\app_thread.py", line 123, in run
    findrefresh()
  File "E:/hupai\component\imgcut.py", line 324, in findrefresh
    img = cv2.cvtColor(sc, cv2.COLOR_BGR2GRAY)  # 转灰度图
cv2.error: C:\projects\opencv-python\opencv\modules\imgproc\src\color.cpp:11073: error: (-215) depth == 0 || depth == 2 || depth == 5 in function cv::cvtColor

Mon, 26 Mar 2018 22:19:42 imgcut.py[line:309] ERROR cut_img 这里出错
Mon, 26 Mar 2018 22:19:42 imgcut.py[line:310] ERROR this is an exception message
Traceback (most recent call last):
  File "E:/hupai\component\imgcut.py", line 302, in cut_img
    set_val('imgpos_lowestprice', img[use_area[0][1]:use_area[0][3], use_area[0][0]:use_area[0][2]])  # ok
IndexError: list index out of range
Mon, 26 Mar 2018 22:19:42 app_thread.py[line:125] ERROR 刷新失败
Mon, 26 Mar 2018 22:19:42 app_thread.py[line:126] ERROR this is an exception message
Traceback (most recent call last):
  File "E:/hupai\component\app_thread.py", line 123, in run
    findrefresh()
  File "E:/hupai\component\imgcut.py", line 324, in findrefresh
    img = cv2.cvtColor(sc, cv2.COLOR_BGR2GRAY)  # 转灰度图
cv2.error: C:\projects\opencv-python\opencv\modules\imgproc\src\color.cpp:11073: error: (-215) depth == 0 || depth == 2 || depth == 5 in function cv::cvtColor

Mon, 26 Mar 2018 22:19:42 imgcut.py[line:309] ERROR cut_img 这里出错
Mon, 26 Mar 2018 22:19:42 imgcut.py[line:310] ERROR this is an exception message
Traceback (most recent call last):
  File "E:/hupai\component\imgcut.py", line 302, in cut_img
    set_val('imgpos_lowestprice', img[use_area[0][1]:use_area[0][3], use_area[0][0]:use_area[0][2]])  # ok
IndexError: list index out of range
Mon, 26 Mar 2018 22:19:42 app_thread.py[line:125] ERROR 刷新失败
Mon, 26 Mar 2018 22:19:42 app_thread.py[line:126] ERROR this is an exception message
Traceback (most recent call last):
  File "E:/hupai\component\app_thread.py", line 123, in run
    findrefresh()
  File "E:/hupai\component\imgcut.py", line 324, in findrefresh
    img = cv2.cvtColor(sc, cv2.COLOR_BGR2GRAY)  # 转灰度图
cv2.error: C:\projects\opencv-python\opencv\modules\imgproc\src\color.cpp:11073: error: (-215) depth == 0 || depth == 2 || depth == 5 in function cv::cvtColor

Mon, 26 Mar 2018 22:19:42 app_thread.py[line:125] ERROR 刷新失败
Mon, 26 Mar 2018 22:19:42 app_thread.py[line:126] ERROR this is an exception message
Traceback (most recent call last):
  File "E:/hupai\component\app_thread.py", line 123, in run
    findrefresh()
  File "E:/hupai\component\imgcut.py", line 324, in findrefresh
    img = cv2.cvtColor(sc, cv2.COLOR_BGR2GRAY)  # 转灰度图
cv2.error: C:\projects\opencv-python\opencv\modules\imgproc\src\color.cpp:11073: error: (-215) depth == 0 || depth == 2 || depth == 5 in function cv::cvtColor

Mon, 26 Mar 2018 22:19:42 imgcut.py[line:309] ERROR cut_img 这里出错
Mon, 26 Mar 2018 22:19:42 imgcut.py[line:310] ERROR this is an exception message
Traceback (most recent call last):
  File "E:/hupai\component\imgcut.py", line 302, in cut_img
    set_val('imgpos_lowestprice', img[use_area[0][1]:use_area[0][3], use_area[0][0]:use_area[0][2]])  # ok
IndexError: list index out of range
Mon, 26 Mar 2018 22:19:42 app_thread.py[line:125] ERROR 刷新失败
Mon, 26 Mar 2018 22:19:42 app_thread.py[line:126] ERROR this is an exception message
Traceback (most recent call last):
  File "E:/hupai\component\app_thread.py", line 123, in run
    findrefresh()
  File "E:/hupai\component\imgcut.py", line 324, in findrefresh
    img = cv2.cvtColor(sc, cv2.COLOR_BGR2GRAY)  # 转灰度图
cv2.error: C:\projects\opencv-python\opencv\modules\imgproc\src\color.cpp:11073: error: (-215) depth == 0 || depth == 2 || depth == 5 in function cv::cvtColor

Mon, 26 Mar 2018 22:19:42 app_thread.py[line:125] ERROR 刷新失败
Mon, 26 Mar 2018 22:19:42 app_thread.py[line:126] ERROR this is an exception message
Traceback (most recent call last):
  File "E:/hupai\component\app_thread.py", line 123, in run
    findrefresh()
  File "E:/hupai\component\imgcut.py", line 324, in findrefresh
    img = cv2.cvtColor(sc, cv2.COLOR_BGR2GRAY)  # 转灰度图
cv2.error: C:\projects\opencv-python\opencv\modules\imgproc\src\color.cpp:11073: error: (-215) depth == 0 || depth == 2 || depth == 5 in function cv::cvtColor

Mon, 26 Mar 2018 22:19:43 imgcut.py[line:309] ERROR cut_img 这里出错
Mon, 26 Mar 2018 22:19:43 imgcut.py[line:310] ERROR this is an exception message
Traceback (most recent call last):
  File "E:/hupai\component\imgcut.py", line 302, in cut_img
    set_val('imgpos_lowestprice', img[use_area[0][1]:use_area[0][3], use_area[0][0]:use_area[0][2]])  # ok
IndexError: list index out of range
Mon, 26 Mar 2018 22:19:43 app_thread.py[line:125] ERROR 刷新失败
Mon, 26 Mar 2018 22:19:43 app_thread.py[line:126] ERROR this is an exception message
Traceback (most recent call last):
  File "E:/hupai\component\app_thread.py", line 123, in run
    findrefresh()
  File "E:/hupai\component\imgcut.py", line 324, in findrefresh
    img = cv2.cvtColor(sc, cv2.COLOR_BGR2GRAY)  # 转灰度图
cv2.error: C:\projects\opencv-python\opencv\modules\imgproc\src\color.cpp:11073: error: (-215) depth == 0 || depth == 2 || depth == 5 in function cv::cvtColor

Mon, 26 Mar 2018 22:19:43 app_thread.py[line:125] ERROR 刷新失败
Mon, 26 Mar 2018 22:19:43 app_thread.py[line:126] ERROR this is an exception message
Traceback (most recent call last):
  File "E:/hupai\component\app_thread.py", line 123, in run
    findrefresh()
  File "E:/hupai\component\imgcut.py", line 324, in findrefresh
    img = cv2.cvtColor(sc, cv2.COLOR_BGR2GRAY)  # 转灰度图
cv2.error: C:\projects\opencv-python\opencv\modules\imgproc\src\color.cpp:11073: error: (-215) depth == 0 || depth == 2 || depth == 5 in function cv::cvtColor

Mon, 26 Mar 2018 22:19:43 imgcut.py[line:309] ERROR cut_img 这里出错
Mon, 26 Mar 2018 22:19:43 imgcut.py[line:310] ERROR this is an exception message
Traceback (most recent call last):
  File "E:/hupai\component\imgcut.py", line 302, in cut_img
    set_val('imgpos_lowestprice', img[use_area[0][1]:use_area[0][3], use_area[0][0]:use_area[0][2]])  # ok
IndexError: list index out of range
Mon, 26 Mar 2018 22:19:43 app_thread.py[line:125] ERROR 刷新失败
Mon, 26 Mar 2018 22:19:43 app_thread.py[line:126] ERROR this is an exception message
Traceback (most recent call last):
  File "E:/hupai\component\app_thread.py", line 123, in run
    findrefresh()
  File "E:/hupai\component\imgcut.py", line 324, in findrefresh
    img = cv2.cvtColor(sc, cv2.COLOR_BGR2GRAY)  # 转灰度图
cv2.error: C:\projects\opencv-python\opencv\modules\imgproc\src\color.cpp:11073: error: (-215) depth == 0 || depth == 2 || depth == 5 in function cv::cvtColor

Mon, 26 Mar 2018 22:19:43 app_thread.py[line:125] ERROR 刷新失败
Mon, 26 Mar 2018 22:19:43 app_thread.py[line:126] ERROR this is an exception message
Traceback (most recent call last):
  File "E:/hupai\component\app_thread.py", line 123, in run
    findrefresh()
  File "E:/hupai\component\imgcut.py", line 324, in findrefresh
    img = cv2.cvtColor(sc, cv2.COLOR_BGR2GRAY)  # 转灰度图
cv2.error: C:\projects\opencv-python\opencv\modules\imgproc\src\color.cpp:11073: error: (-215) depth == 0 || depth == 2 || depth == 5 in function cv::cvtColor

Mon, 26 Mar 2018 22:19:43 imgcut.py[line:309] ERROR cut_img 这里出错
Mon, 26 Mar 2018 22:19:43 imgcut.py[line:310] ERROR this is an exception message
Traceback (most recent call last):
  File "E:/hupai\component\imgcut.py", line 302, in cut_img
    set_val('imgpos_lowestprice', img[use_area[0][1]:use_area[0][3], use_area[0][0]:use_area[0][2]])  # ok
IndexError: list index out of range
Mon, 26 Mar 2018 22:19:43 app_thread.py[line:125] ERROR 刷新失败
Mon, 26 Mar 2018 22:19:43 app_thread.py[line:126] ERROR this is an exception message
Traceback (most recent call last):
  File "E:/hupai\component\app_thread.py", line 123, in run
    findrefresh()
  File "E:/hupai\component\imgcut.py", line 324, in findrefresh
    img = cv2.cvtColor(sc, cv2.COLOR_BGR2GRAY)  # 转灰度图
cv2.error: C:\projects\opencv-python\opencv\modules\imgproc\src\color.cpp:11073: error: (-215) depth == 0 || depth == 2 || depth == 5 in function cv::cvtColor

Mon, 26 Mar 2018 22:19:43 app_thread.py[line:125] ERROR 刷新失败
Mon, 26 Mar 2018 22:19:43 app_thread.py[line:126] ERROR this is an exception message
Traceback (most recent call last):
  File "E:/hupai\component\app_thread.py", line 123, in run
    findrefresh()
  File "E:/hupai\component\imgcut.py", line 324, in findrefresh
    img = cv2.cvtColor(sc, cv2.COLOR_BGR2GRAY)  # 转灰度图
cv2.error: C:\projects\opencv-python\opencv\modules\imgproc\src\color.cpp:11073: error: (-215) depth == 0 || depth == 2 || depth == 5 in function cv::cvtColor

Mon, 26 Mar 2018 22:19:43 imgcut.py[line:309] ERROR cut_img 这里出错
Mon, 26 Mar 2018 22:19:43 imgcut.py[line:310] ERROR this is an exception message
Traceback (most recent call last):
  File "E:/hupai\component\imgcut.py", line 302, in cut_img
    set_val('imgpos_lowestprice', img[use_area[0][1]:use_area[0][3], use_area[0][0]:use_area[0][2]])  # ok
IndexError: list index out of range
Mon, 26 Mar 2018 22:19:43 app_thread.py[line:125] ERROR 刷新失败
Mon, 26 Mar 2018 22:19:43 app_thread.py[line:126] ERROR this is an exception message
Traceback (most recent call last):
  File "E:/hupai\component\app_thread.py", line 123, in run
    findrefresh()
  File "E:/hupai\component\imgcut.py", line 324, in findrefresh
    img = cv2.cvtColor(sc, cv2.COLOR_BGR2GRAY)  # 转灰度图
cv2.error: C:\projects\opencv-python\opencv\modules\imgproc\src\color.cpp:11073: error: (-215) depth == 0 || depth == 2 || depth == 5 in function cv::cvtColor

Mon, 26 Mar 2018 22:19:43 app_thread.py[line:125] ERROR 刷新失败
Mon, 26 Mar 2018 22:19:43 app_thread.py[line:126] ERROR this is an exception message
Traceback (most recent call last):
  File "E:/hupai\component\app_thread.py", line 123, in run
    findrefresh()
  File "E:/hupai\component\imgcut.py", line 324, in findrefresh
    img = cv2.cvtColor(sc, cv2.COLOR_BGR2GRAY)  # 转灰度图
cv2.error: C:\projects\opencv-python\opencv\modules\imgproc\src\color.cpp:11073: error: (-215) depth == 0 || depth == 2 || depth == 5 in function cv::cvtColor

Mon, 26 Mar 2018 22:19:43 imgcut.py[line:309] ERROR cut_img 这里出错
Mon, 26 Mar 2018 22:19:43 imgcut.py[line:310] ERROR this is an exception message
Traceback (most recent call last):
  File "E:/hupai\component\imgcut.py", line 302, in cut_img
    set_val('imgpos_lowestprice', img[use_area[0][1]:use_area[0][3], use_area[0][0]:use_area[0][2]])  # ok
IndexError: list index out of range
Mon, 26 Mar 2018 22:19:43 app_thread.py[line:125] ERROR 刷新失败
Mon, 26 Mar 2018 22:19:43 app_thread.py[line:126] ERROR this is an exception message
Traceback (most recent call last):
  File "E:/hupai\component\app_thread.py", line 123, in run
    findrefresh()
  File "E:/hupai\component\imgcut.py", line 324, in findrefresh
    img = cv2.cvtColor(sc, cv2.COLOR_BGR2GRAY)  # 转灰度图
cv2.error: C:\projects\opencv-python\opencv\modules\imgproc\src\color.cpp:11073: error: (-215) depth == 0 || depth == 2 || depth == 5 in function cv::cvtColor

Mon, 26 Mar 2018 22:19:43 app_thread.py[line:125] ERROR 刷新失败
Mon, 26 Mar 2018 22:19:43 app_thread.py[line:126] ERROR this is an exception message
Traceback (most recent call last):
  File "E:/hupai\component\app_thread.py", line 123, in run
    findrefresh()
  File "E:/hupai\component\imgcut.py", line 324, in findrefresh
    img = cv2.cvtColor(sc, cv2.COLOR_BGR2GRAY)  # 转灰度图
cv2.error: C:\projects\opencv-python\opencv\modules\imgproc\src\color.cpp:11073: error: (-215) depth == 0 || depth == 2 || depth == 5 in function cv::cvtColor

Mon, 26 Mar 2018 22:19:43 imgcut.py[line:309] ERROR cut_img 这里出错
Mon, 26 Mar 2018 22:19:43 imgcut.py[line:310] ERROR this is an exception message
Traceback (most recent call last):
  File "E:/hupai\component\imgcut.py", line 302, in cut_img
    set_val('imgpos_lowestprice', img[use_area[0][1]:use_area[0][3], use_area[0][0]:use_area[0][2]])  # ok
IndexError: list index out of range
Mon, 26 Mar 2018 22:19:43 app_thread.py[line:125] ERROR 刷新失败
Mon, 26 Mar 2018 22:19:43 app_thread.py[line:126] ERROR this is an exception message
Traceback (most recent call last):
  File "E:/hupai\component\app_thread.py", line 123, in run
    findrefresh()
  File "E:/hupai\component\imgcut.py", line 324, in findrefresh
    img = cv2.cvtColor(sc, cv2.COLOR_BGR2GRAY)  # 转灰度图
cv2.error: C:\projects\opencv-python\opencv\modules\imgproc\src\color.cpp:11073: error: (-215) depth == 0 || depth == 2 || depth == 5 in function cv::cvtColor

Mon, 26 Mar 2018 22:19:43 app_thread.py[line:125] ERROR 刷新失败
Mon, 26 Mar 2018 22:19:43 imgcut.py[line:309] ERROR cut_img 这里出错
Mon, 26 Mar 2018 22:19:43 app_thread.py[line:126] ERROR this is an exception message
Traceback (most recent call last):
  File "E:/hupai\component\app_thread.py", line 123, in run
    findrefresh()
  File "E:/hupai\component\imgcut.py", line 324, in findrefresh
    img = cv2.cvtColor(sc, cv2.COLOR_BGR2GRAY)  # 转灰度图
cv2.error: C:\projects\opencv-python\opencv\modules\imgproc\src\color.cpp:11073: error: (-215) depth == 0 || depth == 2 || depth == 5 in function cv::cvtColor

Mon, 26 Mar 2018 22:19:43 imgcut.py[line:310] ERROR this is an exception message
Traceback (most recent call last):
  File "E:/hupai\component\imgcut.py", line 302, in cut_img
    set_val('imgpos_lowestprice', img[use_area[0][1]:use_area[0][3], use_area[0][0]:use_area[0][2]])  # ok
IndexError: list index out of range
Mon, 26 Mar 2018 22:19:43 app_thread.py[line:125] ERROR 刷新失败
Mon, 26 Mar 2018 22:19:43 app_thread.py[line:126] ERROR this is an exception message
Traceback (most recent call last):
  File "E:/hupai\component\app_thread.py", line 123, in run
    findrefresh()
  File "E:/hupai\component\imgcut.py", line 324, in findrefresh
    img = cv2.cvtColor(sc, cv2.COLOR_BGR2GRAY)  # 转灰度图
cv2.error: C:\projects\opencv-python\opencv\modules\imgproc\src\color.cpp:11073: error: (-215) depth == 0 || depth == 2 || depth == 5 in function cv::cvtColor

Mon, 26 Mar 2018 22:19:44 app_thread.py[line:125] ERROR 刷新失败
Mon, 26 Mar 2018 22:19:44 app_thread.py[line:126] ERROR this is an exception message
Traceback (most recent call last):
  File "E:/hupai\component\app_thread.py", line 123, in run
    findrefresh()
  File "E:/hupai\component\imgcut.py", line 324, in findrefresh
    img = cv2.cvtColor(sc, cv2.COLOR_BGR2GRAY)  # 转灰度图
cv2.error: C:\projects\opencv-python\opencv\modules\imgproc\src\color.cpp:11073: error: (-215) depth == 0 || depth == 2 || depth == 5 in function cv::cvtColor

Mon, 26 Mar 2018 22:19:44 imgcut.py[line:309] ERROR cut_img 这里出错
Mon, 26 Mar 2018 22:19:44 imgcut.py[line:310] ERROR this is an exception message
Traceback (most recent call last):
  File "E:/hupai\component\imgcut.py", line 302, in cut_img
    set_val('imgpos_lowestprice', img[use_area[0][1]:use_area[0][3], use_area[0][0]:use_area[0][2]])  # ok
IndexError: list index out of range
Mon, 26 Mar 2018 22:19:44 app_thread.py[line:125] ERROR 刷新失败
Mon, 26 Mar 2018 22:19:44 app_thread.py[line:126] ERROR this is an exception message
Traceback (most recent call last):
  File "E:/hupai\component\app_thread.py", line 123, in run
    findrefresh()
  File "E:/hupai\component\imgcut.py", line 324, in findrefresh
    img = cv2.cvtColor(sc, cv2.COLOR_BGR2GRAY)  # 转灰度图
cv2.error: C:\projects\opencv-python\opencv\modules\imgproc\src\color.cpp:11073: error: (-215) depth == 0 || depth == 2 || depth == 5 in function cv::cvtColor

Mon, 26 Mar 2018 22:19:44 app_thread.py[line:125] ERROR 刷新失败
Mon, 26 Mar 2018 22:19:44 app_thread.py[line:126] ERROR this is an exception message
Traceback (most recent call last):
  File "E:/hupai\component\app_thread.py", line 123, in run
    findrefresh()
  File "E:/hupai\component\imgcut.py", line 324, in findrefresh
    img = cv2.cvtColor(sc, cv2.COLOR_BGR2GRAY)  # 转灰度图
cv2.error: C:\projects\opencv-python\opencv\modules\imgproc\src\color.cpp:11073: error: (-215) depth == 0 || depth == 2 || depth == 5 in function cv::cvtColor

Mon, 26 Mar 2018 22:19:44 imgcut.py[line:309] ERROR cut_img 这里出错
Mon, 26 Mar 2018 22:19:44 imgcut.py[line:310] ERROR this is an exception message
Traceback (most recent call last):
  File "E:/hupai\component\imgcut.py", line 302, in cut_img
    set_val('imgpos_lowestprice', img[use_area[0][1]:use_area[0][3], use_area[0][0]:use_area[0][2]])  # ok
IndexError: list index out of range
Mon, 26 Mar 2018 22:19:44 app_thread.py[line:125] ERROR 刷新失败
Mon, 26 Mar 2018 22:19:44 app_thread.py[line:126] ERROR this is an exception message
Traceback (most recent call last):
  File "E:/hupai\component\app_thread.py", line 123, in run
    findrefresh()
  File "E:/hupai\component\imgcut.py", line 324, in findrefresh
    img = cv2.cvtColor(sc, cv2.COLOR_BGR2GRAY)  # 转灰度图
cv2.error: C:\projects\opencv-python\opencv\modules\imgproc\src\color.cpp:11073: error: (-215) depth == 0 || depth == 2 || depth == 5 in function cv::cvtColor

Mon, 26 Mar 2018 22:19:44 imgcut.py[line:309] ERROR cut_img 这里出错
Mon, 26 Mar 2018 22:19:44 imgcut.py[line:310] ERROR this is an exception message
Traceback (most recent call last):
  File "E:/hupai\component\imgcut.py", line 302, in cut_img
    set_val('imgpos_lowestprice', img[use_area[0][1]:use_area[0][3], use_area[0][0]:use_area[0][2]])  # ok
IndexError: list index out of range
Mon, 26 Mar 2018 22:19:44 app_thread.py[line:125] ERROR 刷新失败
Mon, 26 Mar 2018 22:19:44 app_thread.py[line:126] ERROR this is an exception message
Traceback (most recent call last):
  File "E:/hupai\component\app_thread.py", line 123, in run
    findrefresh()
  File "E:/hupai\component\imgcut.py", line 324, in findrefresh
    img = cv2.cvtColor(sc, cv2.COLOR_BGR2GRAY)  # 转灰度图
cv2.error: C:\projects\opencv-python\opencv\modules\imgproc\src\color.cpp:11073: error: (-215) depth == 0 || depth == 2 || depth == 5 in function cv::cvtColor

Mon, 26 Mar 2018 22:19:44 app_thread.py[line:125] ERROR 刷新失败
Mon, 26 Mar 2018 22:19:44 app_thread.py[line:126] ERROR this is an exception message
Traceback (most recent call last):
  File "E:/hupai\component\app_thread.py", line 123, in run
    findrefresh()
  File "E:/hupai\component\imgcut.py", line 324, in findrefresh
    img = cv2.cvtColor(sc, cv2.COLOR_BGR2GRAY)  # 转灰度图
cv2.error: C:\projects\opencv-python\opencv\modules\imgproc\src\color.cpp:11073: error: (-215) depth == 0 || depth == 2 || depth == 5 in function cv::cvtColor

Mon, 26 Mar 2018 22:19:44 imgcut.py[line:309] ERROR cut_img 这里出错
Mon, 26 Mar 2018 22:19:44 imgcut.py[line:310] ERROR this is an exception message
Traceback (most recent call last):
  File "E:/hupai\component\imgcut.py", line 302, in cut_img
    set_val('imgpos_lowestprice', img[use_area[0][1]:use_area[0][3], use_area[0][0]:use_area[0][2]])  # ok
IndexError: list index out of range
Mon, 26 Mar 2018 22:19:44 app_thread.py[line:125] ERROR 刷新失败
Mon, 26 Mar 2018 22:19:44 app_thread.py[line:126] ERROR this is an exception message
Traceback (most recent call last):
  File "E:/hupai\component\app_thread.py", line 123, in run
    findrefresh()
  File "E:/hupai\component\imgcut.py", line 324, in findrefresh
    img = cv2.cvtColor(sc, cv2.COLOR_BGR2GRAY)  # 转灰度图
cv2.error: C:\projects\opencv-python\opencv\modules\imgproc\src\color.cpp:11073: error: (-215) depth == 0 || depth == 2 || depth == 5 in function cv::cvtColor

Mon, 26 Mar 2018 22:19:44 app_thread.py[line:125] ERROR 刷新失败
Mon, 26 Mar 2018 22:19:44 app_thread.py[line:126] ERROR this is an exception message
Traceback (most recent call last):
  File "E:/hupai\component\app_thread.py", line 123, in run
    findrefresh()
  File "E:/hupai\component\imgcut.py", line 324, in findrefresh
    img = cv2.cvtColor(sc, cv2.COLOR_BGR2GRAY)  # 转灰度图
cv2.error: C:\projects\opencv-python\opencv\modules\imgproc\src\color.cpp:11073: error: (-215) depth == 0 || depth == 2 || depth == 5 in function cv::cvtColor

Mon, 26 Mar 2018 22:19:44 imgcut.py[line:309] ERROR cut_img 这里出错
Mon, 26 Mar 2018 22:19:44 imgcut.py[line:310] ERROR this is an exception message
Traceback (most recent call last):
  File "E:/hupai\component\imgcut.py", line 302, in cut_img
    set_val('imgpos_lowestprice', img[use_area[0][1]:use_area[0][3], use_area[0][0]:use_area[0][2]])  # ok
IndexError: list index out of range
Mon, 26 Mar 2018 22:19:44 app_thread.py[line:125] ERROR 刷新失败
Mon, 26 Mar 2018 22:19:44 app_thread.py[line:126] ERROR this is an exception message
Traceback (most recent call last):
  File "E:/hupai\component\app_thread.py", line 123, in run
    findrefresh()
  File "E:/hupai\component\imgcut.py", line 324, in findrefresh
    img = cv2.cvtColor(sc, cv2.COLOR_BGR2GRAY)  # 转灰度图
cv2.error: C:\projects\opencv-python\opencv\modules\imgproc\src\color.cpp:11073: error: (-215) depth == 0 || depth == 2 || depth == 5 in function cv::cvtColor

Mon, 26 Mar 2018 22:19:44 imgcut.py[line:309] ERROR cut_img 这里出错
Mon, 26 Mar 2018 22:19:44 imgcut.py[line:310] ERROR this is an exception message
Traceback (most recent call last):
  File "E:/hupai\component\imgcut.py", line 302, in cut_img
    set_val('imgpos_lowestprice', img[use_area[0][1]:use_area[0][3], use_area[0][0]:use_area[0][2]])  # ok
IndexError: list index out of range
Mon, 26 Mar 2018 22:19:44 app_thread.py[line:125] ERROR 刷新失败
Mon, 26 Mar 2018 22:19:44 app_thread.py[line:126] ERROR this is an exception message
Traceback (most recent call last):
  File "E:/hupai\component\app_thread.py", line 123, in run
    findrefresh()
  File "E:/hupai\component\imgcut.py", line 324, in findrefresh
    img = cv2.cvtColor(sc, cv2.COLOR_BGR2GRAY)  # 转灰度图
cv2.error: C:\projects\opencv-python\opencv\modules\imgproc\src\color.cpp:11073: error: (-215) depth == 0 || depth == 2 || depth == 5 in function cv::cvtColor

Mon, 26 Mar 2018 22:19:44 app_thread.py[line:125] ERROR 刷新失败
Mon, 26 Mar 2018 22:19:44 app_thread.py[line:126] ERROR this is an exception message
Traceback (most recent call last):
  File "E:/hupai\component\app_thread.py", line 123, in run
    findrefresh()
  File "E:/hupai\component\imgcut.py", line 324, in findrefresh
    img = cv2.cvtColor(sc, cv2.COLOR_BGR2GRAY)  # 转灰度图
cv2.error: C:\projects\opencv-python\opencv\modules\imgproc\src\color.cpp:11073: error: (-215) depth == 0 || depth == 2 || depth == 5 in function cv::cvtColor

Mon, 26 Mar 2018 22:19:44 imgcut.py[line:309] ERROR cut_img 这里出错
Mon, 26 Mar 2018 22:19:44 imgcut.py[line:310] ERROR this is an exception message
Traceback (most recent call last):
  File "E:/hupai\component\imgcut.py", line 302, in cut_img
    set_val('imgpos_lowestprice', img[use_area[0][1]:use_area[0][3], use_area[0][0]:use_area[0][2]])  # ok
IndexError: list index out of range
Mon, 26 Mar 2018 22:19:44 app_thread.py[line:125] ERROR 刷新失败
Mon, 26 Mar 2018 22:19:44 app_thread.py[line:126] ERROR this is an exception message
Traceback (most recent call last):
  File "E:/hupai\component\app_thread.py", line 123, in run
    findrefresh()
  File "E:/hupai\component\imgcut.py", line 324, in findrefresh
    img = cv2.cvtColor(sc, cv2.COLOR_BGR2GRAY)  # 转灰度图
cv2.error: C:\projects\opencv-python\opencv\modules\imgproc\src\color.cpp:11073: error: (-215) depth == 0 || depth == 2 || depth == 5 in function cv::cvtColor

Mon, 26 Mar 2018 22:19:44 imgcut.py[line:309] ERROR cut_img 这里出错
Mon, 26 Mar 2018 22:19:44 imgcut.py[line:310] ERROR this is an exception message
Traceback (most recent call last):
  File "E:/hupai\component\imgcut.py", line 302, in cut_img
    set_val('imgpos_lowestprice', img[use_area[0][1]:use_area[0][3], use_area[0][0]:use_area[0][2]])  # ok
IndexError: list index out of range
Mon, 26 Mar 2018 22:19:44 app_thread.py[line:125] ERROR 刷新失败
Mon, 26 Mar 2018 22:19:44 app_thread.py[line:126] ERROR this is an exception message
Traceback (most recent call last):
  File "E:/hupai\component\app_thread.py", line 123, in run
    findrefresh()
  File "E:/hupai\component\imgcut.py", line 324, in findrefresh
    img = cv2.cvtColor(sc, cv2.COLOR_BGR2GRAY)  # 转灰度图
cv2.error: C:\projects\opencv-python\opencv\modules\imgproc\src\color.cpp:11073: error: (-215) depth == 0 || depth == 2 || depth == 5 in function cv::cvtColor

Mon, 26 Mar 2018 22:20:00 PngImagePlugin.py[line:137] DEBUG STREAM b'IHDR' 16 13
Mon, 26 Mar 2018 22:20:00 PngImagePlugin.py[line:137] DEBUG STREAM b'IDAT' 41 8192
Mon, 26 Mar 2018 22:20:00 PngImagePlugin.py[line:137] DEBUG STREAM b'IHDR' 16 13
Mon, 26 Mar 2018 22:20:00 PngImagePlugin.py[line:137] DEBUG STREAM b'IDAT' 41 985
Mon, 26 Mar 2018 22:20:00 PngImagePlugin.py[line:137] DEBUG STREAM b'IHDR' 16 13
Mon, 26 Mar 2018 22:20:00 PngImagePlugin.py[line:137] DEBUG STREAM b'IDAT' 41 985
Mon, 26 Mar 2018 22:20:00 PngImagePlugin.py[line:137] DEBUG STREAM b'IHDR' 16 13
Mon, 26 Mar 2018 22:20:00 PngImagePlugin.py[line:137] DEBUG STREAM b'IDAT' 41 985
Mon, 26 Mar 2018 22:20:00 PngImagePlugin.py[line:137] DEBUG STREAM b'IHDR' 16 13
Mon, 26 Mar 2018 22:20:00 PngImagePlugin.py[line:137] DEBUG STREAM b'IDAT' 41 985
Mon, 26 Mar 2018 22:20:00 PngImagePlugin.py[line:137] DEBUG STREAM b'IHDR' 16 13
Mon, 26 Mar 2018 22:20:00 PngImagePlugin.py[line:137] DEBUG STREAM b'IDAT' 41 985
Mon, 26 Mar 2018 22:20:00 PngImagePlugin.py[line:137] DEBUG STREAM b'IHDR' 16 13
Mon, 26 Mar 2018 22:20:00 PngImagePlugin.py[line:137] DEBUG STREAM b'IDAT' 41 985
Mon, 26 Mar 2018 22:20:00 PngImagePlugin.py[line:137] DEBUG STREAM b'IHDR' 16 13
Mon, 26 Mar 2018 22:20:00 PngImagePlugin.py[line:137] DEBUG STREAM b'IDAT' 41 985
Mon, 26 Mar 2018 22:20:00 PngImagePlugin.py[line:137] DEBUG STREAM b'IHDR' 16 13
Mon, 26 Mar 2018 22:20:00 PngImagePlugin.py[line:137] DEBUG STREAM b'IDAT' 41 985
Mon, 26 Mar 2018 22:20:00 PngImagePlugin.py[line:137] DEBUG STREAM b'IHDR' 16 13
Mon, 26 Mar 2018 22:20:00 PngImagePlugin.py[line:137] DEBUG STREAM b'IDAT' 41 985
Mon, 26 Mar 2018 22:20:00 PngImagePlugin.py[line:137] DEBUG STREAM b'IHDR' 16 13
Mon, 26 Mar 2018 22:20:00 PngImagePlugin.py[line:137] DEBUG STREAM b'IDAT' 41 985
Mon, 26 Mar 2018 22:20:00 PngImagePlugin.py[line:137] DEBUG STREAM b'IHDR' 16 13
Mon, 26 Mar 2018 22:20:00 PngImagePlugin.py[line:137] DEBUG STREAM b'IDAT' 41 985
Mon, 26 Mar 2018 22:20:01 PngImagePlugin.py[line:137] DEBUG STREAM b'IHDR' 16 13
Mon, 26 Mar 2018 22:20:01 PngImagePlugin.py[line:137] DEBUG STREAM b'IDAT' 41 985
Mon, 26 Mar 2018 22:20:01 PngImagePlugin.py[line:137] DEBUG STREAM b'IHDR' 16 13
Mon, 26 Mar 2018 22:20:01 PngImagePlugin.py[line:137] DEBUG STREAM b'IDAT' 41 985
Mon, 26 Mar 2018 22:20:01 PngImagePlugin.py[line:137] DEBUG STREAM b'IHDR' 16 13
Mon, 26 Mar 2018 22:20:01 PngImagePlugin.py[line:137] DEBUG STREAM b'IDAT' 41 985
Mon, 26 Mar 2018 22:20:01 PngImagePlugin.py[line:137] DEBUG STREAM b'IHDR' 16 13
Mon, 26 Mar 2018 22:20:01 PngImagePlugin.py[line:137] DEBUG STREAM b'IDAT' 41 985
Mon, 26 Mar 2018 22:20:01 PngImagePlugin.py[line:137] DEBUG STREAM b'IHDR' 16 13
Mon, 26 Mar 2018 22:20:01 PngImagePlugin.py[line:137] DEBUG STREAM b'IDAT' 41 985
Mon, 26 Mar 2018 22:20:01 PngImagePlugin.py[line:137] DEBUG STREAM b'IHDR' 16 13
Mon, 26 Mar 2018 22:20:01 PngImagePlugin.py[line:137] DEBUG STREAM b'IDAT' 41 8192
Mon, 26 Mar 2018 22:20:01 PngImagePlugin.py[line:137] DEBUG STREAM b'IHDR' 16 13
Mon, 26 Mar 2018 22:20:01 PngImagePlugin.py[line:137] DEBUG STREAM b'IDAT' 41 8192
Mon, 26 Mar 2018 22:20:01 PngImagePlugin.py[line:137] DEBUG STREAM b'IHDR' 16 13
Mon, 26 Mar 2018 22:20:01 PngImagePlugin.py[line:137] DEBUG STREAM b'IDAT' 41 8192
Mon, 26 Mar 2018 22:20:01 PngImagePlugin.py[line:137] DEBUG STREAM b'IHDR' 16 13
Mon, 26 Mar 2018 22:20:01 PngImagePlugin.py[line:137] DEBUG STREAM b'IDAT' 41 8192
Mon, 26 Mar 2018 22:20:01 PngImagePlugin.py[line:137] DEBUG STREAM b'IHDR' 16 13
Mon, 26 Mar 2018 22:20:01 PngImagePlugin.py[line:137] DEBUG STREAM b'IDAT' 41 8192
Mon, 26 Mar 2018 22:20:01 PngImagePlugin.py[line:137] DEBUG STREAM b'IHDR' 16 13
Mon, 26 Mar 2018 22:20:01 PngImagePlugin.py[line:137] DEBUG STREAM b'IDAT' 41 8192
Mon, 26 Mar 2018 22:20:01 PngImagePlugin.py[line:137] DEBUG STREAM b'IHDR' 16 13
Mon, 26 Mar 2018 22:20:01 PngImagePlugin.py[line:137] DEBUG STREAM b'IDAT' 41 8192
Mon, 26 Mar 2018 22:20:01 PngImagePlugin.py[line:137] DEBUG STREAM b'IHDR' 16 13
Mon, 26 Mar 2018 22:20:01 PngImagePlugin.py[line:137] DEBUG STREAM b'IDAT' 41 8192
Mon, 26 Mar 2018 22:20:01 PngImagePlugin.py[line:137] DEBUG STREAM b'IHDR' 16 13
Mon, 26 Mar 2018 22:20:01 PngImagePlugin.py[line:137] DEBUG STREAM b'IDAT' 41 8192
Mon, 26 Mar 2018 22:20:01 PngImagePlugin.py[line:137] DEBUG STREAM b'IHDR' 16 13
Mon, 26 Mar 2018 22:20:01 PngImagePlugin.py[line:137] DEBUG STREAM b'IDAT' 41 8192
Mon, 26 Mar 2018 22:20:01 PngImagePlugin.py[line:137] DEBUG STREAM b'IHDR' 16 13
Mon, 26 Mar 2018 22:20:01 PngImagePlugin.py[line:137] DEBUG STREAM b'IDAT' 41 8192
Mon, 26 Mar 2018 22:20:02 PngImagePlugin.py[line:137] DEBUG STREAM b'IHDR' 16 13
Mon, 26 Mar 2018 22:20:02 PngImagePlugin.py[line:137] DEBUG STREAM b'IDAT' 41 8192
Mon, 26 Mar 2018 22:20:02 PngImagePlugin.py[line:137] DEBUG STREAM b'IHDR' 16 13
Mon, 26 Mar 2018 22:20:02 PngImagePlugin.py[line:137] DEBUG STREAM b'IDAT' 41 8192
Mon, 26 Mar 2018 22:20:02 PngImagePlugin.py[line:137] DEBUG STREAM b'IHDR' 16 13
Mon, 26 Mar 2018 22:20:02 PngImagePlugin.py[line:137] DEBUG STREAM b'IDAT' 41 8192
Mon, 26 Mar 2018 22:20:02 PngImagePlugin.py[line:137] DEBUG STREAM b'IHDR' 16 13
Mon, 26 Mar 2018 22:20:02 PngImagePlugin.py[line:137] DEBUG STREAM b'IDAT' 41 8192
Mon, 26 Mar 2018 22:20:02 PngImagePlugin.py[line:137] DEBUG STREAM b'IHDR' 16 13
Mon, 26 Mar 2018 22:20:02 PngImagePlugin.py[line:137] DEBUG STREAM b'IDAT' 41 8192
Mon, 26 Mar 2018 22:20:02 PngImagePlugin.py[line:137] DEBUG STREAM b'IHDR' 16 13
Mon, 26 Mar 2018 22:20:02 PngImagePlugin.py[line:137] DEBUG STREAM b'IDAT' 41 8192
Mon, 26 Mar 2018 22:20:02 PngImagePlugin.py[line:137] DEBUG STREAM b'IHDR' 16 13
Mon, 26 Mar 2018 22:20:02 PngImagePlugin.py[line:137] DEBUG STREAM b'IDAT' 41 8192
Mon, 26 Mar 2018 22:20:02 PngImagePlugin.py[line:137] DEBUG STREAM b'IHDR' 16 13
Mon, 26 Mar 2018 22:20:02 PngImagePlugin.py[line:137] DEBUG STREAM b'IDAT' 41 8192
Mon, 26 Mar 2018 22:20:02 PngImagePlugin.py[line:137] DEBUG STREAM b'IHDR' 16 13
Mon, 26 Mar 2018 22:20:02 PngImagePlugin.py[line:137] DEBUG STREAM b'IDAT' 41 8192
Mon, 26 Mar 2018 22:20:02 PngImagePlugin.py[line:137] DEBUG STREAM b'IHDR' 16 13
Mon, 26 Mar 2018 22:20:02 PngImagePlugin.py[line:137] DEBUG STREAM b'IDAT' 41 8192
Mon, 26 Mar 2018 22:20:02 PngImagePlugin.py[line:137] DEBUG STREAM b'IHDR' 16 13
Mon, 26 Mar 2018 22:20:02 PngImagePlugin.py[line:137] DEBUG STREAM b'IDAT' 41 8192
Mon, 26 Mar 2018 22:20:02 PngImagePlugin.py[line:137] DEBUG STREAM b'IHDR' 16 13
Mon, 26 Mar 2018 22:20:02 PngImagePlugin.py[line:137] DEBUG STREAM b'IDAT' 41 8192
Mon, 26 Mar 2018 22:20:02 PngImagePlugin.py[line:137] DEBUG STREAM b'IHDR' 16 13
Mon, 26 Mar 2018 22:20:02 PngImagePlugin.py[line:137] DEBUG STREAM b'IDAT' 41 8192
Mon, 26 Mar 2018 22:20:02 PngImagePlugin.py[line:137] DEBUG STREAM b'IHDR' 16 13
Mon, 26 Mar 2018 22:20:02 PngImagePlugin.py[line:137] DEBUG STREAM b'IDAT' 41 8192
Mon, 26 Mar 2018 22:20:02 PngImagePlugin.py[line:137] DEBUG STREAM b'IHDR' 16 13
Mon, 26 Mar 2018 22:20:02 PngImagePlugin.py[line:137] DEBUG STREAM b'IDAT' 41 8192
Mon, 26 Mar 2018 22:20:02 PngImagePlugin.py[line:137] DEBUG STREAM b'IHDR' 16 13
Mon, 26 Mar 2018 22:20:02 PngImagePlugin.py[line:137] DEBUG STREAM b'IDAT' 41 8192
Mon, 26 Mar 2018 22:20:03 PngImagePlugin.py[line:137] DEBUG STREAM b'IHDR' 16 13
Mon, 26 Mar 2018 22:20:03 PngImagePlugin.py[line:137] DEBUG STREAM b'IDAT' 41 8192
Mon, 26 Mar 2018 22:20:03 PngImagePlugin.py[line:137] DEBUG STREAM b'IHDR' 16 13
Mon, 26 Mar 2018 22:20:03 PngImagePlugin.py[line:137] DEBUG STREAM b'IDAT' 41 8192
Mon, 26 Mar 2018 22:20:03 PngImagePlugin.py[line:137] DEBUG STREAM b'IHDR' 16 13
Mon, 26 Mar 2018 22:20:03 PngImagePlugin.py[line:137] DEBUG STREAM b'IDAT' 41 8192
Mon, 26 Mar 2018 22:20:03 PngImagePlugin.py[line:137] DEBUG STREAM b'IHDR' 16 13
Mon, 26 Mar 2018 22:20:03 PngImagePlugin.py[line:137] DEBUG STREAM b'IDAT' 41 8192
Mon, 26 Mar 2018 22:20:03 PngImagePlugin.py[line:137] DEBUG STREAM b'IHDR' 16 13
Mon, 26 Mar 2018 22:20:03 PngImagePlugin.py[line:137] DEBUG STREAM b'IDAT' 41 8192
Mon, 26 Mar 2018 22:20:03 PngImagePlugin.py[line:137] DEBUG STREAM b'IHDR' 16 13
Mon, 26 Mar 2018 22:20:03 PngImagePlugin.py[line:137] DEBUG STREAM b'IDAT' 41 8192
Mon, 26 Mar 2018 22:20:03 PngImagePlugin.py[line:137] DEBUG STREAM b'IHDR' 16 13
Mon, 26 Mar 2018 22:20:03 PngImagePlugin.py[line:137] DEBUG STREAM b'IDAT' 41 8192
Mon, 26 Mar 2018 22:20:03 PngImagePlugin.py[line:137] DEBUG STREAM b'IHDR' 16 13
Mon, 26 Mar 2018 22:20:03 PngImagePlugin.py[line:137] DEBUG STREAM b'IDAT' 41 8192
Mon, 26 Mar 2018 22:20:03 PngImagePlugin.py[line:137] DEBUG STREAM b'IHDR' 16 13
Mon, 26 Mar 2018 22:20:03 PngImagePlugin.py[line:137] DEBUG STREAM b'IDAT' 41 8192
Mon, 26 Mar 2018 22:20:03 PngImagePlugin.py[line:137] DEBUG STREAM b'IHDR' 16 13
Mon, 26 Mar 2018 22:20:03 PngImagePlugin.py[line:137] DEBUG STREAM b'IDAT' 41 8192
Mon, 26 Mar 2018 22:20:03 PngImagePlugin.py[line:137] DEBUG STREAM b'IHDR' 16 13
Mon, 26 Mar 2018 22:20:03 PngImagePlugin.py[line:137] DEBUG STREAM b'IDAT' 41 8192
Mon, 26 Mar 2018 22:20:03 PngImagePlugin.py[line:137] DEBUG STREAM b'IHDR' 16 13
Mon, 26 Mar 2018 22:20:03 PngImagePlugin.py[line:137] DEBUG STREAM b'IDAT' 41 8192
Mon, 26 Mar 2018 22:20:03 PngImagePlugin.py[line:137] DEBUG STREAM b'IHDR' 16 13
Mon, 26 Mar 2018 22:20:03 PngImagePlugin.py[line:137] DEBUG STREAM b'IDAT' 41 8192
Mon, 26 Mar 2018 22:20:03 PngImagePlugin.py[line:137] DEBUG STREAM b'IHDR' 16 13
Mon, 26 Mar 2018 22:20:03 PngImagePlugin.py[line:137] DEBUG STREAM b'IDAT' 41 8192
Mon, 26 Mar 2018 22:20:03 PngImagePlugin.py[line:137] DEBUG STREAM b'IHDR' 16 13
Mon, 26 Mar 2018 22:20:03 PngImagePlugin.py[line:137] DEBUG STREAM b'IDAT' 41 8192
Mon, 26 Mar 2018 22:20:03 PngImagePlugin.py[line:137] DEBUG STREAM b'IHDR' 16 13
Mon, 26 Mar 2018 22:20:03 PngImagePlugin.py[line:137] DEBUG STREAM b'IDAT' 41 8192
Mon, 26 Mar 2018 22:20:04 PngImagePlugin.py[line:137] DEBUG STREAM b'IHDR' 16 13
Mon, 26 Mar 2018 22:20:04 PngImagePlugin.py[line:137] DEBUG STREAM b'IDAT' 41 8192
Mon, 26 Mar 2018 22:20:30 PngImagePlugin.py[line:137] DEBUG STREAM b'IHDR' 16 13
Mon, 26 Mar 2018 22:20:30 PngImagePlugin.py[line:137] DEBUG STREAM b'IDAT' 41 1315
Mon, 26 Mar 2018 22:20:30 PngImagePlugin.py[line:137] DEBUG STREAM b'IHDR' 16 13
Mon, 26 Mar 2018 22:20:30 PngImagePlugin.py[line:137] DEBUG STREAM b'IDAT' 41 1315
Mon, 26 Mar 2018 22:20:30 PngImagePlugin.py[line:137] DEBUG STREAM b'IHDR' 16 13
Mon, 26 Mar 2018 22:20:30 PngImagePlugin.py[line:137] DEBUG STREAM b'IDAT' 41 1315
Mon, 26 Mar 2018 22:20:42 PngImagePlugin.py[line:137] DEBUG STREAM b'IHDR' 16 13
Mon, 26 Mar 2018 22:20:42 PngImagePlugin.py[line:137] DEBUG STREAM b'IDAT' 41 1315
