Sat, 05 May 2018 23:11:49 PngImagePlugin.py[line:138] DEBUG STREAM b'IHDR' 16 13
Sat, 05 May 2018 23:11:49 PngImagePlugin.py[line:138] DEBUG STREAM b'IDAT' 41 65536
Sat, 05 May 2018 23:11:49 PngImagePlugin.py[line:138] DEBUG STREAM b'IHDR' 16 13
Sat, 05 May 2018 23:11:49 PngImagePlugin.py[line:138] DEBUG STREAM b'IDAT' 41 65536
Sat, 05 May 2018 23:11:51 app_thread.py[line:149] ERROR 刷新失败
Sat, 05 May 2018 23:11:51 app_thread.py[line:150] ERROR this is an exception message
Traceback (most recent call last):
  File "E:\hupai\component\app_thread.py", line 147, in run
    findrefresh()
  File "E:\hupai\component\imgcut.py", line 412, in findrefresh
    img = cv2.cvtColor(sc, cv2.COLOR_BGR2GRAY)  # 转灰度图
cv2.error: C:\projects\opencv-python\opencv\modules\imgproc\src\color.cpp:11073: error: (-215) depth == 0 || depth == 2 || depth == 5 in function cv::cvtColor

Sat, 05 May 2018 23:11:51 imgcut.py[line:397] ERROR cut_img 这里出错
Sat, 05 May 2018 23:11:51 imgcut.py[line:398] ERROR this is an exception message
Traceback (most recent call last):
  File "E:\hupai\component\imgcut.py", line 390, in cut_img
    set_val('imgpos_lowestprice', img[use_area[0][1]:use_area[0][3], use_area[0][0]:use_area[0][2]])  # ok
IndexError: list index out of range
Sat, 05 May 2018 23:11:51 app_thread.py[line:149] ERROR 刷新失败
Sat, 05 May 2018 23:11:51 app_thread.py[line:150] ERROR this is an exception message
Traceback (most recent call last):
  File "E:\hupai\component\app_thread.py", line 147, in run
    findrefresh()
  File "E:\hupai\component\imgcut.py", line 412, in findrefresh
    img = cv2.cvtColor(sc, cv2.COLOR_BGR2GRAY)  # 转灰度图
cv2.error: C:\projects\opencv-python\opencv\modules\imgproc\src\color.cpp:11073: error: (-215) depth == 0 || depth == 2 || depth == 5 in function cv::cvtColor

Sat, 05 May 2018 23:11:51 imgcut.py[line:397] ERROR cut_img 这里出错
Sat, 05 May 2018 23:11:51 imgcut.py[line:398] ERROR this is an exception message
Traceback (most recent call last):
  File "E:\hupai\component\imgcut.py", line 390, in cut_img
    set_val('imgpos_lowestprice', img[use_area[0][1]:use_area[0][3], use_area[0][0]:use_area[0][2]])  # ok
IndexError: list index out of range
Sat, 05 May 2018 23:11:51 app_thread.py[line:149] ERROR 刷新失败
Sat, 05 May 2018 23:11:51 app_thread.py[line:150] ERROR this is an exception message
Traceback (most recent call last):
  File "E:\hupai\component\app_thread.py", line 147, in run
    findrefresh()
  File "E:\hupai\component\imgcut.py", line 412, in findrefresh
    img = cv2.cvtColor(sc, cv2.COLOR_BGR2GRAY)  # 转灰度图
cv2.error: C:\projects\opencv-python\opencv\modules\imgproc\src\color.cpp:11073: error: (-215) depth == 0 || depth == 2 || depth == 5 in function cv::cvtColor

Sat, 05 May 2018 23:11:51 app_thread.py[line:149] ERROR 刷新失败
Sat, 05 May 2018 23:11:51 app_thread.py[line:150] ERROR this is an exception message
Traceback (most recent call last):
  File "E:\hupai\component\app_thread.py", line 147, in run
    findrefresh()
  File "E:\hupai\component\imgcut.py", line 412, in findrefresh
    img = cv2.cvtColor(sc, cv2.COLOR_BGR2GRAY)  # 转灰度图
cv2.error: C:\projects\opencv-python\opencv\modules\imgproc\src\color.cpp:11073: error: (-215) depth == 0 || depth == 2 || depth == 5 in function cv::cvtColor

Sat, 05 May 2018 23:11:51 imgcut.py[line:397] ERROR cut_img 这里出错
Sat, 05 May 2018 23:11:51 imgcut.py[line:398] ERROR this is an exception message
Traceback (most recent call last):
  File "E:\hupai\component\imgcut.py", line 390, in cut_img
    set_val('imgpos_lowestprice', img[use_area[0][1]:use_area[0][3], use_area[0][0]:use_area[0][2]])  # ok
IndexError: list index out of range
Sat, 05 May 2018 23:11:51 app_thread.py[line:149] ERROR 刷新失败
Sat, 05 May 2018 23:11:51 app_thread.py[line:150] ERROR this is an exception message
Traceback (most recent call last):
  File "E:\hupai\component\app_thread.py", line 147, in run
    findrefresh()
  File "E:\hupai\component\imgcut.py", line 412, in findrefresh
    img = cv2.cvtColor(sc, cv2.COLOR_BGR2GRAY)  # 转灰度图
cv2.error: C:\projects\opencv-python\opencv\modules\imgproc\src\color.cpp:11073: error: (-215) depth == 0 || depth == 2 || depth == 5 in function cv::cvtColor

Sat, 05 May 2018 23:11:51 imgcut.py[line:397] ERROR cut_img 这里出错
Sat, 05 May 2018 23:11:51 imgcut.py[line:398] ERROR this is an exception message
Traceback (most recent call last):
  File "E:\hupai\component\imgcut.py", line 390, in cut_img
    set_val('imgpos_lowestprice', img[use_area[0][1]:use_area[0][3], use_area[0][0]:use_area[0][2]])  # ok
IndexError: list index out of range
Sat, 05 May 2018 23:11:51 app_thread.py[line:149] ERROR 刷新失败
Sat, 05 May 2018 23:11:51 app_thread.py[line:150] ERROR this is an exception message
Traceback (most recent call last):
  File "E:\hupai\component\app_thread.py", line 147, in run
    findrefresh()
  File "E:\hupai\component\imgcut.py", line 412, in findrefresh
    img = cv2.cvtColor(sc, cv2.COLOR_BGR2GRAY)  # 转灰度图
cv2.error: C:\projects\opencv-python\opencv\modules\imgproc\src\color.cpp:11073: error: (-215) depth == 0 || depth == 2 || depth == 5 in function cv::cvtColor

Sat, 05 May 2018 23:11:51 imgcut.py[line:397] ERROR cut_img 这里出错
Sat, 05 May 2018 23:11:51 imgcut.py[line:398] ERROR this is an exception message
Traceback (most recent call last):
  File "E:\hupai\component\imgcut.py", line 390, in cut_img
    set_val('imgpos_lowestprice', img[use_area[0][1]:use_area[0][3], use_area[0][0]:use_area[0][2]])  # ok
IndexError: list index out of range
Sat, 05 May 2018 23:11:51 app_thread.py[line:149] ERROR 刷新失败
Sat, 05 May 2018 23:11:51 app_thread.py[line:150] ERROR this is an exception message
Traceback (most recent call last):
  File "E:\hupai\component\app_thread.py", line 147, in run
    findrefresh()
  File "E:\hupai\component\imgcut.py", line 412, in findrefresh
    img = cv2.cvtColor(sc, cv2.COLOR_BGR2GRAY)  # 转灰度图
cv2.error: C:\projects\opencv-python\opencv\modules\imgproc\src\color.cpp:11073: error: (-215) depth == 0 || depth == 2 || depth == 5 in function cv::cvtColor

Sat, 05 May 2018 23:11:51 imgcut.py[line:397] ERROR cut_img 这里出错
Sat, 05 May 2018 23:11:51 imgcut.py[line:398] ERROR this is an exception message
Traceback (most recent call last):
  File "E:\hupai\component\imgcut.py", line 390, in cut_img
    set_val('imgpos_lowestprice', img[use_area[0][1]:use_area[0][3], use_area[0][0]:use_area[0][2]])  # ok
IndexError: list index out of range
Sat, 05 May 2018 23:11:51 app_thread.py[line:149] ERROR 刷新失败
Sat, 05 May 2018 23:11:51 app_thread.py[line:150] ERROR this is an exception message
Traceback (most recent call last):
  File "E:\hupai\component\app_thread.py", line 147, in run
    findrefresh()
  File "E:\hupai\component\imgcut.py", line 412, in findrefresh
    img = cv2.cvtColor(sc, cv2.COLOR_BGR2GRAY)  # 转灰度图
cv2.error: C:\projects\opencv-python\opencv\modules\imgproc\src\color.cpp:11073: error: (-215) depth == 0 || depth == 2 || depth == 5 in function cv::cvtColor

Sat, 05 May 2018 23:11:51 app_thread.py[line:149] ERROR 刷新失败
Sat, 05 May 2018 23:11:51 app_thread.py[line:150] ERROR this is an exception message
Traceback (most recent call last):
  File "E:\hupai\component\app_thread.py", line 147, in run
    findrefresh()
  File "E:\hupai\component\imgcut.py", line 412, in findrefresh
    img = cv2.cvtColor(sc, cv2.COLOR_BGR2GRAY)  # 转灰度图
cv2.error: C:\projects\opencv-python\opencv\modules\imgproc\src\color.cpp:11073: error: (-215) depth == 0 || depth == 2 || depth == 5 in function cv::cvtColor

Sat, 05 May 2018 23:11:51 imgcut.py[line:397] ERROR cut_img 这里出错
Sat, 05 May 2018 23:11:51 imgcut.py[line:398] ERROR this is an exception message
Traceback (most recent call last):
  File "E:\hupai\component\imgcut.py", line 390, in cut_img
    set_val('imgpos_lowestprice', img[use_area[0][1]:use_area[0][3], use_area[0][0]:use_area[0][2]])  # ok
IndexError: list index out of range
Sat, 05 May 2018 23:11:51 app_thread.py[line:149] ERROR 刷新失败
Sat, 05 May 2018 23:11:51 app_thread.py[line:150] ERROR this is an exception message
Traceback (most recent call last):
  File "E:\hupai\component\app_thread.py", line 147, in run
    findrefresh()
  File "E:\hupai\component\imgcut.py", line 412, in findrefresh
    img = cv2.cvtColor(sc, cv2.COLOR_BGR2GRAY)  # 转灰度图
cv2.error: C:\projects\opencv-python\opencv\modules\imgproc\src\color.cpp:11073: error: (-215) depth == 0 || depth == 2 || depth == 5 in function cv::cvtColor

Sat, 05 May 2018 23:11:51 imgcut.py[line:397] ERROR cut_img 这里出错
Sat, 05 May 2018 23:11:51 imgcut.py[line:398] ERROR this is an exception message
Traceback (most recent call last):
  File "E:\hupai\component\imgcut.py", line 390, in cut_img
    set_val('imgpos_lowestprice', img[use_area[0][1]:use_area[0][3], use_area[0][0]:use_area[0][2]])  # ok
IndexError: list index out of range
Sat, 05 May 2018 23:11:51 app_thread.py[line:149] ERROR 刷新失败
Sat, 05 May 2018 23:11:51 app_thread.py[line:150] ERROR this is an exception message
Traceback (most recent call last):
  File "E:\hupai\component\app_thread.py", line 147, in run
    findrefresh()
  File "E:\hupai\component\imgcut.py", line 412, in findrefresh
    img = cv2.cvtColor(sc, cv2.COLOR_BGR2GRAY)  # 转灰度图
cv2.error: C:\projects\opencv-python\opencv\modules\imgproc\src\color.cpp:11073: error: (-215) depth == 0 || depth == 2 || depth == 5 in function cv::cvtColor

Sat, 05 May 2018 23:11:51 imgcut.py[line:397] ERROR cut_img 这里出错
Sat, 05 May 2018 23:11:51 imgcut.py[line:398] ERROR this is an exception message
Traceback (most recent call last):
  File "E:\hupai\component\imgcut.py", line 390, in cut_img
    set_val('imgpos_lowestprice', img[use_area[0][1]:use_area[0][3], use_area[0][0]:use_area[0][2]])  # ok
IndexError: list index out of range
Sat, 05 May 2018 23:11:51 app_thread.py[line:149] ERROR 刷新失败
Sat, 05 May 2018 23:11:51 app_thread.py[line:150] ERROR this is an exception message
Traceback (most recent call last):
  File "E:\hupai\component\app_thread.py", line 147, in run
    findrefresh()
  File "E:\hupai\component\imgcut.py", line 412, in findrefresh
    img = cv2.cvtColor(sc, cv2.COLOR_BGR2GRAY)  # 转灰度图
cv2.error: C:\projects\opencv-python\opencv\modules\imgproc\src\color.cpp:11073: error: (-215) depth == 0 || depth == 2 || depth == 5 in function cv::cvtColor

Sat, 05 May 2018 23:11:51 imgcut.py[line:397] ERROR cut_img 这里出错
Sat, 05 May 2018 23:11:51 imgcut.py[line:398] ERROR this is an exception message
Traceback (most recent call last):
  File "E:\hupai\component\imgcut.py", line 390, in cut_img
    set_val('imgpos_lowestprice', img[use_area[0][1]:use_area[0][3], use_area[0][0]:use_area[0][2]])  # ok
IndexError: list index out of range
Sat, 05 May 2018 23:11:51 app_thread.py[line:149] ERROR 刷新失败
Sat, 05 May 2018 23:11:51 app_thread.py[line:150] ERROR this is an exception message
Traceback (most recent call last):
  File "E:\hupai\component\app_thread.py", line 147, in run
    findrefresh()
  File "E:\hupai\component\imgcut.py", line 412, in findrefresh
    img = cv2.cvtColor(sc, cv2.COLOR_BGR2GRAY)  # 转灰度图
cv2.error: C:\projects\opencv-python\opencv\modules\imgproc\src\color.cpp:11073: error: (-215) depth == 0 || depth == 2 || depth == 5 in function cv::cvtColor

Sat, 05 May 2018 23:11:52 app_thread.py[line:149] ERROR 刷新失败
Sat, 05 May 2018 23:11:52 app_thread.py[line:150] ERROR this is an exception message
Traceback (most recent call last):
  File "E:\hupai\component\app_thread.py", line 147, in run
    findrefresh()
  File "E:\hupai\component\imgcut.py", line 412, in findrefresh
    img = cv2.cvtColor(sc, cv2.COLOR_BGR2GRAY)  # 转灰度图
cv2.error: C:\projects\opencv-python\opencv\modules\imgproc\src\color.cpp:11073: error: (-215) depth == 0 || depth == 2 || depth == 5 in function cv::cvtColor

Sat, 05 May 2018 23:11:52 imgcut.py[line:397] ERROR cut_img 这里出错
Sat, 05 May 2018 23:11:52 imgcut.py[line:398] ERROR this is an exception message
Traceback (most recent call last):
  File "E:\hupai\component\imgcut.py", line 390, in cut_img
    set_val('imgpos_lowestprice', img[use_area[0][1]:use_area[0][3], use_area[0][0]:use_area[0][2]])  # ok
IndexError: list index out of range
Sat, 05 May 2018 23:11:52 app_thread.py[line:149] ERROR 刷新失败
Sat, 05 May 2018 23:11:52 app_thread.py[line:150] ERROR this is an exception message
Traceback (most recent call last):
  File "E:\hupai\component\app_thread.py", line 147, in run
    findrefresh()
  File "E:\hupai\component\imgcut.py", line 412, in findrefresh
    img = cv2.cvtColor(sc, cv2.COLOR_BGR2GRAY)  # 转灰度图
cv2.error: C:\projects\opencv-python\opencv\modules\imgproc\src\color.cpp:11073: error: (-215) depth == 0 || depth == 2 || depth == 5 in function cv::cvtColor

Sat, 05 May 2018 23:11:52 imgcut.py[line:397] ERROR cut_img 这里出错
Sat, 05 May 2018 23:11:52 imgcut.py[line:398] ERROR this is an exception message
Traceback (most recent call last):
  File "E:\hupai\component\imgcut.py", line 390, in cut_img
    set_val('imgpos_lowestprice', img[use_area[0][1]:use_area[0][3], use_area[0][0]:use_area[0][2]])  # ok
IndexError: list index out of range
Sat, 05 May 2018 23:11:52 app_thread.py[line:149] ERROR 刷新失败
Sat, 05 May 2018 23:11:52 app_thread.py[line:150] ERROR this is an exception message
Traceback (most recent call last):
  File "E:\hupai\component\app_thread.py", line 147, in run
    findrefresh()
  File "E:\hupai\component\imgcut.py", line 412, in findrefresh
    img = cv2.cvtColor(sc, cv2.COLOR_BGR2GRAY)  # 转灰度图
cv2.error: C:\projects\opencv-python\opencv\modules\imgproc\src\color.cpp:11073: error: (-215) depth == 0 || depth == 2 || depth == 5 in function cv::cvtColor

Sat, 05 May 2018 23:11:52 imgcut.py[line:397] ERROR cut_img 这里出错
Sat, 05 May 2018 23:11:52 imgcut.py[line:398] ERROR this is an exception message
Traceback (most recent call last):
  File "E:\hupai\component\imgcut.py", line 390, in cut_img
    set_val('imgpos_lowestprice', img[use_area[0][1]:use_area[0][3], use_area[0][0]:use_area[0][2]])  # ok
IndexError: list index out of range
Sat, 05 May 2018 23:11:52 app_thread.py[line:149] ERROR 刷新失败
Sat, 05 May 2018 23:11:52 app_thread.py[line:150] ERROR this is an exception message
Traceback (most recent call last):
  File "E:\hupai\component\app_thread.py", line 147, in run
    findrefresh()
  File "E:\hupai\component\imgcut.py", line 412, in findrefresh
    img = cv2.cvtColor(sc, cv2.COLOR_BGR2GRAY)  # 转灰度图
cv2.error: C:\projects\opencv-python\opencv\modules\imgproc\src\color.cpp:11073: error: (-215) depth == 0 || depth == 2 || depth == 5 in function cv::cvtColor

Sat, 05 May 2018 23:11:52 app_thread.py[line:149] ERROR 刷新失败
Sat, 05 May 2018 23:11:52 app_thread.py[line:150] ERROR this is an exception message
Traceback (most recent call last):
  File "E:\hupai\component\app_thread.py", line 147, in run
    findrefresh()
  File "E:\hupai\component\imgcut.py", line 412, in findrefresh
    img = cv2.cvtColor(sc, cv2.COLOR_BGR2GRAY)  # 转灰度图
cv2.error: C:\projects\opencv-python\opencv\modules\imgproc\src\color.cpp:11073: error: (-215) depth == 0 || depth == 2 || depth == 5 in function cv::cvtColor

Sat, 05 May 2018 23:11:52 imgcut.py[line:397] ERROR cut_img 这里出错
Sat, 05 May 2018 23:11:52 imgcut.py[line:398] ERROR this is an exception message
Traceback (most recent call last):
  File "E:\hupai\component\imgcut.py", line 390, in cut_img
    set_val('imgpos_lowestprice', img[use_area[0][1]:use_area[0][3], use_area[0][0]:use_area[0][2]])  # ok
IndexError: list index out of range
Sat, 05 May 2018 23:11:52 app_thread.py[line:149] ERROR 刷新失败
Sat, 05 May 2018 23:11:52 app_thread.py[line:150] ERROR this is an exception message
Traceback (most recent call last):
  File "E:\hupai\component\app_thread.py", line 147, in run
    findrefresh()
  File "E:\hupai\component\imgcut.py", line 412, in findrefresh
    img = cv2.cvtColor(sc, cv2.COLOR_BGR2GRAY)  # 转灰度图
cv2.error: C:\projects\opencv-python\opencv\modules\imgproc\src\color.cpp:11073: error: (-215) depth == 0 || depth == 2 || depth == 5 in function cv::cvtColor

Sat, 05 May 2018 23:11:52 imgcut.py[line:397] ERROR cut_img 这里出错
Sat, 05 May 2018 23:11:52 imgcut.py[line:398] ERROR this is an exception message
Traceback (most recent call last):
  File "E:\hupai\component\imgcut.py", line 390, in cut_img
    set_val('imgpos_lowestprice', img[use_area[0][1]:use_area[0][3], use_area[0][0]:use_area[0][2]])  # ok
IndexError: list index out of range
Sat, 05 May 2018 23:11:52 app_thread.py[line:149] ERROR 刷新失败
Sat, 05 May 2018 23:11:52 app_thread.py[line:150] ERROR this is an exception message
Traceback (most recent call last):
  File "E:\hupai\component\app_thread.py", line 147, in run
    findrefresh()
  File "E:\hupai\component\imgcut.py", line 412, in findrefresh
    img = cv2.cvtColor(sc, cv2.COLOR_BGR2GRAY)  # 转灰度图
cv2.error: C:\projects\opencv-python\opencv\modules\imgproc\src\color.cpp:11073: error: (-215) depth == 0 || depth == 2 || depth == 5 in function cv::cvtColor

Sat, 05 May 2018 23:11:52 app_thread.py[line:149] ERROR 刷新失败
Sat, 05 May 2018 23:11:52 app_thread.py[line:150] ERROR this is an exception message
Traceback (most recent call last):
  File "E:\hupai\component\app_thread.py", line 147, in run
    findrefresh()
  File "E:\hupai\component\imgcut.py", line 412, in findrefresh
    img = cv2.cvtColor(sc, cv2.COLOR_BGR2GRAY)  # 转灰度图
cv2.error: C:\projects\opencv-python\opencv\modules\imgproc\src\color.cpp:11073: error: (-215) depth == 0 || depth == 2 || depth == 5 in function cv::cvtColor

Sat, 05 May 2018 23:11:52 imgcut.py[line:397] ERROR cut_img 这里出错
Sat, 05 May 2018 23:11:52 imgcut.py[line:398] ERROR this is an exception message
Traceback (most recent call last):
  File "E:\hupai\component\imgcut.py", line 390, in cut_img
    set_val('imgpos_lowestprice', img[use_area[0][1]:use_area[0][3], use_area[0][0]:use_area[0][2]])  # ok
IndexError: list index out of range
Sat, 05 May 2018 23:11:52 app_thread.py[line:149] ERROR 刷新失败
Sat, 05 May 2018 23:11:52 app_thread.py[line:150] ERROR this is an exception message
Traceback (most recent call last):
  File "E:\hupai\component\app_thread.py", line 147, in run
    findrefresh()
  File "E:\hupai\component\imgcut.py", line 412, in findrefresh
    img = cv2.cvtColor(sc, cv2.COLOR_BGR2GRAY)  # 转灰度图
cv2.error: C:\projects\opencv-python\opencv\modules\imgproc\src\color.cpp:11073: error: (-215) depth == 0 || depth == 2 || depth == 5 in function cv::cvtColor

Sat, 05 May 2018 23:11:52 imgcut.py[line:397] ERROR cut_img 这里出错
Sat, 05 May 2018 23:11:52 app_thread.py[line:149] ERROR 刷新失败
Sat, 05 May 2018 23:11:52 imgcut.py[line:398] ERROR this is an exception message
Traceback (most recent call last):
  File "E:\hupai\component\imgcut.py", line 390, in cut_img
    set_val('imgpos_lowestprice', img[use_area[0][1]:use_area[0][3], use_area[0][0]:use_area[0][2]])  # ok
IndexError: list index out of range
Sat, 05 May 2018 23:11:52 app_thread.py[line:150] ERROR this is an exception message
Traceback (most recent call last):
  File "E:\hupai\component\app_thread.py", line 147, in run
    findrefresh()
  File "E:\hupai\component\imgcut.py", line 412, in findrefresh
    img = cv2.cvtColor(sc, cv2.COLOR_BGR2GRAY)  # 转灰度图
cv2.error: C:\projects\opencv-python\opencv\modules\imgproc\src\color.cpp:11073: error: (-215) depth == 0 || depth == 2 || depth == 5 in function cv::cvtColor

Sat, 05 May 2018 23:11:52 app_thread.py[line:149] ERROR 刷新失败
Sat, 05 May 2018 23:11:52 app_thread.py[line:150] ERROR this is an exception message
Traceback (most recent call last):
  File "E:\hupai\component\app_thread.py", line 147, in run
    findrefresh()
  File "E:\hupai\component\imgcut.py", line 412, in findrefresh
    img = cv2.cvtColor(sc, cv2.COLOR_BGR2GRAY)  # 转灰度图
cv2.error: C:\projects\opencv-python\opencv\modules\imgproc\src\color.cpp:11073: error: (-215) depth == 0 || depth == 2 || depth == 5 in function cv::cvtColor

Sat, 05 May 2018 23:11:52 imgcut.py[line:397] ERROR cut_img 这里出错
Sat, 05 May 2018 23:11:52 imgcut.py[line:398] ERROR this is an exception message
Traceback (most recent call last):
  File "E:\hupai\component\imgcut.py", line 390, in cut_img
    set_val('imgpos_lowestprice', img[use_area[0][1]:use_area[0][3], use_area[0][0]:use_area[0][2]])  # ok
IndexError: list index out of range
Sat, 05 May 2018 23:11:52 app_thread.py[line:149] ERROR 刷新失败
Sat, 05 May 2018 23:11:52 app_thread.py[line:150] ERROR this is an exception message
Traceback (most recent call last):
  File "E:\hupai\component\app_thread.py", line 147, in run
    findrefresh()
  File "E:\hupai\component\imgcut.py", line 412, in findrefresh
    img = cv2.cvtColor(sc, cv2.COLOR_BGR2GRAY)  # 转灰度图
cv2.error: C:\projects\opencv-python\opencv\modules\imgproc\src\color.cpp:11073: error: (-215) depth == 0 || depth == 2 || depth == 5 in function cv::cvtColor

Sat, 05 May 2018 23:11:52 imgcut.py[line:397] ERROR cut_img 这里出错
Sat, 05 May 2018 23:11:52 imgcut.py[line:398] ERROR this is an exception message
Traceback (most recent call last):
  File "E:\hupai\component\imgcut.py", line 390, in cut_img
    set_val('imgpos_lowestprice', img[use_area[0][1]:use_area[0][3], use_area[0][0]:use_area[0][2]])  # ok
IndexError: list index out of range
Sat, 05 May 2018 23:11:52 app_thread.py[line:149] ERROR 刷新失败
Sat, 05 May 2018 23:11:52 app_thread.py[line:150] ERROR this is an exception message
Traceback (most recent call last):
  File "E:\hupai\component\app_thread.py", line 147, in run
    findrefresh()
  File "E:\hupai\component\imgcut.py", line 412, in findrefresh
    img = cv2.cvtColor(sc, cv2.COLOR_BGR2GRAY)  # 转灰度图
cv2.error: C:\projects\opencv-python\opencv\modules\imgproc\src\color.cpp:11073: error: (-215) depth == 0 || depth == 2 || depth == 5 in function cv::cvtColor

Sat, 05 May 2018 23:11:52 app_thread.py[line:149] ERROR 刷新失败
Sat, 05 May 2018 23:11:52 app_thread.py[line:150] ERROR this is an exception message
Traceback (most recent call last):
  File "E:\hupai\component\app_thread.py", line 147, in run
    findrefresh()
  File "E:\hupai\component\imgcut.py", line 412, in findrefresh
    img = cv2.cvtColor(sc, cv2.COLOR_BGR2GRAY)  # 转灰度图
cv2.error: C:\projects\opencv-python\opencv\modules\imgproc\src\color.cpp:11073: error: (-215) depth == 0 || depth == 2 || depth == 5 in function cv::cvtColor

Sat, 05 May 2018 23:11:52 imgcut.py[line:397] ERROR cut_img 这里出错
Sat, 05 May 2018 23:11:52 imgcut.py[line:398] ERROR this is an exception message
Traceback (most recent call last):
  File "E:\hupai\component\imgcut.py", line 390, in cut_img
    set_val('imgpos_lowestprice', img[use_area[0][1]:use_area[0][3], use_area[0][0]:use_area[0][2]])  # ok
IndexError: list index out of range
Sat, 05 May 2018 23:11:52 app_thread.py[line:149] ERROR 刷新失败
Sat, 05 May 2018 23:11:52 app_thread.py[line:150] ERROR this is an exception message
Traceback (most recent call last):
  File "E:\hupai\component\app_thread.py", line 147, in run
    findrefresh()
  File "E:\hupai\component\imgcut.py", line 412, in findrefresh
    img = cv2.cvtColor(sc, cv2.COLOR_BGR2GRAY)  # 转灰度图
cv2.error: C:\projects\opencv-python\opencv\modules\imgproc\src\color.cpp:11073: error: (-215) depth == 0 || depth == 2 || depth == 5 in function cv::cvtColor

Sat, 05 May 2018 23:11:52 imgcut.py[line:270] ERROR this is an exception message
Traceback (most recent call last):
  File "E:\hupai\component\imgcut.py", line 240, in timeset
    currenttime = cv2.cvtColor(imgpos_currenttime, cv2.COLOR_BGR2GRAY)
cv2.error: C:\projects\opencv-python\opencv\modules\imgproc\src\color.cpp:11073: error: (-215) depth == 0 || depth == 2 || depth == 5 in function cv::cvtColor

Sat, 05 May 2018 23:11:52 app_thread.py[line:149] ERROR 刷新失败
Sat, 05 May 2018 23:11:52 app_thread.py[line:150] ERROR this is an exception message
Traceback (most recent call last):
  File "E:\hupai\component\app_thread.py", line 147, in run
    findrefresh()
  File "E:\hupai\component\imgcut.py", line 412, in findrefresh
    img = cv2.cvtColor(sc, cv2.COLOR_BGR2GRAY)  # 转灰度图
cv2.error: C:\projects\opencv-python\opencv\modules\imgproc\src\color.cpp:11073: error: (-215) depth == 0 || depth == 2 || depth == 5 in function cv::cvtColor

Sat, 05 May 2018 23:11:52 imgcut.py[line:397] ERROR cut_img 这里出错
Sat, 05 May 2018 23:11:52 imgcut.py[line:398] ERROR this is an exception message
Traceback (most recent call last):
  File "E:\hupai\component\imgcut.py", line 390, in cut_img
    set_val('imgpos_lowestprice', img[use_area[0][1]:use_area[0][3], use_area[0][0]:use_area[0][2]])  # ok
IndexError: list index out of range
Sat, 05 May 2018 23:11:52 app_thread.py[line:149] ERROR 刷新失败
Sat, 05 May 2018 23:11:52 app_thread.py[line:150] ERROR this is an exception message
Traceback (most recent call last):
  File "E:\hupai\component\app_thread.py", line 147, in run
    findrefresh()
  File "E:\hupai\component\imgcut.py", line 412, in findrefresh
    img = cv2.cvtColor(sc, cv2.COLOR_BGR2GRAY)  # 转灰度图
cv2.error: C:\projects\opencv-python\opencv\modules\imgproc\src\color.cpp:11073: error: (-215) depth == 0 || depth == 2 || depth == 5 in function cv::cvtColor

Sat, 05 May 2018 23:11:52 app_thread.py[line:149] ERROR 刷新失败
Sat, 05 May 2018 23:11:52 app_thread.py[line:150] ERROR this is an exception message
Traceback (most recent call last):
  File "E:\hupai\component\app_thread.py", line 147, in run
    findrefresh()
  File "E:\hupai\component\imgcut.py", line 412, in findrefresh
    img = cv2.cvtColor(sc, cv2.COLOR_BGR2GRAY)  # 转灰度图
cv2.error: C:\projects\opencv-python\opencv\modules\imgproc\src\color.cpp:11073: error: (-215) depth == 0 || depth == 2 || depth == 5 in function cv::cvtColor

Sat, 05 May 2018 23:11:53 PngImagePlugin.py[line:138] DEBUG STREAM b'IHDR' 16 13
Sat, 05 May 2018 23:11:53 PngImagePlugin.py[line:138] DEBUG STREAM b'IDAT' 41 8192
Sat, 05 May 2018 23:11:53 PngImagePlugin.py[line:138] DEBUG STREAM b'IHDR' 16 13
Sat, 05 May 2018 23:11:53 PngImagePlugin.py[line:138] DEBUG STREAM b'IDAT' 41 8192
Sat, 05 May 2018 23:11:53 PngImagePlugin.py[line:138] DEBUG STREAM b'IHDR' 16 13
Sat, 05 May 2018 23:11:53 PngImagePlugin.py[line:138] DEBUG STREAM b'IDAT' 41 8192
Sat, 05 May 2018 23:11:54 PngImagePlugin.py[line:138] DEBUG STREAM b'IHDR' 16 13
Sat, 05 May 2018 23:11:54 PngImagePlugin.py[line:138] DEBUG STREAM b'IDAT' 41 8192
Sat, 05 May 2018 23:11:54 PngImagePlugin.py[line:138] DEBUG STREAM b'IHDR' 16 13
Sat, 05 May 2018 23:11:54 PngImagePlugin.py[line:138] DEBUG STREAM b'IDAT' 41 8192
Sat, 05 May 2018 23:11:54 PngImagePlugin.py[line:138] DEBUG STREAM b'IHDR' 16 13
Sat, 05 May 2018 23:11:54 PngImagePlugin.py[line:138] DEBUG STREAM b'IDAT' 41 8192
Sat, 05 May 2018 23:11:54 PngImagePlugin.py[line:138] DEBUG STREAM b'IHDR' 16 13
Sat, 05 May 2018 23:11:54 PngImagePlugin.py[line:138] DEBUG STREAM b'IDAT' 41 8192
Sat, 05 May 2018 23:11:54 PngImagePlugin.py[line:138] DEBUG STREAM b'IHDR' 16 13
Sat, 05 May 2018 23:11:54 PngImagePlugin.py[line:138] DEBUG STREAM b'IDAT' 41 8192
Sat, 05 May 2018 23:11:54 PngImagePlugin.py[line:138] DEBUG STREAM b'IHDR' 16 13
Sat, 05 May 2018 23:11:54 PngImagePlugin.py[line:138] DEBUG STREAM b'IDAT' 41 8192
Sat, 05 May 2018 23:11:54 PngImagePlugin.py[line:138] DEBUG STREAM b'IHDR' 16 13
Sat, 05 May 2018 23:11:54 PngImagePlugin.py[line:138] DEBUG STREAM b'IDAT' 41 8192
Sat, 05 May 2018 23:11:54 PngImagePlugin.py[line:138] DEBUG STREAM b'IHDR' 16 13
Sat, 05 May 2018 23:11:54 PngImagePlugin.py[line:138] DEBUG STREAM b'IDAT' 41 8192
Sat, 05 May 2018 23:11:54 PngImagePlugin.py[line:138] DEBUG STREAM b'IHDR' 16 13
Sat, 05 May 2018 23:11:54 PngImagePlugin.py[line:138] DEBUG STREAM b'IDAT' 41 8192
Sat, 05 May 2018 23:11:54 PngImagePlugin.py[line:138] DEBUG STREAM b'IHDR' 16 13
Sat, 05 May 2018 23:11:54 PngImagePlugin.py[line:138] DEBUG STREAM b'IDAT' 41 8192
Sat, 05 May 2018 23:11:54 PngImagePlugin.py[line:138] DEBUG STREAM b'IHDR' 16 13
Sat, 05 May 2018 23:11:54 PngImagePlugin.py[line:138] DEBUG STREAM b'IDAT' 41 8192
Sat, 05 May 2018 23:11:54 PngImagePlugin.py[line:138] DEBUG STREAM b'IHDR' 16 13
Sat, 05 May 2018 23:11:54 PngImagePlugin.py[line:138] DEBUG STREAM b'IDAT' 41 8192
Sat, 05 May 2018 23:11:54 PngImagePlugin.py[line:138] DEBUG STREAM b'IHDR' 16 13
Sat, 05 May 2018 23:11:54 PngImagePlugin.py[line:138] DEBUG STREAM b'IDAT' 41 8192
Sat, 05 May 2018 23:11:54 PngImagePlugin.py[line:138] DEBUG STREAM b'IHDR' 16 13
Sat, 05 May 2018 23:11:54 PngImagePlugin.py[line:138] DEBUG STREAM b'IDAT' 41 8192
Sat, 05 May 2018 23:11:54 PngImagePlugin.py[line:138] DEBUG STREAM b'IHDR' 16 13
Sat, 05 May 2018 23:11:54 PngImagePlugin.py[line:138] DEBUG STREAM b'IDAT' 41 8192
Sat, 05 May 2018 23:11:54 PngImagePlugin.py[line:138] DEBUG STREAM b'IHDR' 16 13
Sat, 05 May 2018 23:11:54 PngImagePlugin.py[line:138] DEBUG STREAM b'IDAT' 41 8192
Sat, 05 May 2018 23:11:54 PngImagePlugin.py[line:138] DEBUG STREAM b'IHDR' 16 13
Sat, 05 May 2018 23:11:54 PngImagePlugin.py[line:138] DEBUG STREAM b'IDAT' 41 8192
Sat, 05 May 2018 23:11:54 PngImagePlugin.py[line:138] DEBUG STREAM b'IHDR' 16 13
Sat, 05 May 2018 23:11:54 PngImagePlugin.py[line:138] DEBUG STREAM b'IDAT' 41 8192
Sat, 05 May 2018 23:11:54 PngImagePlugin.py[line:138] DEBUG STREAM b'IHDR' 16 13
Sat, 05 May 2018 23:11:54 PngImagePlugin.py[line:138] DEBUG STREAM b'IDAT' 41 8192
Sat, 05 May 2018 23:11:55 PngImagePlugin.py[line:138] DEBUG STREAM b'IHDR' 16 13
Sat, 05 May 2018 23:11:55 PngImagePlugin.py[line:138] DEBUG STREAM b'IDAT' 41 8192
Sat, 05 May 2018 23:11:55 PngImagePlugin.py[line:138] DEBUG STREAM b'IHDR' 16 13
Sat, 05 May 2018 23:11:55 PngImagePlugin.py[line:138] DEBUG STREAM b'IDAT' 41 985
Sat, 05 May 2018 23:11:55 PngImagePlugin.py[line:138] DEBUG STREAM b'IHDR' 16 13
Sat, 05 May 2018 23:11:55 PngImagePlugin.py[line:138] DEBUG STREAM b'IDAT' 41 985
Sat, 05 May 2018 23:11:55 PngImagePlugin.py[line:138] DEBUG STREAM b'IHDR' 16 13
Sat, 05 May 2018 23:11:55 PngImagePlugin.py[line:138] DEBUG STREAM b'IDAT' 41 985
Sat, 05 May 2018 23:11:55 PngImagePlugin.py[line:138] DEBUG STREAM b'IHDR' 16 13
Sat, 05 May 2018 23:11:55 PngImagePlugin.py[line:138] DEBUG STREAM b'IDAT' 41 985
Sat, 05 May 2018 23:11:55 PngImagePlugin.py[line:138] DEBUG STREAM b'IHDR' 16 13
Sat, 05 May 2018 23:11:55 PngImagePlugin.py[line:138] DEBUG STREAM b'IDAT' 41 985
Sat, 05 May 2018 23:11:55 PngImagePlugin.py[line:138] DEBUG STREAM b'IHDR' 16 13
Sat, 05 May 2018 23:11:55 PngImagePlugin.py[line:138] DEBUG STREAM b'IDAT' 41 985
Sat, 05 May 2018 23:11:55 PngImagePlugin.py[line:138] DEBUG STREAM b'IHDR' 16 13
Sat, 05 May 2018 23:11:55 PngImagePlugin.py[line:138] DEBUG STREAM b'IDAT' 41 985
Sat, 05 May 2018 23:11:55 PngImagePlugin.py[line:138] DEBUG STREAM b'IHDR' 16 13
Sat, 05 May 2018 23:11:55 PngImagePlugin.py[line:138] DEBUG STREAM b'IDAT' 41 985
Sat, 05 May 2018 23:11:55 PngImagePlugin.py[line:138] DEBUG STREAM b'IHDR' 16 13
Sat, 05 May 2018 23:11:55 PngImagePlugin.py[line:138] DEBUG STREAM b'IDAT' 41 8192
Sat, 05 May 2018 23:11:55 PngImagePlugin.py[line:138] DEBUG STREAM b'IHDR' 16 13
Sat, 05 May 2018 23:11:55 PngImagePlugin.py[line:138] DEBUG STREAM b'IDAT' 41 985
Sat, 05 May 2018 23:11:55 PngImagePlugin.py[line:138] DEBUG STREAM b'IHDR' 16 13
Sat, 05 May 2018 23:11:55 PngImagePlugin.py[line:138] DEBUG STREAM b'IDAT' 41 985
Sat, 05 May 2018 23:11:56 PngImagePlugin.py[line:138] DEBUG STREAM b'IHDR' 16 13
Sat, 05 May 2018 23:11:56 PngImagePlugin.py[line:138] DEBUG STREAM b'IDAT' 41 985
Sat, 05 May 2018 23:11:56 PngImagePlugin.py[line:138] DEBUG STREAM b'IHDR' 16 13
Sat, 05 May 2018 23:11:56 PngImagePlugin.py[line:138] DEBUG STREAM b'IDAT' 41 985
Sat, 05 May 2018 23:11:56 PngImagePlugin.py[line:138] DEBUG STREAM b'IHDR' 16 13
Sat, 05 May 2018 23:11:56 PngImagePlugin.py[line:138] DEBUG STREAM b'IDAT' 41 985
Sat, 05 May 2018 23:11:56 PngImagePlugin.py[line:138] DEBUG STREAM b'IHDR' 16 13
Sat, 05 May 2018 23:11:56 PngImagePlugin.py[line:138] DEBUG STREAM b'IDAT' 41 985
Sat, 05 May 2018 23:11:56 PngImagePlugin.py[line:138] DEBUG STREAM b'IHDR' 16 13
Sat, 05 May 2018 23:11:56 PngImagePlugin.py[line:138] DEBUG STREAM b'IDAT' 41 985
Sat, 05 May 2018 23:11:56 PngImagePlugin.py[line:138] DEBUG STREAM b'IHDR' 16 13
Sat, 05 May 2018 23:11:56 PngImagePlugin.py[line:138] DEBUG STREAM b'IDAT' 41 985
Sat, 05 May 2018 23:11:56 PngImagePlugin.py[line:138] DEBUG STREAM b'IHDR' 16 13
Sat, 05 May 2018 23:11:56 PngImagePlugin.py[line:138] DEBUG STREAM b'IDAT' 41 985
