Mon, 02 Apr 2018 18:47:13 PngImagePlugin.py[line:137] DEBUG STREAM b'IHDR' 16 13
Mon, 02 Apr 2018 18:47:13 PngImagePlugin.py[line:137] DEBUG STREAM b'IDAT' 41 8192
Mon, 02 Apr 2018 18:47:13 PngImagePlugin.py[line:137] DEBUG STREAM b'IHDR' 16 13
Mon, 02 Apr 2018 18:47:13 PngImagePlugin.py[line:137] DEBUG STREAM b'IDAT' 41 65536
Mon, 02 Apr 2018 18:47:13 app_thread.py[line:125] ERROR 刷新失败
Mon, 02 Apr 2018 18:47:13 app_thread.py[line:126] ERROR this is an exception message
Traceback (most recent call last):
  File "E:\hupai\component\app_thread.py", line 123, in run
    findrefresh()
  File "E:\hupai\component\imgcut.py", line 386, in findrefresh
    img = cv2.cvtColor(sc, cv2.COLOR_BGR2GRAY)  # 转灰度图
cv2.error: C:\projects\opencv-python\opencv\modules\imgproc\src\color.cpp:11073: error: (-215) depth == 0 || depth == 2 || depth == 5 in function cv::cvtColor

Mon, 02 Apr 2018 18:47:13 app_thread.py[line:125] ERROR 刷新失败
Mon, 02 Apr 2018 18:47:13 app_thread.py[line:126] ERROR this is an exception message
Traceback (most recent call last):
  File "E:\hupai\component\app_thread.py", line 123, in run
    findrefresh()
  File "E:\hupai\component\imgcut.py", line 386, in findrefresh
    img = cv2.cvtColor(sc, cv2.COLOR_BGR2GRAY)  # 转灰度图
cv2.error: C:\projects\opencv-python\opencv\modules\imgproc\src\color.cpp:11073: error: (-215) depth == 0 || depth == 2 || depth == 5 in function cv::cvtColor

Mon, 02 Apr 2018 18:47:13 imgcut.py[line:371] ERROR cut_img 这里出错
Mon, 02 Apr 2018 18:47:13 imgcut.py[line:372] ERROR this is an exception message
Traceback (most recent call last):
  File "E:\hupai\component\imgcut.py", line 364, in cut_img
    set_val('imgpos_lowestprice', img[use_area[0][1]:use_area[0][3], use_area[0][0]:use_area[0][2]])  # ok
IndexError: list index out of range
Mon, 02 Apr 2018 18:47:13 app_thread.py[line:125] ERROR 刷新失败
Mon, 02 Apr 2018 18:47:13 app_thread.py[line:126] ERROR this is an exception message
Traceback (most recent call last):
  File "E:\hupai\component\app_thread.py", line 123, in run
    findrefresh()
  File "E:\hupai\component\imgcut.py", line 386, in findrefresh
    img = cv2.cvtColor(sc, cv2.COLOR_BGR2GRAY)  # 转灰度图
cv2.error: C:\projects\opencv-python\opencv\modules\imgproc\src\color.cpp:11073: error: (-215) depth == 0 || depth == 2 || depth == 5 in function cv::cvtColor

Mon, 02 Apr 2018 18:47:13 imgcut.py[line:371] ERROR cut_img 这里出错
Mon, 02 Apr 2018 18:47:13 imgcut.py[line:372] ERROR this is an exception message
Traceback (most recent call last):
  File "E:\hupai\component\imgcut.py", line 364, in cut_img
    set_val('imgpos_lowestprice', img[use_area[0][1]:use_area[0][3], use_area[0][0]:use_area[0][2]])  # ok
IndexError: list index out of range
Mon, 02 Apr 2018 18:47:13 app_thread.py[line:125] ERROR 刷新失败
Mon, 02 Apr 2018 18:47:13 app_thread.py[line:126] ERROR this is an exception message
Traceback (most recent call last):
  File "E:\hupai\component\app_thread.py", line 123, in run
    findrefresh()
  File "E:\hupai\component\imgcut.py", line 386, in findrefresh
    img = cv2.cvtColor(sc, cv2.COLOR_BGR2GRAY)  # 转灰度图
cv2.error: C:\projects\opencv-python\opencv\modules\imgproc\src\color.cpp:11073: error: (-215) depth == 0 || depth == 2 || depth == 5 in function cv::cvtColor

Mon, 02 Apr 2018 18:47:13 imgcut.py[line:371] ERROR cut_img 这里出错
Mon, 02 Apr 2018 18:47:13 imgcut.py[line:372] ERROR this is an exception message
Traceback (most recent call last):
  File "E:\hupai\component\imgcut.py", line 364, in cut_img
    set_val('imgpos_lowestprice', img[use_area[0][1]:use_area[0][3], use_area[0][0]:use_area[0][2]])  # ok
IndexError: list index out of range
Mon, 02 Apr 2018 18:47:13 app_thread.py[line:125] ERROR 刷新失败
Mon, 02 Apr 2018 18:47:13 app_thread.py[line:126] ERROR this is an exception message
Traceback (most recent call last):
  File "E:\hupai\component\app_thread.py", line 123, in run
    findrefresh()
  File "E:\hupai\component\imgcut.py", line 386, in findrefresh
    img = cv2.cvtColor(sc, cv2.COLOR_BGR2GRAY)  # 转灰度图
cv2.error: C:\projects\opencv-python\opencv\modules\imgproc\src\color.cpp:11073: error: (-215) depth == 0 || depth == 2 || depth == 5 in function cv::cvtColor

Mon, 02 Apr 2018 18:47:13 app_thread.py[line:125] ERROR 刷新失败
Mon, 02 Apr 2018 18:47:13 app_thread.py[line:126] ERROR this is an exception message
Traceback (most recent call last):
  File "E:\hupai\component\app_thread.py", line 123, in run
    findrefresh()
  File "E:\hupai\component\imgcut.py", line 386, in findrefresh
    img = cv2.cvtColor(sc, cv2.COLOR_BGR2GRAY)  # 转灰度图
cv2.error: C:\projects\opencv-python\opencv\modules\imgproc\src\color.cpp:11073: error: (-215) depth == 0 || depth == 2 || depth == 5 in function cv::cvtColor

Mon, 02 Apr 2018 18:47:13 imgcut.py[line:371] ERROR cut_img 这里出错
Mon, 02 Apr 2018 18:47:13 imgcut.py[line:372] ERROR this is an exception message
Traceback (most recent call last):
  File "E:\hupai\component\imgcut.py", line 364, in cut_img
    set_val('imgpos_lowestprice', img[use_area[0][1]:use_area[0][3], use_area[0][0]:use_area[0][2]])  # ok
IndexError: list index out of range
Mon, 02 Apr 2018 18:47:13 app_thread.py[line:125] ERROR 刷新失败
Mon, 02 Apr 2018 18:47:13 app_thread.py[line:126] ERROR this is an exception message
Traceback (most recent call last):
  File "E:\hupai\component\app_thread.py", line 123, in run
    findrefresh()
  File "E:\hupai\component\imgcut.py", line 386, in findrefresh
    img = cv2.cvtColor(sc, cv2.COLOR_BGR2GRAY)  # 转灰度图
cv2.error: C:\projects\opencv-python\opencv\modules\imgproc\src\color.cpp:11073: error: (-215) depth == 0 || depth == 2 || depth == 5 in function cv::cvtColor

Mon, 02 Apr 2018 18:47:13 imgcut.py[line:371] ERROR cut_img 这里出错
Mon, 02 Apr 2018 18:47:13 imgcut.py[line:372] ERROR this is an exception message
Traceback (most recent call last):
  File "E:\hupai\component\imgcut.py", line 364, in cut_img
    set_val('imgpos_lowestprice', img[use_area[0][1]:use_area[0][3], use_area[0][0]:use_area[0][2]])  # ok
IndexError: list index out of range
Mon, 02 Apr 2018 18:47:13 app_thread.py[line:125] ERROR 刷新失败
Mon, 02 Apr 2018 18:47:13 app_thread.py[line:126] ERROR this is an exception message
Traceback (most recent call last):
  File "E:\hupai\component\app_thread.py", line 123, in run
    findrefresh()
  File "E:\hupai\component\imgcut.py", line 386, in findrefresh
    img = cv2.cvtColor(sc, cv2.COLOR_BGR2GRAY)  # 转灰度图
cv2.error: C:\projects\opencv-python\opencv\modules\imgproc\src\color.cpp:11073: error: (-215) depth == 0 || depth == 2 || depth == 5 in function cv::cvtColor

Mon, 02 Apr 2018 18:47:13 imgcut.py[line:371] ERROR cut_img 这里出错
Mon, 02 Apr 2018 18:47:13 imgcut.py[line:372] ERROR this is an exception message
Traceback (most recent call last):
  File "E:\hupai\component\imgcut.py", line 364, in cut_img
    set_val('imgpos_lowestprice', img[use_area[0][1]:use_area[0][3], use_area[0][0]:use_area[0][2]])  # ok
IndexError: list index out of range
Mon, 02 Apr 2018 18:47:13 app_thread.py[line:125] ERROR 刷新失败
Mon, 02 Apr 2018 18:47:13 app_thread.py[line:126] ERROR this is an exception message
Traceback (most recent call last):
  File "E:\hupai\component\app_thread.py", line 123, in run
    findrefresh()
  File "E:\hupai\component\imgcut.py", line 386, in findrefresh
    img = cv2.cvtColor(sc, cv2.COLOR_BGR2GRAY)  # 转灰度图
cv2.error: C:\projects\opencv-python\opencv\modules\imgproc\src\color.cpp:11073: error: (-215) depth == 0 || depth == 2 || depth == 5 in function cv::cvtColor

Mon, 02 Apr 2018 18:47:14 imgcut.py[line:371] ERROR cut_img 这里出错
Mon, 02 Apr 2018 18:47:14 imgcut.py[line:372] ERROR this is an exception message
Traceback (most recent call last):
  File "E:\hupai\component\imgcut.py", line 364, in cut_img
    set_val('imgpos_lowestprice', img[use_area[0][1]:use_area[0][3], use_area[0][0]:use_area[0][2]])  # ok
IndexError: list index out of range
Mon, 02 Apr 2018 18:47:14 app_thread.py[line:125] ERROR 刷新失败
Mon, 02 Apr 2018 18:47:14 app_thread.py[line:126] ERROR this is an exception message
Traceback (most recent call last):
  File "E:\hupai\component\app_thread.py", line 123, in run
    findrefresh()
  File "E:\hupai\component\imgcut.py", line 386, in findrefresh
    img = cv2.cvtColor(sc, cv2.COLOR_BGR2GRAY)  # 转灰度图
cv2.error: C:\projects\opencv-python\opencv\modules\imgproc\src\color.cpp:11073: error: (-215) depth == 0 || depth == 2 || depth == 5 in function cv::cvtColor

Mon, 02 Apr 2018 18:47:14 app_thread.py[line:125] ERROR 刷新失败
Mon, 02 Apr 2018 18:47:14 imgcut.py[line:371] ERROR cut_img 这里出错
Mon, 02 Apr 2018 18:47:14 app_thread.py[line:126] ERROR this is an exception message
Traceback (most recent call last):
  File "E:\hupai\component\app_thread.py", line 123, in run
    findrefresh()
  File "E:\hupai\component\imgcut.py", line 386, in findrefresh
    img = cv2.cvtColor(sc, cv2.COLOR_BGR2GRAY)  # 转灰度图
cv2.error: C:\projects\opencv-python\opencv\modules\imgproc\src\color.cpp:11073: error: (-215) depth == 0 || depth == 2 || depth == 5 in function cv::cvtColor

Mon, 02 Apr 2018 18:47:14 imgcut.py[line:372] ERROR this is an exception message
Traceback (most recent call last):
  File "E:\hupai\component\imgcut.py", line 364, in cut_img
    set_val('imgpos_lowestprice', img[use_area[0][1]:use_area[0][3], use_area[0][0]:use_area[0][2]])  # ok
IndexError: list index out of range
Mon, 02 Apr 2018 18:47:14 app_thread.py[line:125] ERROR 刷新失败
Mon, 02 Apr 2018 18:47:14 app_thread.py[line:126] ERROR this is an exception message
Traceback (most recent call last):
  File "E:\hupai\component\app_thread.py", line 123, in run
    findrefresh()
  File "E:\hupai\component\imgcut.py", line 386, in findrefresh
    img = cv2.cvtColor(sc, cv2.COLOR_BGR2GRAY)  # 转灰度图
cv2.error: C:\projects\opencv-python\opencv\modules\imgproc\src\color.cpp:11073: error: (-215) depth == 0 || depth == 2 || depth == 5 in function cv::cvtColor

Mon, 02 Apr 2018 18:47:14 imgcut.py[line:371] ERROR cut_img 这里出错
Mon, 02 Apr 2018 18:47:14 imgcut.py[line:372] ERROR this is an exception message
Traceback (most recent call last):
  File "E:\hupai\component\imgcut.py", line 364, in cut_img
    set_val('imgpos_lowestprice', img[use_area[0][1]:use_area[0][3], use_area[0][0]:use_area[0][2]])  # ok
IndexError: list index out of range
Mon, 02 Apr 2018 18:47:14 app_thread.py[line:125] ERROR 刷新失败
Mon, 02 Apr 2018 18:47:14 app_thread.py[line:126] ERROR this is an exception message
Traceback (most recent call last):
  File "E:\hupai\component\app_thread.py", line 123, in run
    findrefresh()
  File "E:\hupai\component\imgcut.py", line 386, in findrefresh
    img = cv2.cvtColor(sc, cv2.COLOR_BGR2GRAY)  # 转灰度图
cv2.error: C:\projects\opencv-python\opencv\modules\imgproc\src\color.cpp:11073: error: (-215) depth == 0 || depth == 2 || depth == 5 in function cv::cvtColor

Mon, 02 Apr 2018 18:47:14 imgcut.py[line:371] ERROR cut_img 这里出错
Mon, 02 Apr 2018 18:47:14 imgcut.py[line:372] ERROR this is an exception message
Traceback (most recent call last):
  File "E:\hupai\component\imgcut.py", line 364, in cut_img
    set_val('imgpos_lowestprice', img[use_area[0][1]:use_area[0][3], use_area[0][0]:use_area[0][2]])  # ok
IndexError: list index out of range
Mon, 02 Apr 2018 18:47:14 app_thread.py[line:125] ERROR 刷新失败
Mon, 02 Apr 2018 18:47:14 app_thread.py[line:126] ERROR this is an exception message
Traceback (most recent call last):
  File "E:\hupai\component\app_thread.py", line 123, in run
    findrefresh()
  File "E:\hupai\component\imgcut.py", line 386, in findrefresh
    img = cv2.cvtColor(sc, cv2.COLOR_BGR2GRAY)  # 转灰度图
cv2.error: C:\projects\opencv-python\opencv\modules\imgproc\src\color.cpp:11073: error: (-215) depth == 0 || depth == 2 || depth == 5 in function cv::cvtColor

Mon, 02 Apr 2018 18:47:14 app_thread.py[line:125] ERROR 刷新失败
Mon, 02 Apr 2018 18:47:14 imgcut.py[line:371] ERROR cut_img 这里出错
Mon, 02 Apr 2018 18:47:14 app_thread.py[line:126] ERROR this is an exception message
Traceback (most recent call last):
  File "E:\hupai\component\app_thread.py", line 123, in run
    findrefresh()
  File "E:\hupai\component\imgcut.py", line 386, in findrefresh
    img = cv2.cvtColor(sc, cv2.COLOR_BGR2GRAY)  # 转灰度图
cv2.error: C:\projects\opencv-python\opencv\modules\imgproc\src\color.cpp:11073: error: (-215) depth == 0 || depth == 2 || depth == 5 in function cv::cvtColor

Mon, 02 Apr 2018 18:47:14 imgcut.py[line:372] ERROR this is an exception message
Traceback (most recent call last):
  File "E:\hupai\component\imgcut.py", line 364, in cut_img
    set_val('imgpos_lowestprice', img[use_area[0][1]:use_area[0][3], use_area[0][0]:use_area[0][2]])  # ok
IndexError: list index out of range
Mon, 02 Apr 2018 18:47:14 app_thread.py[line:125] ERROR 刷新失败
Mon, 02 Apr 2018 18:47:14 app_thread.py[line:126] ERROR this is an exception message
Traceback (most recent call last):
  File "E:\hupai\component\app_thread.py", line 123, in run
    findrefresh()
  File "E:\hupai\component\imgcut.py", line 386, in findrefresh
    img = cv2.cvtColor(sc, cv2.COLOR_BGR2GRAY)  # 转灰度图
cv2.error: C:\projects\opencv-python\opencv\modules\imgproc\src\color.cpp:11073: error: (-215) depth == 0 || depth == 2 || depth == 5 in function cv::cvtColor

Mon, 02 Apr 2018 18:47:14 imgcut.py[line:371] ERROR cut_img 这里出错
Mon, 02 Apr 2018 18:47:14 imgcut.py[line:372] ERROR this is an exception message
Traceback (most recent call last):
  File "E:\hupai\component\imgcut.py", line 364, in cut_img
    set_val('imgpos_lowestprice', img[use_area[0][1]:use_area[0][3], use_area[0][0]:use_area[0][2]])  # ok
IndexError: list index out of range
Mon, 02 Apr 2018 18:47:14 app_thread.py[line:125] ERROR 刷新失败
Mon, 02 Apr 2018 18:47:14 app_thread.py[line:126] ERROR this is an exception message
Traceback (most recent call last):
  File "E:\hupai\component\app_thread.py", line 123, in run
    findrefresh()
  File "E:\hupai\component\imgcut.py", line 386, in findrefresh
    img = cv2.cvtColor(sc, cv2.COLOR_BGR2GRAY)  # 转灰度图
cv2.error: C:\projects\opencv-python\opencv\modules\imgproc\src\color.cpp:11073: error: (-215) depth == 0 || depth == 2 || depth == 5 in function cv::cvtColor

Mon, 02 Apr 2018 18:47:14 imgcut.py[line:371] ERROR cut_img 这里出错
Mon, 02 Apr 2018 18:47:14 imgcut.py[line:372] ERROR this is an exception message
Traceback (most recent call last):
  File "E:\hupai\component\imgcut.py", line 364, in cut_img
    set_val('imgpos_lowestprice', img[use_area[0][1]:use_area[0][3], use_area[0][0]:use_area[0][2]])  # ok
IndexError: list index out of range
Mon, 02 Apr 2018 18:47:14 app_thread.py[line:125] ERROR 刷新失败
Mon, 02 Apr 2018 18:47:14 app_thread.py[line:126] ERROR this is an exception message
Traceback (most recent call last):
  File "E:\hupai\component\app_thread.py", line 123, in run
    findrefresh()
  File "E:\hupai\component\imgcut.py", line 386, in findrefresh
    img = cv2.cvtColor(sc, cv2.COLOR_BGR2GRAY)  # 转灰度图
cv2.error: C:\projects\opencv-python\opencv\modules\imgproc\src\color.cpp:11073: error: (-215) depth == 0 || depth == 2 || depth == 5 in function cv::cvtColor

Mon, 02 Apr 2018 18:47:14 app_thread.py[line:125] ERROR 刷新失败
Mon, 02 Apr 2018 18:47:14 app_thread.py[line:126] ERROR this is an exception message
Traceback (most recent call last):
  File "E:\hupai\component\app_thread.py", line 123, in run
    findrefresh()
  File "E:\hupai\component\imgcut.py", line 386, in findrefresh
    img = cv2.cvtColor(sc, cv2.COLOR_BGR2GRAY)  # 转灰度图
cv2.error: C:\projects\opencv-python\opencv\modules\imgproc\src\color.cpp:11073: error: (-215) depth == 0 || depth == 2 || depth == 5 in function cv::cvtColor

Mon, 02 Apr 2018 18:47:14 imgcut.py[line:371] ERROR cut_img 这里出错
Mon, 02 Apr 2018 18:47:14 imgcut.py[line:372] ERROR this is an exception message
Traceback (most recent call last):
  File "E:\hupai\component\imgcut.py", line 364, in cut_img
    set_val('imgpos_lowestprice', img[use_area[0][1]:use_area[0][3], use_area[0][0]:use_area[0][2]])  # ok
IndexError: list index out of range
Mon, 02 Apr 2018 18:47:14 app_thread.py[line:125] ERROR 刷新失败
Mon, 02 Apr 2018 18:47:14 app_thread.py[line:126] ERROR this is an exception message
Traceback (most recent call last):
  File "E:\hupai\component\app_thread.py", line 123, in run
    findrefresh()
  File "E:\hupai\component\imgcut.py", line 386, in findrefresh
    img = cv2.cvtColor(sc, cv2.COLOR_BGR2GRAY)  # 转灰度图
cv2.error: C:\projects\opencv-python\opencv\modules\imgproc\src\color.cpp:11073: error: (-215) depth == 0 || depth == 2 || depth == 5 in function cv::cvtColor

Mon, 02 Apr 2018 18:47:14 imgcut.py[line:371] ERROR cut_img 这里出错
Mon, 02 Apr 2018 18:47:14 imgcut.py[line:372] ERROR this is an exception message
Traceback (most recent call last):
  File "E:\hupai\component\imgcut.py", line 364, in cut_img
    set_val('imgpos_lowestprice', img[use_area[0][1]:use_area[0][3], use_area[0][0]:use_area[0][2]])  # ok
IndexError: list index out of range
Mon, 02 Apr 2018 18:47:14 app_thread.py[line:125] ERROR 刷新失败
Mon, 02 Apr 2018 18:47:14 app_thread.py[line:126] ERROR this is an exception message
Traceback (most recent call last):
  File "E:\hupai\component\app_thread.py", line 123, in run
    findrefresh()
  File "E:\hupai\component\imgcut.py", line 386, in findrefresh
    img = cv2.cvtColor(sc, cv2.COLOR_BGR2GRAY)  # 转灰度图
cv2.error: C:\projects\opencv-python\opencv\modules\imgproc\src\color.cpp:11073: error: (-215) depth == 0 || depth == 2 || depth == 5 in function cv::cvtColor

Mon, 02 Apr 2018 18:47:14 app_thread.py[line:125] ERROR 刷新失败
Mon, 02 Apr 2018 18:47:14 app_thread.py[line:126] ERROR this is an exception message
Traceback (most recent call last):
  File "E:\hupai\component\app_thread.py", line 123, in run
    findrefresh()
  File "E:\hupai\component\imgcut.py", line 386, in findrefresh
    img = cv2.cvtColor(sc, cv2.COLOR_BGR2GRAY)  # 转灰度图
cv2.error: C:\projects\opencv-python\opencv\modules\imgproc\src\color.cpp:11073: error: (-215) depth == 0 || depth == 2 || depth == 5 in function cv::cvtColor

Mon, 02 Apr 2018 18:47:14 imgcut.py[line:371] ERROR cut_img 这里出错
Mon, 02 Apr 2018 18:47:14 imgcut.py[line:372] ERROR this is an exception message
Traceback (most recent call last):
  File "E:\hupai\component\imgcut.py", line 364, in cut_img
    set_val('imgpos_lowestprice', img[use_area[0][1]:use_area[0][3], use_area[0][0]:use_area[0][2]])  # ok
IndexError: list index out of range
Mon, 02 Apr 2018 18:47:14 app_thread.py[line:125] ERROR 刷新失败
Mon, 02 Apr 2018 18:47:14 app_thread.py[line:126] ERROR this is an exception message
Traceback (most recent call last):
  File "E:\hupai\component\app_thread.py", line 123, in run
    findrefresh()
  File "E:\hupai\component\imgcut.py", line 386, in findrefresh
    img = cv2.cvtColor(sc, cv2.COLOR_BGR2GRAY)  # 转灰度图
cv2.error: C:\projects\opencv-python\opencv\modules\imgproc\src\color.cpp:11073: error: (-215) depth == 0 || depth == 2 || depth == 5 in function cv::cvtColor

Mon, 02 Apr 2018 18:47:15 imgcut.py[line:371] ERROR cut_img 这里出错
Mon, 02 Apr 2018 18:47:15 app_thread.py[line:125] ERROR 刷新失败
Mon, 02 Apr 2018 18:47:15 imgcut.py[line:372] ERROR this is an exception message
Traceback (most recent call last):
  File "E:\hupai\component\imgcut.py", line 364, in cut_img
    set_val('imgpos_lowestprice', img[use_area[0][1]:use_area[0][3], use_area[0][0]:use_area[0][2]])  # ok
IndexError: list index out of range
Mon, 02 Apr 2018 18:47:15 app_thread.py[line:126] ERROR this is an exception message
Traceback (most recent call last):
  File "E:\hupai\component\app_thread.py", line 123, in run
    findrefresh()
  File "E:\hupai\component\imgcut.py", line 386, in findrefresh
    img = cv2.cvtColor(sc, cv2.COLOR_BGR2GRAY)  # 转灰度图
cv2.error: C:\projects\opencv-python\opencv\modules\imgproc\src\color.cpp:11073: error: (-215) depth == 0 || depth == 2 || depth == 5 in function cv::cvtColor

Mon, 02 Apr 2018 18:47:15 app_thread.py[line:125] ERROR 刷新失败
Mon, 02 Apr 2018 18:47:15 imgcut.py[line:371] ERROR cut_img 这里出错
Mon, 02 Apr 2018 18:47:15 app_thread.py[line:126] ERROR this is an exception message
Traceback (most recent call last):
  File "E:\hupai\component\app_thread.py", line 123, in run
    findrefresh()
  File "E:\hupai\component\imgcut.py", line 386, in findrefresh
    img = cv2.cvtColor(sc, cv2.COLOR_BGR2GRAY)  # 转灰度图
cv2.error: C:\projects\opencv-python\opencv\modules\imgproc\src\color.cpp:11073: error: (-215) depth == 0 || depth == 2 || depth == 5 in function cv::cvtColor

Mon, 02 Apr 2018 18:47:15 imgcut.py[line:372] ERROR this is an exception message
Traceback (most recent call last):
  File "E:\hupai\component\imgcut.py", line 364, in cut_img
    set_val('imgpos_lowestprice', img[use_area[0][1]:use_area[0][3], use_area[0][0]:use_area[0][2]])  # ok
IndexError: list index out of range
Mon, 02 Apr 2018 18:47:15 app_thread.py[line:125] ERROR 刷新失败
Mon, 02 Apr 2018 18:47:15 app_thread.py[line:126] ERROR this is an exception message
Traceback (most recent call last):
  File "E:\hupai\component\app_thread.py", line 123, in run
    findrefresh()
  File "E:\hupai\component\imgcut.py", line 386, in findrefresh
    img = cv2.cvtColor(sc, cv2.COLOR_BGR2GRAY)  # 转灰度图
cv2.error: C:\projects\opencv-python\opencv\modules\imgproc\src\color.cpp:11073: error: (-215) depth == 0 || depth == 2 || depth == 5 in function cv::cvtColor

Mon, 02 Apr 2018 18:47:15 imgcut.py[line:371] ERROR cut_img 这里出错
Mon, 02 Apr 2018 18:47:15 imgcut.py[line:372] ERROR this is an exception message
Traceback (most recent call last):
  File "E:\hupai\component\imgcut.py", line 364, in cut_img
    set_val('imgpos_lowestprice', img[use_area[0][1]:use_area[0][3], use_area[0][0]:use_area[0][2]])  # ok
IndexError: list index out of range
Mon, 02 Apr 2018 18:47:15 app_thread.py[line:125] ERROR 刷新失败
Mon, 02 Apr 2018 18:47:15 app_thread.py[line:126] ERROR this is an exception message
Traceback (most recent call last):
  File "E:\hupai\component\app_thread.py", line 123, in run
    findrefresh()
  File "E:\hupai\component\imgcut.py", line 386, in findrefresh
    img = cv2.cvtColor(sc, cv2.COLOR_BGR2GRAY)  # 转灰度图
cv2.error: C:\projects\opencv-python\opencv\modules\imgproc\src\color.cpp:11073: error: (-215) depth == 0 || depth == 2 || depth == 5 in function cv::cvtColor

Mon, 02 Apr 2018 18:47:15 imgcut.py[line:371] ERROR cut_img 这里出错
Mon, 02 Apr 2018 18:47:15 imgcut.py[line:372] ERROR this is an exception message
Traceback (most recent call last):
  File "E:\hupai\component\imgcut.py", line 364, in cut_img
    set_val('imgpos_lowestprice', img[use_area[0][1]:use_area[0][3], use_area[0][0]:use_area[0][2]])  # ok
IndexError: list index out of range
Mon, 02 Apr 2018 18:47:15 app_thread.py[line:125] ERROR 刷新失败
Mon, 02 Apr 2018 18:47:15 app_thread.py[line:126] ERROR this is an exception message
Traceback (most recent call last):
  File "E:\hupai\component\app_thread.py", line 123, in run
    findrefresh()
  File "E:\hupai\component\imgcut.py", line 386, in findrefresh
    img = cv2.cvtColor(sc, cv2.COLOR_BGR2GRAY)  # 转灰度图
cv2.error: C:\projects\opencv-python\opencv\modules\imgproc\src\color.cpp:11073: error: (-215) depth == 0 || depth == 2 || depth == 5 in function cv::cvtColor

Mon, 02 Apr 2018 18:47:15 app_thread.py[line:125] ERROR 刷新失败
Mon, 02 Apr 2018 18:47:15 app_thread.py[line:126] ERROR this is an exception message
Traceback (most recent call last):
  File "E:\hupai\component\app_thread.py", line 123, in run
    findrefresh()
  File "E:\hupai\component\imgcut.py", line 386, in findrefresh
    img = cv2.cvtColor(sc, cv2.COLOR_BGR2GRAY)  # 转灰度图
cv2.error: C:\projects\opencv-python\opencv\modules\imgproc\src\color.cpp:11073: error: (-215) depth == 0 || depth == 2 || depth == 5 in function cv::cvtColor

Mon, 02 Apr 2018 18:47:15 imgcut.py[line:371] ERROR cut_img 这里出错
Mon, 02 Apr 2018 18:47:15 imgcut.py[line:372] ERROR this is an exception message
Traceback (most recent call last):
  File "E:\hupai\component\imgcut.py", line 364, in cut_img
    set_val('imgpos_lowestprice', img[use_area[0][1]:use_area[0][3], use_area[0][0]:use_area[0][2]])  # ok
IndexError: list index out of range
Mon, 02 Apr 2018 18:47:15 app_thread.py[line:125] ERROR 刷新失败
Mon, 02 Apr 2018 18:47:15 app_thread.py[line:126] ERROR this is an exception message
Traceback (most recent call last):
  File "E:\hupai\component\app_thread.py", line 123, in run
    findrefresh()
  File "E:\hupai\component\imgcut.py", line 386, in findrefresh
    img = cv2.cvtColor(sc, cv2.COLOR_BGR2GRAY)  # 转灰度图
cv2.error: C:\projects\opencv-python\opencv\modules\imgproc\src\color.cpp:11073: error: (-215) depth == 0 || depth == 2 || depth == 5 in function cv::cvtColor

Mon, 02 Apr 2018 18:47:15 app_thread.py[line:125] ERROR 刷新失败
Mon, 02 Apr 2018 18:47:15 app_thread.py[line:126] ERROR this is an exception message
Traceback (most recent call last):
  File "E:\hupai\component\app_thread.py", line 123, in run
    findrefresh()
  File "E:\hupai\component\imgcut.py", line 386, in findrefresh
    img = cv2.cvtColor(sc, cv2.COLOR_BGR2GRAY)  # 转灰度图
cv2.error: C:\projects\opencv-python\opencv\modules\imgproc\src\color.cpp:11073: error: (-215) depth == 0 || depth == 2 || depth == 5 in function cv::cvtColor

Mon, 02 Apr 2018 18:47:15 imgcut.py[line:371] ERROR cut_img 这里出错
Mon, 02 Apr 2018 18:47:15 imgcut.py[line:372] ERROR this is an exception message
Traceback (most recent call last):
  File "E:\hupai\component\imgcut.py", line 364, in cut_img
    set_val('imgpos_lowestprice', img[use_area[0][1]:use_area[0][3], use_area[0][0]:use_area[0][2]])  # ok
IndexError: list index out of range
Mon, 02 Apr 2018 18:47:15 app_thread.py[line:125] ERROR 刷新失败
Mon, 02 Apr 2018 18:47:15 app_thread.py[line:126] ERROR this is an exception message
Traceback (most recent call last):
  File "E:\hupai\component\app_thread.py", line 123, in run
    findrefresh()
  File "E:\hupai\component\imgcut.py", line 386, in findrefresh
    img = cv2.cvtColor(sc, cv2.COLOR_BGR2GRAY)  # 转灰度图
cv2.error: C:\projects\opencv-python\opencv\modules\imgproc\src\color.cpp:11073: error: (-215) depth == 0 || depth == 2 || depth == 5 in function cv::cvtColor

Mon, 02 Apr 2018 18:47:15 app_thread.py[line:125] ERROR 刷新失败
Mon, 02 Apr 2018 18:47:15 app_thread.py[line:126] ERROR this is an exception message
Traceback (most recent call last):
  File "E:\hupai\component\app_thread.py", line 123, in run
    findrefresh()
  File "E:\hupai\component\imgcut.py", line 386, in findrefresh
    img = cv2.cvtColor(sc, cv2.COLOR_BGR2GRAY)  # 转灰度图
cv2.error: C:\projects\opencv-python\opencv\modules\imgproc\src\color.cpp:11073: error: (-215) depth == 0 || depth == 2 || depth == 5 in function cv::cvtColor

Mon, 02 Apr 2018 18:47:15 imgcut.py[line:371] ERROR cut_img 这里出错
Mon, 02 Apr 2018 18:47:15 imgcut.py[line:372] ERROR this is an exception message
Traceback (most recent call last):
  File "E:\hupai\component\imgcut.py", line 364, in cut_img
    set_val('imgpos_lowestprice', img[use_area[0][1]:use_area[0][3], use_area[0][0]:use_area[0][2]])  # ok
IndexError: list index out of range
Mon, 02 Apr 2018 18:47:15 app_thread.py[line:125] ERROR 刷新失败
Mon, 02 Apr 2018 18:47:15 app_thread.py[line:126] ERROR this is an exception message
Traceback (most recent call last):
  File "E:\hupai\component\app_thread.py", line 123, in run
    findrefresh()
  File "E:\hupai\component\imgcut.py", line 386, in findrefresh
    img = cv2.cvtColor(sc, cv2.COLOR_BGR2GRAY)  # 转灰度图
cv2.error: C:\projects\opencv-python\opencv\modules\imgproc\src\color.cpp:11073: error: (-215) depth == 0 || depth == 2 || depth == 5 in function cv::cvtColor

Mon, 02 Apr 2018 18:47:15 imgcut.py[line:371] ERROR cut_img 这里出错
Mon, 02 Apr 2018 18:47:15 imgcut.py[line:372] ERROR this is an exception message
Traceback (most recent call last):
  File "E:\hupai\component\imgcut.py", line 364, in cut_img
    set_val('imgpos_lowestprice', img[use_area[0][1]:use_area[0][3], use_area[0][0]:use_area[0][2]])  # ok
IndexError: list index out of range
Mon, 02 Apr 2018 18:47:15 app_thread.py[line:125] ERROR 刷新失败
Mon, 02 Apr 2018 18:47:15 app_thread.py[line:126] ERROR this is an exception message
Traceback (most recent call last):
  File "E:\hupai\component\app_thread.py", line 123, in run
    findrefresh()
  File "E:\hupai\component\imgcut.py", line 386, in findrefresh
    img = cv2.cvtColor(sc, cv2.COLOR_BGR2GRAY)  # 转灰度图
cv2.error: C:\projects\opencv-python\opencv\modules\imgproc\src\color.cpp:11073: error: (-215) depth == 0 || depth == 2 || depth == 5 in function cv::cvtColor

Mon, 02 Apr 2018 18:47:15 imgcut.py[line:371] ERROR cut_img 这里出错
Mon, 02 Apr 2018 18:47:15 imgcut.py[line:372] ERROR this is an exception message
Traceback (most recent call last):
  File "E:\hupai\component\imgcut.py", line 364, in cut_img
    set_val('imgpos_lowestprice', img[use_area[0][1]:use_area[0][3], use_area[0][0]:use_area[0][2]])  # ok
IndexError: list index out of range
Mon, 02 Apr 2018 18:47:15 app_thread.py[line:125] ERROR 刷新失败
Mon, 02 Apr 2018 18:47:15 app_thread.py[line:126] ERROR this is an exception message
Traceback (most recent call last):
  File "E:\hupai\component\app_thread.py", line 123, in run
    findrefresh()
  File "E:\hupai\component\imgcut.py", line 386, in findrefresh
    img = cv2.cvtColor(sc, cv2.COLOR_BGR2GRAY)  # 转灰度图
cv2.error: C:\projects\opencv-python\opencv\modules\imgproc\src\color.cpp:11073: error: (-215) depth == 0 || depth == 2 || depth == 5 in function cv::cvtColor

Mon, 02 Apr 2018 18:47:15 imgcut.py[line:371] ERROR cut_img 这里出错
Mon, 02 Apr 2018 18:47:15 imgcut.py[line:372] ERROR this is an exception message
Traceback (most recent call last):
  File "E:\hupai\component\imgcut.py", line 364, in cut_img
    set_val('imgpos_lowestprice', img[use_area[0][1]:use_area[0][3], use_area[0][0]:use_area[0][2]])  # ok
IndexError: list index out of range
Mon, 02 Apr 2018 18:47:16 app_thread.py[line:125] ERROR 刷新失败
Mon, 02 Apr 2018 18:47:16 app_thread.py[line:126] ERROR this is an exception message
Traceback (most recent call last):
  File "E:\hupai\component\app_thread.py", line 123, in run
    findrefresh()
  File "E:\hupai\component\imgcut.py", line 386, in findrefresh
    img = cv2.cvtColor(sc, cv2.COLOR_BGR2GRAY)  # 转灰度图
cv2.error: C:\projects\opencv-python\opencv\modules\imgproc\src\color.cpp:11073: error: (-215) depth == 0 || depth == 2 || depth == 5 in function cv::cvtColor

Mon, 02 Apr 2018 18:47:16 imgcut.py[line:371] ERROR cut_img 这里出错
Mon, 02 Apr 2018 18:47:16 imgcut.py[line:372] ERROR this is an exception message
Traceback (most recent call last):
  File "E:\hupai\component\imgcut.py", line 364, in cut_img
    set_val('imgpos_lowestprice', img[use_area[0][1]:use_area[0][3], use_area[0][0]:use_area[0][2]])  # ok
IndexError: list index out of range
Mon, 02 Apr 2018 18:47:16 app_thread.py[line:125] ERROR 刷新失败
Mon, 02 Apr 2018 18:47:16 app_thread.py[line:126] ERROR this is an exception message
Traceback (most recent call last):
  File "E:\hupai\component\app_thread.py", line 123, in run
    findrefresh()
  File "E:\hupai\component\imgcut.py", line 386, in findrefresh
    img = cv2.cvtColor(sc, cv2.COLOR_BGR2GRAY)  # 转灰度图
cv2.error: C:\projects\opencv-python\opencv\modules\imgproc\src\color.cpp:11073: error: (-215) depth == 0 || depth == 2 || depth == 5 in function cv::cvtColor

Mon, 02 Apr 2018 18:47:16 imgcut.py[line:371] ERROR cut_img 这里出错
Mon, 02 Apr 2018 18:47:16 imgcut.py[line:372] ERROR this is an exception message
Traceback (most recent call last):
  File "E:\hupai\component\imgcut.py", line 364, in cut_img
    set_val('imgpos_lowestprice', img[use_area[0][1]:use_area[0][3], use_area[0][0]:use_area[0][2]])  # ok
IndexError: list index out of range
Mon, 02 Apr 2018 18:47:16 app_thread.py[line:125] ERROR 刷新失败
Mon, 02 Apr 2018 18:47:16 app_thread.py[line:126] ERROR this is an exception message
Traceback (most recent call last):
  File "E:\hupai\component\app_thread.py", line 123, in run
    findrefresh()
  File "E:\hupai\component\imgcut.py", line 386, in findrefresh
    img = cv2.cvtColor(sc, cv2.COLOR_BGR2GRAY)  # 转灰度图
cv2.error: C:\projects\opencv-python\opencv\modules\imgproc\src\color.cpp:11073: error: (-215) depth == 0 || depth == 2 || depth == 5 in function cv::cvtColor

Mon, 02 Apr 2018 18:47:16 imgcut.py[line:371] ERROR cut_img 这里出错
Mon, 02 Apr 2018 18:47:16 imgcut.py[line:372] ERROR this is an exception message
Traceback (most recent call last):
  File "E:\hupai\component\imgcut.py", line 364, in cut_img
    set_val('imgpos_lowestprice', img[use_area[0][1]:use_area[0][3], use_area[0][0]:use_area[0][2]])  # ok
IndexError: list index out of range
Mon, 02 Apr 2018 18:47:16 app_thread.py[line:125] ERROR 刷新失败
Mon, 02 Apr 2018 18:47:16 app_thread.py[line:126] ERROR this is an exception message
Traceback (most recent call last):
  File "E:\hupai\component\app_thread.py", line 123, in run
    findrefresh()
  File "E:\hupai\component\imgcut.py", line 386, in findrefresh
    img = cv2.cvtColor(sc, cv2.COLOR_BGR2GRAY)  # 转灰度图
cv2.error: C:\projects\opencv-python\opencv\modules\imgproc\src\color.cpp:11073: error: (-215) depth == 0 || depth == 2 || depth == 5 in function cv::cvtColor

Mon, 02 Apr 2018 18:47:16 imgcut.py[line:371] ERROR cut_img 这里出错
Mon, 02 Apr 2018 18:47:16 imgcut.py[line:372] ERROR this is an exception message
Traceback (most recent call last):
  File "E:\hupai\component\imgcut.py", line 364, in cut_img
    set_val('imgpos_lowestprice', img[use_area[0][1]:use_area[0][3], use_area[0][0]:use_area[0][2]])  # ok
IndexError: list index out of range
Mon, 02 Apr 2018 18:47:16 app_thread.py[line:125] ERROR 刷新失败
Mon, 02 Apr 2018 18:47:16 app_thread.py[line:126] ERROR this is an exception message
Traceback (most recent call last):
  File "E:\hupai\component\app_thread.py", line 123, in run
    findrefresh()
  File "E:\hupai\component\imgcut.py", line 386, in findrefresh
    img = cv2.cvtColor(sc, cv2.COLOR_BGR2GRAY)  # 转灰度图
cv2.error: C:\projects\opencv-python\opencv\modules\imgproc\src\color.cpp:11073: error: (-215) depth == 0 || depth == 2 || depth == 5 in function cv::cvtColor

Mon, 02 Apr 2018 18:47:16 app_thread.py[line:125] ERROR 刷新失败
Mon, 02 Apr 2018 18:47:16 app_thread.py[line:126] ERROR this is an exception message
Traceback (most recent call last):
  File "E:\hupai\component\app_thread.py", line 123, in run
    findrefresh()
  File "E:\hupai\component\imgcut.py", line 386, in findrefresh
    img = cv2.cvtColor(sc, cv2.COLOR_BGR2GRAY)  # 转灰度图
cv2.error: C:\projects\opencv-python\opencv\modules\imgproc\src\color.cpp:11073: error: (-215) depth == 0 || depth == 2 || depth == 5 in function cv::cvtColor

Mon, 02 Apr 2018 18:47:16 imgcut.py[line:371] ERROR cut_img 这里出错
Mon, 02 Apr 2018 18:47:16 imgcut.py[line:372] ERROR this is an exception message
Traceback (most recent call last):
  File "E:\hupai\component\imgcut.py", line 364, in cut_img
    set_val('imgpos_lowestprice', img[use_area[0][1]:use_area[0][3], use_area[0][0]:use_area[0][2]])  # ok
IndexError: list index out of range
Mon, 02 Apr 2018 18:47:16 app_thread.py[line:125] ERROR 刷新失败
Mon, 02 Apr 2018 18:47:16 app_thread.py[line:126] ERROR this is an exception message
Traceback (most recent call last):
  File "E:\hupai\component\app_thread.py", line 123, in run
    findrefresh()
  File "E:\hupai\component\imgcut.py", line 386, in findrefresh
    img = cv2.cvtColor(sc, cv2.COLOR_BGR2GRAY)  # 转灰度图
cv2.error: C:\projects\opencv-python\opencv\modules\imgproc\src\color.cpp:11073: error: (-215) depth == 0 || depth == 2 || depth == 5 in function cv::cvtColor

Mon, 02 Apr 2018 18:47:16 app_thread.py[line:125] ERROR 刷新失败
Mon, 02 Apr 2018 18:47:16 app_thread.py[line:126] ERROR this is an exception message
Traceback (most recent call last):
  File "E:\hupai\component\app_thread.py", line 123, in run
    findrefresh()
  File "E:\hupai\component\imgcut.py", line 386, in findrefresh
    img = cv2.cvtColor(sc, cv2.COLOR_BGR2GRAY)  # 转灰度图
cv2.error: C:\projects\opencv-python\opencv\modules\imgproc\src\color.cpp:11073: error: (-215) depth == 0 || depth == 2 || depth == 5 in function cv::cvtColor

Mon, 02 Apr 2018 18:47:16 imgcut.py[line:371] ERROR cut_img 这里出错
Mon, 02 Apr 2018 18:47:16 imgcut.py[line:372] ERROR this is an exception message
Traceback (most recent call last):
  File "E:\hupai\component\imgcut.py", line 364, in cut_img
    set_val('imgpos_lowestprice', img[use_area[0][1]:use_area[0][3], use_area[0][0]:use_area[0][2]])  # ok
IndexError: list index out of range
Mon, 02 Apr 2018 18:47:16 app_thread.py[line:125] ERROR 刷新失败
Mon, 02 Apr 2018 18:47:16 app_thread.py[line:126] ERROR this is an exception message
Traceback (most recent call last):
  File "E:\hupai\component\app_thread.py", line 123, in run
    findrefresh()
  File "E:\hupai\component\imgcut.py", line 386, in findrefresh
    img = cv2.cvtColor(sc, cv2.COLOR_BGR2GRAY)  # 转灰度图
cv2.error: C:\projects\opencv-python\opencv\modules\imgproc\src\color.cpp:11073: error: (-215) depth == 0 || depth == 2 || depth == 5 in function cv::cvtColor

Mon, 02 Apr 2018 18:47:16 imgcut.py[line:371] ERROR cut_img 这里出错
Mon, 02 Apr 2018 18:47:16 imgcut.py[line:372] ERROR this is an exception message
Traceback (most recent call last):
  File "E:\hupai\component\imgcut.py", line 364, in cut_img
    set_val('imgpos_lowestprice', img[use_area[0][1]:use_area[0][3], use_area[0][0]:use_area[0][2]])  # ok
IndexError: list index out of range
Mon, 02 Apr 2018 18:47:16 app_thread.py[line:125] ERROR 刷新失败
Mon, 02 Apr 2018 18:47:16 app_thread.py[line:126] ERROR this is an exception message
Traceback (most recent call last):
  File "E:\hupai\component\app_thread.py", line 123, in run
    findrefresh()
  File "E:\hupai\component\imgcut.py", line 386, in findrefresh
    img = cv2.cvtColor(sc, cv2.COLOR_BGR2GRAY)  # 转灰度图
cv2.error: C:\projects\opencv-python\opencv\modules\imgproc\src\color.cpp:11073: error: (-215) depth == 0 || depth == 2 || depth == 5 in function cv::cvtColor

Mon, 02 Apr 2018 18:47:16 imgcut.py[line:371] ERROR cut_img 这里出错
Mon, 02 Apr 2018 18:47:16 imgcut.py[line:372] ERROR this is an exception message
Traceback (most recent call last):
  File "E:\hupai\component\imgcut.py", line 364, in cut_img
    set_val('imgpos_lowestprice', img[use_area[0][1]:use_area[0][3], use_area[0][0]:use_area[0][2]])  # ok
IndexError: list index out of range
Mon, 02 Apr 2018 18:47:16 app_thread.py[line:125] ERROR 刷新失败
Mon, 02 Apr 2018 18:47:16 app_thread.py[line:126] ERROR this is an exception message
Traceback (most recent call last):
  File "E:\hupai\component\app_thread.py", line 123, in run
    findrefresh()
  File "E:\hupai\component\imgcut.py", line 386, in findrefresh
    img = cv2.cvtColor(sc, cv2.COLOR_BGR2GRAY)  # 转灰度图
cv2.error: C:\projects\opencv-python\opencv\modules\imgproc\src\color.cpp:11073: error: (-215) depth == 0 || depth == 2 || depth == 5 in function cv::cvtColor

Mon, 02 Apr 2018 18:47:16 imgcut.py[line:371] ERROR cut_img 这里出错
Mon, 02 Apr 2018 18:47:16 imgcut.py[line:372] ERROR this is an exception message
Traceback (most recent call last):
  File "E:\hupai\component\imgcut.py", line 364, in cut_img
    set_val('imgpos_lowestprice', img[use_area[0][1]:use_area[0][3], use_area[0][0]:use_area[0][2]])  # ok
IndexError: list index out of range
Mon, 02 Apr 2018 18:47:16 app_thread.py[line:125] ERROR 刷新失败
Mon, 02 Apr 2018 18:47:16 app_thread.py[line:126] ERROR this is an exception message
Traceback (most recent call last):
  File "E:\hupai\component\app_thread.py", line 123, in run
    findrefresh()
  File "E:\hupai\component\imgcut.py", line 386, in findrefresh
    img = cv2.cvtColor(sc, cv2.COLOR_BGR2GRAY)  # 转灰度图
cv2.error: C:\projects\opencv-python\opencv\modules\imgproc\src\color.cpp:11073: error: (-215) depth == 0 || depth == 2 || depth == 5 in function cv::cvtColor

Mon, 02 Apr 2018 18:47:16 imgcut.py[line:371] ERROR cut_img 这里出错
Mon, 02 Apr 2018 18:47:16 imgcut.py[line:372] ERROR this is an exception message
Traceback (most recent call last):
  File "E:\hupai\component\imgcut.py", line 364, in cut_img
    set_val('imgpos_lowestprice', img[use_area[0][1]:use_area[0][3], use_area[0][0]:use_area[0][2]])  # ok
IndexError: list index out of range
Mon, 02 Apr 2018 18:47:16 app_thread.py[line:125] ERROR 刷新失败
Mon, 02 Apr 2018 18:47:16 app_thread.py[line:126] ERROR this is an exception message
Traceback (most recent call last):
  File "E:\hupai\component\app_thread.py", line 123, in run
    findrefresh()
  File "E:\hupai\component\imgcut.py", line 386, in findrefresh
    img = cv2.cvtColor(sc, cv2.COLOR_BGR2GRAY)  # 转灰度图
cv2.error: C:\projects\opencv-python\opencv\modules\imgproc\src\color.cpp:11073: error: (-215) depth == 0 || depth == 2 || depth == 5 in function cv::cvtColor

Mon, 02 Apr 2018 18:47:16 app_thread.py[line:125] ERROR 刷新失败
Mon, 02 Apr 2018 18:47:16 app_thread.py[line:126] ERROR this is an exception message
Traceback (most recent call last):
  File "E:\hupai\component\app_thread.py", line 123, in run
    findrefresh()
  File "E:\hupai\component\imgcut.py", line 386, in findrefresh
    img = cv2.cvtColor(sc, cv2.COLOR_BGR2GRAY)  # 转灰度图
cv2.error: C:\projects\opencv-python\opencv\modules\imgproc\src\color.cpp:11073: error: (-215) depth == 0 || depth == 2 || depth == 5 in function cv::cvtColor

Mon, 02 Apr 2018 18:47:16 imgcut.py[line:371] ERROR cut_img 这里出错
Mon, 02 Apr 2018 18:47:16 imgcut.py[line:372] ERROR this is an exception message
Traceback (most recent call last):
  File "E:\hupai\component\imgcut.py", line 364, in cut_img
    set_val('imgpos_lowestprice', img[use_area[0][1]:use_area[0][3], use_area[0][0]:use_area[0][2]])  # ok
IndexError: list index out of range
Mon, 02 Apr 2018 18:47:16 app_thread.py[line:125] ERROR 刷新失败
Mon, 02 Apr 2018 18:47:16 app_thread.py[line:126] ERROR this is an exception message
Traceback (most recent call last):
  File "E:\hupai\component\app_thread.py", line 123, in run
    findrefresh()
  File "E:\hupai\component\imgcut.py", line 386, in findrefresh
    img = cv2.cvtColor(sc, cv2.COLOR_BGR2GRAY)  # 转灰度图
cv2.error: C:\projects\opencv-python\opencv\modules\imgproc\src\color.cpp:11073: error: (-215) depth == 0 || depth == 2 || depth == 5 in function cv::cvtColor

Mon, 02 Apr 2018 18:47:16 imgcut.py[line:371] ERROR cut_img 这里出错
Mon, 02 Apr 2018 18:47:16 imgcut.py[line:372] ERROR this is an exception message
Traceback (most recent call last):
  File "E:\hupai\component\imgcut.py", line 364, in cut_img
    set_val('imgpos_lowestprice', img[use_area[0][1]:use_area[0][3], use_area[0][0]:use_area[0][2]])  # ok
IndexError: list index out of range
Mon, 02 Apr 2018 18:47:17 app_thread.py[line:125] ERROR 刷新失败
Mon, 02 Apr 2018 18:47:17 app_thread.py[line:126] ERROR this is an exception message
Traceback (most recent call last):
  File "E:\hupai\component\app_thread.py", line 123, in run
    findrefresh()
  File "E:\hupai\component\imgcut.py", line 386, in findrefresh
    img = cv2.cvtColor(sc, cv2.COLOR_BGR2GRAY)  # 转灰度图
cv2.error: C:\projects\opencv-python\opencv\modules\imgproc\src\color.cpp:11073: error: (-215) depth == 0 || depth == 2 || depth == 5 in function cv::cvtColor

Mon, 02 Apr 2018 18:47:17 imgcut.py[line:371] ERROR cut_img 这里出错
Mon, 02 Apr 2018 18:47:17 imgcut.py[line:372] ERROR this is an exception message
Traceback (most recent call last):
  File "E:\hupai\component\imgcut.py", line 364, in cut_img
    set_val('imgpos_lowestprice', img[use_area[0][1]:use_area[0][3], use_area[0][0]:use_area[0][2]])  # ok
IndexError: list index out of range
Mon, 02 Apr 2018 18:47:17 app_thread.py[line:125] ERROR 刷新失败
Mon, 02 Apr 2018 18:47:17 app_thread.py[line:126] ERROR this is an exception message
Traceback (most recent call last):
  File "E:\hupai\component\app_thread.py", line 123, in run
    findrefresh()
  File "E:\hupai\component\imgcut.py", line 386, in findrefresh
    img = cv2.cvtColor(sc, cv2.COLOR_BGR2GRAY)  # 转灰度图
cv2.error: C:\projects\opencv-python\opencv\modules\imgproc\src\color.cpp:11073: error: (-215) depth == 0 || depth == 2 || depth == 5 in function cv::cvtColor

Mon, 02 Apr 2018 18:47:17 app_thread.py[line:125] ERROR 刷新失败
Mon, 02 Apr 2018 18:47:17 imgcut.py[line:371] ERROR cut_img 这里出错
Mon, 02 Apr 2018 18:47:17 app_thread.py[line:126] ERROR this is an exception message
Traceback (most recent call last):
  File "E:\hupai\component\app_thread.py", line 123, in run
    findrefresh()
  File "E:\hupai\component\imgcut.py", line 386, in findrefresh
    img = cv2.cvtColor(sc, cv2.COLOR_BGR2GRAY)  # 转灰度图
cv2.error: C:\projects\opencv-python\opencv\modules\imgproc\src\color.cpp:11073: error: (-215) depth == 0 || depth == 2 || depth == 5 in function cv::cvtColor

Mon, 02 Apr 2018 18:47:17 imgcut.py[line:372] ERROR this is an exception message
Traceback (most recent call last):
  File "E:\hupai\component\imgcut.py", line 364, in cut_img
    set_val('imgpos_lowestprice', img[use_area[0][1]:use_area[0][3], use_area[0][0]:use_area[0][2]])  # ok
IndexError: list index out of range
Mon, 02 Apr 2018 18:47:17 app_thread.py[line:125] ERROR 刷新失败
Mon, 02 Apr 2018 18:47:17 app_thread.py[line:126] ERROR this is an exception message
Traceback (most recent call last):
  File "E:\hupai\component\app_thread.py", line 123, in run
    findrefresh()
  File "E:\hupai\component\imgcut.py", line 386, in findrefresh
    img = cv2.cvtColor(sc, cv2.COLOR_BGR2GRAY)  # 转灰度图
cv2.error: C:\projects\opencv-python\opencv\modules\imgproc\src\color.cpp:11073: error: (-215) depth == 0 || depth == 2 || depth == 5 in function cv::cvtColor

Mon, 02 Apr 2018 18:47:17 imgcut.py[line:371] ERROR cut_img 这里出错
Mon, 02 Apr 2018 18:47:17 imgcut.py[line:372] ERROR this is an exception message
Traceback (most recent call last):
  File "E:\hupai\component\imgcut.py", line 364, in cut_img
    set_val('imgpos_lowestprice', img[use_area[0][1]:use_area[0][3], use_area[0][0]:use_area[0][2]])  # ok
IndexError: list index out of range
Mon, 02 Apr 2018 18:47:17 app_thread.py[line:125] ERROR 刷新失败
Mon, 02 Apr 2018 18:47:17 app_thread.py[line:126] ERROR this is an exception message
Traceback (most recent call last):
  File "E:\hupai\component\app_thread.py", line 123, in run
    findrefresh()
  File "E:\hupai\component\imgcut.py", line 386, in findrefresh
    img = cv2.cvtColor(sc, cv2.COLOR_BGR2GRAY)  # 转灰度图
cv2.error: C:\projects\opencv-python\opencv\modules\imgproc\src\color.cpp:11073: error: (-215) depth == 0 || depth == 2 || depth == 5 in function cv::cvtColor

Mon, 02 Apr 2018 18:47:17 imgcut.py[line:371] ERROR cut_img 这里出错
Mon, 02 Apr 2018 18:47:17 imgcut.py[line:372] ERROR this is an exception message
Traceback (most recent call last):
  File "E:\hupai\component\imgcut.py", line 364, in cut_img
    set_val('imgpos_lowestprice', img[use_area[0][1]:use_area[0][3], use_area[0][0]:use_area[0][2]])  # ok
IndexError: list index out of range
Mon, 02 Apr 2018 18:47:17 app_thread.py[line:125] ERROR 刷新失败
Mon, 02 Apr 2018 18:47:17 app_thread.py[line:126] ERROR this is an exception message
Traceback (most recent call last):
  File "E:\hupai\component\app_thread.py", line 123, in run
    findrefresh()
  File "E:\hupai\component\imgcut.py", line 386, in findrefresh
    img = cv2.cvtColor(sc, cv2.COLOR_BGR2GRAY)  # 转灰度图
cv2.error: C:\projects\opencv-python\opencv\modules\imgproc\src\color.cpp:11073: error: (-215) depth == 0 || depth == 2 || depth == 5 in function cv::cvtColor

Mon, 02 Apr 2018 18:47:17 imgcut.py[line:371] ERROR cut_img 这里出错
Mon, 02 Apr 2018 18:47:17 imgcut.py[line:372] ERROR this is an exception message
Traceback (most recent call last):
  File "E:\hupai\component\imgcut.py", line 364, in cut_img
    set_val('imgpos_lowestprice', img[use_area[0][1]:use_area[0][3], use_area[0][0]:use_area[0][2]])  # ok
IndexError: list index out of range
Mon, 02 Apr 2018 18:47:17 app_thread.py[line:125] ERROR 刷新失败
Mon, 02 Apr 2018 18:47:17 app_thread.py[line:126] ERROR this is an exception message
Traceback (most recent call last):
  File "E:\hupai\component\app_thread.py", line 123, in run
    findrefresh()
  File "E:\hupai\component\imgcut.py", line 386, in findrefresh
    img = cv2.cvtColor(sc, cv2.COLOR_BGR2GRAY)  # 转灰度图
cv2.error: C:\projects\opencv-python\opencv\modules\imgproc\src\color.cpp:11073: error: (-215) depth == 0 || depth == 2 || depth == 5 in function cv::cvtColor

Mon, 02 Apr 2018 18:47:17 imgcut.py[line:371] ERROR cut_img 这里出错
Mon, 02 Apr 2018 18:47:17 imgcut.py[line:372] ERROR this is an exception message
Traceback (most recent call last):
  File "E:\hupai\component\imgcut.py", line 364, in cut_img
    set_val('imgpos_lowestprice', img[use_area[0][1]:use_area[0][3], use_area[0][0]:use_area[0][2]])  # ok
IndexError: list index out of range
Mon, 02 Apr 2018 18:47:17 app_thread.py[line:125] ERROR 刷新失败
Mon, 02 Apr 2018 18:47:17 app_thread.py[line:126] ERROR this is an exception message
Traceback (most recent call last):
  File "E:\hupai\component\app_thread.py", line 123, in run
    findrefresh()
  File "E:\hupai\component\imgcut.py", line 386, in findrefresh
    img = cv2.cvtColor(sc, cv2.COLOR_BGR2GRAY)  # 转灰度图
cv2.error: C:\projects\opencv-python\opencv\modules\imgproc\src\color.cpp:11073: error: (-215) depth == 0 || depth == 2 || depth == 5 in function cv::cvtColor

Mon, 02 Apr 2018 18:47:17 imgcut.py[line:371] ERROR cut_img 这里出错
Mon, 02 Apr 2018 18:47:17 imgcut.py[line:372] ERROR this is an exception message
Traceback (most recent call last):
  File "E:\hupai\component\imgcut.py", line 364, in cut_img
    set_val('imgpos_lowestprice', img[use_area[0][1]:use_area[0][3], use_area[0][0]:use_area[0][2]])  # ok
IndexError: list index out of range
Mon, 02 Apr 2018 18:47:17 app_thread.py[line:125] ERROR 刷新失败
Mon, 02 Apr 2018 18:47:17 app_thread.py[line:126] ERROR this is an exception message
Traceback (most recent call last):
  File "E:\hupai\component\app_thread.py", line 123, in run
    findrefresh()
  File "E:\hupai\component\imgcut.py", line 386, in findrefresh
    img = cv2.cvtColor(sc, cv2.COLOR_BGR2GRAY)  # 转灰度图
cv2.error: C:\projects\opencv-python\opencv\modules\imgproc\src\color.cpp:11073: error: (-215) depth == 0 || depth == 2 || depth == 5 in function cv::cvtColor

Mon, 02 Apr 2018 18:47:17 app_thread.py[line:125] ERROR 刷新失败
Mon, 02 Apr 2018 18:47:17 app_thread.py[line:126] ERROR this is an exception message
Traceback (most recent call last):
  File "E:\hupai\component\app_thread.py", line 123, in run
    findrefresh()
  File "E:\hupai\component\imgcut.py", line 386, in findrefresh
    img = cv2.cvtColor(sc, cv2.COLOR_BGR2GRAY)  # 转灰度图
cv2.error: C:\projects\opencv-python\opencv\modules\imgproc\src\color.cpp:11073: error: (-215) depth == 0 || depth == 2 || depth == 5 in function cv::cvtColor

Mon, 02 Apr 2018 18:47:17 imgcut.py[line:371] ERROR cut_img 这里出错
Mon, 02 Apr 2018 18:47:17 imgcut.py[line:372] ERROR this is an exception message
Traceback (most recent call last):
  File "E:\hupai\component\imgcut.py", line 364, in cut_img
    set_val('imgpos_lowestprice', img[use_area[0][1]:use_area[0][3], use_area[0][0]:use_area[0][2]])  # ok
IndexError: list index out of range
Mon, 02 Apr 2018 18:47:17 app_thread.py[line:125] ERROR 刷新失败
Mon, 02 Apr 2018 18:47:17 app_thread.py[line:126] ERROR this is an exception message
Traceback (most recent call last):
  File "E:\hupai\component\app_thread.py", line 123, in run
    findrefresh()
  File "E:\hupai\component\imgcut.py", line 386, in findrefresh
    img = cv2.cvtColor(sc, cv2.COLOR_BGR2GRAY)  # 转灰度图
cv2.error: C:\projects\opencv-python\opencv\modules\imgproc\src\color.cpp:11073: error: (-215) depth == 0 || depth == 2 || depth == 5 in function cv::cvtColor

