Mon, 26 Mar 2018 17:03:28 PngImagePlugin.py[line:130] DEBUG STREAM b'IHDR' 16 13
Mon, 26 Mar 2018 17:03:28 PngImagePlugin.py[line:130] DEBUG STREAM b'IDAT' 41 65536
Mon, 26 Mar 2018 17:03:28 PngImagePlugin.py[line:130] DEBUG STREAM b'IHDR' 16 13
Mon, 26 Mar 2018 17:03:28 PngImagePlugin.py[line:130] DEBUG STREAM b'IDAT' 41 65536
Mon, 26 Mar 2018 17:03:28 app_thread.py[line:113] ERROR 刷新失败
Mon, 26 Mar 2018 17:03:28 app_thread.py[line:114] ERROR this is an exception message
Traceback (most recent call last):
  File "F:/BestAssistant\component\app_thread.py", line 111, in run
    findrefresh()
  File "F:/BestAssistant\component\imgcut.py", line 324, in findrefresh
    img = cv2.cvtColor(sc, cv2.COLOR_BGR2GRAY)  # 转灰度图
cv2.error: C:\projects\opencv-python\opencv\modules\imgproc\src\color.cpp:10600: error: (-215) depth == CV_8U || depth == CV_16U || depth == CV_32F in function cv::cvtColor

Mon, 26 Mar 2018 17:03:28 imgcut.py[line:309] ERROR cut_img 这里出错
Mon, 26 Mar 2018 17:03:28 imgcut.py[line:310] ERROR this is an exception message
Traceback (most recent call last):
  File "F:/BestAssistant\component\imgcut.py", line 302, in cut_img
    set_val('imgpos_lowestprice', img[use_area[0][1]:use_area[0][3], use_area[0][0]:use_area[0][2]])  # ok
IndexError: list index out of range
Mon, 26 Mar 2018 17:03:28 app_thread.py[line:113] ERROR 刷新失败
Mon, 26 Mar 2018 17:03:28 app_thread.py[line:114] ERROR this is an exception message
Traceback (most recent call last):
  File "F:/BestAssistant\component\app_thread.py", line 111, in run
    findrefresh()
  File "F:/BestAssistant\component\imgcut.py", line 324, in findrefresh
    img = cv2.cvtColor(sc, cv2.COLOR_BGR2GRAY)  # 转灰度图
cv2.error: C:\projects\opencv-python\opencv\modules\imgproc\src\color.cpp:10600: error: (-215) depth == CV_8U || depth == CV_16U || depth == CV_32F in function cv::cvtColor

Mon, 26 Mar 2018 17:03:28 imgcut.py[line:309] ERROR cut_img 这里出错
Mon, 26 Mar 2018 17:03:28 imgcut.py[line:310] ERROR this is an exception message
Traceback (most recent call last):
  File "F:/BestAssistant\component\imgcut.py", line 302, in cut_img
    set_val('imgpos_lowestprice', img[use_area[0][1]:use_area[0][3], use_area[0][0]:use_area[0][2]])  # ok
IndexError: list index out of range
Mon, 26 Mar 2018 17:03:28 app_thread.py[line:113] ERROR 刷新失败
Mon, 26 Mar 2018 17:03:28 app_thread.py[line:114] ERROR this is an exception message
Traceback (most recent call last):
  File "F:/BestAssistant\component\app_thread.py", line 111, in run
    findrefresh()
  File "F:/BestAssistant\component\imgcut.py", line 324, in findrefresh
    img = cv2.cvtColor(sc, cv2.COLOR_BGR2GRAY)  # 转灰度图
cv2.error: C:\projects\opencv-python\opencv\modules\imgproc\src\color.cpp:10600: error: (-215) depth == CV_8U || depth == CV_16U || depth == CV_32F in function cv::cvtColor

Mon, 26 Mar 2018 17:03:28 app_thread.py[line:113] ERROR 刷新失败
Mon, 26 Mar 2018 17:03:28 app_thread.py[line:114] ERROR this is an exception message
Traceback (most recent call last):
  File "F:/BestAssistant\component\app_thread.py", line 111, in run
    findrefresh()
  File "F:/BestAssistant\component\imgcut.py", line 324, in findrefresh
    img = cv2.cvtColor(sc, cv2.COLOR_BGR2GRAY)  # 转灰度图
cv2.error: C:\projects\opencv-python\opencv\modules\imgproc\src\color.cpp:10600: error: (-215) depth == CV_8U || depth == CV_16U || depth == CV_32F in function cv::cvtColor

Mon, 26 Mar 2018 17:03:28 imgcut.py[line:309] ERROR cut_img 这里出错
Mon, 26 Mar 2018 17:03:28 imgcut.py[line:310] ERROR this is an exception message
Traceback (most recent call last):
  File "F:/BestAssistant\component\imgcut.py", line 302, in cut_img
    set_val('imgpos_lowestprice', img[use_area[0][1]:use_area[0][3], use_area[0][0]:use_area[0][2]])  # ok
IndexError: list index out of range
Mon, 26 Mar 2018 17:03:28 app_thread.py[line:113] ERROR 刷新失败
Mon, 26 Mar 2018 17:03:28 app_thread.py[line:114] ERROR this is an exception message
Traceback (most recent call last):
  File "F:/BestAssistant\component\app_thread.py", line 111, in run
    findrefresh()
  File "F:/BestAssistant\component\imgcut.py", line 324, in findrefresh
    img = cv2.cvtColor(sc, cv2.COLOR_BGR2GRAY)  # 转灰度图
cv2.error: C:\projects\opencv-python\opencv\modules\imgproc\src\color.cpp:10600: error: (-215) depth == CV_8U || depth == CV_16U || depth == CV_32F in function cv::cvtColor

Mon, 26 Mar 2018 17:03:28 app_thread.py[line:113] ERROR 刷新失败
Mon, 26 Mar 2018 17:03:28 app_thread.py[line:114] ERROR this is an exception message
Traceback (most recent call last):
  File "F:/BestAssistant\component\app_thread.py", line 111, in run
    findrefresh()
  File "F:/BestAssistant\component\imgcut.py", line 324, in findrefresh
    img = cv2.cvtColor(sc, cv2.COLOR_BGR2GRAY)  # 转灰度图
cv2.error: C:\projects\opencv-python\opencv\modules\imgproc\src\color.cpp:10600: error: (-215) depth == CV_8U || depth == CV_16U || depth == CV_32F in function cv::cvtColor

Mon, 26 Mar 2018 17:03:28 imgcut.py[line:309] ERROR cut_img 这里出错
Mon, 26 Mar 2018 17:03:28 imgcut.py[line:310] ERROR this is an exception message
Traceback (most recent call last):
  File "F:/BestAssistant\component\imgcut.py", line 302, in cut_img
    set_val('imgpos_lowestprice', img[use_area[0][1]:use_area[0][3], use_area[0][0]:use_area[0][2]])  # ok
IndexError: list index out of range
Mon, 26 Mar 2018 17:03:28 imgcut.py[line:309] ERROR cut_img 这里出错
Mon, 26 Mar 2018 17:03:28 imgcut.py[line:310] ERROR this is an exception message
Traceback (most recent call last):
  File "F:/BestAssistant\component\imgcut.py", line 302, in cut_img
    set_val('imgpos_lowestprice', img[use_area[0][1]:use_area[0][3], use_area[0][0]:use_area[0][2]])  # ok
IndexError: list index out of range
Mon, 26 Mar 2018 17:03:28 app_thread.py[line:113] ERROR 刷新失败
Mon, 26 Mar 2018 17:03:28 app_thread.py[line:114] ERROR this is an exception message
Traceback (most recent call last):
  File "F:/BestAssistant\component\app_thread.py", line 111, in run
    findrefresh()
  File "F:/BestAssistant\component\imgcut.py", line 324, in findrefresh
    img = cv2.cvtColor(sc, cv2.COLOR_BGR2GRAY)  # 转灰度图
cv2.error: C:\projects\opencv-python\opencv\modules\imgproc\src\color.cpp:10600: error: (-215) depth == CV_8U || depth == CV_16U || depth == CV_32F in function cv::cvtColor

Mon, 26 Mar 2018 17:03:29 app_thread.py[line:113] ERROR 刷新失败
Mon, 26 Mar 2018 17:03:29 app_thread.py[line:114] ERROR this is an exception message
Traceback (most recent call last):
  File "F:/BestAssistant\component\app_thread.py", line 111, in run
    findrefresh()
  File "F:/BestAssistant\component\imgcut.py", line 324, in findrefresh
    img = cv2.cvtColor(sc, cv2.COLOR_BGR2GRAY)  # 转灰度图
cv2.error: C:\projects\opencv-python\opencv\modules\imgproc\src\color.cpp:10600: error: (-215) depth == CV_8U || depth == CV_16U || depth == CV_32F in function cv::cvtColor

Mon, 26 Mar 2018 17:03:29 app_thread.py[line:113] ERROR 刷新失败
Mon, 26 Mar 2018 17:03:29 app_thread.py[line:114] ERROR this is an exception message
Traceback (most recent call last):
  File "F:/BestAssistant\component\app_thread.py", line 111, in run
    findrefresh()
  File "F:/BestAssistant\component\imgcut.py", line 324, in findrefresh
    img = cv2.cvtColor(sc, cv2.COLOR_BGR2GRAY)  # 转灰度图
cv2.error: C:\projects\opencv-python\opencv\modules\imgproc\src\color.cpp:10600: error: (-215) depth == CV_8U || depth == CV_16U || depth == CV_32F in function cv::cvtColor

Mon, 26 Mar 2018 17:03:29 imgcut.py[line:309] ERROR cut_img 这里出错
Mon, 26 Mar 2018 17:03:29 imgcut.py[line:310] ERROR this is an exception message
Traceback (most recent call last):
  File "F:/BestAssistant\component\imgcut.py", line 302, in cut_img
    set_val('imgpos_lowestprice', img[use_area[0][1]:use_area[0][3], use_area[0][0]:use_area[0][2]])  # ok
IndexError: list index out of range
Mon, 26 Mar 2018 17:03:29 app_thread.py[line:113] ERROR 刷新失败
Mon, 26 Mar 2018 17:03:29 app_thread.py[line:114] ERROR this is an exception message
Traceback (most recent call last):
  File "F:/BestAssistant\component\app_thread.py", line 111, in run
    findrefresh()
  File "F:/BestAssistant\component\imgcut.py", line 324, in findrefresh
    img = cv2.cvtColor(sc, cv2.COLOR_BGR2GRAY)  # 转灰度图
cv2.error: C:\projects\opencv-python\opencv\modules\imgproc\src\color.cpp:10600: error: (-215) depth == CV_8U || depth == CV_16U || depth == CV_32F in function cv::cvtColor

Mon, 26 Mar 2018 17:03:29 app_thread.py[line:113] ERROR 刷新失败
Mon, 26 Mar 2018 17:03:29 app_thread.py[line:114] ERROR this is an exception message
Traceback (most recent call last):
  File "F:/BestAssistant\component\app_thread.py", line 111, in run
    findrefresh()
  File "F:/BestAssistant\component\imgcut.py", line 324, in findrefresh
    img = cv2.cvtColor(sc, cv2.COLOR_BGR2GRAY)  # 转灰度图
cv2.error: C:\projects\opencv-python\opencv\modules\imgproc\src\color.cpp:10600: error: (-215) depth == CV_8U || depth == CV_16U || depth == CV_32F in function cv::cvtColor

Mon, 26 Mar 2018 17:03:29 app_thread.py[line:113] ERROR 刷新失败
Mon, 26 Mar 2018 17:03:29 app_thread.py[line:114] ERROR this is an exception message
Traceback (most recent call last):
  File "F:/BestAssistant\component\app_thread.py", line 111, in run
    findrefresh()
  File "F:/BestAssistant\component\imgcut.py", line 324, in findrefresh
    img = cv2.cvtColor(sc, cv2.COLOR_BGR2GRAY)  # 转灰度图
cv2.error: C:\projects\opencv-python\opencv\modules\imgproc\src\color.cpp:10600: error: (-215) depth == CV_8U || depth == CV_16U || depth == CV_32F in function cv::cvtColor

Mon, 26 Mar 2018 17:03:29 imgcut.py[line:309] ERROR cut_img 这里出错
Mon, 26 Mar 2018 17:03:29 imgcut.py[line:310] ERROR this is an exception message
Traceback (most recent call last):
  File "F:/BestAssistant\component\imgcut.py", line 302, in cut_img
    set_val('imgpos_lowestprice', img[use_area[0][1]:use_area[0][3], use_area[0][0]:use_area[0][2]])  # ok
IndexError: list index out of range
Mon, 26 Mar 2018 17:03:29 app_thread.py[line:113] ERROR 刷新失败
Mon, 26 Mar 2018 17:03:29 app_thread.py[line:114] ERROR this is an exception message
Traceback (most recent call last):
  File "F:/BestAssistant\component\app_thread.py", line 111, in run
    findrefresh()
  File "F:/BestAssistant\component\imgcut.py", line 324, in findrefresh
    img = cv2.cvtColor(sc, cv2.COLOR_BGR2GRAY)  # 转灰度图
cv2.error: C:\projects\opencv-python\opencv\modules\imgproc\src\color.cpp:10600: error: (-215) depth == CV_8U || depth == CV_16U || depth == CV_32F in function cv::cvtColor

Mon, 26 Mar 2018 17:03:29 imgcut.py[line:309] ERROR cut_img 这里出错
Mon, 26 Mar 2018 17:03:29 imgcut.py[line:310] ERROR this is an exception message
Traceback (most recent call last):
  File "F:/BestAssistant\component\imgcut.py", line 302, in cut_img
    set_val('imgpos_lowestprice', img[use_area[0][1]:use_area[0][3], use_area[0][0]:use_area[0][2]])  # ok
IndexError: list index out of range
Mon, 26 Mar 2018 17:03:29 app_thread.py[line:113] ERROR 刷新失败
Mon, 26 Mar 2018 17:03:29 app_thread.py[line:114] ERROR this is an exception message
Traceback (most recent call last):
  File "F:/BestAssistant\component\app_thread.py", line 111, in run
    findrefresh()
  File "F:/BestAssistant\component\imgcut.py", line 324, in findrefresh
    img = cv2.cvtColor(sc, cv2.COLOR_BGR2GRAY)  # 转灰度图
cv2.error: C:\projects\opencv-python\opencv\modules\imgproc\src\color.cpp:10600: error: (-215) depth == CV_8U || depth == CV_16U || depth == CV_32F in function cv::cvtColor

Mon, 26 Mar 2018 17:03:29 app_thread.py[line:113] ERROR 刷新失败
Mon, 26 Mar 2018 17:03:29 app_thread.py[line:114] ERROR this is an exception message
Traceback (most recent call last):
  File "F:/BestAssistant\component\app_thread.py", line 111, in run
    findrefresh()
  File "F:/BestAssistant\component\imgcut.py", line 324, in findrefresh
    img = cv2.cvtColor(sc, cv2.COLOR_BGR2GRAY)  # 转灰度图
cv2.error: C:\projects\opencv-python\opencv\modules\imgproc\src\color.cpp:10600: error: (-215) depth == CV_8U || depth == CV_16U || depth == CV_32F in function cv::cvtColor

Mon, 26 Mar 2018 17:03:29 imgcut.py[line:309] ERROR cut_img 这里出错
Mon, 26 Mar 2018 17:03:29 imgcut.py[line:310] ERROR this is an exception message
Traceback (most recent call last):
  File "F:/BestAssistant\component\imgcut.py", line 302, in cut_img
    set_val('imgpos_lowestprice', img[use_area[0][1]:use_area[0][3], use_area[0][0]:use_area[0][2]])  # ok
IndexError: list index out of range
Mon, 26 Mar 2018 17:03:29 app_thread.py[line:113] ERROR 刷新失败
Mon, 26 Mar 2018 17:03:29 app_thread.py[line:114] ERROR this is an exception message
Traceback (most recent call last):
  File "F:/BestAssistant\component\app_thread.py", line 111, in run
    findrefresh()
  File "F:/BestAssistant\component\imgcut.py", line 324, in findrefresh
    img = cv2.cvtColor(sc, cv2.COLOR_BGR2GRAY)  # 转灰度图
cv2.error: C:\projects\opencv-python\opencv\modules\imgproc\src\color.cpp:10600: error: (-215) depth == CV_8U || depth == CV_16U || depth == CV_32F in function cv::cvtColor

Mon, 26 Mar 2018 17:03:30 app_thread.py[line:113] ERROR 刷新失败
Mon, 26 Mar 2018 17:03:30 app_thread.py[line:114] ERROR this is an exception message
Traceback (most recent call last):
  File "F:/BestAssistant\component\app_thread.py", line 111, in run
    findrefresh()
  File "F:/BestAssistant\component\imgcut.py", line 324, in findrefresh
    img = cv2.cvtColor(sc, cv2.COLOR_BGR2GRAY)  # 转灰度图
cv2.error: C:\projects\opencv-python\opencv\modules\imgproc\src\color.cpp:10600: error: (-215) depth == CV_8U || depth == CV_16U || depth == CV_32F in function cv::cvtColor

Mon, 26 Mar 2018 17:03:30 imgcut.py[line:309] ERROR cut_img 这里出错
Mon, 26 Mar 2018 17:03:30 imgcut.py[line:310] ERROR this is an exception message
Traceback (most recent call last):
  File "F:/BestAssistant\component\imgcut.py", line 302, in cut_img
    set_val('imgpos_lowestprice', img[use_area[0][1]:use_area[0][3], use_area[0][0]:use_area[0][2]])  # ok
IndexError: list index out of range
Mon, 26 Mar 2018 17:03:30 imgcut.py[line:309] ERROR cut_img 这里出错
Mon, 26 Mar 2018 17:03:30 imgcut.py[line:310] ERROR this is an exception message
Traceback (most recent call last):
  File "F:/BestAssistant\component\imgcut.py", line 302, in cut_img
    set_val('imgpos_lowestprice', img[use_area[0][1]:use_area[0][3], use_area[0][0]:use_area[0][2]])  # ok
IndexError: list index out of range
Mon, 26 Mar 2018 17:03:30 app_thread.py[line:113] ERROR 刷新失败
Mon, 26 Mar 2018 17:03:30 app_thread.py[line:114] ERROR this is an exception message
Traceback (most recent call last):
  File "F:/BestAssistant\component\app_thread.py", line 111, in run
    findrefresh()
  File "F:/BestAssistant\component\imgcut.py", line 324, in findrefresh
    img = cv2.cvtColor(sc, cv2.COLOR_BGR2GRAY)  # 转灰度图
cv2.error: C:\projects\opencv-python\opencv\modules\imgproc\src\color.cpp:10600: error: (-215) depth == CV_8U || depth == CV_16U || depth == CV_32F in function cv::cvtColor

Mon, 26 Mar 2018 17:03:30 app_thread.py[line:113] ERROR 刷新失败
Mon, 26 Mar 2018 17:03:30 app_thread.py[line:114] ERROR this is an exception message
Traceback (most recent call last):
  File "F:/BestAssistant\component\app_thread.py", line 111, in run
    findrefresh()
  File "F:/BestAssistant\component\imgcut.py", line 324, in findrefresh
    img = cv2.cvtColor(sc, cv2.COLOR_BGR2GRAY)  # 转灰度图
cv2.error: C:\projects\opencv-python\opencv\modules\imgproc\src\color.cpp:10600: error: (-215) depth == CV_8U || depth == CV_16U || depth == CV_32F in function cv::cvtColor

Mon, 26 Mar 2018 17:03:30 imgcut.py[line:309] ERROR cut_img 这里出错
Mon, 26 Mar 2018 17:03:30 imgcut.py[line:310] ERROR this is an exception message
Traceback (most recent call last):
  File "F:/BestAssistant\component\imgcut.py", line 302, in cut_img
    set_val('imgpos_lowestprice', img[use_area[0][1]:use_area[0][3], use_area[0][0]:use_area[0][2]])  # ok
IndexError: list index out of range
Mon, 26 Mar 2018 17:03:30 app_thread.py[line:113] ERROR 刷新失败
Mon, 26 Mar 2018 17:03:30 app_thread.py[line:114] ERROR this is an exception message
Traceback (most recent call last):
  File "F:/BestAssistant\component\app_thread.py", line 111, in run
    findrefresh()
  File "F:/BestAssistant\component\imgcut.py", line 324, in findrefresh
    img = cv2.cvtColor(sc, cv2.COLOR_BGR2GRAY)  # 转灰度图
cv2.error: C:\projects\opencv-python\opencv\modules\imgproc\src\color.cpp:10600: error: (-215) depth == CV_8U || depth == CV_16U || depth == CV_32F in function cv::cvtColor

Mon, 26 Mar 2018 17:03:30 imgcut.py[line:309] ERROR cut_img 这里出错
Mon, 26 Mar 2018 17:03:30 imgcut.py[line:310] ERROR this is an exception message
Traceback (most recent call last):
  File "F:/BestAssistant\component\imgcut.py", line 302, in cut_img
    set_val('imgpos_lowestprice', img[use_area[0][1]:use_area[0][3], use_area[0][0]:use_area[0][2]])  # ok
IndexError: list index out of range
Mon, 26 Mar 2018 17:03:30 app_thread.py[line:113] ERROR 刷新失败
Mon, 26 Mar 2018 17:03:30 app_thread.py[line:114] ERROR this is an exception message
Traceback (most recent call last):
  File "F:/BestAssistant\component\app_thread.py", line 111, in run
    findrefresh()
  File "F:/BestAssistant\component\imgcut.py", line 324, in findrefresh
    img = cv2.cvtColor(sc, cv2.COLOR_BGR2GRAY)  # 转灰度图
cv2.error: C:\projects\opencv-python\opencv\modules\imgproc\src\color.cpp:10600: error: (-215) depth == CV_8U || depth == CV_16U || depth == CV_32F in function cv::cvtColor

Mon, 26 Mar 2018 17:03:30 imgcut.py[line:309] ERROR cut_img 这里出错
Mon, 26 Mar 2018 17:03:30 imgcut.py[line:310] ERROR this is an exception message
Traceback (most recent call last):
  File "F:/BestAssistant\component\imgcut.py", line 302, in cut_img
    set_val('imgpos_lowestprice', img[use_area[0][1]:use_area[0][3], use_area[0][0]:use_area[0][2]])  # ok
IndexError: list index out of range
Mon, 26 Mar 2018 17:03:30 app_thread.py[line:113] ERROR 刷新失败
Mon, 26 Mar 2018 17:03:30 app_thread.py[line:114] ERROR this is an exception message
Traceback (most recent call last):
  File "F:/BestAssistant\component\app_thread.py", line 111, in run
    findrefresh()
  File "F:/BestAssistant\component\imgcut.py", line 324, in findrefresh
    img = cv2.cvtColor(sc, cv2.COLOR_BGR2GRAY)  # 转灰度图
cv2.error: C:\projects\opencv-python\opencv\modules\imgproc\src\color.cpp:10600: error: (-215) depth == CV_8U || depth == CV_16U || depth == CV_32F in function cv::cvtColor

Mon, 26 Mar 2018 17:03:30 imgcut.py[line:309] ERROR cut_img 这里出错
Mon, 26 Mar 2018 17:03:30 imgcut.py[line:310] ERROR this is an exception message
Traceback (most recent call last):
  File "F:/BestAssistant\component\imgcut.py", line 302, in cut_img
    set_val('imgpos_lowestprice', img[use_area[0][1]:use_area[0][3], use_area[0][0]:use_area[0][2]])  # ok
IndexError: list index out of range
Mon, 26 Mar 2018 17:03:30 app_thread.py[line:113] ERROR 刷新失败
Mon, 26 Mar 2018 17:03:30 app_thread.py[line:114] ERROR this is an exception message
Traceback (most recent call last):
  File "F:/BestAssistant\component\app_thread.py", line 111, in run
    findrefresh()
  File "F:/BestAssistant\component\imgcut.py", line 324, in findrefresh
    img = cv2.cvtColor(sc, cv2.COLOR_BGR2GRAY)  # 转灰度图
cv2.error: C:\projects\opencv-python\opencv\modules\imgproc\src\color.cpp:10600: error: (-215) depth == CV_8U || depth == CV_16U || depth == CV_32F in function cv::cvtColor

Mon, 26 Mar 2018 17:03:30 imgcut.py[line:309] ERROR cut_img 这里出错
Mon, 26 Mar 2018 17:03:30 imgcut.py[line:310] ERROR this is an exception message
Traceback (most recent call last):
  File "F:/BestAssistant\component\imgcut.py", line 302, in cut_img
    set_val('imgpos_lowestprice', img[use_area[0][1]:use_area[0][3], use_area[0][0]:use_area[0][2]])  # ok
IndexError: list index out of range
Mon, 26 Mar 2018 17:03:30 app_thread.py[line:113] ERROR 刷新失败
Mon, 26 Mar 2018 17:03:30 app_thread.py[line:114] ERROR this is an exception message
Traceback (most recent call last):
  File "F:/BestAssistant\component\app_thread.py", line 111, in run
    findrefresh()
  File "F:/BestAssistant\component\imgcut.py", line 324, in findrefresh
    img = cv2.cvtColor(sc, cv2.COLOR_BGR2GRAY)  # 转灰度图
cv2.error: C:\projects\opencv-python\opencv\modules\imgproc\src\color.cpp:10600: error: (-215) depth == CV_8U || depth == CV_16U || depth == CV_32F in function cv::cvtColor

Mon, 26 Mar 2018 17:03:30 imgcut.py[line:309] ERROR cut_img 这里出错
Mon, 26 Mar 2018 17:03:30 imgcut.py[line:310] ERROR this is an exception message
Traceback (most recent call last):
  File "F:/BestAssistant\component\imgcut.py", line 302, in cut_img
    set_val('imgpos_lowestprice', img[use_area[0][1]:use_area[0][3], use_area[0][0]:use_area[0][2]])  # ok
IndexError: list index out of range
Mon, 26 Mar 2018 17:03:30 app_thread.py[line:113] ERROR 刷新失败
Mon, 26 Mar 2018 17:03:30 app_thread.py[line:114] ERROR this is an exception message
Traceback (most recent call last):
  File "F:/BestAssistant\component\app_thread.py", line 111, in run
    findrefresh()
  File "F:/BestAssistant\component\imgcut.py", line 324, in findrefresh
    img = cv2.cvtColor(sc, cv2.COLOR_BGR2GRAY)  # 转灰度图
cv2.error: C:\projects\opencv-python\opencv\modules\imgproc\src\color.cpp:10600: error: (-215) depth == CV_8U || depth == CV_16U || depth == CV_32F in function cv::cvtColor

Mon, 26 Mar 2018 17:03:30 imgcut.py[line:309] ERROR cut_img 这里出错
Mon, 26 Mar 2018 17:03:30 imgcut.py[line:310] ERROR this is an exception message
Traceback (most recent call last):
  File "F:/BestAssistant\component\imgcut.py", line 302, in cut_img
    set_val('imgpos_lowestprice', img[use_area[0][1]:use_area[0][3], use_area[0][0]:use_area[0][2]])  # ok
IndexError: list index out of range
Mon, 26 Mar 2018 17:03:30 app_thread.py[line:113] ERROR 刷新失败
Mon, 26 Mar 2018 17:03:30 app_thread.py[line:114] ERROR this is an exception message
Traceback (most recent call last):
  File "F:/BestAssistant\component\app_thread.py", line 111, in run
    findrefresh()
  File "F:/BestAssistant\component\imgcut.py", line 324, in findrefresh
    img = cv2.cvtColor(sc, cv2.COLOR_BGR2GRAY)  # 转灰度图
cv2.error: C:\projects\opencv-python\opencv\modules\imgproc\src\color.cpp:10600: error: (-215) depth == CV_8U || depth == CV_16U || depth == CV_32F in function cv::cvtColor

Mon, 26 Mar 2018 17:03:30 imgcut.py[line:309] ERROR cut_img 这里出错
Mon, 26 Mar 2018 17:03:30 imgcut.py[line:310] ERROR this is an exception message
Traceback (most recent call last):
  File "F:/BestAssistant\component\imgcut.py", line 302, in cut_img
    set_val('imgpos_lowestprice', img[use_area[0][1]:use_area[0][3], use_area[0][0]:use_area[0][2]])  # ok
IndexError: list index out of range
Mon, 26 Mar 2018 17:03:30 app_thread.py[line:113] ERROR 刷新失败
Mon, 26 Mar 2018 17:03:30 app_thread.py[line:114] ERROR this is an exception message
Traceback (most recent call last):
  File "F:/BestAssistant\component\app_thread.py", line 111, in run
    findrefresh()
  File "F:/BestAssistant\component\imgcut.py", line 324, in findrefresh
    img = cv2.cvtColor(sc, cv2.COLOR_BGR2GRAY)  # 转灰度图
cv2.error: C:\projects\opencv-python\opencv\modules\imgproc\src\color.cpp:10600: error: (-215) depth == CV_8U || depth == CV_16U || depth == CV_32F in function cv::cvtColor

Mon, 26 Mar 2018 17:03:30 imgcut.py[line:309] ERROR cut_img 这里出错
Mon, 26 Mar 2018 17:03:30 imgcut.py[line:310] ERROR this is an exception message
Traceback (most recent call last):
  File "F:/BestAssistant\component\imgcut.py", line 302, in cut_img
    set_val('imgpos_lowestprice', img[use_area[0][1]:use_area[0][3], use_area[0][0]:use_area[0][2]])  # ok
IndexError: list index out of range
Mon, 26 Mar 2018 17:03:30 app_thread.py[line:113] ERROR 刷新失败
Mon, 26 Mar 2018 17:03:30 app_thread.py[line:114] ERROR this is an exception message
Traceback (most recent call last):
  File "F:/BestAssistant\component\app_thread.py", line 111, in run
    findrefresh()
  File "F:/BestAssistant\component\imgcut.py", line 324, in findrefresh
    img = cv2.cvtColor(sc, cv2.COLOR_BGR2GRAY)  # 转灰度图
cv2.error: C:\projects\opencv-python\opencv\modules\imgproc\src\color.cpp:10600: error: (-215) depth == CV_8U || depth == CV_16U || depth == CV_32F in function cv::cvtColor

Mon, 26 Mar 2018 17:03:30 app_thread.py[line:113] ERROR 刷新失败
Mon, 26 Mar 2018 17:03:30 app_thread.py[line:114] ERROR this is an exception message
Traceback (most recent call last):
  File "F:/BestAssistant\component\app_thread.py", line 111, in run
    findrefresh()
  File "F:/BestAssistant\component\imgcut.py", line 324, in findrefresh
    img = cv2.cvtColor(sc, cv2.COLOR_BGR2GRAY)  # 转灰度图
cv2.error: C:\projects\opencv-python\opencv\modules\imgproc\src\color.cpp:10600: error: (-215) depth == CV_8U || depth == CV_16U || depth == CV_32F in function cv::cvtColor

Mon, 26 Mar 2018 17:03:30 imgcut.py[line:309] ERROR cut_img 这里出错
Mon, 26 Mar 2018 17:03:30 imgcut.py[line:310] ERROR this is an exception message
Traceback (most recent call last):
  File "F:/BestAssistant\component\imgcut.py", line 302, in cut_img
    set_val('imgpos_lowestprice', img[use_area[0][1]:use_area[0][3], use_area[0][0]:use_area[0][2]])  # ok
IndexError: list index out of range
Mon, 26 Mar 2018 17:03:31 app_thread.py[line:113] ERROR 刷新失败
Mon, 26 Mar 2018 17:03:31 app_thread.py[line:114] ERROR this is an exception message
Traceback (most recent call last):
  File "F:/BestAssistant\component\app_thread.py", line 111, in run
    findrefresh()
  File "F:/BestAssistant\component\imgcut.py", line 324, in findrefresh
    img = cv2.cvtColor(sc, cv2.COLOR_BGR2GRAY)  # 转灰度图
cv2.error: C:\projects\opencv-python\opencv\modules\imgproc\src\color.cpp:10600: error: (-215) depth == CV_8U || depth == CV_16U || depth == CV_32F in function cv::cvtColor

Mon, 26 Mar 2018 17:03:31 imgcut.py[line:309] ERROR cut_img 这里出错
Mon, 26 Mar 2018 17:03:31 imgcut.py[line:310] ERROR this is an exception message
Traceback (most recent call last):
  File "F:/BestAssistant\component\imgcut.py", line 302, in cut_img
    set_val('imgpos_lowestprice', img[use_area[0][1]:use_area[0][3], use_area[0][0]:use_area[0][2]])  # ok
IndexError: list index out of range
Mon, 26 Mar 2018 17:03:31 app_thread.py[line:113] ERROR 刷新失败
Mon, 26 Mar 2018 17:03:31 app_thread.py[line:114] ERROR this is an exception message
Traceback (most recent call last):
  File "F:/BestAssistant\component\app_thread.py", line 111, in run
    findrefresh()
  File "F:/BestAssistant\component\imgcut.py", line 324, in findrefresh
    img = cv2.cvtColor(sc, cv2.COLOR_BGR2GRAY)  # 转灰度图
cv2.error: C:\projects\opencv-python\opencv\modules\imgproc\src\color.cpp:10600: error: (-215) depth == CV_8U || depth == CV_16U || depth == CV_32F in function cv::cvtColor

Mon, 26 Mar 2018 17:03:31 app_thread.py[line:113] ERROR 刷新失败
Mon, 26 Mar 2018 17:03:31 app_thread.py[line:114] ERROR this is an exception message
Traceback (most recent call last):
  File "F:/BestAssistant\component\app_thread.py", line 111, in run
    findrefresh()
  File "F:/BestAssistant\component\imgcut.py", line 324, in findrefresh
    img = cv2.cvtColor(sc, cv2.COLOR_BGR2GRAY)  # 转灰度图
cv2.error: C:\projects\opencv-python\opencv\modules\imgproc\src\color.cpp:10600: error: (-215) depth == CV_8U || depth == CV_16U || depth == CV_32F in function cv::cvtColor

Mon, 26 Mar 2018 17:03:31 imgcut.py[line:309] ERROR cut_img 这里出错
Mon, 26 Mar 2018 17:03:31 imgcut.py[line:310] ERROR this is an exception message
Traceback (most recent call last):
  File "F:/BestAssistant\component\imgcut.py", line 302, in cut_img
    set_val('imgpos_lowestprice', img[use_area[0][1]:use_area[0][3], use_area[0][0]:use_area[0][2]])  # ok
IndexError: list index out of range
Mon, 26 Mar 2018 17:03:31 app_thread.py[line:113] ERROR 刷新失败
Mon, 26 Mar 2018 17:03:31 app_thread.py[line:114] ERROR this is an exception message
Traceback (most recent call last):
  File "F:/BestAssistant\component\app_thread.py", line 111, in run
    findrefresh()
  File "F:/BestAssistant\component\imgcut.py", line 324, in findrefresh
    img = cv2.cvtColor(sc, cv2.COLOR_BGR2GRAY)  # 转灰度图
cv2.error: C:\projects\opencv-python\opencv\modules\imgproc\src\color.cpp:10600: error: (-215) depth == CV_8U || depth == CV_16U || depth == CV_32F in function cv::cvtColor

Mon, 26 Mar 2018 17:03:31 imgcut.py[line:309] ERROR cut_img 这里出错
Mon, 26 Mar 2018 17:03:31 imgcut.py[line:310] ERROR this is an exception message
Traceback (most recent call last):
  File "F:/BestAssistant\component\imgcut.py", line 302, in cut_img
    set_val('imgpos_lowestprice', img[use_area[0][1]:use_area[0][3], use_area[0][0]:use_area[0][2]])  # ok
IndexError: list index out of range
Mon, 26 Mar 2018 17:03:31 app_thread.py[line:113] ERROR 刷新失败
Mon, 26 Mar 2018 17:03:31 app_thread.py[line:114] ERROR this is an exception message
Traceback (most recent call last):
  File "F:/BestAssistant\component\app_thread.py", line 111, in run
    findrefresh()
  File "F:/BestAssistant\component\imgcut.py", line 324, in findrefresh
    img = cv2.cvtColor(sc, cv2.COLOR_BGR2GRAY)  # 转灰度图
cv2.error: C:\projects\opencv-python\opencv\modules\imgproc\src\color.cpp:10600: error: (-215) depth == CV_8U || depth == CV_16U || depth == CV_32F in function cv::cvtColor

Mon, 26 Mar 2018 17:03:31 imgcut.py[line:309] ERROR cut_img 这里出错
Mon, 26 Mar 2018 17:03:31 imgcut.py[line:310] ERROR this is an exception message
Traceback (most recent call last):
  File "F:/BestAssistant\component\imgcut.py", line 302, in cut_img
    set_val('imgpos_lowestprice', img[use_area[0][1]:use_area[0][3], use_area[0][0]:use_area[0][2]])  # ok
IndexError: list index out of range
Mon, 26 Mar 2018 17:03:31 app_thread.py[line:113] ERROR 刷新失败
Mon, 26 Mar 2018 17:03:31 app_thread.py[line:114] ERROR this is an exception message
Traceback (most recent call last):
  File "F:/BestAssistant\component\app_thread.py", line 111, in run
    findrefresh()
  File "F:/BestAssistant\component\imgcut.py", line 324, in findrefresh
    img = cv2.cvtColor(sc, cv2.COLOR_BGR2GRAY)  # 转灰度图
cv2.error: C:\projects\opencv-python\opencv\modules\imgproc\src\color.cpp:10600: error: (-215) depth == CV_8U || depth == CV_16U || depth == CV_32F in function cv::cvtColor

Mon, 26 Mar 2018 17:03:31 app_thread.py[line:113] ERROR 刷新失败
Mon, 26 Mar 2018 17:03:31 app_thread.py[line:114] ERROR this is an exception message
Traceback (most recent call last):
  File "F:/BestAssistant\component\app_thread.py", line 111, in run
    findrefresh()
  File "F:/BestAssistant\component\imgcut.py", line 324, in findrefresh
    img = cv2.cvtColor(sc, cv2.COLOR_BGR2GRAY)  # 转灰度图
cv2.error: C:\projects\opencv-python\opencv\modules\imgproc\src\color.cpp:10600: error: (-215) depth == CV_8U || depth == CV_16U || depth == CV_32F in function cv::cvtColor

Mon, 26 Mar 2018 17:03:31 imgcut.py[line:309] ERROR cut_img 这里出错
Mon, 26 Mar 2018 17:03:31 imgcut.py[line:310] ERROR this is an exception message
Traceback (most recent call last):
  File "F:/BestAssistant\component\imgcut.py", line 302, in cut_img
    set_val('imgpos_lowestprice', img[use_area[0][1]:use_area[0][3], use_area[0][0]:use_area[0][2]])  # ok
IndexError: list index out of range
Mon, 26 Mar 2018 17:03:31 app_thread.py[line:113] ERROR 刷新失败
Mon, 26 Mar 2018 17:03:31 app_thread.py[line:114] ERROR this is an exception message
Traceback (most recent call last):
  File "F:/BestAssistant\component\app_thread.py", line 111, in run
    findrefresh()
  File "F:/BestAssistant\component\imgcut.py", line 324, in findrefresh
    img = cv2.cvtColor(sc, cv2.COLOR_BGR2GRAY)  # 转灰度图
cv2.error: C:\projects\opencv-python\opencv\modules\imgproc\src\color.cpp:10600: error: (-215) depth == CV_8U || depth == CV_16U || depth == CV_32F in function cv::cvtColor

Mon, 26 Mar 2018 17:03:31 imgcut.py[line:309] ERROR cut_img 这里出错
Mon, 26 Mar 2018 17:03:31 imgcut.py[line:310] ERROR this is an exception message
Traceback (most recent call last):
  File "F:/BestAssistant\component\imgcut.py", line 302, in cut_img
    set_val('imgpos_lowestprice', img[use_area[0][1]:use_area[0][3], use_area[0][0]:use_area[0][2]])  # ok
IndexError: list index out of range
Mon, 26 Mar 2018 17:03:31 app_thread.py[line:113] ERROR 刷新失败
Mon, 26 Mar 2018 17:03:31 app_thread.py[line:114] ERROR this is an exception message
Traceback (most recent call last):
  File "F:/BestAssistant\component\app_thread.py", line 111, in run
    findrefresh()
  File "F:/BestAssistant\component\imgcut.py", line 324, in findrefresh
    img = cv2.cvtColor(sc, cv2.COLOR_BGR2GRAY)  # 转灰度图
cv2.error: C:\projects\opencv-python\opencv\modules\imgproc\src\color.cpp:10600: error: (-215) depth == CV_8U || depth == CV_16U || depth == CV_32F in function cv::cvtColor

Mon, 26 Mar 2018 17:03:31 app_thread.py[line:113] ERROR 刷新失败
Mon, 26 Mar 2018 17:03:31 app_thread.py[line:114] ERROR this is an exception message
Traceback (most recent call last):
  File "F:/BestAssistant\component\app_thread.py", line 111, in run
    findrefresh()
  File "F:/BestAssistant\component\imgcut.py", line 324, in findrefresh
    img = cv2.cvtColor(sc, cv2.COLOR_BGR2GRAY)  # 转灰度图
cv2.error: C:\projects\opencv-python\opencv\modules\imgproc\src\color.cpp:10600: error: (-215) depth == CV_8U || depth == CV_16U || depth == CV_32F in function cv::cvtColor

Mon, 26 Mar 2018 17:03:31 imgcut.py[line:309] ERROR cut_img 这里出错
Mon, 26 Mar 2018 17:03:31 imgcut.py[line:310] ERROR this is an exception message
Traceback (most recent call last):
  File "F:/BestAssistant\component\imgcut.py", line 302, in cut_img
    set_val('imgpos_lowestprice', img[use_area[0][1]:use_area[0][3], use_area[0][0]:use_area[0][2]])  # ok
IndexError: list index out of range
Mon, 26 Mar 2018 17:03:31 imgcut.py[line:309] ERROR cut_img 这里出错
Mon, 26 Mar 2018 17:03:31 imgcut.py[line:310] ERROR this is an exception message
Traceback (most recent call last):
  File "F:/BestAssistant\component\imgcut.py", line 302, in cut_img
    set_val('imgpos_lowestprice', img[use_area[0][1]:use_area[0][3], use_area[0][0]:use_area[0][2]])  # ok
IndexError: list index out of range
Mon, 26 Mar 2018 17:03:31 app_thread.py[line:113] ERROR 刷新失败
Mon, 26 Mar 2018 17:03:31 app_thread.py[line:114] ERROR this is an exception message
Traceback (most recent call last):
  File "F:/BestAssistant\component\app_thread.py", line 111, in run
    findrefresh()
  File "F:/BestAssistant\component\imgcut.py", line 324, in findrefresh
    img = cv2.cvtColor(sc, cv2.COLOR_BGR2GRAY)  # 转灰度图
cv2.error: C:\projects\opencv-python\opencv\modules\imgproc\src\color.cpp:10600: error: (-215) depth == CV_8U || depth == CV_16U || depth == CV_32F in function cv::cvtColor

Mon, 26 Mar 2018 17:03:32 app_thread.py[line:113] ERROR 刷新失败
Mon, 26 Mar 2018 17:03:32 app_thread.py[line:114] ERROR this is an exception message
Traceback (most recent call last):
  File "F:/BestAssistant\component\app_thread.py", line 111, in run
    findrefresh()
  File "F:/BestAssistant\component\imgcut.py", line 324, in findrefresh
    img = cv2.cvtColor(sc, cv2.COLOR_BGR2GRAY)  # 转灰度图
cv2.error: C:\projects\opencv-python\opencv\modules\imgproc\src\color.cpp:10600: error: (-215) depth == CV_8U || depth == CV_16U || depth == CV_32F in function cv::cvtColor

Mon, 26 Mar 2018 17:03:32 imgcut.py[line:309] ERROR cut_img 这里出错
Mon, 26 Mar 2018 17:03:32 imgcut.py[line:310] ERROR this is an exception message
Traceback (most recent call last):
  File "F:/BestAssistant\component\imgcut.py", line 302, in cut_img
    set_val('imgpos_lowestprice', img[use_area[0][1]:use_area[0][3], use_area[0][0]:use_area[0][2]])  # ok
IndexError: list index out of range
Mon, 26 Mar 2018 17:03:32 app_thread.py[line:113] ERROR 刷新失败
Mon, 26 Mar 2018 17:03:32 app_thread.py[line:114] ERROR this is an exception message
Traceback (most recent call last):
  File "F:/BestAssistant\component\app_thread.py", line 111, in run
    findrefresh()
  File "F:/BestAssistant\component\imgcut.py", line 324, in findrefresh
    img = cv2.cvtColor(sc, cv2.COLOR_BGR2GRAY)  # 转灰度图
cv2.error: C:\projects\opencv-python\opencv\modules\imgproc\src\color.cpp:10600: error: (-215) depth == CV_8U || depth == CV_16U || depth == CV_32F in function cv::cvtColor

Mon, 26 Mar 2018 17:03:32 imgcut.py[line:309] ERROR cut_img 这里出错
Mon, 26 Mar 2018 17:03:32 imgcut.py[line:310] ERROR this is an exception message
Traceback (most recent call last):
  File "F:/BestAssistant\component\imgcut.py", line 302, in cut_img
    set_val('imgpos_lowestprice', img[use_area[0][1]:use_area[0][3], use_area[0][0]:use_area[0][2]])  # ok
IndexError: list index out of range
Mon, 26 Mar 2018 17:03:32 app_thread.py[line:113] ERROR 刷新失败
Mon, 26 Mar 2018 17:03:32 app_thread.py[line:114] ERROR this is an exception message
Traceback (most recent call last):
  File "F:/BestAssistant\component\app_thread.py", line 111, in run
    findrefresh()
  File "F:/BestAssistant\component\imgcut.py", line 324, in findrefresh
    img = cv2.cvtColor(sc, cv2.COLOR_BGR2GRAY)  # 转灰度图
cv2.error: C:\projects\opencv-python\opencv\modules\imgproc\src\color.cpp:10600: error: (-215) depth == CV_8U || depth == CV_16U || depth == CV_32F in function cv::cvtColor

Mon, 26 Mar 2018 17:03:32 imgcut.py[line:309] ERROR cut_img 这里出错
Mon, 26 Mar 2018 17:03:32 imgcut.py[line:310] ERROR this is an exception message
Traceback (most recent call last):
  File "F:/BestAssistant\component\imgcut.py", line 302, in cut_img
    set_val('imgpos_lowestprice', img[use_area[0][1]:use_area[0][3], use_area[0][0]:use_area[0][2]])  # ok
IndexError: list index out of range
Mon, 26 Mar 2018 17:03:32 app_thread.py[line:113] ERROR 刷新失败
Mon, 26 Mar 2018 17:03:32 app_thread.py[line:114] ERROR this is an exception message
Traceback (most recent call last):
  File "F:/BestAssistant\component\app_thread.py", line 111, in run
    findrefresh()
  File "F:/BestAssistant\component\imgcut.py", line 324, in findrefresh
    img = cv2.cvtColor(sc, cv2.COLOR_BGR2GRAY)  # 转灰度图
cv2.error: C:\projects\opencv-python\opencv\modules\imgproc\src\color.cpp:10600: error: (-215) depth == CV_8U || depth == CV_16U || depth == CV_32F in function cv::cvtColor

Mon, 26 Mar 2018 17:03:32 imgcut.py[line:309] ERROR cut_img 这里出错
Mon, 26 Mar 2018 17:03:32 imgcut.py[line:310] ERROR this is an exception message
Traceback (most recent call last):
  File "F:/BestAssistant\component\imgcut.py", line 302, in cut_img
    set_val('imgpos_lowestprice', img[use_area[0][1]:use_area[0][3], use_area[0][0]:use_area[0][2]])  # ok
IndexError: list index out of range
Mon, 26 Mar 2018 17:03:32 app_thread.py[line:113] ERROR 刷新失败
Mon, 26 Mar 2018 17:03:32 app_thread.py[line:114] ERROR this is an exception message
Traceback (most recent call last):
  File "F:/BestAssistant\component\app_thread.py", line 111, in run
    findrefresh()
  File "F:/BestAssistant\component\imgcut.py", line 324, in findrefresh
    img = cv2.cvtColor(sc, cv2.COLOR_BGR2GRAY)  # 转灰度图
cv2.error: C:\projects\opencv-python\opencv\modules\imgproc\src\color.cpp:10600: error: (-215) depth == CV_8U || depth == CV_16U || depth == CV_32F in function cv::cvtColor

Mon, 26 Mar 2018 17:03:32 imgcut.py[line:309] ERROR cut_img 这里出错
Mon, 26 Mar 2018 17:03:32 imgcut.py[line:310] ERROR this is an exception message
Traceback (most recent call last):
  File "F:/BestAssistant\component\imgcut.py", line 302, in cut_img
    set_val('imgpos_lowestprice', img[use_area[0][1]:use_area[0][3], use_area[0][0]:use_area[0][2]])  # ok
IndexError: list index out of range
Mon, 26 Mar 2018 17:03:32 app_thread.py[line:113] ERROR 刷新失败
Mon, 26 Mar 2018 17:03:32 app_thread.py[line:114] ERROR this is an exception message
Traceback (most recent call last):
  File "F:/BestAssistant\component\app_thread.py", line 111, in run
    findrefresh()
  File "F:/BestAssistant\component\imgcut.py", line 324, in findrefresh
    img = cv2.cvtColor(sc, cv2.COLOR_BGR2GRAY)  # 转灰度图
cv2.error: C:\projects\opencv-python\opencv\modules\imgproc\src\color.cpp:10600: error: (-215) depth == CV_8U || depth == CV_16U || depth == CV_32F in function cv::cvtColor

Mon, 26 Mar 2018 17:03:32 app_thread.py[line:113] ERROR 刷新失败
Mon, 26 Mar 2018 17:03:32 app_thread.py[line:114] ERROR this is an exception message
Traceback (most recent call last):
  File "F:/BestAssistant\component\app_thread.py", line 111, in run
    findrefresh()
  File "F:/BestAssistant\component\imgcut.py", line 324, in findrefresh
    img = cv2.cvtColor(sc, cv2.COLOR_BGR2GRAY)  # 转灰度图
cv2.error: C:\projects\opencv-python\opencv\modules\imgproc\src\color.cpp:10600: error: (-215) depth == CV_8U || depth == CV_16U || depth == CV_32F in function cv::cvtColor

Mon, 26 Mar 2018 17:03:32 imgcut.py[line:309] ERROR cut_img 这里出错
Mon, 26 Mar 2018 17:03:32 app_thread.py[line:113] ERROR 刷新失败
Mon, 26 Mar 2018 17:03:32 imgcut.py[line:310] ERROR this is an exception message
Traceback (most recent call last):
  File "F:/BestAssistant\component\imgcut.py", line 302, in cut_img
    set_val('imgpos_lowestprice', img[use_area[0][1]:use_area[0][3], use_area[0][0]:use_area[0][2]])  # ok
IndexError: list index out of range
Mon, 26 Mar 2018 17:03:32 app_thread.py[line:114] ERROR this is an exception message
Traceback (most recent call last):
  File "F:/BestAssistant\component\app_thread.py", line 111, in run
    findrefresh()
  File "F:/BestAssistant\component\imgcut.py", line 324, in findrefresh
    img = cv2.cvtColor(sc, cv2.COLOR_BGR2GRAY)  # 转灰度图
cv2.error: C:\projects\opencv-python\opencv\modules\imgproc\src\color.cpp:10600: error: (-215) depth == CV_8U || depth == CV_16U || depth == CV_32F in function cv::cvtColor

Mon, 26 Mar 2018 17:03:32 app_thread.py[line:113] ERROR 刷新失败
Mon, 26 Mar 2018 17:03:32 app_thread.py[line:114] ERROR this is an exception message
Traceback (most recent call last):
  File "F:/BestAssistant\component\app_thread.py", line 111, in run
    findrefresh()
  File "F:/BestAssistant\component\imgcut.py", line 324, in findrefresh
    img = cv2.cvtColor(sc, cv2.COLOR_BGR2GRAY)  # 转灰度图
cv2.error: C:\projects\opencv-python\opencv\modules\imgproc\src\color.cpp:10600: error: (-215) depth == CV_8U || depth == CV_16U || depth == CV_32F in function cv::cvtColor

Mon, 26 Mar 2018 17:03:32 imgcut.py[line:309] ERROR cut_img 这里出错
Mon, 26 Mar 2018 17:03:32 imgcut.py[line:310] ERROR this is an exception message
Traceback (most recent call last):
  File "F:/BestAssistant\component\imgcut.py", line 302, in cut_img
    set_val('imgpos_lowestprice', img[use_area[0][1]:use_area[0][3], use_area[0][0]:use_area[0][2]])  # ok
IndexError: list index out of range
Mon, 26 Mar 2018 17:03:32 app_thread.py[line:113] ERROR 刷新失败
Mon, 26 Mar 2018 17:03:32 app_thread.py[line:114] ERROR this is an exception message
Traceback (most recent call last):
  File "F:/BestAssistant\component\app_thread.py", line 111, in run
    findrefresh()
  File "F:/BestAssistant\component\imgcut.py", line 324, in findrefresh
    img = cv2.cvtColor(sc, cv2.COLOR_BGR2GRAY)  # 转灰度图
cv2.error: C:\projects\opencv-python\opencv\modules\imgproc\src\color.cpp:10600: error: (-215) depth == CV_8U || depth == CV_16U || depth == CV_32F in function cv::cvtColor

Mon, 26 Mar 2018 17:03:32 imgcut.py[line:309] ERROR cut_img 这里出错
Mon, 26 Mar 2018 17:03:32 imgcut.py[line:310] ERROR this is an exception message
Traceback (most recent call last):
  File "F:/BestAssistant\component\imgcut.py", line 302, in cut_img
    set_val('imgpos_lowestprice', img[use_area[0][1]:use_area[0][3], use_area[0][0]:use_area[0][2]])  # ok
IndexError: list index out of range
Mon, 26 Mar 2018 17:03:32 app_thread.py[line:113] ERROR 刷新失败
Mon, 26 Mar 2018 17:03:32 app_thread.py[line:114] ERROR this is an exception message
Traceback (most recent call last):
  File "F:/BestAssistant\component\app_thread.py", line 111, in run
    findrefresh()
  File "F:/BestAssistant\component\imgcut.py", line 324, in findrefresh
    img = cv2.cvtColor(sc, cv2.COLOR_BGR2GRAY)  # 转灰度图
cv2.error: C:\projects\opencv-python\opencv\modules\imgproc\src\color.cpp:10600: error: (-215) depth == CV_8U || depth == CV_16U || depth == CV_32F in function cv::cvtColor

Mon, 26 Mar 2018 17:03:32 imgcut.py[line:309] ERROR cut_img 这里出错
Mon, 26 Mar 2018 17:03:32 imgcut.py[line:310] ERROR this is an exception message
Traceback (most recent call last):
  File "F:/BestAssistant\component\imgcut.py", line 302, in cut_img
    set_val('imgpos_lowestprice', img[use_area[0][1]:use_area[0][3], use_area[0][0]:use_area[0][2]])  # ok
IndexError: list index out of range
Mon, 26 Mar 2018 17:03:32 app_thread.py[line:113] ERROR 刷新失败
Mon, 26 Mar 2018 17:03:32 app_thread.py[line:114] ERROR this is an exception message
Traceback (most recent call last):
  File "F:/BestAssistant\component\app_thread.py", line 111, in run
    findrefresh()
  File "F:/BestAssistant\component\imgcut.py", line 324, in findrefresh
    img = cv2.cvtColor(sc, cv2.COLOR_BGR2GRAY)  # 转灰度图
cv2.error: C:\projects\opencv-python\opencv\modules\imgproc\src\color.cpp:10600: error: (-215) depth == CV_8U || depth == CV_16U || depth == CV_32F in function cv::cvtColor

Mon, 26 Mar 2018 17:03:32 imgcut.py[line:309] ERROR cut_img 这里出错
Mon, 26 Mar 2018 17:03:32 imgcut.py[line:310] ERROR this is an exception message
Traceback (most recent call last):
  File "F:/BestAssistant\component\imgcut.py", line 302, in cut_img
    set_val('imgpos_lowestprice', img[use_area[0][1]:use_area[0][3], use_area[0][0]:use_area[0][2]])  # ok
IndexError: list index out of range
Mon, 26 Mar 2018 17:03:32 app_thread.py[line:113] ERROR 刷新失败
Mon, 26 Mar 2018 17:03:32 app_thread.py[line:114] ERROR this is an exception message
Traceback (most recent call last):
  File "F:/BestAssistant\component\app_thread.py", line 111, in run
    findrefresh()
  File "F:/BestAssistant\component\imgcut.py", line 324, in findrefresh
    img = cv2.cvtColor(sc, cv2.COLOR_BGR2GRAY)  # 转灰度图
cv2.error: C:\projects\opencv-python\opencv\modules\imgproc\src\color.cpp:10600: error: (-215) depth == CV_8U || depth == CV_16U || depth == CV_32F in function cv::cvtColor

Mon, 26 Mar 2018 17:03:32 imgcut.py[line:309] ERROR cut_img 这里出错
Mon, 26 Mar 2018 17:03:32 imgcut.py[line:310] ERROR this is an exception message
Traceback (most recent call last):
  File "F:/BestAssistant\component\imgcut.py", line 302, in cut_img
    set_val('imgpos_lowestprice', img[use_area[0][1]:use_area[0][3], use_area[0][0]:use_area[0][2]])  # ok
IndexError: list index out of range
Mon, 26 Mar 2018 17:03:32 app_thread.py[line:113] ERROR 刷新失败
Mon, 26 Mar 2018 17:03:32 app_thread.py[line:114] ERROR this is an exception message
Traceback (most recent call last):
  File "F:/BestAssistant\component\app_thread.py", line 111, in run
    findrefresh()
  File "F:/BestAssistant\component\imgcut.py", line 324, in findrefresh
    img = cv2.cvtColor(sc, cv2.COLOR_BGR2GRAY)  # 转灰度图
cv2.error: C:\projects\opencv-python\opencv\modules\imgproc\src\color.cpp:10600: error: (-215) depth == CV_8U || depth == CV_16U || depth == CV_32F in function cv::cvtColor

Mon, 26 Mar 2018 17:03:32 app_thread.py[line:113] ERROR 刷新失败
Mon, 26 Mar 2018 17:03:32 app_thread.py[line:114] ERROR this is an exception message
Traceback (most recent call last):
  File "F:/BestAssistant\component\app_thread.py", line 111, in run
    findrefresh()
  File "F:/BestAssistant\component\imgcut.py", line 324, in findrefresh
    img = cv2.cvtColor(sc, cv2.COLOR_BGR2GRAY)  # 转灰度图
cv2.error: C:\projects\opencv-python\opencv\modules\imgproc\src\color.cpp:10600: error: (-215) depth == CV_8U || depth == CV_16U || depth == CV_32F in function cv::cvtColor

Mon, 26 Mar 2018 17:03:33 imgcut.py[line:309] ERROR cut_img 这里出错
Mon, 26 Mar 2018 17:03:33 imgcut.py[line:310] ERROR this is an exception message
Traceback (most recent call last):
  File "F:/BestAssistant\component\imgcut.py", line 302, in cut_img
    set_val('imgpos_lowestprice', img[use_area[0][1]:use_area[0][3], use_area[0][0]:use_area[0][2]])  # ok
IndexError: list index out of range
Mon, 26 Mar 2018 17:03:33 app_thread.py[line:113] ERROR 刷新失败
Mon, 26 Mar 2018 17:03:33 app_thread.py[line:114] ERROR this is an exception message
Traceback (most recent call last):
  File "F:/BestAssistant\component\app_thread.py", line 111, in run
    findrefresh()
  File "F:/BestAssistant\component\imgcut.py", line 324, in findrefresh
    img = cv2.cvtColor(sc, cv2.COLOR_BGR2GRAY)  # 转灰度图
cv2.error: C:\projects\opencv-python\opencv\modules\imgproc\src\color.cpp:10600: error: (-215) depth == CV_8U || depth == CV_16U || depth == CV_32F in function cv::cvtColor

Mon, 26 Mar 2018 17:03:33 app_thread.py[line:113] ERROR 刷新失败
Mon, 26 Mar 2018 17:03:33 imgcut.py[line:309] ERROR cut_img 这里出错
Mon, 26 Mar 2018 17:03:33 app_thread.py[line:114] ERROR this is an exception message
Traceback (most recent call last):
  File "F:/BestAssistant\component\app_thread.py", line 111, in run
    findrefresh()
  File "F:/BestAssistant\component\imgcut.py", line 324, in findrefresh
    img = cv2.cvtColor(sc, cv2.COLOR_BGR2GRAY)  # 转灰度图
cv2.error: C:\projects\opencv-python\opencv\modules\imgproc\src\color.cpp:10600: error: (-215) depth == CV_8U || depth == CV_16U || depth == CV_32F in function cv::cvtColor

Mon, 26 Mar 2018 17:03:33 imgcut.py[line:310] ERROR this is an exception message
Traceback (most recent call last):
  File "F:/BestAssistant\component\imgcut.py", line 302, in cut_img
    set_val('imgpos_lowestprice', img[use_area[0][1]:use_area[0][3], use_area[0][0]:use_area[0][2]])  # ok
IndexError: list index out of range
Mon, 26 Mar 2018 17:03:33 app_thread.py[line:113] ERROR 刷新失败
Mon, 26 Mar 2018 17:03:33 app_thread.py[line:114] ERROR this is an exception message
Traceback (most recent call last):
  File "F:/BestAssistant\component\app_thread.py", line 111, in run
    findrefresh()
  File "F:/BestAssistant\component\imgcut.py", line 324, in findrefresh
    img = cv2.cvtColor(sc, cv2.COLOR_BGR2GRAY)  # 转灰度图
cv2.error: C:\projects\opencv-python\opencv\modules\imgproc\src\color.cpp:10600: error: (-215) depth == CV_8U || depth == CV_16U || depth == CV_32F in function cv::cvtColor

Mon, 26 Mar 2018 17:03:33 imgcut.py[line:309] ERROR cut_img 这里出错
Mon, 26 Mar 2018 17:03:33 imgcut.py[line:310] ERROR this is an exception message
Traceback (most recent call last):
  File "F:/BestAssistant\component\imgcut.py", line 302, in cut_img
    set_val('imgpos_lowestprice', img[use_area[0][1]:use_area[0][3], use_area[0][0]:use_area[0][2]])  # ok
IndexError: list index out of range
Mon, 26 Mar 2018 17:03:33 app_thread.py[line:113] ERROR 刷新失败
Mon, 26 Mar 2018 17:03:33 app_thread.py[line:114] ERROR this is an exception message
Traceback (most recent call last):
  File "F:/BestAssistant\component\app_thread.py", line 111, in run
    findrefresh()
  File "F:/BestAssistant\component\imgcut.py", line 324, in findrefresh
    img = cv2.cvtColor(sc, cv2.COLOR_BGR2GRAY)  # 转灰度图
cv2.error: C:\projects\opencv-python\opencv\modules\imgproc\src\color.cpp:10600: error: (-215) depth == CV_8U || depth == CV_16U || depth == CV_32F in function cv::cvtColor

Mon, 26 Mar 2018 17:03:33 imgcut.py[line:309] ERROR cut_img 这里出错
Mon, 26 Mar 2018 17:03:33 imgcut.py[line:310] ERROR this is an exception message
Traceback (most recent call last):
  File "F:/BestAssistant\component\imgcut.py", line 302, in cut_img
    set_val('imgpos_lowestprice', img[use_area[0][1]:use_area[0][3], use_area[0][0]:use_area[0][2]])  # ok
IndexError: list index out of range
Mon, 26 Mar 2018 17:03:33 app_thread.py[line:113] ERROR 刷新失败
Mon, 26 Mar 2018 17:03:33 app_thread.py[line:114] ERROR this is an exception message
Traceback (most recent call last):
  File "F:/BestAssistant\component\app_thread.py", line 111, in run
    findrefresh()
  File "F:/BestAssistant\component\imgcut.py", line 324, in findrefresh
    img = cv2.cvtColor(sc, cv2.COLOR_BGR2GRAY)  # 转灰度图
cv2.error: C:\projects\opencv-python\opencv\modules\imgproc\src\color.cpp:10600: error: (-215) depth == CV_8U || depth == CV_16U || depth == CV_32F in function cv::cvtColor

Mon, 26 Mar 2018 17:03:33 imgcut.py[line:309] ERROR cut_img 这里出错
Mon, 26 Mar 2018 17:03:33 imgcut.py[line:310] ERROR this is an exception message
Traceback (most recent call last):
  File "F:/BestAssistant\component\imgcut.py", line 302, in cut_img
    set_val('imgpos_lowestprice', img[use_area[0][1]:use_area[0][3], use_area[0][0]:use_area[0][2]])  # ok
IndexError: list index out of range
Mon, 26 Mar 2018 17:03:33 app_thread.py[line:113] ERROR 刷新失败
Mon, 26 Mar 2018 17:03:33 app_thread.py[line:114] ERROR this is an exception message
Traceback (most recent call last):
  File "F:/BestAssistant\component\app_thread.py", line 111, in run
    findrefresh()
  File "F:/BestAssistant\component\imgcut.py", line 324, in findrefresh
    img = cv2.cvtColor(sc, cv2.COLOR_BGR2GRAY)  # 转灰度图
cv2.error: C:\projects\opencv-python\opencv\modules\imgproc\src\color.cpp:10600: error: (-215) depth == CV_8U || depth == CV_16U || depth == CV_32F in function cv::cvtColor

Mon, 26 Mar 2018 17:03:33 imgcut.py[line:309] ERROR cut_img 这里出错
Mon, 26 Mar 2018 17:03:33 imgcut.py[line:310] ERROR this is an exception message
Traceback (most recent call last):
  File "F:/BestAssistant\component\imgcut.py", line 302, in cut_img
    set_val('imgpos_lowestprice', img[use_area[0][1]:use_area[0][3], use_area[0][0]:use_area[0][2]])  # ok
IndexError: list index out of range
Mon, 26 Mar 2018 17:03:33 app_thread.py[line:113] ERROR 刷新失败
Mon, 26 Mar 2018 17:03:33 app_thread.py[line:114] ERROR this is an exception message
Traceback (most recent call last):
  File "F:/BestAssistant\component\app_thread.py", line 111, in run
    findrefresh()
  File "F:/BestAssistant\component\imgcut.py", line 324, in findrefresh
    img = cv2.cvtColor(sc, cv2.COLOR_BGR2GRAY)  # 转灰度图
cv2.error: C:\projects\opencv-python\opencv\modules\imgproc\src\color.cpp:10600: error: (-215) depth == CV_8U || depth == CV_16U || depth == CV_32F in function cv::cvtColor

Mon, 26 Mar 2018 17:03:33 app_thread.py[line:113] ERROR 刷新失败
Mon, 26 Mar 2018 17:03:33 app_thread.py[line:114] ERROR this is an exception message
Traceback (most recent call last):
  File "F:/BestAssistant\component\app_thread.py", line 111, in run
    findrefresh()
  File "F:/BestAssistant\component\imgcut.py", line 324, in findrefresh
    img = cv2.cvtColor(sc, cv2.COLOR_BGR2GRAY)  # 转灰度图
cv2.error: C:\projects\opencv-python\opencv\modules\imgproc\src\color.cpp:10600: error: (-215) depth == CV_8U || depth == CV_16U || depth == CV_32F in function cv::cvtColor

Mon, 26 Mar 2018 17:03:33 imgcut.py[line:309] ERROR cut_img 这里出错
Mon, 26 Mar 2018 17:03:33 imgcut.py[line:310] ERROR this is an exception message
Traceback (most recent call last):
  File "F:/BestAssistant\component\imgcut.py", line 302, in cut_img
    set_val('imgpos_lowestprice', img[use_area[0][1]:use_area[0][3], use_area[0][0]:use_area[0][2]])  # ok
IndexError: list index out of range
Mon, 26 Mar 2018 17:03:33 imgcut.py[line:309] ERROR cut_img 这里出错
Mon, 26 Mar 2018 17:03:33 imgcut.py[line:310] ERROR this is an exception message
Traceback (most recent call last):
  File "F:/BestAssistant\component\imgcut.py", line 302, in cut_img
    set_val('imgpos_lowestprice', img[use_area[0][1]:use_area[0][3], use_area[0][0]:use_area[0][2]])  # ok
IndexError: list index out of range
Mon, 26 Mar 2018 17:03:33 app_thread.py[line:113] ERROR 刷新失败
Mon, 26 Mar 2018 17:03:33 app_thread.py[line:114] ERROR this is an exception message
Traceback (most recent call last):
  File "F:/BestAssistant\component\app_thread.py", line 111, in run
    findrefresh()
  File "F:/BestAssistant\component\imgcut.py", line 324, in findrefresh
    img = cv2.cvtColor(sc, cv2.COLOR_BGR2GRAY)  # 转灰度图
cv2.error: C:\projects\opencv-python\opencv\modules\imgproc\src\color.cpp:10600: error: (-215) depth == CV_8U || depth == CV_16U || depth == CV_32F in function cv::cvtColor

Mon, 26 Mar 2018 17:03:33 imgcut.py[line:309] ERROR cut_img 这里出错
Mon, 26 Mar 2018 17:03:33 imgcut.py[line:310] ERROR this is an exception message
Traceback (most recent call last):
  File "F:/BestAssistant\component\imgcut.py", line 302, in cut_img
    set_val('imgpos_lowestprice', img[use_area[0][1]:use_area[0][3], use_area[0][0]:use_area[0][2]])  # ok
IndexError: list index out of range
Mon, 26 Mar 2018 17:03:33 app_thread.py[line:113] ERROR 刷新失败
Mon, 26 Mar 2018 17:03:33 app_thread.py[line:114] ERROR this is an exception message
Traceback (most recent call last):
  File "F:/BestAssistant\component\app_thread.py", line 111, in run
    findrefresh()
  File "F:/BestAssistant\component\imgcut.py", line 324, in findrefresh
    img = cv2.cvtColor(sc, cv2.COLOR_BGR2GRAY)  # 转灰度图
cv2.error: C:\projects\opencv-python\opencv\modules\imgproc\src\color.cpp:10600: error: (-215) depth == CV_8U || depth == CV_16U || depth == CV_32F in function cv::cvtColor

Mon, 26 Mar 2018 17:03:33 imgcut.py[line:309] ERROR cut_img 这里出错
Mon, 26 Mar 2018 17:03:33 imgcut.py[line:310] ERROR this is an exception message
Traceback (most recent call last):
  File "F:/BestAssistant\component\imgcut.py", line 302, in cut_img
    set_val('imgpos_lowestprice', img[use_area[0][1]:use_area[0][3], use_area[0][0]:use_area[0][2]])  # ok
IndexError: list index out of range
Mon, 26 Mar 2018 17:03:33 app_thread.py[line:113] ERROR 刷新失败
Mon, 26 Mar 2018 17:03:33 app_thread.py[line:114] ERROR this is an exception message
Traceback (most recent call last):
  File "F:/BestAssistant\component\app_thread.py", line 111, in run
    findrefresh()
  File "F:/BestAssistant\component\imgcut.py", line 324, in findrefresh
    img = cv2.cvtColor(sc, cv2.COLOR_BGR2GRAY)  # 转灰度图
cv2.error: C:\projects\opencv-python\opencv\modules\imgproc\src\color.cpp:10600: error: (-215) depth == CV_8U || depth == CV_16U || depth == CV_32F in function cv::cvtColor

Mon, 26 Mar 2018 17:03:33 imgcut.py[line:309] ERROR cut_img 这里出错
Mon, 26 Mar 2018 17:03:33 imgcut.py[line:310] ERROR this is an exception message
Traceback (most recent call last):
  File "F:/BestAssistant\component\imgcut.py", line 302, in cut_img
    set_val('imgpos_lowestprice', img[use_area[0][1]:use_area[0][3], use_area[0][0]:use_area[0][2]])  # ok
IndexError: list index out of range
Mon, 26 Mar 2018 17:03:33 app_thread.py[line:113] ERROR 刷新失败
Mon, 26 Mar 2018 17:03:33 app_thread.py[line:114] ERROR this is an exception message
Traceback (most recent call last):
  File "F:/BestAssistant\component\app_thread.py", line 111, in run
    findrefresh()
  File "F:/BestAssistant\component\imgcut.py", line 324, in findrefresh
    img = cv2.cvtColor(sc, cv2.COLOR_BGR2GRAY)  # 转灰度图
cv2.error: C:\projects\opencv-python\opencv\modules\imgproc\src\color.cpp:10600: error: (-215) depth == CV_8U || depth == CV_16U || depth == CV_32F in function cv::cvtColor

Mon, 26 Mar 2018 17:03:33 imgcut.py[line:309] ERROR cut_img 这里出错
Mon, 26 Mar 2018 17:03:33 imgcut.py[line:310] ERROR this is an exception message
Traceback (most recent call last):
  File "F:/BestAssistant\component\imgcut.py", line 302, in cut_img
    set_val('imgpos_lowestprice', img[use_area[0][1]:use_area[0][3], use_area[0][0]:use_area[0][2]])  # ok
IndexError: list index out of range
Mon, 26 Mar 2018 17:03:33 app_thread.py[line:113] ERROR 刷新失败
Mon, 26 Mar 2018 17:03:33 app_thread.py[line:114] ERROR this is an exception message
Traceback (most recent call last):
  File "F:/BestAssistant\component\app_thread.py", line 111, in run
    findrefresh()
  File "F:/BestAssistant\component\imgcut.py", line 324, in findrefresh
    img = cv2.cvtColor(sc, cv2.COLOR_BGR2GRAY)  # 转灰度图
cv2.error: C:\projects\opencv-python\opencv\modules\imgproc\src\color.cpp:10600: error: (-215) depth == CV_8U || depth == CV_16U || depth == CV_32F in function cv::cvtColor

Mon, 26 Mar 2018 17:03:33 imgcut.py[line:309] ERROR cut_img 这里出错
Mon, 26 Mar 2018 17:03:33 imgcut.py[line:310] ERROR this is an exception message
Traceback (most recent call last):
  File "F:/BestAssistant\component\imgcut.py", line 302, in cut_img
    set_val('imgpos_lowestprice', img[use_area[0][1]:use_area[0][3], use_area[0][0]:use_area[0][2]])  # ok
IndexError: list index out of range
Mon, 26 Mar 2018 17:03:34 app_thread.py[line:113] ERROR 刷新失败
Mon, 26 Mar 2018 17:03:34 app_thread.py[line:114] ERROR this is an exception message
Traceback (most recent call last):
  File "F:/BestAssistant\component\app_thread.py", line 111, in run
    findrefresh()
  File "F:/BestAssistant\component\imgcut.py", line 324, in findrefresh
    img = cv2.cvtColor(sc, cv2.COLOR_BGR2GRAY)  # 转灰度图
cv2.error: C:\projects\opencv-python\opencv\modules\imgproc\src\color.cpp:10600: error: (-215) depth == CV_8U || depth == CV_16U || depth == CV_32F in function cv::cvtColor

Mon, 26 Mar 2018 17:03:34 imgcut.py[line:309] ERROR cut_img 这里出错
Mon, 26 Mar 2018 17:03:34 imgcut.py[line:310] ERROR this is an exception message
Traceback (most recent call last):
  File "F:/BestAssistant\component\imgcut.py", line 302, in cut_img
    set_val('imgpos_lowestprice', img[use_area[0][1]:use_area[0][3], use_area[0][0]:use_area[0][2]])  # ok
IndexError: list index out of range
Mon, 26 Mar 2018 17:03:34 imgcut.py[line:309] ERROR cut_img 这里出错
Mon, 26 Mar 2018 17:03:34 imgcut.py[line:310] ERROR this is an exception message
Traceback (most recent call last):
  File "F:/BestAssistant\component\imgcut.py", line 302, in cut_img
    set_val('imgpos_lowestprice', img[use_area[0][1]:use_area[0][3], use_area[0][0]:use_area[0][2]])  # ok
IndexError: list index out of range
Mon, 26 Mar 2018 17:03:34 app_thread.py[line:113] ERROR 刷新失败
Mon, 26 Mar 2018 17:03:34 app_thread.py[line:114] ERROR this is an exception message
Traceback (most recent call last):
  File "F:/BestAssistant\component\app_thread.py", line 111, in run
    findrefresh()
  File "F:/BestAssistant\component\imgcut.py", line 324, in findrefresh
    img = cv2.cvtColor(sc, cv2.COLOR_BGR2GRAY)  # 转灰度图
cv2.error: C:\projects\opencv-python\opencv\modules\imgproc\src\color.cpp:10600: error: (-215) depth == CV_8U || depth == CV_16U || depth == CV_32F in function cv::cvtColor

Mon, 26 Mar 2018 17:03:34 app_thread.py[line:113] ERROR 刷新失败
Mon, 26 Mar 2018 17:03:34 app_thread.py[line:114] ERROR this is an exception message
Traceback (most recent call last):
  File "F:/BestAssistant\component\app_thread.py", line 111, in run
    findrefresh()
  File "F:/BestAssistant\component\imgcut.py", line 324, in findrefresh
    img = cv2.cvtColor(sc, cv2.COLOR_BGR2GRAY)  # 转灰度图
cv2.error: C:\projects\opencv-python\opencv\modules\imgproc\src\color.cpp:10600: error: (-215) depth == CV_8U || depth == CV_16U || depth == CV_32F in function cv::cvtColor

Mon, 26 Mar 2018 17:03:34 imgcut.py[line:309] ERROR cut_img 这里出错
Mon, 26 Mar 2018 17:03:34 imgcut.py[line:310] ERROR this is an exception message
Traceback (most recent call last):
  File "F:/BestAssistant\component\imgcut.py", line 302, in cut_img
    set_val('imgpos_lowestprice', img[use_area[0][1]:use_area[0][3], use_area[0][0]:use_area[0][2]])  # ok
IndexError: list index out of range
Mon, 26 Mar 2018 17:03:34 app_thread.py[line:113] ERROR 刷新失败
Mon, 26 Mar 2018 17:03:34 app_thread.py[line:114] ERROR this is an exception message
Traceback (most recent call last):
  File "F:/BestAssistant\component\app_thread.py", line 111, in run
    findrefresh()
  File "F:/BestAssistant\component\imgcut.py", line 324, in findrefresh
    img = cv2.cvtColor(sc, cv2.COLOR_BGR2GRAY)  # 转灰度图
cv2.error: C:\projects\opencv-python\opencv\modules\imgproc\src\color.cpp:10600: error: (-215) depth == CV_8U || depth == CV_16U || depth == CV_32F in function cv::cvtColor

Mon, 26 Mar 2018 17:03:34 imgcut.py[line:309] ERROR cut_img 这里出错
Mon, 26 Mar 2018 17:03:34 imgcut.py[line:310] ERROR this is an exception message
Traceback (most recent call last):
  File "F:/BestAssistant\component\imgcut.py", line 302, in cut_img
    set_val('imgpos_lowestprice', img[use_area[0][1]:use_area[0][3], use_area[0][0]:use_area[0][2]])  # ok
IndexError: list index out of range
Mon, 26 Mar 2018 17:03:34 app_thread.py[line:113] ERROR 刷新失败
Mon, 26 Mar 2018 17:03:34 app_thread.py[line:114] ERROR this is an exception message
Traceback (most recent call last):
  File "F:/BestAssistant\component\app_thread.py", line 111, in run
    findrefresh()
  File "F:/BestAssistant\component\imgcut.py", line 324, in findrefresh
    img = cv2.cvtColor(sc, cv2.COLOR_BGR2GRAY)  # 转灰度图
cv2.error: C:\projects\opencv-python\opencv\modules\imgproc\src\color.cpp:10600: error: (-215) depth == CV_8U || depth == CV_16U || depth == CV_32F in function cv::cvtColor

Mon, 26 Mar 2018 17:03:34 imgcut.py[line:309] ERROR cut_img 这里出错
Mon, 26 Mar 2018 17:03:34 imgcut.py[line:310] ERROR this is an exception message
Traceback (most recent call last):
  File "F:/BestAssistant\component\imgcut.py", line 302, in cut_img
    set_val('imgpos_lowestprice', img[use_area[0][1]:use_area[0][3], use_area[0][0]:use_area[0][2]])  # ok
IndexError: list index out of range
Mon, 26 Mar 2018 17:03:34 app_thread.py[line:113] ERROR 刷新失败
Mon, 26 Mar 2018 17:03:34 app_thread.py[line:114] ERROR this is an exception message
Traceback (most recent call last):
  File "F:/BestAssistant\component\app_thread.py", line 111, in run
    findrefresh()
  File "F:/BestAssistant\component\imgcut.py", line 324, in findrefresh
    img = cv2.cvtColor(sc, cv2.COLOR_BGR2GRAY)  # 转灰度图
cv2.error: C:\projects\opencv-python\opencv\modules\imgproc\src\color.cpp:10600: error: (-215) depth == CV_8U || depth == CV_16U || depth == CV_32F in function cv::cvtColor

Mon, 26 Mar 2018 17:03:34 imgcut.py[line:309] ERROR cut_img 这里出错
Mon, 26 Mar 2018 17:03:34 imgcut.py[line:310] ERROR this is an exception message
Traceback (most recent call last):
  File "F:/BestAssistant\component\imgcut.py", line 302, in cut_img
    set_val('imgpos_lowestprice', img[use_area[0][1]:use_area[0][3], use_area[0][0]:use_area[0][2]])  # ok
IndexError: list index out of range
Mon, 26 Mar 2018 17:03:34 imgcut.py[line:309] ERROR cut_img 这里出错
Mon, 26 Mar 2018 17:03:34 imgcut.py[line:310] ERROR this is an exception message
Traceback (most recent call last):
  File "F:/BestAssistant\component\imgcut.py", line 302, in cut_img
    set_val('imgpos_lowestprice', img[use_area[0][1]:use_area[0][3], use_area[0][0]:use_area[0][2]])  # ok
IndexError: list index out of range
Mon, 26 Mar 2018 17:03:34 app_thread.py[line:113] ERROR 刷新失败
Mon, 26 Mar 2018 17:03:34 app_thread.py[line:114] ERROR this is an exception message
Traceback (most recent call last):
  File "F:/BestAssistant\component\app_thread.py", line 111, in run
    findrefresh()
  File "F:/BestAssistant\component\imgcut.py", line 324, in findrefresh
    img = cv2.cvtColor(sc, cv2.COLOR_BGR2GRAY)  # 转灰度图
cv2.error: C:\projects\opencv-python\opencv\modules\imgproc\src\color.cpp:10600: error: (-215) depth == CV_8U || depth == CV_16U || depth == CV_32F in function cv::cvtColor

Mon, 26 Mar 2018 17:03:34 app_thread.py[line:113] ERROR 刷新失败
Mon, 26 Mar 2018 17:03:34 app_thread.py[line:114] ERROR this is an exception message
Traceback (most recent call last):
  File "F:/BestAssistant\component\app_thread.py", line 111, in run
    findrefresh()
  File "F:/BestAssistant\component\imgcut.py", line 324, in findrefresh
    img = cv2.cvtColor(sc, cv2.COLOR_BGR2GRAY)  # 转灰度图
cv2.error: C:\projects\opencv-python\opencv\modules\imgproc\src\color.cpp:10600: error: (-215) depth == CV_8U || depth == CV_16U || depth == CV_32F in function cv::cvtColor

Mon, 26 Mar 2018 17:03:34 imgcut.py[line:309] ERROR cut_img 这里出错
Mon, 26 Mar 2018 17:03:34 imgcut.py[line:310] ERROR this is an exception message
Traceback (most recent call last):
  File "F:/BestAssistant\component\imgcut.py", line 302, in cut_img
    set_val('imgpos_lowestprice', img[use_area[0][1]:use_area[0][3], use_area[0][0]:use_area[0][2]])  # ok
IndexError: list index out of range
Mon, 26 Mar 2018 17:03:34 imgcut.py[line:309] ERROR cut_img 这里出错
Mon, 26 Mar 2018 17:03:34 imgcut.py[line:310] ERROR this is an exception message
Traceback (most recent call last):
  File "F:/BestAssistant\component\imgcut.py", line 302, in cut_img
    set_val('imgpos_lowestprice', img[use_area[0][1]:use_area[0][3], use_area[0][0]:use_area[0][2]])  # ok
IndexError: list index out of range
Mon, 26 Mar 2018 17:03:34 app_thread.py[line:113] ERROR 刷新失败
Mon, 26 Mar 2018 17:03:34 app_thread.py[line:114] ERROR this is an exception message
Traceback (most recent call last):
  File "F:/BestAssistant\component\app_thread.py", line 111, in run
    findrefresh()
  File "F:/BestAssistant\component\imgcut.py", line 324, in findrefresh
    img = cv2.cvtColor(sc, cv2.COLOR_BGR2GRAY)  # 转灰度图
cv2.error: C:\projects\opencv-python\opencv\modules\imgproc\src\color.cpp:10600: error: (-215) depth == CV_8U || depth == CV_16U || depth == CV_32F in function cv::cvtColor

Mon, 26 Mar 2018 17:03:34 app_thread.py[line:113] ERROR 刷新失败
Mon, 26 Mar 2018 17:03:34 app_thread.py[line:114] ERROR this is an exception message
Traceback (most recent call last):
  File "F:/BestAssistant\component\app_thread.py", line 111, in run
    findrefresh()
  File "F:/BestAssistant\component\imgcut.py", line 324, in findrefresh
    img = cv2.cvtColor(sc, cv2.COLOR_BGR2GRAY)  # 转灰度图
cv2.error: C:\projects\opencv-python\opencv\modules\imgproc\src\color.cpp:10600: error: (-215) depth == CV_8U || depth == CV_16U || depth == CV_32F in function cv::cvtColor

Mon, 26 Mar 2018 17:03:34 imgcut.py[line:309] ERROR cut_img 这里出错
Mon, 26 Mar 2018 17:03:34 imgcut.py[line:310] ERROR this is an exception message
Traceback (most recent call last):
  File "F:/BestAssistant\component\imgcut.py", line 302, in cut_img
    set_val('imgpos_lowestprice', img[use_area[0][1]:use_area[0][3], use_area[0][0]:use_area[0][2]])  # ok
IndexError: list index out of range
Mon, 26 Mar 2018 17:03:34 app_thread.py[line:113] ERROR 刷新失败
Mon, 26 Mar 2018 17:03:34 app_thread.py[line:114] ERROR this is an exception message
Traceback (most recent call last):
  File "F:/BestAssistant\component\app_thread.py", line 111, in run
    findrefresh()
  File "F:/BestAssistant\component\imgcut.py", line 324, in findrefresh
    img = cv2.cvtColor(sc, cv2.COLOR_BGR2GRAY)  # 转灰度图
cv2.error: C:\projects\opencv-python\opencv\modules\imgproc\src\color.cpp:10600: error: (-215) depth == CV_8U || depth == CV_16U || depth == CV_32F in function cv::cvtColor

Mon, 26 Mar 2018 17:03:34 imgcut.py[line:309] ERROR cut_img 这里出错
Mon, 26 Mar 2018 17:03:34 imgcut.py[line:310] ERROR this is an exception message
Traceback (most recent call last):
  File "F:/BestAssistant\component\imgcut.py", line 302, in cut_img
    set_val('imgpos_lowestprice', img[use_area[0][1]:use_area[0][3], use_area[0][0]:use_area[0][2]])  # ok
IndexError: list index out of range
Mon, 26 Mar 2018 17:03:34 imgcut.py[line:309] ERROR cut_img 这里出错
Mon, 26 Mar 2018 17:03:34 imgcut.py[line:310] ERROR this is an exception message
Traceback (most recent call last):
  File "F:/BestAssistant\component\imgcut.py", line 302, in cut_img
    set_val('imgpos_lowestprice', img[use_area[0][1]:use_area[0][3], use_area[0][0]:use_area[0][2]])  # ok
IndexError: list index out of range
Mon, 26 Mar 2018 17:03:34 app_thread.py[line:113] ERROR 刷新失败
Mon, 26 Mar 2018 17:03:34 app_thread.py[line:114] ERROR this is an exception message
Traceback (most recent call last):
  File "F:/BestAssistant\component\app_thread.py", line 111, in run
    findrefresh()
  File "F:/BestAssistant\component\imgcut.py", line 324, in findrefresh
    img = cv2.cvtColor(sc, cv2.COLOR_BGR2GRAY)  # 转灰度图
cv2.error: C:\projects\opencv-python\opencv\modules\imgproc\src\color.cpp:10600: error: (-215) depth == CV_8U || depth == CV_16U || depth == CV_32F in function cv::cvtColor

Mon, 26 Mar 2018 17:03:34 app_thread.py[line:113] ERROR 刷新失败
Mon, 26 Mar 2018 17:03:34 app_thread.py[line:114] ERROR this is an exception message
Traceback (most recent call last):
  File "F:/BestAssistant\component\app_thread.py", line 111, in run
    findrefresh()
  File "F:/BestAssistant\component\imgcut.py", line 324, in findrefresh
    img = cv2.cvtColor(sc, cv2.COLOR_BGR2GRAY)  # 转灰度图
cv2.error: C:\projects\opencv-python\opencv\modules\imgproc\src\color.cpp:10600: error: (-215) depth == CV_8U || depth == CV_16U || depth == CV_32F in function cv::cvtColor

Mon, 26 Mar 2018 17:03:34 imgcut.py[line:309] ERROR cut_img 这里出错
Mon, 26 Mar 2018 17:03:34 imgcut.py[line:310] ERROR this is an exception message
Traceback (most recent call last):
  File "F:/BestAssistant\component\imgcut.py", line 302, in cut_img
    set_val('imgpos_lowestprice', img[use_area[0][1]:use_area[0][3], use_area[0][0]:use_area[0][2]])  # ok
IndexError: list index out of range
Mon, 26 Mar 2018 17:03:34 app_thread.py[line:113] ERROR 刷新失败
Mon, 26 Mar 2018 17:03:34 app_thread.py[line:114] ERROR this is an exception message
Traceback (most recent call last):
  File "F:/BestAssistant\component\app_thread.py", line 111, in run
    findrefresh()
  File "F:/BestAssistant\component\imgcut.py", line 324, in findrefresh
    img = cv2.cvtColor(sc, cv2.COLOR_BGR2GRAY)  # 转灰度图
cv2.error: C:\projects\opencv-python\opencv\modules\imgproc\src\color.cpp:10600: error: (-215) depth == CV_8U || depth == CV_16U || depth == CV_32F in function cv::cvtColor

Mon, 26 Mar 2018 17:03:34 imgcut.py[line:309] ERROR cut_img 这里出错
Mon, 26 Mar 2018 17:03:34 imgcut.py[line:310] ERROR this is an exception message
Traceback (most recent call last):
  File "F:/BestAssistant\component\imgcut.py", line 302, in cut_img
    set_val('imgpos_lowestprice', img[use_area[0][1]:use_area[0][3], use_area[0][0]:use_area[0][2]])  # ok
IndexError: list index out of range
Mon, 26 Mar 2018 17:03:34 app_thread.py[line:113] ERROR 刷新失败
Mon, 26 Mar 2018 17:03:34 app_thread.py[line:114] ERROR this is an exception message
Traceback (most recent call last):
  File "F:/BestAssistant\component\app_thread.py", line 111, in run
    findrefresh()
  File "F:/BestAssistant\component\imgcut.py", line 324, in findrefresh
    img = cv2.cvtColor(sc, cv2.COLOR_BGR2GRAY)  # 转灰度图
cv2.error: C:\projects\opencv-python\opencv\modules\imgproc\src\color.cpp:10600: error: (-215) depth == CV_8U || depth == CV_16U || depth == CV_32F in function cv::cvtColor

Mon, 26 Mar 2018 17:03:35 app_thread.py[line:113] ERROR 刷新失败
Mon, 26 Mar 2018 17:03:35 app_thread.py[line:114] ERROR this is an exception message
Traceback (most recent call last):
  File "F:/BestAssistant\component\app_thread.py", line 111, in run
    findrefresh()
  File "F:/BestAssistant\component\imgcut.py", line 324, in findrefresh
    img = cv2.cvtColor(sc, cv2.COLOR_BGR2GRAY)  # 转灰度图
cv2.error: C:\projects\opencv-python\opencv\modules\imgproc\src\color.cpp:10600: error: (-215) depth == CV_8U || depth == CV_16U || depth == CV_32F in function cv::cvtColor

Mon, 26 Mar 2018 17:03:35 imgcut.py[line:309] ERROR cut_img 这里出错
Mon, 26 Mar 2018 17:03:35 imgcut.py[line:310] ERROR this is an exception message
Traceback (most recent call last):
  File "F:/BestAssistant\component\imgcut.py", line 302, in cut_img
    set_val('imgpos_lowestprice', img[use_area[0][1]:use_area[0][3], use_area[0][0]:use_area[0][2]])  # ok
IndexError: list index out of range
Mon, 26 Mar 2018 17:03:35 app_thread.py[line:113] ERROR 刷新失败
Mon, 26 Mar 2018 17:03:35 app_thread.py[line:114] ERROR this is an exception message
Traceback (most recent call last):
  File "F:/BestAssistant\component\app_thread.py", line 111, in run
    findrefresh()
  File "F:/BestAssistant\component\imgcut.py", line 324, in findrefresh
    img = cv2.cvtColor(sc, cv2.COLOR_BGR2GRAY)  # 转灰度图
cv2.error: C:\projects\opencv-python\opencv\modules\imgproc\src\color.cpp:10600: error: (-215) depth == CV_8U || depth == CV_16U || depth == CV_32F in function cv::cvtColor

Mon, 26 Mar 2018 17:03:35 imgcut.py[line:309] ERROR cut_img 这里出错
Mon, 26 Mar 2018 17:03:35 imgcut.py[line:310] ERROR this is an exception message
Traceback (most recent call last):
  File "F:/BestAssistant\component\imgcut.py", line 302, in cut_img
    set_val('imgpos_lowestprice', img[use_area[0][1]:use_area[0][3], use_area[0][0]:use_area[0][2]])  # ok
IndexError: list index out of range
Mon, 26 Mar 2018 17:03:35 app_thread.py[line:113] ERROR 刷新失败
Mon, 26 Mar 2018 17:03:35 app_thread.py[line:114] ERROR this is an exception message
Traceback (most recent call last):
  File "F:/BestAssistant\component\app_thread.py", line 111, in run
    findrefresh()
  File "F:/BestAssistant\component\imgcut.py", line 324, in findrefresh
    img = cv2.cvtColor(sc, cv2.COLOR_BGR2GRAY)  # 转灰度图
cv2.error: C:\projects\opencv-python\opencv\modules\imgproc\src\color.cpp:10600: error: (-215) depth == CV_8U || depth == CV_16U || depth == CV_32F in function cv::cvtColor

Mon, 26 Mar 2018 17:03:35 imgcut.py[line:309] ERROR cut_img 这里出错
Mon, 26 Mar 2018 17:03:35 imgcut.py[line:310] ERROR this is an exception message
Traceback (most recent call last):
  File "F:/BestAssistant\component\imgcut.py", line 302, in cut_img
    set_val('imgpos_lowestprice', img[use_area[0][1]:use_area[0][3], use_area[0][0]:use_area[0][2]])  # ok
IndexError: list index out of range
Mon, 26 Mar 2018 17:03:35 app_thread.py[line:113] ERROR 刷新失败
Mon, 26 Mar 2018 17:03:35 app_thread.py[line:114] ERROR this is an exception message
Traceback (most recent call last):
  File "F:/BestAssistant\component\app_thread.py", line 111, in run
    findrefresh()
  File "F:/BestAssistant\component\imgcut.py", line 324, in findrefresh
    img = cv2.cvtColor(sc, cv2.COLOR_BGR2GRAY)  # 转灰度图
cv2.error: C:\projects\opencv-python\opencv\modules\imgproc\src\color.cpp:10600: error: (-215) depth == CV_8U || depth == CV_16U || depth == CV_32F in function cv::cvtColor

Mon, 26 Mar 2018 17:03:35 imgcut.py[line:309] ERROR cut_img 这里出错
Mon, 26 Mar 2018 17:03:35 imgcut.py[line:310] ERROR this is an exception message
Traceback (most recent call last):
  File "F:/BestAssistant\component\imgcut.py", line 302, in cut_img
    set_val('imgpos_lowestprice', img[use_area[0][1]:use_area[0][3], use_area[0][0]:use_area[0][2]])  # ok
IndexError: list index out of range
Mon, 26 Mar 2018 17:03:35 app_thread.py[line:113] ERROR 刷新失败
Mon, 26 Mar 2018 17:03:35 app_thread.py[line:114] ERROR this is an exception message
Traceback (most recent call last):
  File "F:/BestAssistant\component\app_thread.py", line 111, in run
    findrefresh()
  File "F:/BestAssistant\component\imgcut.py", line 324, in findrefresh
    img = cv2.cvtColor(sc, cv2.COLOR_BGR2GRAY)  # 转灰度图
cv2.error: C:\projects\opencv-python\opencv\modules\imgproc\src\color.cpp:10600: error: (-215) depth == CV_8U || depth == CV_16U || depth == CV_32F in function cv::cvtColor

Mon, 26 Mar 2018 17:03:35 imgcut.py[line:309] ERROR cut_img 这里出错
Mon, 26 Mar 2018 17:03:35 imgcut.py[line:310] ERROR this is an exception message
Traceback (most recent call last):
  File "F:/BestAssistant\component\imgcut.py", line 302, in cut_img
    set_val('imgpos_lowestprice', img[use_area[0][1]:use_area[0][3], use_area[0][0]:use_area[0][2]])  # ok
IndexError: list index out of range
Mon, 26 Mar 2018 17:03:35 app_thread.py[line:113] ERROR 刷新失败
Mon, 26 Mar 2018 17:03:35 app_thread.py[line:114] ERROR this is an exception message
Traceback (most recent call last):
  File "F:/BestAssistant\component\app_thread.py", line 111, in run
    findrefresh()
  File "F:/BestAssistant\component\imgcut.py", line 324, in findrefresh
    img = cv2.cvtColor(sc, cv2.COLOR_BGR2GRAY)  # 转灰度图
cv2.error: C:\projects\opencv-python\opencv\modules\imgproc\src\color.cpp:10600: error: (-215) depth == CV_8U || depth == CV_16U || depth == CV_32F in function cv::cvtColor

Mon, 26 Mar 2018 17:03:35 imgcut.py[line:309] ERROR cut_img 这里出错
Mon, 26 Mar 2018 17:03:35 imgcut.py[line:310] ERROR this is an exception message
Traceback (most recent call last):
  File "F:/BestAssistant\component\imgcut.py", line 302, in cut_img
    set_val('imgpos_lowestprice', img[use_area[0][1]:use_area[0][3], use_area[0][0]:use_area[0][2]])  # ok
IndexError: list index out of range
Mon, 26 Mar 2018 17:03:35 app_thread.py[line:113] ERROR 刷新失败
Mon, 26 Mar 2018 17:03:35 app_thread.py[line:114] ERROR this is an exception message
Traceback (most recent call last):
  File "F:/BestAssistant\component\app_thread.py", line 111, in run
    findrefresh()
  File "F:/BestAssistant\component\imgcut.py", line 324, in findrefresh
    img = cv2.cvtColor(sc, cv2.COLOR_BGR2GRAY)  # 转灰度图
cv2.error: C:\projects\opencv-python\opencv\modules\imgproc\src\color.cpp:10600: error: (-215) depth == CV_8U || depth == CV_16U || depth == CV_32F in function cv::cvtColor

Mon, 26 Mar 2018 17:03:35 app_thread.py[line:113] ERROR 刷新失败
Mon, 26 Mar 2018 17:03:35 app_thread.py[line:114] ERROR this is an exception message
Traceback (most recent call last):
  File "F:/BestAssistant\component\app_thread.py", line 111, in run
    findrefresh()
  File "F:/BestAssistant\component\imgcut.py", line 324, in findrefresh
    img = cv2.cvtColor(sc, cv2.COLOR_BGR2GRAY)  # 转灰度图
cv2.error: C:\projects\opencv-python\opencv\modules\imgproc\src\color.cpp:10600: error: (-215) depth == CV_8U || depth == CV_16U || depth == CV_32F in function cv::cvtColor

Mon, 26 Mar 2018 17:03:35 imgcut.py[line:309] ERROR cut_img 这里出错
Mon, 26 Mar 2018 17:03:35 imgcut.py[line:310] ERROR this is an exception message
Traceback (most recent call last):
  File "F:/BestAssistant\component\imgcut.py", line 302, in cut_img
    set_val('imgpos_lowestprice', img[use_area[0][1]:use_area[0][3], use_area[0][0]:use_area[0][2]])  # ok
IndexError: list index out of range
Mon, 26 Mar 2018 17:03:35 imgcut.py[line:309] ERROR cut_img 这里出错
Mon, 26 Mar 2018 17:03:35 imgcut.py[line:310] ERROR this is an exception message
Traceback (most recent call last):
  File "F:/BestAssistant\component\imgcut.py", line 302, in cut_img
    set_val('imgpos_lowestprice', img[use_area[0][1]:use_area[0][3], use_area[0][0]:use_area[0][2]])  # ok
IndexError: list index out of range
Mon, 26 Mar 2018 17:03:35 app_thread.py[line:113] ERROR 刷新失败
Mon, 26 Mar 2018 17:03:35 app_thread.py[line:114] ERROR this is an exception message
Traceback (most recent call last):
  File "F:/BestAssistant\component\app_thread.py", line 111, in run
    findrefresh()
  File "F:/BestAssistant\component\imgcut.py", line 324, in findrefresh
    img = cv2.cvtColor(sc, cv2.COLOR_BGR2GRAY)  # 转灰度图
cv2.error: C:\projects\opencv-python\opencv\modules\imgproc\src\color.cpp:10600: error: (-215) depth == CV_8U || depth == CV_16U || depth == CV_32F in function cv::cvtColor

Mon, 26 Mar 2018 17:03:35 imgcut.py[line:309] ERROR cut_img 这里出错
Mon, 26 Mar 2018 17:03:35 imgcut.py[line:310] ERROR this is an exception message
Traceback (most recent call last):
  File "F:/BestAssistant\component\imgcut.py", line 302, in cut_img
    set_val('imgpos_lowestprice', img[use_area[0][1]:use_area[0][3], use_area[0][0]:use_area[0][2]])  # ok
IndexError: list index out of range
Mon, 26 Mar 2018 17:03:35 app_thread.py[line:113] ERROR 刷新失败
Mon, 26 Mar 2018 17:03:35 app_thread.py[line:114] ERROR this is an exception message
Traceback (most recent call last):
  File "F:/BestAssistant\component\app_thread.py", line 111, in run
    findrefresh()
  File "F:/BestAssistant\component\imgcut.py", line 324, in findrefresh
    img = cv2.cvtColor(sc, cv2.COLOR_BGR2GRAY)  # 转灰度图
cv2.error: C:\projects\opencv-python\opencv\modules\imgproc\src\color.cpp:10600: error: (-215) depth == CV_8U || depth == CV_16U || depth == CV_32F in function cv::cvtColor

Mon, 26 Mar 2018 17:03:35 app_thread.py[line:113] ERROR 刷新失败
Mon, 26 Mar 2018 17:03:35 app_thread.py[line:114] ERROR this is an exception message
Traceback (most recent call last):
  File "F:/BestAssistant\component\app_thread.py", line 111, in run
    findrefresh()
  File "F:/BestAssistant\component\imgcut.py", line 324, in findrefresh
    img = cv2.cvtColor(sc, cv2.COLOR_BGR2GRAY)  # 转灰度图
cv2.error: C:\projects\opencv-python\opencv\modules\imgproc\src\color.cpp:10600: error: (-215) depth == CV_8U || depth == CV_16U || depth == CV_32F in function cv::cvtColor

Mon, 26 Mar 2018 17:03:35 imgcut.py[line:309] ERROR cut_img 这里出错
Mon, 26 Mar 2018 17:03:35 imgcut.py[line:310] ERROR this is an exception message
Traceback (most recent call last):
  File "F:/BestAssistant\component\imgcut.py", line 302, in cut_img
    set_val('imgpos_lowestprice', img[use_area[0][1]:use_area[0][3], use_area[0][0]:use_area[0][2]])  # ok
IndexError: list index out of range
Mon, 26 Mar 2018 17:03:35 app_thread.py[line:113] ERROR 刷新失败
Mon, 26 Mar 2018 17:03:35 app_thread.py[line:114] ERROR this is an exception message
Traceback (most recent call last):
  File "F:/BestAssistant\component\app_thread.py", line 111, in run
    findrefresh()
  File "F:/BestAssistant\component\imgcut.py", line 324, in findrefresh
    img = cv2.cvtColor(sc, cv2.COLOR_BGR2GRAY)  # 转灰度图
cv2.error: C:\projects\opencv-python\opencv\modules\imgproc\src\color.cpp:10600: error: (-215) depth == CV_8U || depth == CV_16U || depth == CV_32F in function cv::cvtColor

Mon, 26 Mar 2018 17:03:35 imgcut.py[line:309] ERROR cut_img 这里出错
Mon, 26 Mar 2018 17:03:35 imgcut.py[line:310] ERROR this is an exception message
Traceback (most recent call last):
  File "F:/BestAssistant\component\imgcut.py", line 302, in cut_img
    set_val('imgpos_lowestprice', img[use_area[0][1]:use_area[0][3], use_area[0][0]:use_area[0][2]])  # ok
IndexError: list index out of range
Mon, 26 Mar 2018 17:03:35 app_thread.py[line:113] ERROR 刷新失败
Mon, 26 Mar 2018 17:03:35 app_thread.py[line:114] ERROR this is an exception message
Traceback (most recent call last):
  File "F:/BestAssistant\component\app_thread.py", line 111, in run
    findrefresh()
  File "F:/BestAssistant\component\imgcut.py", line 324, in findrefresh
    img = cv2.cvtColor(sc, cv2.COLOR_BGR2GRAY)  # 转灰度图
cv2.error: C:\projects\opencv-python\opencv\modules\imgproc\src\color.cpp:10600: error: (-215) depth == CV_8U || depth == CV_16U || depth == CV_32F in function cv::cvtColor

Mon, 26 Mar 2018 17:03:35 app_thread.py[line:113] ERROR 刷新失败
Mon, 26 Mar 2018 17:03:35 app_thread.py[line:114] ERROR this is an exception message
Traceback (most recent call last):
  File "F:/BestAssistant\component\app_thread.py", line 111, in run
    findrefresh()
  File "F:/BestAssistant\component\imgcut.py", line 324, in findrefresh
    img = cv2.cvtColor(sc, cv2.COLOR_BGR2GRAY)  # 转灰度图
cv2.error: C:\projects\opencv-python\opencv\modules\imgproc\src\color.cpp:10600: error: (-215) depth == CV_8U || depth == CV_16U || depth == CV_32F in function cv::cvtColor

Mon, 26 Mar 2018 17:03:35 imgcut.py[line:309] ERROR cut_img 这里出错
Mon, 26 Mar 2018 17:03:35 imgcut.py[line:310] ERROR this is an exception message
Traceback (most recent call last):
  File "F:/BestAssistant\component\imgcut.py", line 302, in cut_img
    set_val('imgpos_lowestprice', img[use_area[0][1]:use_area[0][3], use_area[0][0]:use_area[0][2]])  # ok
IndexError: list index out of range
Mon, 26 Mar 2018 17:03:36 app_thread.py[line:113] ERROR 刷新失败
Mon, 26 Mar 2018 17:03:36 app_thread.py[line:114] ERROR this is an exception message
Traceback (most recent call last):
  File "F:/BestAssistant\component\app_thread.py", line 111, in run
    findrefresh()
  File "F:/BestAssistant\component\imgcut.py", line 324, in findrefresh
    img = cv2.cvtColor(sc, cv2.COLOR_BGR2GRAY)  # 转灰度图
cv2.error: C:\projects\opencv-python\opencv\modules\imgproc\src\color.cpp:10600: error: (-215) depth == CV_8U || depth == CV_16U || depth == CV_32F in function cv::cvtColor

Mon, 26 Mar 2018 17:03:36 imgcut.py[line:309] ERROR cut_img 这里出错
Mon, 26 Mar 2018 17:03:36 imgcut.py[line:310] ERROR this is an exception message
Traceback (most recent call last):
  File "F:/BestAssistant\component\imgcut.py", line 302, in cut_img
    set_val('imgpos_lowestprice', img[use_area[0][1]:use_area[0][3], use_area[0][0]:use_area[0][2]])  # ok
IndexError: list index out of range
Mon, 26 Mar 2018 17:03:36 imgcut.py[line:309] ERROR cut_img 这里出错
Mon, 26 Mar 2018 17:03:36 imgcut.py[line:310] ERROR this is an exception message
Traceback (most recent call last):
  File "F:/BestAssistant\component\imgcut.py", line 302, in cut_img
    set_val('imgpos_lowestprice', img[use_area[0][1]:use_area[0][3], use_area[0][0]:use_area[0][2]])  # ok
IndexError: list index out of range
Mon, 26 Mar 2018 17:03:36 app_thread.py[line:113] ERROR 刷新失败
Mon, 26 Mar 2018 17:03:36 app_thread.py[line:114] ERROR this is an exception message
Traceback (most recent call last):
  File "F:/BestAssistant\component\app_thread.py", line 111, in run
    findrefresh()
  File "F:/BestAssistant\component\imgcut.py", line 324, in findrefresh
    img = cv2.cvtColor(sc, cv2.COLOR_BGR2GRAY)  # 转灰度图
cv2.error: C:\projects\opencv-python\opencv\modules\imgproc\src\color.cpp:10600: error: (-215) depth == CV_8U || depth == CV_16U || depth == CV_32F in function cv::cvtColor

Mon, 26 Mar 2018 17:03:36 imgcut.py[line:309] ERROR cut_img 这里出错
Mon, 26 Mar 2018 17:03:36 imgcut.py[line:310] ERROR this is an exception message
Traceback (most recent call last):
  File "F:/BestAssistant\component\imgcut.py", line 302, in cut_img
    set_val('imgpos_lowestprice', img[use_area[0][1]:use_area[0][3], use_area[0][0]:use_area[0][2]])  # ok
IndexError: list index out of range
Mon, 26 Mar 2018 17:03:36 app_thread.py[line:113] ERROR 刷新失败
Mon, 26 Mar 2018 17:03:36 app_thread.py[line:114] ERROR this is an exception message
Traceback (most recent call last):
  File "F:/BestAssistant\component\app_thread.py", line 111, in run
    findrefresh()
  File "F:/BestAssistant\component\imgcut.py", line 324, in findrefresh
    img = cv2.cvtColor(sc, cv2.COLOR_BGR2GRAY)  # 转灰度图
cv2.error: C:\projects\opencv-python\opencv\modules\imgproc\src\color.cpp:10600: error: (-215) depth == CV_8U || depth == CV_16U || depth == CV_32F in function cv::cvtColor

Mon, 26 Mar 2018 17:03:36 app_thread.py[line:113] ERROR 刷新失败
Mon, 26 Mar 2018 17:03:36 app_thread.py[line:114] ERROR this is an exception message
Traceback (most recent call last):
  File "F:/BestAssistant\component\app_thread.py", line 111, in run
    findrefresh()
  File "F:/BestAssistant\component\imgcut.py", line 324, in findrefresh
    img = cv2.cvtColor(sc, cv2.COLOR_BGR2GRAY)  # 转灰度图
cv2.error: C:\projects\opencv-python\opencv\modules\imgproc\src\color.cpp:10600: error: (-215) depth == CV_8U || depth == CV_16U || depth == CV_32F in function cv::cvtColor

Mon, 26 Mar 2018 17:03:36 imgcut.py[line:309] ERROR cut_img 这里出错
Mon, 26 Mar 2018 17:03:36 imgcut.py[line:310] ERROR this is an exception message
Traceback (most recent call last):
  File "F:/BestAssistant\component\imgcut.py", line 302, in cut_img
    set_val('imgpos_lowestprice', img[use_area[0][1]:use_area[0][3], use_area[0][0]:use_area[0][2]])  # ok
IndexError: list index out of range
Mon, 26 Mar 2018 17:03:36 app_thread.py[line:113] ERROR 刷新失败
Mon, 26 Mar 2018 17:03:36 app_thread.py[line:114] ERROR this is an exception message
Traceback (most recent call last):
  File "F:/BestAssistant\component\app_thread.py", line 111, in run
    findrefresh()
  File "F:/BestAssistant\component\imgcut.py", line 324, in findrefresh
    img = cv2.cvtColor(sc, cv2.COLOR_BGR2GRAY)  # 转灰度图
cv2.error: C:\projects\opencv-python\opencv\modules\imgproc\src\color.cpp:10600: error: (-215) depth == CV_8U || depth == CV_16U || depth == CV_32F in function cv::cvtColor

Mon, 26 Mar 2018 17:03:36 imgcut.py[line:309] ERROR cut_img 这里出错
Mon, 26 Mar 2018 17:03:36 imgcut.py[line:310] ERROR this is an exception message
Traceback (most recent call last):
  File "F:/BestAssistant\component\imgcut.py", line 302, in cut_img
    set_val('imgpos_lowestprice', img[use_area[0][1]:use_area[0][3], use_area[0][0]:use_area[0][2]])  # ok
IndexError: list index out of range
Mon, 26 Mar 2018 17:03:36 app_thread.py[line:113] ERROR 刷新失败
Mon, 26 Mar 2018 17:03:36 app_thread.py[line:114] ERROR this is an exception message
Traceback (most recent call last):
  File "F:/BestAssistant\component\app_thread.py", line 111, in run
    findrefresh()
  File "F:/BestAssistant\component\imgcut.py", line 324, in findrefresh
    img = cv2.cvtColor(sc, cv2.COLOR_BGR2GRAY)  # 转灰度图
cv2.error: C:\projects\opencv-python\opencv\modules\imgproc\src\color.cpp:10600: error: (-215) depth == CV_8U || depth == CV_16U || depth == CV_32F in function cv::cvtColor

Mon, 26 Mar 2018 17:03:36 imgcut.py[line:309] ERROR cut_img 这里出错
Mon, 26 Mar 2018 17:03:36 imgcut.py[line:310] ERROR this is an exception message
Traceback (most recent call last):
  File "F:/BestAssistant\component\imgcut.py", line 302, in cut_img
    set_val('imgpos_lowestprice', img[use_area[0][1]:use_area[0][3], use_area[0][0]:use_area[0][2]])  # ok
IndexError: list index out of range
Mon, 26 Mar 2018 17:03:36 app_thread.py[line:113] ERROR 刷新失败
Mon, 26 Mar 2018 17:03:36 app_thread.py[line:114] ERROR this is an exception message
Traceback (most recent call last):
  File "F:/BestAssistant\component\app_thread.py", line 111, in run
    findrefresh()
  File "F:/BestAssistant\component\imgcut.py", line 324, in findrefresh
    img = cv2.cvtColor(sc, cv2.COLOR_BGR2GRAY)  # 转灰度图
cv2.error: C:\projects\opencv-python\opencv\modules\imgproc\src\color.cpp:10600: error: (-215) depth == CV_8U || depth == CV_16U || depth == CV_32F in function cv::cvtColor

Mon, 26 Mar 2018 17:03:36 app_thread.py[line:113] ERROR 刷新失败
Mon, 26 Mar 2018 17:03:36 imgcut.py[line:309] ERROR cut_img 这里出错
Mon, 26 Mar 2018 17:03:36 app_thread.py[line:114] ERROR this is an exception message
Traceback (most recent call last):
  File "F:/BestAssistant\component\app_thread.py", line 111, in run
    findrefresh()
  File "F:/BestAssistant\component\imgcut.py", line 324, in findrefresh
    img = cv2.cvtColor(sc, cv2.COLOR_BGR2GRAY)  # 转灰度图
cv2.error: C:\projects\opencv-python\opencv\modules\imgproc\src\color.cpp:10600: error: (-215) depth == CV_8U || depth == CV_16U || depth == CV_32F in function cv::cvtColor

Mon, 26 Mar 2018 17:03:36 imgcut.py[line:310] ERROR this is an exception message
Traceback (most recent call last):
  File "F:/BestAssistant\component\imgcut.py", line 302, in cut_img
    set_val('imgpos_lowestprice', img[use_area[0][1]:use_area[0][3], use_area[0][0]:use_area[0][2]])  # ok
IndexError: list index out of range
Mon, 26 Mar 2018 17:03:36 imgcut.py[line:309] ERROR cut_img 这里出错
Mon, 26 Mar 2018 17:03:36 app_thread.py[line:113] ERROR 刷新失败
Mon, 26 Mar 2018 17:03:36 imgcut.py[line:310] ERROR this is an exception message
Traceback (most recent call last):
  File "F:/BestAssistant\component\imgcut.py", line 302, in cut_img
    set_val('imgpos_lowestprice', img[use_area[0][1]:use_area[0][3], use_area[0][0]:use_area[0][2]])  # ok
IndexError: list index out of range
Mon, 26 Mar 2018 17:03:36 app_thread.py[line:114] ERROR this is an exception message
Traceback (most recent call last):
  File "F:/BestAssistant\component\app_thread.py", line 111, in run
    findrefresh()
  File "F:/BestAssistant\component\imgcut.py", line 324, in findrefresh
    img = cv2.cvtColor(sc, cv2.COLOR_BGR2GRAY)  # 转灰度图
cv2.error: C:\projects\opencv-python\opencv\modules\imgproc\src\color.cpp:10600: error: (-215) depth == CV_8U || depth == CV_16U || depth == CV_32F in function cv::cvtColor

Mon, 26 Mar 2018 17:03:36 app_thread.py[line:113] ERROR 刷新失败
Mon, 26 Mar 2018 17:03:36 app_thread.py[line:114] ERROR this is an exception message
Traceback (most recent call last):
  File "F:/BestAssistant\component\app_thread.py", line 111, in run
    findrefresh()
  File "F:/BestAssistant\component\imgcut.py", line 324, in findrefresh
    img = cv2.cvtColor(sc, cv2.COLOR_BGR2GRAY)  # 转灰度图
cv2.error: C:\projects\opencv-python\opencv\modules\imgproc\src\color.cpp:10600: error: (-215) depth == CV_8U || depth == CV_16U || depth == CV_32F in function cv::cvtColor

Mon, 26 Mar 2018 17:03:36 imgcut.py[line:309] ERROR cut_img 这里出错
Mon, 26 Mar 2018 17:03:36 imgcut.py[line:310] ERROR this is an exception message
Traceback (most recent call last):
  File "F:/BestAssistant\component\imgcut.py", line 302, in cut_img
    set_val('imgpos_lowestprice', img[use_area[0][1]:use_area[0][3], use_area[0][0]:use_area[0][2]])  # ok
IndexError: list index out of range
Mon, 26 Mar 2018 17:03:36 app_thread.py[line:113] ERROR 刷新失败
Mon, 26 Mar 2018 17:03:36 app_thread.py[line:114] ERROR this is an exception message
Traceback (most recent call last):
  File "F:/BestAssistant\component\app_thread.py", line 111, in run
    findrefresh()
  File "F:/BestAssistant\component\imgcut.py", line 324, in findrefresh
    img = cv2.cvtColor(sc, cv2.COLOR_BGR2GRAY)  # 转灰度图
cv2.error: C:\projects\opencv-python\opencv\modules\imgproc\src\color.cpp:10600: error: (-215) depth == CV_8U || depth == CV_16U || depth == CV_32F in function cv::cvtColor

Mon, 26 Mar 2018 17:03:36 imgcut.py[line:309] ERROR cut_img 这里出错
Mon, 26 Mar 2018 17:03:36 imgcut.py[line:310] ERROR this is an exception message
Traceback (most recent call last):
  File "F:/BestAssistant\component\imgcut.py", line 302, in cut_img
    set_val('imgpos_lowestprice', img[use_area[0][1]:use_area[0][3], use_area[0][0]:use_area[0][2]])  # ok
IndexError: list index out of range
Mon, 26 Mar 2018 17:03:36 imgcut.py[line:309] ERROR cut_img 这里出错
Mon, 26 Mar 2018 17:03:36 imgcut.py[line:310] ERROR this is an exception message
Traceback (most recent call last):
  File "F:/BestAssistant\component\imgcut.py", line 302, in cut_img
    set_val('imgpos_lowestprice', img[use_area[0][1]:use_area[0][3], use_area[0][0]:use_area[0][2]])  # ok
IndexError: list index out of range
Mon, 26 Mar 2018 17:03:36 app_thread.py[line:113] ERROR 刷新失败
Mon, 26 Mar 2018 17:03:36 app_thread.py[line:114] ERROR this is an exception message
Traceback (most recent call last):
  File "F:/BestAssistant\component\app_thread.py", line 111, in run
    findrefresh()
  File "F:/BestAssistant\component\imgcut.py", line 324, in findrefresh
    img = cv2.cvtColor(sc, cv2.COLOR_BGR2GRAY)  # 转灰度图
cv2.error: C:\projects\opencv-python\opencv\modules\imgproc\src\color.cpp:10600: error: (-215) depth == CV_8U || depth == CV_16U || depth == CV_32F in function cv::cvtColor

Mon, 26 Mar 2018 17:03:36 app_thread.py[line:113] ERROR 刷新失败
Mon, 26 Mar 2018 17:03:36 imgcut.py[line:309] ERROR cut_img 这里出错
Mon, 26 Mar 2018 17:03:36 app_thread.py[line:114] ERROR this is an exception message
Traceback (most recent call last):
  File "F:/BestAssistant\component\app_thread.py", line 111, in run
    findrefresh()
  File "F:/BestAssistant\component\imgcut.py", line 324, in findrefresh
    img = cv2.cvtColor(sc, cv2.COLOR_BGR2GRAY)  # 转灰度图
cv2.error: C:\projects\opencv-python\opencv\modules\imgproc\src\color.cpp:10600: error: (-215) depth == CV_8U || depth == CV_16U || depth == CV_32F in function cv::cvtColor

Mon, 26 Mar 2018 17:03:36 imgcut.py[line:310] ERROR this is an exception message
Traceback (most recent call last):
  File "F:/BestAssistant\component\imgcut.py", line 302, in cut_img
    set_val('imgpos_lowestprice', img[use_area[0][1]:use_area[0][3], use_area[0][0]:use_area[0][2]])  # ok
IndexError: list index out of range
Mon, 26 Mar 2018 17:03:36 imgcut.py[line:309] ERROR cut_img 这里出错
Mon, 26 Mar 2018 17:03:36 imgcut.py[line:310] ERROR this is an exception message
Traceback (most recent call last):
  File "F:/BestAssistant\component\imgcut.py", line 302, in cut_img
    set_val('imgpos_lowestprice', img[use_area[0][1]:use_area[0][3], use_area[0][0]:use_area[0][2]])  # ok
IndexError: list index out of range
Mon, 26 Mar 2018 17:03:36 app_thread.py[line:113] ERROR 刷新失败
Mon, 26 Mar 2018 17:03:36 app_thread.py[line:114] ERROR this is an exception message
Traceback (most recent call last):
  File "F:/BestAssistant\component\app_thread.py", line 111, in run
    findrefresh()
  File "F:/BestAssistant\component\imgcut.py", line 324, in findrefresh
    img = cv2.cvtColor(sc, cv2.COLOR_BGR2GRAY)  # 转灰度图
cv2.error: C:\projects\opencv-python\opencv\modules\imgproc\src\color.cpp:10600: error: (-215) depth == CV_8U || depth == CV_16U || depth == CV_32F in function cv::cvtColor

Mon, 26 Mar 2018 17:03:37 imgcut.py[line:309] ERROR cut_img 这里出错
Mon, 26 Mar 2018 17:03:37 imgcut.py[line:310] ERROR this is an exception message
Traceback (most recent call last):
  File "F:/BestAssistant\component\imgcut.py", line 302, in cut_img
    set_val('imgpos_lowestprice', img[use_area[0][1]:use_area[0][3], use_area[0][0]:use_area[0][2]])  # ok
IndexError: list index out of range
Mon, 26 Mar 2018 17:03:37 app_thread.py[line:113] ERROR 刷新失败
Mon, 26 Mar 2018 17:03:37 app_thread.py[line:114] ERROR this is an exception message
Traceback (most recent call last):
  File "F:/BestAssistant\component\app_thread.py", line 111, in run
    findrefresh()
  File "F:/BestAssistant\component\imgcut.py", line 324, in findrefresh
    img = cv2.cvtColor(sc, cv2.COLOR_BGR2GRAY)  # 转灰度图
cv2.error: C:\projects\opencv-python\opencv\modules\imgproc\src\color.cpp:10600: error: (-215) depth == CV_8U || depth == CV_16U || depth == CV_32F in function cv::cvtColor

Mon, 26 Mar 2018 17:03:37 app_thread.py[line:113] ERROR 刷新失败
Mon, 26 Mar 2018 17:03:37 app_thread.py[line:114] ERROR this is an exception message
Traceback (most recent call last):
  File "F:/BestAssistant\component\app_thread.py", line 111, in run
    findrefresh()
  File "F:/BestAssistant\component\imgcut.py", line 324, in findrefresh
    img = cv2.cvtColor(sc, cv2.COLOR_BGR2GRAY)  # 转灰度图
cv2.error: C:\projects\opencv-python\opencv\modules\imgproc\src\color.cpp:10600: error: (-215) depth == CV_8U || depth == CV_16U || depth == CV_32F in function cv::cvtColor

Mon, 26 Mar 2018 17:03:37 imgcut.py[line:309] ERROR cut_img 这里出错
Mon, 26 Mar 2018 17:03:37 imgcut.py[line:310] ERROR this is an exception message
Traceback (most recent call last):
  File "F:/BestAssistant\component\imgcut.py", line 302, in cut_img
    set_val('imgpos_lowestprice', img[use_area[0][1]:use_area[0][3], use_area[0][0]:use_area[0][2]])  # ok
IndexError: list index out of range
Mon, 26 Mar 2018 17:03:37 app_thread.py[line:113] ERROR 刷新失败
Mon, 26 Mar 2018 17:03:37 app_thread.py[line:114] ERROR this is an exception message
Traceback (most recent call last):
  File "F:/BestAssistant\component\app_thread.py", line 111, in run
    findrefresh()
  File "F:/BestAssistant\component\imgcut.py", line 324, in findrefresh
    img = cv2.cvtColor(sc, cv2.COLOR_BGR2GRAY)  # 转灰度图
cv2.error: C:\projects\opencv-python\opencv\modules\imgproc\src\color.cpp:10600: error: (-215) depth == CV_8U || depth == CV_16U || depth == CV_32F in function cv::cvtColor

Mon, 26 Mar 2018 17:03:37 imgcut.py[line:309] ERROR cut_img 这里出错
Mon, 26 Mar 2018 17:03:37 imgcut.py[line:310] ERROR this is an exception message
Traceback (most recent call last):
  File "F:/BestAssistant\component\imgcut.py", line 302, in cut_img
    set_val('imgpos_lowestprice', img[use_area[0][1]:use_area[0][3], use_area[0][0]:use_area[0][2]])  # ok
IndexError: list index out of range
Mon, 26 Mar 2018 17:03:37 imgcut.py[line:309] ERROR cut_img 这里出错
Mon, 26 Mar 2018 17:03:37 imgcut.py[line:310] ERROR this is an exception message
Traceback (most recent call last):
  File "F:/BestAssistant\component\imgcut.py", line 302, in cut_img
    set_val('imgpos_lowestprice', img[use_area[0][1]:use_area[0][3], use_area[0][0]:use_area[0][2]])  # ok
IndexError: list index out of range
Mon, 26 Mar 2018 17:03:37 app_thread.py[line:113] ERROR 刷新失败
Mon, 26 Mar 2018 17:03:37 app_thread.py[line:114] ERROR this is an exception message
Traceback (most recent call last):
  File "F:/BestAssistant\component\app_thread.py", line 111, in run
    findrefresh()
  File "F:/BestAssistant\component\imgcut.py", line 324, in findrefresh
    img = cv2.cvtColor(sc, cv2.COLOR_BGR2GRAY)  # 转灰度图
cv2.error: C:\projects\opencv-python\opencv\modules\imgproc\src\color.cpp:10600: error: (-215) depth == CV_8U || depth == CV_16U || depth == CV_32F in function cv::cvtColor

Mon, 26 Mar 2018 17:03:37 imgcut.py[line:309] ERROR cut_img 这里出错
Mon, 26 Mar 2018 17:03:37 imgcut.py[line:310] ERROR this is an exception message
Traceback (most recent call last):
  File "F:/BestAssistant\component\imgcut.py", line 302, in cut_img
    set_val('imgpos_lowestprice', img[use_area[0][1]:use_area[0][3], use_area[0][0]:use_area[0][2]])  # ok
IndexError: list index out of range
Mon, 26 Mar 2018 17:03:37 app_thread.py[line:113] ERROR 刷新失败
Mon, 26 Mar 2018 17:03:37 app_thread.py[line:114] ERROR this is an exception message
Traceback (most recent call last):
  File "F:/BestAssistant\component\app_thread.py", line 111, in run
    findrefresh()
  File "F:/BestAssistant\component\imgcut.py", line 324, in findrefresh
    img = cv2.cvtColor(sc, cv2.COLOR_BGR2GRAY)  # 转灰度图
cv2.error: C:\projects\opencv-python\opencv\modules\imgproc\src\color.cpp:10600: error: (-215) depth == CV_8U || depth == CV_16U || depth == CV_32F in function cv::cvtColor

Mon, 26 Mar 2018 17:03:37 imgcut.py[line:309] ERROR cut_img 这里出错
Mon, 26 Mar 2018 17:03:37 imgcut.py[line:310] ERROR this is an exception message
Traceback (most recent call last):
  File "F:/BestAssistant\component\imgcut.py", line 302, in cut_img
    set_val('imgpos_lowestprice', img[use_area[0][1]:use_area[0][3], use_area[0][0]:use_area[0][2]])  # ok
IndexError: list index out of range
Mon, 26 Mar 2018 17:03:37 app_thread.py[line:113] ERROR 刷新失败
Mon, 26 Mar 2018 17:03:37 app_thread.py[line:114] ERROR this is an exception message
Traceback (most recent call last):
  File "F:/BestAssistant\component\app_thread.py", line 111, in run
    findrefresh()
  File "F:/BestAssistant\component\imgcut.py", line 324, in findrefresh
    img = cv2.cvtColor(sc, cv2.COLOR_BGR2GRAY)  # 转灰度图
cv2.error: C:\projects\opencv-python\opencv\modules\imgproc\src\color.cpp:10600: error: (-215) depth == CV_8U || depth == CV_16U || depth == CV_32F in function cv::cvtColor

Mon, 26 Mar 2018 17:03:37 imgcut.py[line:309] ERROR cut_img 这里出错
Mon, 26 Mar 2018 17:03:37 imgcut.py[line:310] ERROR this is an exception message
Traceback (most recent call last):
  File "F:/BestAssistant\component\imgcut.py", line 302, in cut_img
    set_val('imgpos_lowestprice', img[use_area[0][1]:use_area[0][3], use_area[0][0]:use_area[0][2]])  # ok
IndexError: list index out of range
Mon, 26 Mar 2018 17:03:37 app_thread.py[line:113] ERROR 刷新失败
Mon, 26 Mar 2018 17:03:37 app_thread.py[line:114] ERROR this is an exception message
Traceback (most recent call last):
  File "F:/BestAssistant\component\app_thread.py", line 111, in run
    findrefresh()
  File "F:/BestAssistant\component\imgcut.py", line 324, in findrefresh
    img = cv2.cvtColor(sc, cv2.COLOR_BGR2GRAY)  # 转灰度图
cv2.error: C:\projects\opencv-python\opencv\modules\imgproc\src\color.cpp:10600: error: (-215) depth == CV_8U || depth == CV_16U || depth == CV_32F in function cv::cvtColor

Mon, 26 Mar 2018 17:03:37 imgcut.py[line:309] ERROR cut_img 这里出错
Mon, 26 Mar 2018 17:03:37 imgcut.py[line:310] ERROR this is an exception message
Traceback (most recent call last):
  File "F:/BestAssistant\component\imgcut.py", line 302, in cut_img
    set_val('imgpos_lowestprice', img[use_area[0][1]:use_area[0][3], use_area[0][0]:use_area[0][2]])  # ok
IndexError: list index out of range
Mon, 26 Mar 2018 17:03:37 imgcut.py[line:309] ERROR cut_img 这里出错
Mon, 26 Mar 2018 17:03:37 imgcut.py[line:310] ERROR this is an exception message
Traceback (most recent call last):
  File "F:/BestAssistant\component\imgcut.py", line 302, in cut_img
    set_val('imgpos_lowestprice', img[use_area[0][1]:use_area[0][3], use_area[0][0]:use_area[0][2]])  # ok
IndexError: list index out of range
Mon, 26 Mar 2018 17:03:37 app_thread.py[line:113] ERROR 刷新失败
Mon, 26 Mar 2018 17:03:37 app_thread.py[line:114] ERROR this is an exception message
Traceback (most recent call last):
  File "F:/BestAssistant\component\app_thread.py", line 111, in run
    findrefresh()
  File "F:/BestAssistant\component\imgcut.py", line 324, in findrefresh
    img = cv2.cvtColor(sc, cv2.COLOR_BGR2GRAY)  # 转灰度图
cv2.error: C:\projects\opencv-python\opencv\modules\imgproc\src\color.cpp:10600: error: (-215) depth == CV_8U || depth == CV_16U || depth == CV_32F in function cv::cvtColor

Mon, 26 Mar 2018 17:03:37 imgcut.py[line:309] ERROR cut_img 这里出错
Mon, 26 Mar 2018 17:03:37 imgcut.py[line:310] ERROR this is an exception message
Traceback (most recent call last):
  File "F:/BestAssistant\component\imgcut.py", line 302, in cut_img
    set_val('imgpos_lowestprice', img[use_area[0][1]:use_area[0][3], use_area[0][0]:use_area[0][2]])  # ok
IndexError: list index out of range
Mon, 26 Mar 2018 17:03:37 app_thread.py[line:113] ERROR 刷新失败
Mon, 26 Mar 2018 17:03:37 app_thread.py[line:114] ERROR this is an exception message
Traceback (most recent call last):
  File "F:/BestAssistant\component\app_thread.py", line 111, in run
    findrefresh()
  File "F:/BestAssistant\component\imgcut.py", line 324, in findrefresh
    img = cv2.cvtColor(sc, cv2.COLOR_BGR2GRAY)  # 转灰度图
cv2.error: C:\projects\opencv-python\opencv\modules\imgproc\src\color.cpp:10600: error: (-215) depth == CV_8U || depth == CV_16U || depth == CV_32F in function cv::cvtColor

Mon, 26 Mar 2018 17:03:37 app_thread.py[line:113] ERROR 刷新失败
Mon, 26 Mar 2018 17:03:37 imgcut.py[line:309] ERROR cut_img 这里出错
Mon, 26 Mar 2018 17:03:37 imgcut.py[line:310] ERROR this is an exception message
Traceback (most recent call last):
  File "F:/BestAssistant\component\imgcut.py", line 302, in cut_img
    set_val('imgpos_lowestprice', img[use_area[0][1]:use_area[0][3], use_area[0][0]:use_area[0][2]])  # ok
IndexError: list index out of range
Mon, 26 Mar 2018 17:03:37 app_thread.py[line:114] ERROR this is an exception message
Traceback (most recent call last):
  File "F:/BestAssistant\component\app_thread.py", line 111, in run
    findrefresh()
  File "F:/BestAssistant\component\imgcut.py", line 324, in findrefresh
    img = cv2.cvtColor(sc, cv2.COLOR_BGR2GRAY)  # 转灰度图
cv2.error: C:\projects\opencv-python\opencv\modules\imgproc\src\color.cpp:10600: error: (-215) depth == CV_8U || depth == CV_16U || depth == CV_32F in function cv::cvtColor

Mon, 26 Mar 2018 17:03:37 imgcut.py[line:309] ERROR cut_img 这里出错
Mon, 26 Mar 2018 17:03:37 imgcut.py[line:310] ERROR this is an exception message
Traceback (most recent call last):
  File "F:/BestAssistant\component\imgcut.py", line 302, in cut_img
    set_val('imgpos_lowestprice', img[use_area[0][1]:use_area[0][3], use_area[0][0]:use_area[0][2]])  # ok
IndexError: list index out of range
Mon, 26 Mar 2018 17:03:37 app_thread.py[line:113] ERROR 刷新失败
Mon, 26 Mar 2018 17:03:37 app_thread.py[line:114] ERROR this is an exception message
Traceback (most recent call last):
  File "F:/BestAssistant\component\app_thread.py", line 111, in run
    findrefresh()
  File "F:/BestAssistant\component\imgcut.py", line 324, in findrefresh
    img = cv2.cvtColor(sc, cv2.COLOR_BGR2GRAY)  # 转灰度图
cv2.error: C:\projects\opencv-python\opencv\modules\imgproc\src\color.cpp:10600: error: (-215) depth == CV_8U || depth == CV_16U || depth == CV_32F in function cv::cvtColor

Mon, 26 Mar 2018 17:03:37 imgcut.py[line:309] ERROR cut_img 这里出错
Mon, 26 Mar 2018 17:03:37 imgcut.py[line:310] ERROR this is an exception message
Traceback (most recent call last):
  File "F:/BestAssistant\component\imgcut.py", line 302, in cut_img
    set_val('imgpos_lowestprice', img[use_area[0][1]:use_area[0][3], use_area[0][0]:use_area[0][2]])  # ok
IndexError: list index out of range
Mon, 26 Mar 2018 17:03:37 imgcut.py[line:309] ERROR cut_img 这里出错
Mon, 26 Mar 2018 17:03:37 imgcut.py[line:310] ERROR this is an exception message
Traceback (most recent call last):
  File "F:/BestAssistant\component\imgcut.py", line 302, in cut_img
    set_val('imgpos_lowestprice', img[use_area[0][1]:use_area[0][3], use_area[0][0]:use_area[0][2]])  # ok
IndexError: list index out of range
Mon, 26 Mar 2018 17:03:37 app_thread.py[line:113] ERROR 刷新失败
Mon, 26 Mar 2018 17:03:37 app_thread.py[line:114] ERROR this is an exception message
Traceback (most recent call last):
  File "F:/BestAssistant\component\app_thread.py", line 111, in run
    findrefresh()
  File "F:/BestAssistant\component\imgcut.py", line 324, in findrefresh
    img = cv2.cvtColor(sc, cv2.COLOR_BGR2GRAY)  # 转灰度图
cv2.error: C:\projects\opencv-python\opencv\modules\imgproc\src\color.cpp:10600: error: (-215) depth == CV_8U || depth == CV_16U || depth == CV_32F in function cv::cvtColor

Mon, 26 Mar 2018 17:03:37 imgcut.py[line:309] ERROR cut_img 这里出错
Mon, 26 Mar 2018 17:03:37 imgcut.py[line:310] ERROR this is an exception message
Traceback (most recent call last):
  File "F:/BestAssistant\component\imgcut.py", line 302, in cut_img
    set_val('imgpos_lowestprice', img[use_area[0][1]:use_area[0][3], use_area[0][0]:use_area[0][2]])  # ok
IndexError: list index out of range
Mon, 26 Mar 2018 17:03:37 app_thread.py[line:113] ERROR 刷新失败
Mon, 26 Mar 2018 17:03:37 app_thread.py[line:114] ERROR this is an exception message
Traceback (most recent call last):
  File "F:/BestAssistant\component\app_thread.py", line 111, in run
    findrefresh()
  File "F:/BestAssistant\component\imgcut.py", line 324, in findrefresh
    img = cv2.cvtColor(sc, cv2.COLOR_BGR2GRAY)  # 转灰度图
cv2.error: C:\projects\opencv-python\opencv\modules\imgproc\src\color.cpp:10600: error: (-215) depth == CV_8U || depth == CV_16U || depth == CV_32F in function cv::cvtColor

Mon, 26 Mar 2018 17:03:37 imgcut.py[line:309] ERROR cut_img 这里出错
Mon, 26 Mar 2018 17:03:37 imgcut.py[line:310] ERROR this is an exception message
Traceback (most recent call last):
  File "F:/BestAssistant\component\imgcut.py", line 302, in cut_img
    set_val('imgpos_lowestprice', img[use_area[0][1]:use_area[0][3], use_area[0][0]:use_area[0][2]])  # ok
IndexError: list index out of range
Mon, 26 Mar 2018 17:03:38 app_thread.py[line:113] ERROR 刷新失败
Mon, 26 Mar 2018 17:03:38 app_thread.py[line:114] ERROR this is an exception message
Traceback (most recent call last):
  File "F:/BestAssistant\component\app_thread.py", line 111, in run
    findrefresh()
  File "F:/BestAssistant\component\imgcut.py", line 324, in findrefresh
    img = cv2.cvtColor(sc, cv2.COLOR_BGR2GRAY)  # 转灰度图
cv2.error: C:\projects\opencv-python\opencv\modules\imgproc\src\color.cpp:10600: error: (-215) depth == CV_8U || depth == CV_16U || depth == CV_32F in function cv::cvtColor

Mon, 26 Mar 2018 17:03:38 imgcut.py[line:309] ERROR cut_img 这里出错
Mon, 26 Mar 2018 17:03:38 imgcut.py[line:310] ERROR this is an exception message
Traceback (most recent call last):
  File "F:/BestAssistant\component\imgcut.py", line 302, in cut_img
    set_val('imgpos_lowestprice', img[use_area[0][1]:use_area[0][3], use_area[0][0]:use_area[0][2]])  # ok
IndexError: list index out of range
Mon, 26 Mar 2018 17:03:38 app_thread.py[line:113] ERROR 刷新失败
Mon, 26 Mar 2018 17:03:38 app_thread.py[line:114] ERROR this is an exception message
Traceback (most recent call last):
  File "F:/BestAssistant\component\app_thread.py", line 111, in run
    findrefresh()
  File "F:/BestAssistant\component\imgcut.py", line 324, in findrefresh
    img = cv2.cvtColor(sc, cv2.COLOR_BGR2GRAY)  # 转灰度图
cv2.error: C:\projects\opencv-python\opencv\modules\imgproc\src\color.cpp:10600: error: (-215) depth == CV_8U || depth == CV_16U || depth == CV_32F in function cv::cvtColor

Mon, 26 Mar 2018 17:03:38 imgcut.py[line:309] ERROR cut_img 这里出错
Mon, 26 Mar 2018 17:03:38 app_thread.py[line:113] ERROR 刷新失败
Mon, 26 Mar 2018 17:03:38 app_thread.py[line:114] ERROR this is an exception message
Traceback (most recent call last):
  File "F:/BestAssistant\component\app_thread.py", line 111, in run
    findrefresh()
  File "F:/BestAssistant\component\imgcut.py", line 324, in findrefresh
    img = cv2.cvtColor(sc, cv2.COLOR_BGR2GRAY)  # 转灰度图
cv2.error: C:\projects\opencv-python\opencv\modules\imgproc\src\color.cpp:10600: error: (-215) depth == CV_8U || depth == CV_16U || depth == CV_32F in function cv::cvtColor

Mon, 26 Mar 2018 17:03:38 imgcut.py[line:310] ERROR this is an exception message
Traceback (most recent call last):
  File "F:/BestAssistant\component\imgcut.py", line 302, in cut_img
    set_val('imgpos_lowestprice', img[use_area[0][1]:use_area[0][3], use_area[0][0]:use_area[0][2]])  # ok
IndexError: list index out of range
Mon, 26 Mar 2018 17:03:38 imgcut.py[line:309] ERROR cut_img 这里出错
Mon, 26 Mar 2018 17:03:38 imgcut.py[line:310] ERROR this is an exception message
Traceback (most recent call last):
  File "F:/BestAssistant\component\imgcut.py", line 302, in cut_img
    set_val('imgpos_lowestprice', img[use_area[0][1]:use_area[0][3], use_area[0][0]:use_area[0][2]])  # ok
IndexError: list index out of range
Mon, 26 Mar 2018 17:03:38 app_thread.py[line:113] ERROR 刷新失败
Mon, 26 Mar 2018 17:03:38 app_thread.py[line:114] ERROR this is an exception message
Traceback (most recent call last):
  File "F:/BestAssistant\component\app_thread.py", line 111, in run
    findrefresh()
  File "F:/BestAssistant\component\imgcut.py", line 324, in findrefresh
    img = cv2.cvtColor(sc, cv2.COLOR_BGR2GRAY)  # 转灰度图
cv2.error: C:\projects\opencv-python\opencv\modules\imgproc\src\color.cpp:10600: error: (-215) depth == CV_8U || depth == CV_16U || depth == CV_32F in function cv::cvtColor

Mon, 26 Mar 2018 17:03:38 imgcut.py[line:309] ERROR cut_img 这里出错
Mon, 26 Mar 2018 17:03:38 imgcut.py[line:310] ERROR this is an exception message
Traceback (most recent call last):
  File "F:/BestAssistant\component\imgcut.py", line 302, in cut_img
    set_val('imgpos_lowestprice', img[use_area[0][1]:use_area[0][3], use_area[0][0]:use_area[0][2]])  # ok
IndexError: list index out of range
Mon, 26 Mar 2018 17:03:38 app_thread.py[line:113] ERROR 刷新失败
Mon, 26 Mar 2018 17:03:38 app_thread.py[line:114] ERROR this is an exception message
Traceback (most recent call last):
  File "F:/BestAssistant\component\app_thread.py", line 111, in run
    findrefresh()
  File "F:/BestAssistant\component\imgcut.py", line 324, in findrefresh
    img = cv2.cvtColor(sc, cv2.COLOR_BGR2GRAY)  # 转灰度图
cv2.error: C:\projects\opencv-python\opencv\modules\imgproc\src\color.cpp:10600: error: (-215) depth == CV_8U || depth == CV_16U || depth == CV_32F in function cv::cvtColor

Mon, 26 Mar 2018 17:03:38 imgcut.py[line:309] ERROR cut_img 这里出错
Mon, 26 Mar 2018 17:03:38 imgcut.py[line:310] ERROR this is an exception message
Traceback (most recent call last):
  File "F:/BestAssistant\component\imgcut.py", line 302, in cut_img
    set_val('imgpos_lowestprice', img[use_area[0][1]:use_area[0][3], use_area[0][0]:use_area[0][2]])  # ok
IndexError: list index out of range
Mon, 26 Mar 2018 17:03:38 app_thread.py[line:113] ERROR 刷新失败
Mon, 26 Mar 2018 17:03:38 app_thread.py[line:114] ERROR this is an exception message
Traceback (most recent call last):
  File "F:/BestAssistant\component\app_thread.py", line 111, in run
    findrefresh()
  File "F:/BestAssistant\component\imgcut.py", line 324, in findrefresh
    img = cv2.cvtColor(sc, cv2.COLOR_BGR2GRAY)  # 转灰度图
cv2.error: C:\projects\opencv-python\opencv\modules\imgproc\src\color.cpp:10600: error: (-215) depth == CV_8U || depth == CV_16U || depth == CV_32F in function cv::cvtColor

Mon, 26 Mar 2018 17:03:38 imgcut.py[line:309] ERROR cut_img 这里出错
Mon, 26 Mar 2018 17:03:38 imgcut.py[line:310] ERROR this is an exception message
Traceback (most recent call last):
  File "F:/BestAssistant\component\imgcut.py", line 302, in cut_img
    set_val('imgpos_lowestprice', img[use_area[0][1]:use_area[0][3], use_area[0][0]:use_area[0][2]])  # ok
IndexError: list index out of range
Mon, 26 Mar 2018 17:03:38 app_thread.py[line:113] ERROR 刷新失败
Mon, 26 Mar 2018 17:03:38 app_thread.py[line:114] ERROR this is an exception message
Traceback (most recent call last):
  File "F:/BestAssistant\component\app_thread.py", line 111, in run
    findrefresh()
  File "F:/BestAssistant\component\imgcut.py", line 324, in findrefresh
    img = cv2.cvtColor(sc, cv2.COLOR_BGR2GRAY)  # 转灰度图
cv2.error: C:\projects\opencv-python\opencv\modules\imgproc\src\color.cpp:10600: error: (-215) depth == CV_8U || depth == CV_16U || depth == CV_32F in function cv::cvtColor

Mon, 26 Mar 2018 17:03:38 app_thread.py[line:113] ERROR 刷新失败
Mon, 26 Mar 2018 17:03:38 app_thread.py[line:114] ERROR this is an exception message
Traceback (most recent call last):
  File "F:/BestAssistant\component\app_thread.py", line 111, in run
    findrefresh()
  File "F:/BestAssistant\component\imgcut.py", line 324, in findrefresh
    img = cv2.cvtColor(sc, cv2.COLOR_BGR2GRAY)  # 转灰度图
cv2.error: C:\projects\opencv-python\opencv\modules\imgproc\src\color.cpp:10600: error: (-215) depth == CV_8U || depth == CV_16U || depth == CV_32F in function cv::cvtColor

Mon, 26 Mar 2018 17:03:38 imgcut.py[line:309] ERROR cut_img 这里出错
Mon, 26 Mar 2018 17:03:38 imgcut.py[line:310] ERROR this is an exception message
Traceback (most recent call last):
  File "F:/BestAssistant\component\imgcut.py", line 302, in cut_img
    set_val('imgpos_lowestprice', img[use_area[0][1]:use_area[0][3], use_area[0][0]:use_area[0][2]])  # ok
IndexError: list index out of range
Mon, 26 Mar 2018 17:03:38 app_thread.py[line:113] ERROR 刷新失败
Mon, 26 Mar 2018 17:03:38 app_thread.py[line:114] ERROR this is an exception message
Traceback (most recent call last):
  File "F:/BestAssistant\component\app_thread.py", line 111, in run
    findrefresh()
  File "F:/BestAssistant\component\imgcut.py", line 324, in findrefresh
    img = cv2.cvtColor(sc, cv2.COLOR_BGR2GRAY)  # 转灰度图
cv2.error: C:\projects\opencv-python\opencv\modules\imgproc\src\color.cpp:10600: error: (-215) depth == CV_8U || depth == CV_16U || depth == CV_32F in function cv::cvtColor

Mon, 26 Mar 2018 17:03:38 imgcut.py[line:309] ERROR cut_img 这里出错
Mon, 26 Mar 2018 17:03:38 imgcut.py[line:310] ERROR this is an exception message
Traceback (most recent call last):
  File "F:/BestAssistant\component\imgcut.py", line 302, in cut_img
    set_val('imgpos_lowestprice', img[use_area[0][1]:use_area[0][3], use_area[0][0]:use_area[0][2]])  # ok
IndexError: list index out of range
Mon, 26 Mar 2018 17:03:38 app_thread.py[line:113] ERROR 刷新失败
Mon, 26 Mar 2018 17:03:38 app_thread.py[line:114] ERROR this is an exception message
Traceback (most recent call last):
  File "F:/BestAssistant\component\app_thread.py", line 111, in run
    findrefresh()
  File "F:/BestAssistant\component\imgcut.py", line 324, in findrefresh
    img = cv2.cvtColor(sc, cv2.COLOR_BGR2GRAY)  # 转灰度图
cv2.error: C:\projects\opencv-python\opencv\modules\imgproc\src\color.cpp:10600: error: (-215) depth == CV_8U || depth == CV_16U || depth == CV_32F in function cv::cvtColor

Mon, 26 Mar 2018 17:03:38 imgcut.py[line:309] ERROR cut_img 这里出错
Mon, 26 Mar 2018 17:03:38 imgcut.py[line:310] ERROR this is an exception message
Traceback (most recent call last):
  File "F:/BestAssistant\component\imgcut.py", line 302, in cut_img
    set_val('imgpos_lowestprice', img[use_area[0][1]:use_area[0][3], use_area[0][0]:use_area[0][2]])  # ok
IndexError: list index out of range
Mon, 26 Mar 2018 17:03:38 app_thread.py[line:113] ERROR 刷新失败
Mon, 26 Mar 2018 17:03:38 app_thread.py[line:114] ERROR this is an exception message
Traceback (most recent call last):
  File "F:/BestAssistant\component\app_thread.py", line 111, in run
    findrefresh()
  File "F:/BestAssistant\component\imgcut.py", line 324, in findrefresh
    img = cv2.cvtColor(sc, cv2.COLOR_BGR2GRAY)  # 转灰度图
cv2.error: C:\projects\opencv-python\opencv\modules\imgproc\src\color.cpp:10600: error: (-215) depth == CV_8U || depth == CV_16U || depth == CV_32F in function cv::cvtColor

Mon, 26 Mar 2018 17:03:38 app_thread.py[line:113] ERROR 刷新失败
Mon, 26 Mar 2018 17:03:38 app_thread.py[line:114] ERROR this is an exception message
Traceback (most recent call last):
  File "F:/BestAssistant\component\app_thread.py", line 111, in run
    findrefresh()
  File "F:/BestAssistant\component\imgcut.py", line 324, in findrefresh
    img = cv2.cvtColor(sc, cv2.COLOR_BGR2GRAY)  # 转灰度图
cv2.error: C:\projects\opencv-python\opencv\modules\imgproc\src\color.cpp:10600: error: (-215) depth == CV_8U || depth == CV_16U || depth == CV_32F in function cv::cvtColor

Mon, 26 Mar 2018 17:03:38 imgcut.py[line:309] ERROR cut_img 这里出错
Mon, 26 Mar 2018 17:03:38 imgcut.py[line:310] ERROR this is an exception message
Traceback (most recent call last):
  File "F:/BestAssistant\component\imgcut.py", line 302, in cut_img
    set_val('imgpos_lowestprice', img[use_area[0][1]:use_area[0][3], use_area[0][0]:use_area[0][2]])  # ok
IndexError: list index out of range
Mon, 26 Mar 2018 17:03:38 app_thread.py[line:113] ERROR 刷新失败
Mon, 26 Mar 2018 17:03:38 app_thread.py[line:114] ERROR this is an exception message
Traceback (most recent call last):
  File "F:/BestAssistant\component\app_thread.py", line 111, in run
    findrefresh()
  File "F:/BestAssistant\component\imgcut.py", line 324, in findrefresh
    img = cv2.cvtColor(sc, cv2.COLOR_BGR2GRAY)  # 转灰度图
cv2.error: C:\projects\opencv-python\opencv\modules\imgproc\src\color.cpp:10600: error: (-215) depth == CV_8U || depth == CV_16U || depth == CV_32F in function cv::cvtColor

Mon, 26 Mar 2018 17:03:38 imgcut.py[line:309] ERROR cut_img 这里出错
Mon, 26 Mar 2018 17:03:38 imgcut.py[line:310] ERROR this is an exception message
Traceback (most recent call last):
  File "F:/BestAssistant\component\imgcut.py", line 302, in cut_img
    set_val('imgpos_lowestprice', img[use_area[0][1]:use_area[0][3], use_area[0][0]:use_area[0][2]])  # ok
IndexError: list index out of range
Mon, 26 Mar 2018 17:03:38 app_thread.py[line:113] ERROR 刷新失败
Mon, 26 Mar 2018 17:03:38 app_thread.py[line:114] ERROR this is an exception message
Traceback (most recent call last):
  File "F:/BestAssistant\component\app_thread.py", line 111, in run
    findrefresh()
  File "F:/BestAssistant\component\imgcut.py", line 324, in findrefresh
    img = cv2.cvtColor(sc, cv2.COLOR_BGR2GRAY)  # 转灰度图
cv2.error: C:\projects\opencv-python\opencv\modules\imgproc\src\color.cpp:10600: error: (-215) depth == CV_8U || depth == CV_16U || depth == CV_32F in function cv::cvtColor

Mon, 26 Mar 2018 17:03:38 imgcut.py[line:309] ERROR cut_img 这里出错
Mon, 26 Mar 2018 17:03:38 imgcut.py[line:310] ERROR this is an exception message
Traceback (most recent call last):
  File "F:/BestAssistant\component\imgcut.py", line 302, in cut_img
    set_val('imgpos_lowestprice', img[use_area[0][1]:use_area[0][3], use_area[0][0]:use_area[0][2]])  # ok
IndexError: list index out of range
Mon, 26 Mar 2018 17:03:38 app_thread.py[line:113] ERROR 刷新失败
Mon, 26 Mar 2018 17:03:38 app_thread.py[line:114] ERROR this is an exception message
Traceback (most recent call last):
  File "F:/BestAssistant\component\app_thread.py", line 111, in run
    findrefresh()
  File "F:/BestAssistant\component\imgcut.py", line 324, in findrefresh
    img = cv2.cvtColor(sc, cv2.COLOR_BGR2GRAY)  # 转灰度图
cv2.error: C:\projects\opencv-python\opencv\modules\imgproc\src\color.cpp:10600: error: (-215) depth == CV_8U || depth == CV_16U || depth == CV_32F in function cv::cvtColor

Mon, 26 Mar 2018 17:03:39 app_thread.py[line:113] ERROR 刷新失败
Mon, 26 Mar 2018 17:03:39 app_thread.py[line:114] ERROR this is an exception message
Traceback (most recent call last):
  File "F:/BestAssistant\component\app_thread.py", line 111, in run
    findrefresh()
  File "F:/BestAssistant\component\imgcut.py", line 324, in findrefresh
    img = cv2.cvtColor(sc, cv2.COLOR_BGR2GRAY)  # 转灰度图
cv2.error: C:\projects\opencv-python\opencv\modules\imgproc\src\color.cpp:10600: error: (-215) depth == CV_8U || depth == CV_16U || depth == CV_32F in function cv::cvtColor

Mon, 26 Mar 2018 17:03:39 imgcut.py[line:309] ERROR cut_img 这里出错
Mon, 26 Mar 2018 17:03:39 imgcut.py[line:310] ERROR this is an exception message
Traceback (most recent call last):
  File "F:/BestAssistant\component\imgcut.py", line 302, in cut_img
    set_val('imgpos_lowestprice', img[use_area[0][1]:use_area[0][3], use_area[0][0]:use_area[0][2]])  # ok
IndexError: list index out of range
Mon, 26 Mar 2018 17:03:39 app_thread.py[line:113] ERROR 刷新失败
Mon, 26 Mar 2018 17:03:39 app_thread.py[line:114] ERROR this is an exception message
Traceback (most recent call last):
  File "F:/BestAssistant\component\app_thread.py", line 111, in run
    findrefresh()
  File "F:/BestAssistant\component\imgcut.py", line 324, in findrefresh
    img = cv2.cvtColor(sc, cv2.COLOR_BGR2GRAY)  # 转灰度图
cv2.error: C:\projects\opencv-python\opencv\modules\imgproc\src\color.cpp:10600: error: (-215) depth == CV_8U || depth == CV_16U || depth == CV_32F in function cv::cvtColor

Mon, 26 Mar 2018 17:03:39 imgcut.py[line:309] ERROR cut_img 这里出错
Mon, 26 Mar 2018 17:03:39 imgcut.py[line:310] ERROR this is an exception message
Traceback (most recent call last):
  File "F:/BestAssistant\component\imgcut.py", line 302, in cut_img
    set_val('imgpos_lowestprice', img[use_area[0][1]:use_area[0][3], use_area[0][0]:use_area[0][2]])  # ok
IndexError: list index out of range
Mon, 26 Mar 2018 17:03:39 app_thread.py[line:113] ERROR 刷新失败
Mon, 26 Mar 2018 17:03:39 app_thread.py[line:114] ERROR this is an exception message
Traceback (most recent call last):
  File "F:/BestAssistant\component\app_thread.py", line 111, in run
    findrefresh()
  File "F:/BestAssistant\component\imgcut.py", line 324, in findrefresh
    img = cv2.cvtColor(sc, cv2.COLOR_BGR2GRAY)  # 转灰度图
cv2.error: C:\projects\opencv-python\opencv\modules\imgproc\src\color.cpp:10600: error: (-215) depth == CV_8U || depth == CV_16U || depth == CV_32F in function cv::cvtColor

Mon, 26 Mar 2018 17:03:39 imgcut.py[line:309] ERROR cut_img 这里出错
Mon, 26 Mar 2018 17:03:39 imgcut.py[line:310] ERROR this is an exception message
Traceback (most recent call last):
  File "F:/BestAssistant\component\imgcut.py", line 302, in cut_img
    set_val('imgpos_lowestprice', img[use_area[0][1]:use_area[0][3], use_area[0][0]:use_area[0][2]])  # ok
IndexError: list index out of range
Mon, 26 Mar 2018 17:03:39 imgcut.py[line:309] ERROR cut_img 这里出错
Mon, 26 Mar 2018 17:03:39 imgcut.py[line:310] ERROR this is an exception message
Traceback (most recent call last):
  File "F:/BestAssistant\component\imgcut.py", line 302, in cut_img
    set_val('imgpos_lowestprice', img[use_area[0][1]:use_area[0][3], use_area[0][0]:use_area[0][2]])  # ok
IndexError: list index out of range
Mon, 26 Mar 2018 17:03:39 app_thread.py[line:113] ERROR 刷新失败
Mon, 26 Mar 2018 17:03:39 app_thread.py[line:114] ERROR this is an exception message
Traceback (most recent call last):
  File "F:/BestAssistant\component\app_thread.py", line 111, in run
    findrefresh()
  File "F:/BestAssistant\component\imgcut.py", line 324, in findrefresh
    img = cv2.cvtColor(sc, cv2.COLOR_BGR2GRAY)  # 转灰度图
cv2.error: C:\projects\opencv-python\opencv\modules\imgproc\src\color.cpp:10600: error: (-215) depth == CV_8U || depth == CV_16U || depth == CV_32F in function cv::cvtColor

Mon, 26 Mar 2018 17:03:39 app_thread.py[line:113] ERROR 刷新失败
Mon, 26 Mar 2018 17:03:39 app_thread.py[line:114] ERROR this is an exception message
Traceback (most recent call last):
  File "F:/BestAssistant\component\app_thread.py", line 111, in run
    findrefresh()
  File "F:/BestAssistant\component\imgcut.py", line 324, in findrefresh
    img = cv2.cvtColor(sc, cv2.COLOR_BGR2GRAY)  # 转灰度图
cv2.error: C:\projects\opencv-python\opencv\modules\imgproc\src\color.cpp:10600: error: (-215) depth == CV_8U || depth == CV_16U || depth == CV_32F in function cv::cvtColor

Mon, 26 Mar 2018 17:03:39 imgcut.py[line:309] ERROR cut_img 这里出错
Mon, 26 Mar 2018 17:03:39 imgcut.py[line:310] ERROR this is an exception message
Traceback (most recent call last):
  File "F:/BestAssistant\component\imgcut.py", line 302, in cut_img
    set_val('imgpos_lowestprice', img[use_area[0][1]:use_area[0][3], use_area[0][0]:use_area[0][2]])  # ok
IndexError: list index out of range
Mon, 26 Mar 2018 17:03:39 app_thread.py[line:113] ERROR 刷新失败
Mon, 26 Mar 2018 17:03:39 app_thread.py[line:114] ERROR this is an exception message
Traceback (most recent call last):
  File "F:/BestAssistant\component\app_thread.py", line 111, in run
    findrefresh()
  File "F:/BestAssistant\component\imgcut.py", line 324, in findrefresh
    img = cv2.cvtColor(sc, cv2.COLOR_BGR2GRAY)  # 转灰度图
cv2.error: C:\projects\opencv-python\opencv\modules\imgproc\src\color.cpp:10600: error: (-215) depth == CV_8U || depth == CV_16U || depth == CV_32F in function cv::cvtColor

Mon, 26 Mar 2018 17:03:39 imgcut.py[line:309] ERROR cut_img 这里出错
Mon, 26 Mar 2018 17:03:39 imgcut.py[line:310] ERROR this is an exception message
Traceback (most recent call last):
  File "F:/BestAssistant\component\imgcut.py", line 302, in cut_img
    set_val('imgpos_lowestprice', img[use_area[0][1]:use_area[0][3], use_area[0][0]:use_area[0][2]])  # ok
IndexError: list index out of range
Mon, 26 Mar 2018 17:03:39 app_thread.py[line:113] ERROR 刷新失败
Mon, 26 Mar 2018 17:03:39 app_thread.py[line:114] ERROR this is an exception message
Traceback (most recent call last):
  File "F:/BestAssistant\component\app_thread.py", line 111, in run
    findrefresh()
  File "F:/BestAssistant\component\imgcut.py", line 324, in findrefresh
    img = cv2.cvtColor(sc, cv2.COLOR_BGR2GRAY)  # 转灰度图
cv2.error: C:\projects\opencv-python\opencv\modules\imgproc\src\color.cpp:10600: error: (-215) depth == CV_8U || depth == CV_16U || depth == CV_32F in function cv::cvtColor

Mon, 26 Mar 2018 17:03:39 imgcut.py[line:309] ERROR cut_img 这里出错
Mon, 26 Mar 2018 17:03:39 imgcut.py[line:310] ERROR this is an exception message
Traceback (most recent call last):
  File "F:/BestAssistant\component\imgcut.py", line 302, in cut_img
    set_val('imgpos_lowestprice', img[use_area[0][1]:use_area[0][3], use_area[0][0]:use_area[0][2]])  # ok
IndexError: list index out of range
Mon, 26 Mar 2018 17:03:39 app_thread.py[line:113] ERROR 刷新失败
Mon, 26 Mar 2018 17:03:39 app_thread.py[line:114] ERROR this is an exception message
Traceback (most recent call last):
  File "F:/BestAssistant\component\app_thread.py", line 111, in run
    findrefresh()
  File "F:/BestAssistant\component\imgcut.py", line 324, in findrefresh
    img = cv2.cvtColor(sc, cv2.COLOR_BGR2GRAY)  # 转灰度图
cv2.error: C:\projects\opencv-python\opencv\modules\imgproc\src\color.cpp:10600: error: (-215) depth == CV_8U || depth == CV_16U || depth == CV_32F in function cv::cvtColor

Mon, 26 Mar 2018 17:03:39 imgcut.py[line:309] ERROR cut_img 这里出错
Mon, 26 Mar 2018 17:03:39 imgcut.py[line:310] ERROR this is an exception message
Traceback (most recent call last):
  File "F:/BestAssistant\component\imgcut.py", line 302, in cut_img
    set_val('imgpos_lowestprice', img[use_area[0][1]:use_area[0][3], use_area[0][0]:use_area[0][2]])  # ok
IndexError: list index out of range
Mon, 26 Mar 2018 17:03:39 imgcut.py[line:309] ERROR cut_img 这里出错
Mon, 26 Mar 2018 17:03:39 imgcut.py[line:310] ERROR this is an exception message
Traceback (most recent call last):
  File "F:/BestAssistant\component\imgcut.py", line 302, in cut_img
    set_val('imgpos_lowestprice', img[use_area[0][1]:use_area[0][3], use_area[0][0]:use_area[0][2]])  # ok
IndexError: list index out of range
Mon, 26 Mar 2018 17:03:39 app_thread.py[line:113] ERROR 刷新失败
Mon, 26 Mar 2018 17:03:39 app_thread.py[line:114] ERROR this is an exception message
Traceback (most recent call last):
  File "F:/BestAssistant\component\app_thread.py", line 111, in run
    findrefresh()
  File "F:/BestAssistant\component\imgcut.py", line 324, in findrefresh
    img = cv2.cvtColor(sc, cv2.COLOR_BGR2GRAY)  # 转灰度图
cv2.error: C:\projects\opencv-python\opencv\modules\imgproc\src\color.cpp:10600: error: (-215) depth == CV_8U || depth == CV_16U || depth == CV_32F in function cv::cvtColor

Mon, 26 Mar 2018 17:03:39 imgcut.py[line:309] ERROR cut_img 这里出错
Mon, 26 Mar 2018 17:03:39 imgcut.py[line:310] ERROR this is an exception message
Traceback (most recent call last):
  File "F:/BestAssistant\component\imgcut.py", line 302, in cut_img
    set_val('imgpos_lowestprice', img[use_area[0][1]:use_area[0][3], use_area[0][0]:use_area[0][2]])  # ok
IndexError: list index out of range
Mon, 26 Mar 2018 17:03:39 app_thread.py[line:113] ERROR 刷新失败
Mon, 26 Mar 2018 17:03:39 app_thread.py[line:114] ERROR this is an exception message
Traceback (most recent call last):
  File "F:/BestAssistant\component\app_thread.py", line 111, in run
    findrefresh()
  File "F:/BestAssistant\component\imgcut.py", line 324, in findrefresh
    img = cv2.cvtColor(sc, cv2.COLOR_BGR2GRAY)  # 转灰度图
cv2.error: C:\projects\opencv-python\opencv\modules\imgproc\src\color.cpp:10600: error: (-215) depth == CV_8U || depth == CV_16U || depth == CV_32F in function cv::cvtColor

Mon, 26 Mar 2018 17:03:39 imgcut.py[line:309] ERROR cut_img 这里出错
Mon, 26 Mar 2018 17:03:39 imgcut.py[line:310] ERROR this is an exception message
Traceback (most recent call last):
  File "F:/BestAssistant\component\imgcut.py", line 302, in cut_img
    set_val('imgpos_lowestprice', img[use_area[0][1]:use_area[0][3], use_area[0][0]:use_area[0][2]])  # ok
IndexError: list index out of range
Mon, 26 Mar 2018 17:03:39 app_thread.py[line:113] ERROR 刷新失败
Mon, 26 Mar 2018 17:03:39 app_thread.py[line:114] ERROR this is an exception message
Traceback (most recent call last):
  File "F:/BestAssistant\component\app_thread.py", line 111, in run
    findrefresh()
  File "F:/BestAssistant\component\imgcut.py", line 324, in findrefresh
    img = cv2.cvtColor(sc, cv2.COLOR_BGR2GRAY)  # 转灰度图
cv2.error: C:\projects\opencv-python\opencv\modules\imgproc\src\color.cpp:10600: error: (-215) depth == CV_8U || depth == CV_16U || depth == CV_32F in function cv::cvtColor

Mon, 26 Mar 2018 17:03:39 imgcut.py[line:309] ERROR cut_img 这里出错
Mon, 26 Mar 2018 17:03:39 imgcut.py[line:310] ERROR this is an exception message
Traceback (most recent call last):
  File "F:/BestAssistant\component\imgcut.py", line 302, in cut_img
    set_val('imgpos_lowestprice', img[use_area[0][1]:use_area[0][3], use_area[0][0]:use_area[0][2]])  # ok
IndexError: list index out of range
Mon, 26 Mar 2018 17:03:39 app_thread.py[line:113] ERROR 刷新失败
Mon, 26 Mar 2018 17:03:39 app_thread.py[line:114] ERROR this is an exception message
Traceback (most recent call last):
  File "F:/BestAssistant\component\app_thread.py", line 111, in run
    findrefresh()
  File "F:/BestAssistant\component\imgcut.py", line 324, in findrefresh
    img = cv2.cvtColor(sc, cv2.COLOR_BGR2GRAY)  # 转灰度图
cv2.error: C:\projects\opencv-python\opencv\modules\imgproc\src\color.cpp:10600: error: (-215) depth == CV_8U || depth == CV_16U || depth == CV_32F in function cv::cvtColor

Mon, 26 Mar 2018 17:03:39 imgcut.py[line:309] ERROR cut_img 这里出错
Mon, 26 Mar 2018 17:03:39 imgcut.py[line:310] ERROR this is an exception message
Traceback (most recent call last):
  File "F:/BestAssistant\component\imgcut.py", line 302, in cut_img
    set_val('imgpos_lowestprice', img[use_area[0][1]:use_area[0][3], use_area[0][0]:use_area[0][2]])  # ok
IndexError: list index out of range
Mon, 26 Mar 2018 17:03:39 app_thread.py[line:113] ERROR 刷新失败
Mon, 26 Mar 2018 17:03:39 app_thread.py[line:114] ERROR this is an exception message
Traceback (most recent call last):
  File "F:/BestAssistant\component\app_thread.py", line 111, in run
    findrefresh()
  File "F:/BestAssistant\component\imgcut.py", line 324, in findrefresh
    img = cv2.cvtColor(sc, cv2.COLOR_BGR2GRAY)  # 转灰度图
cv2.error: C:\projects\opencv-python\opencv\modules\imgproc\src\color.cpp:10600: error: (-215) depth == CV_8U || depth == CV_16U || depth == CV_32F in function cv::cvtColor

Mon, 26 Mar 2018 17:03:39 imgcut.py[line:309] ERROR cut_img 这里出错
Mon, 26 Mar 2018 17:03:39 imgcut.py[line:310] ERROR this is an exception message
Traceback (most recent call last):
  File "F:/BestAssistant\component\imgcut.py", line 302, in cut_img
    set_val('imgpos_lowestprice', img[use_area[0][1]:use_area[0][3], use_area[0][0]:use_area[0][2]])  # ok
IndexError: list index out of range
Mon, 26 Mar 2018 17:03:39 app_thread.py[line:113] ERROR 刷新失败
Mon, 26 Mar 2018 17:03:39 app_thread.py[line:114] ERROR this is an exception message
Traceback (most recent call last):
  File "F:/BestAssistant\component\app_thread.py", line 111, in run
    findrefresh()
  File "F:/BestAssistant\component\imgcut.py", line 324, in findrefresh
    img = cv2.cvtColor(sc, cv2.COLOR_BGR2GRAY)  # 转灰度图
cv2.error: C:\projects\opencv-python\opencv\modules\imgproc\src\color.cpp:10600: error: (-215) depth == CV_8U || depth == CV_16U || depth == CV_32F in function cv::cvtColor

Mon, 26 Mar 2018 17:03:40 imgcut.py[line:309] ERROR cut_img 这里出错
Mon, 26 Mar 2018 17:03:40 imgcut.py[line:310] ERROR this is an exception message
Traceback (most recent call last):
  File "F:/BestAssistant\component\imgcut.py", line 302, in cut_img
    set_val('imgpos_lowestprice', img[use_area[0][1]:use_area[0][3], use_area[0][0]:use_area[0][2]])  # ok
IndexError: list index out of range
Mon, 26 Mar 2018 17:03:40 app_thread.py[line:113] ERROR 刷新失败
Mon, 26 Mar 2018 17:03:40 app_thread.py[line:114] ERROR this is an exception message
Traceback (most recent call last):
  File "F:/BestAssistant\component\app_thread.py", line 111, in run
    findrefresh()
  File "F:/BestAssistant\component\imgcut.py", line 324, in findrefresh
    img = cv2.cvtColor(sc, cv2.COLOR_BGR2GRAY)  # 转灰度图
cv2.error: C:\projects\opencv-python\opencv\modules\imgproc\src\color.cpp:10600: error: (-215) depth == CV_8U || depth == CV_16U || depth == CV_32F in function cv::cvtColor

Mon, 26 Mar 2018 17:03:40 imgcut.py[line:309] ERROR cut_img 这里出错
Mon, 26 Mar 2018 17:03:40 imgcut.py[line:310] ERROR this is an exception message
Traceback (most recent call last):
  File "F:/BestAssistant\component\imgcut.py", line 302, in cut_img
    set_val('imgpos_lowestprice', img[use_area[0][1]:use_area[0][3], use_area[0][0]:use_area[0][2]])  # ok
IndexError: list index out of range
Mon, 26 Mar 2018 17:03:40 app_thread.py[line:113] ERROR 刷新失败
Mon, 26 Mar 2018 17:03:40 app_thread.py[line:114] ERROR this is an exception message
Traceback (most recent call last):
  File "F:/BestAssistant\component\app_thread.py", line 111, in run
    findrefresh()
  File "F:/BestAssistant\component\imgcut.py", line 324, in findrefresh
    img = cv2.cvtColor(sc, cv2.COLOR_BGR2GRAY)  # 转灰度图
cv2.error: C:\projects\opencv-python\opencv\modules\imgproc\src\color.cpp:10600: error: (-215) depth == CV_8U || depth == CV_16U || depth == CV_32F in function cv::cvtColor

Mon, 26 Mar 2018 17:03:40 imgcut.py[line:309] ERROR cut_img 这里出错
Mon, 26 Mar 2018 17:03:40 imgcut.py[line:310] ERROR this is an exception message
Traceback (most recent call last):
  File "F:/BestAssistant\component\imgcut.py", line 302, in cut_img
    set_val('imgpos_lowestprice', img[use_area[0][1]:use_area[0][3], use_area[0][0]:use_area[0][2]])  # ok
IndexError: list index out of range
Mon, 26 Mar 2018 17:03:40 app_thread.py[line:113] ERROR 刷新失败
Mon, 26 Mar 2018 17:03:40 app_thread.py[line:114] ERROR this is an exception message
Traceback (most recent call last):
  File "F:/BestAssistant\component\app_thread.py", line 111, in run
    findrefresh()
  File "F:/BestAssistant\component\imgcut.py", line 324, in findrefresh
    img = cv2.cvtColor(sc, cv2.COLOR_BGR2GRAY)  # 转灰度图
cv2.error: C:\projects\opencv-python\opencv\modules\imgproc\src\color.cpp:10600: error: (-215) depth == CV_8U || depth == CV_16U || depth == CV_32F in function cv::cvtColor

Mon, 26 Mar 2018 17:03:40 imgcut.py[line:309] ERROR cut_img 这里出错
Mon, 26 Mar 2018 17:03:40 imgcut.py[line:310] ERROR this is an exception message
Traceback (most recent call last):
  File "F:/BestAssistant\component\imgcut.py", line 302, in cut_img
    set_val('imgpos_lowestprice', img[use_area[0][1]:use_area[0][3], use_area[0][0]:use_area[0][2]])  # ok
IndexError: list index out of range
Mon, 26 Mar 2018 17:03:40 imgcut.py[line:309] ERROR cut_img 这里出错
Mon, 26 Mar 2018 17:03:40 imgcut.py[line:310] ERROR this is an exception message
Traceback (most recent call last):
  File "F:/BestAssistant\component\imgcut.py", line 302, in cut_img
    set_val('imgpos_lowestprice', img[use_area[0][1]:use_area[0][3], use_area[0][0]:use_area[0][2]])  # ok
IndexError: list index out of range
Mon, 26 Mar 2018 17:03:40 app_thread.py[line:113] ERROR 刷新失败
Mon, 26 Mar 2018 17:03:40 app_thread.py[line:114] ERROR this is an exception message
Traceback (most recent call last):
  File "F:/BestAssistant\component\app_thread.py", line 111, in run
    findrefresh()
  File "F:/BestAssistant\component\imgcut.py", line 324, in findrefresh
    img = cv2.cvtColor(sc, cv2.COLOR_BGR2GRAY)  # 转灰度图
cv2.error: C:\projects\opencv-python\opencv\modules\imgproc\src\color.cpp:10600: error: (-215) depth == CV_8U || depth == CV_16U || depth == CV_32F in function cv::cvtColor

Mon, 26 Mar 2018 17:03:40 app_thread.py[line:113] ERROR 刷新失败
Mon, 26 Mar 2018 17:03:40 app_thread.py[line:114] ERROR this is an exception message
Traceback (most recent call last):
  File "F:/BestAssistant\component\app_thread.py", line 111, in run
    findrefresh()
  File "F:/BestAssistant\component\imgcut.py", line 324, in findrefresh
    img = cv2.cvtColor(sc, cv2.COLOR_BGR2GRAY)  # 转灰度图
cv2.error: C:\projects\opencv-python\opencv\modules\imgproc\src\color.cpp:10600: error: (-215) depth == CV_8U || depth == CV_16U || depth == CV_32F in function cv::cvtColor

Mon, 26 Mar 2018 17:03:40 imgcut.py[line:309] ERROR cut_img 这里出错
Mon, 26 Mar 2018 17:03:40 imgcut.py[line:310] ERROR this is an exception message
Traceback (most recent call last):
  File "F:/BestAssistant\component\imgcut.py", line 302, in cut_img
    set_val('imgpos_lowestprice', img[use_area[0][1]:use_area[0][3], use_area[0][0]:use_area[0][2]])  # ok
IndexError: list index out of range
Mon, 26 Mar 2018 17:03:40 app_thread.py[line:113] ERROR 刷新失败
Mon, 26 Mar 2018 17:03:40 app_thread.py[line:114] ERROR this is an exception message
Traceback (most recent call last):
  File "F:/BestAssistant\component\app_thread.py", line 111, in run
    findrefresh()
  File "F:/BestAssistant\component\imgcut.py", line 324, in findrefresh
    img = cv2.cvtColor(sc, cv2.COLOR_BGR2GRAY)  # 转灰度图
cv2.error: C:\projects\opencv-python\opencv\modules\imgproc\src\color.cpp:10600: error: (-215) depth == CV_8U || depth == CV_16U || depth == CV_32F in function cv::cvtColor

Mon, 26 Mar 2018 17:03:40 imgcut.py[line:309] ERROR cut_img 这里出错
Mon, 26 Mar 2018 17:03:40 imgcut.py[line:310] ERROR this is an exception message
Traceback (most recent call last):
  File "F:/BestAssistant\component\imgcut.py", line 302, in cut_img
    set_val('imgpos_lowestprice', img[use_area[0][1]:use_area[0][3], use_area[0][0]:use_area[0][2]])  # ok
IndexError: list index out of range
Mon, 26 Mar 2018 17:03:40 app_thread.py[line:113] ERROR 刷新失败
Mon, 26 Mar 2018 17:03:40 app_thread.py[line:114] ERROR this is an exception message
Traceback (most recent call last):
  File "F:/BestAssistant\component\app_thread.py", line 111, in run
    findrefresh()
  File "F:/BestAssistant\component\imgcut.py", line 324, in findrefresh
    img = cv2.cvtColor(sc, cv2.COLOR_BGR2GRAY)  # 转灰度图
cv2.error: C:\projects\opencv-python\opencv\modules\imgproc\src\color.cpp:10600: error: (-215) depth == CV_8U || depth == CV_16U || depth == CV_32F in function cv::cvtColor

Mon, 26 Mar 2018 17:03:40 imgcut.py[line:309] ERROR cut_img 这里出错
Mon, 26 Mar 2018 17:03:40 imgcut.py[line:310] ERROR this is an exception message
Traceback (most recent call last):
  File "F:/BestAssistant\component\imgcut.py", line 302, in cut_img
    set_val('imgpos_lowestprice', img[use_area[0][1]:use_area[0][3], use_area[0][0]:use_area[0][2]])  # ok
IndexError: list index out of range
Mon, 26 Mar 2018 17:03:40 imgcut.py[line:309] ERROR cut_img 这里出错
Mon, 26 Mar 2018 17:03:40 imgcut.py[line:310] ERROR this is an exception message
Traceback (most recent call last):
  File "F:/BestAssistant\component\imgcut.py", line 302, in cut_img
    set_val('imgpos_lowestprice', img[use_area[0][1]:use_area[0][3], use_area[0][0]:use_area[0][2]])  # ok
IndexError: list index out of range
Mon, 26 Mar 2018 17:03:40 imgcut.py[line:309] ERROR cut_img 这里出错
Mon, 26 Mar 2018 17:03:40 imgcut.py[line:310] ERROR this is an exception message
Traceback (most recent call last):
  File "F:/BestAssistant\component\imgcut.py", line 302, in cut_img
    set_val('imgpos_lowestprice', img[use_area[0][1]:use_area[0][3], use_area[0][0]:use_area[0][2]])  # ok
IndexError: list index out of range
Mon, 26 Mar 2018 17:03:40 app_thread.py[line:113] ERROR 刷新失败
Mon, 26 Mar 2018 17:03:40 app_thread.py[line:114] ERROR this is an exception message
Traceback (most recent call last):
  File "F:/BestAssistant\component\app_thread.py", line 111, in run
    findrefresh()
  File "F:/BestAssistant\component\imgcut.py", line 324, in findrefresh
    img = cv2.cvtColor(sc, cv2.COLOR_BGR2GRAY)  # 转灰度图
cv2.error: C:\projects\opencv-python\opencv\modules\imgproc\src\color.cpp:10600: error: (-215) depth == CV_8U || depth == CV_16U || depth == CV_32F in function cv::cvtColor

Mon, 26 Mar 2018 17:03:40 imgcut.py[line:309] ERROR cut_img 这里出错
Mon, 26 Mar 2018 17:03:40 imgcut.py[line:310] ERROR this is an exception message
Traceback (most recent call last):
  File "F:/BestAssistant\component\imgcut.py", line 302, in cut_img
    set_val('imgpos_lowestprice', img[use_area[0][1]:use_area[0][3], use_area[0][0]:use_area[0][2]])  # ok
IndexError: list index out of range
Mon, 26 Mar 2018 17:03:40 app_thread.py[line:113] ERROR 刷新失败
Mon, 26 Mar 2018 17:03:40 app_thread.py[line:114] ERROR this is an exception message
Traceback (most recent call last):
  File "F:/BestAssistant\component\app_thread.py", line 111, in run
    findrefresh()
  File "F:/BestAssistant\component\imgcut.py", line 324, in findrefresh
    img = cv2.cvtColor(sc, cv2.COLOR_BGR2GRAY)  # 转灰度图
cv2.error: C:\projects\opencv-python\opencv\modules\imgproc\src\color.cpp:10600: error: (-215) depth == CV_8U || depth == CV_16U || depth == CV_32F in function cv::cvtColor

Mon, 26 Mar 2018 17:03:40 app_thread.py[line:113] ERROR 刷新失败
Mon, 26 Mar 2018 17:03:40 app_thread.py[line:114] ERROR this is an exception message
Traceback (most recent call last):
  File "F:/BestAssistant\component\app_thread.py", line 111, in run
    findrefresh()
  File "F:/BestAssistant\component\imgcut.py", line 324, in findrefresh
    img = cv2.cvtColor(sc, cv2.COLOR_BGR2GRAY)  # 转灰度图
cv2.error: C:\projects\opencv-python\opencv\modules\imgproc\src\color.cpp:10600: error: (-215) depth == CV_8U || depth == CV_16U || depth == CV_32F in function cv::cvtColor

Mon, 26 Mar 2018 17:03:40 imgcut.py[line:309] ERROR cut_img 这里出错
Mon, 26 Mar 2018 17:03:40 imgcut.py[line:310] ERROR this is an exception message
Traceback (most recent call last):
  File "F:/BestAssistant\component\imgcut.py", line 302, in cut_img
    set_val('imgpos_lowestprice', img[use_area[0][1]:use_area[0][3], use_area[0][0]:use_area[0][2]])  # ok
IndexError: list index out of range
Mon, 26 Mar 2018 17:03:40 imgcut.py[line:309] ERROR cut_img 这里出错
Mon, 26 Mar 2018 17:03:40 imgcut.py[line:310] ERROR this is an exception message
Traceback (most recent call last):
  File "F:/BestAssistant\component\imgcut.py", line 302, in cut_img
    set_val('imgpos_lowestprice', img[use_area[0][1]:use_area[0][3], use_area[0][0]:use_area[0][2]])  # ok
IndexError: list index out of range
Mon, 26 Mar 2018 17:03:40 app_thread.py[line:113] ERROR 刷新失败
Mon, 26 Mar 2018 17:03:40 app_thread.py[line:114] ERROR this is an exception message
Traceback (most recent call last):
  File "F:/BestAssistant\component\app_thread.py", line 111, in run
    findrefresh()
  File "F:/BestAssistant\component\imgcut.py", line 324, in findrefresh
    img = cv2.cvtColor(sc, cv2.COLOR_BGR2GRAY)  # 转灰度图
cv2.error: C:\projects\opencv-python\opencv\modules\imgproc\src\color.cpp:10600: error: (-215) depth == CV_8U || depth == CV_16U || depth == CV_32F in function cv::cvtColor

Mon, 26 Mar 2018 17:03:40 imgcut.py[line:309] ERROR cut_img 这里出错
Mon, 26 Mar 2018 17:03:40 imgcut.py[line:310] ERROR this is an exception message
Traceback (most recent call last):
  File "F:/BestAssistant\component\imgcut.py", line 302, in cut_img
    set_val('imgpos_lowestprice', img[use_area[0][1]:use_area[0][3], use_area[0][0]:use_area[0][2]])  # ok
IndexError: list index out of range
Mon, 26 Mar 2018 17:03:40 app_thread.py[line:113] ERROR 刷新失败
Mon, 26 Mar 2018 17:03:40 app_thread.py[line:114] ERROR this is an exception message
Traceback (most recent call last):
  File "F:/BestAssistant\component\app_thread.py", line 111, in run
    findrefresh()
  File "F:/BestAssistant\component\imgcut.py", line 324, in findrefresh
    img = cv2.cvtColor(sc, cv2.COLOR_BGR2GRAY)  # 转灰度图
cv2.error: C:\projects\opencv-python\opencv\modules\imgproc\src\color.cpp:10600: error: (-215) depth == CV_8U || depth == CV_16U || depth == CV_32F in function cv::cvtColor

Mon, 26 Mar 2018 17:03:40 imgcut.py[line:309] ERROR cut_img 这里出错
Mon, 26 Mar 2018 17:03:40 imgcut.py[line:310] ERROR this is an exception message
Traceback (most recent call last):
  File "F:/BestAssistant\component\imgcut.py", line 302, in cut_img
    set_val('imgpos_lowestprice', img[use_area[0][1]:use_area[0][3], use_area[0][0]:use_area[0][2]])  # ok
IndexError: list index out of range
Mon, 26 Mar 2018 17:03:41 app_thread.py[line:113] ERROR 刷新失败
Mon, 26 Mar 2018 17:03:41 app_thread.py[line:114] ERROR this is an exception message
Traceback (most recent call last):
  File "F:/BestAssistant\component\app_thread.py", line 111, in run
    findrefresh()
  File "F:/BestAssistant\component\imgcut.py", line 324, in findrefresh
    img = cv2.cvtColor(sc, cv2.COLOR_BGR2GRAY)  # 转灰度图
cv2.error: C:\projects\opencv-python\opencv\modules\imgproc\src\color.cpp:10600: error: (-215) depth == CV_8U || depth == CV_16U || depth == CV_32F in function cv::cvtColor

Mon, 26 Mar 2018 17:03:41 imgcut.py[line:309] ERROR cut_img 这里出错
Mon, 26 Mar 2018 17:03:41 imgcut.py[line:310] ERROR this is an exception message
Traceback (most recent call last):
  File "F:/BestAssistant\component\imgcut.py", line 302, in cut_img
    set_val('imgpos_lowestprice', img[use_area[0][1]:use_area[0][3], use_area[0][0]:use_area[0][2]])  # ok
IndexError: list index out of range
Mon, 26 Mar 2018 17:03:41 app_thread.py[line:113] ERROR 刷新失败
Mon, 26 Mar 2018 17:03:41 app_thread.py[line:114] ERROR this is an exception message
Traceback (most recent call last):
  File "F:/BestAssistant\component\app_thread.py", line 111, in run
    findrefresh()
  File "F:/BestAssistant\component\imgcut.py", line 324, in findrefresh
    img = cv2.cvtColor(sc, cv2.COLOR_BGR2GRAY)  # 转灰度图
cv2.error: C:\projects\opencv-python\opencv\modules\imgproc\src\color.cpp:10600: error: (-215) depth == CV_8U || depth == CV_16U || depth == CV_32F in function cv::cvtColor

Mon, 26 Mar 2018 17:03:41 imgcut.py[line:309] ERROR cut_img 这里出错
Mon, 26 Mar 2018 17:03:41 imgcut.py[line:310] ERROR this is an exception message
Traceback (most recent call last):
  File "F:/BestAssistant\component\imgcut.py", line 302, in cut_img
    set_val('imgpos_lowestprice', img[use_area[0][1]:use_area[0][3], use_area[0][0]:use_area[0][2]])  # ok
IndexError: list index out of range
Mon, 26 Mar 2018 17:03:41 app_thread.py[line:113] ERROR 刷新失败
Mon, 26 Mar 2018 17:03:41 app_thread.py[line:114] ERROR this is an exception message
Traceback (most recent call last):
  File "F:/BestAssistant\component\app_thread.py", line 111, in run
    findrefresh()
  File "F:/BestAssistant\component\imgcut.py", line 324, in findrefresh
    img = cv2.cvtColor(sc, cv2.COLOR_BGR2GRAY)  # 转灰度图
cv2.error: C:\projects\opencv-python\opencv\modules\imgproc\src\color.cpp:10600: error: (-215) depth == CV_8U || depth == CV_16U || depth == CV_32F in function cv::cvtColor

Mon, 26 Mar 2018 17:03:41 app_thread.py[line:113] ERROR 刷新失败
Mon, 26 Mar 2018 17:03:41 app_thread.py[line:114] ERROR this is an exception message
Traceback (most recent call last):
  File "F:/BestAssistant\component\app_thread.py", line 111, in run
    findrefresh()
  File "F:/BestAssistant\component\imgcut.py", line 324, in findrefresh
    img = cv2.cvtColor(sc, cv2.COLOR_BGR2GRAY)  # 转灰度图
cv2.error: C:\projects\opencv-python\opencv\modules\imgproc\src\color.cpp:10600: error: (-215) depth == CV_8U || depth == CV_16U || depth == CV_32F in function cv::cvtColor

Mon, 26 Mar 2018 17:03:41 imgcut.py[line:309] ERROR cut_img 这里出错
Mon, 26 Mar 2018 17:03:41 imgcut.py[line:310] ERROR this is an exception message
Traceback (most recent call last):
  File "F:/BestAssistant\component\imgcut.py", line 302, in cut_img
    set_val('imgpos_lowestprice', img[use_area[0][1]:use_area[0][3], use_area[0][0]:use_area[0][2]])  # ok
IndexError: list index out of range
Mon, 26 Mar 2018 17:03:41 app_thread.py[line:113] ERROR 刷新失败
Mon, 26 Mar 2018 17:03:41 imgcut.py[line:309] ERROR cut_img 这里出错
Mon, 26 Mar 2018 17:03:41 app_thread.py[line:114] ERROR this is an exception message
Traceback (most recent call last):
  File "F:/BestAssistant\component\app_thread.py", line 111, in run
    findrefresh()
  File "F:/BestAssistant\component\imgcut.py", line 324, in findrefresh
    img = cv2.cvtColor(sc, cv2.COLOR_BGR2GRAY)  # 转灰度图
cv2.error: C:\projects\opencv-python\opencv\modules\imgproc\src\color.cpp:10600: error: (-215) depth == CV_8U || depth == CV_16U || depth == CV_32F in function cv::cvtColor

Mon, 26 Mar 2018 17:03:41 imgcut.py[line:310] ERROR this is an exception message
Traceback (most recent call last):
  File "F:/BestAssistant\component\imgcut.py", line 302, in cut_img
    set_val('imgpos_lowestprice', img[use_area[0][1]:use_area[0][3], use_area[0][0]:use_area[0][2]])  # ok
IndexError: list index out of range
Mon, 26 Mar 2018 17:03:41 app_thread.py[line:113] ERROR 刷新失败
Mon, 26 Mar 2018 17:03:41 app_thread.py[line:114] ERROR this is an exception message
Traceback (most recent call last):
  File "F:/BestAssistant\component\app_thread.py", line 111, in run
    findrefresh()
  File "F:/BestAssistant\component\imgcut.py", line 324, in findrefresh
    img = cv2.cvtColor(sc, cv2.COLOR_BGR2GRAY)  # 转灰度图
cv2.error: C:\projects\opencv-python\opencv\modules\imgproc\src\color.cpp:10600: error: (-215) depth == CV_8U || depth == CV_16U || depth == CV_32F in function cv::cvtColor

Mon, 26 Mar 2018 17:03:41 imgcut.py[line:309] ERROR cut_img 这里出错
Mon, 26 Mar 2018 17:03:41 imgcut.py[line:310] ERROR this is an exception message
Traceback (most recent call last):
  File "F:/BestAssistant\component\imgcut.py", line 302, in cut_img
    set_val('imgpos_lowestprice', img[use_area[0][1]:use_area[0][3], use_area[0][0]:use_area[0][2]])  # ok
IndexError: list index out of range
Mon, 26 Mar 2018 17:03:41 app_thread.py[line:113] ERROR 刷新失败
Mon, 26 Mar 2018 17:03:41 app_thread.py[line:114] ERROR this is an exception message
Traceback (most recent call last):
  File "F:/BestAssistant\component\app_thread.py", line 111, in run
    findrefresh()
  File "F:/BestAssistant\component\imgcut.py", line 324, in findrefresh
    img = cv2.cvtColor(sc, cv2.COLOR_BGR2GRAY)  # 转灰度图
cv2.error: C:\projects\opencv-python\opencv\modules\imgproc\src\color.cpp:10600: error: (-215) depth == CV_8U || depth == CV_16U || depth == CV_32F in function cv::cvtColor

Mon, 26 Mar 2018 17:03:41 imgcut.py[line:309] ERROR cut_img 这里出错
Mon, 26 Mar 2018 17:03:41 imgcut.py[line:310] ERROR this is an exception message
Traceback (most recent call last):
  File "F:/BestAssistant\component\imgcut.py", line 302, in cut_img
    set_val('imgpos_lowestprice', img[use_area[0][1]:use_area[0][3], use_area[0][0]:use_area[0][2]])  # ok
IndexError: list index out of range
Mon, 26 Mar 2018 17:03:41 imgcut.py[line:309] ERROR cut_img 这里出错
Mon, 26 Mar 2018 17:03:41 app_thread.py[line:113] ERROR 刷新失败
Mon, 26 Mar 2018 17:03:41 imgcut.py[line:310] ERROR this is an exception message
Traceback (most recent call last):
  File "F:/BestAssistant\component\imgcut.py", line 302, in cut_img
    set_val('imgpos_lowestprice', img[use_area[0][1]:use_area[0][3], use_area[0][0]:use_area[0][2]])  # ok
IndexError: list index out of range
Mon, 26 Mar 2018 17:03:41 app_thread.py[line:114] ERROR this is an exception message
Traceback (most recent call last):
  File "F:/BestAssistant\component\app_thread.py", line 111, in run
    findrefresh()
  File "F:/BestAssistant\component\imgcut.py", line 324, in findrefresh
    img = cv2.cvtColor(sc, cv2.COLOR_BGR2GRAY)  # 转灰度图
cv2.error: C:\projects\opencv-python\opencv\modules\imgproc\src\color.cpp:10600: error: (-215) depth == CV_8U || depth == CV_16U || depth == CV_32F in function cv::cvtColor

Mon, 26 Mar 2018 17:03:41 app_thread.py[line:113] ERROR 刷新失败
Mon, 26 Mar 2018 17:03:41 app_thread.py[line:114] ERROR this is an exception message
Traceback (most recent call last):
  File "F:/BestAssistant\component\app_thread.py", line 111, in run
    findrefresh()
  File "F:/BestAssistant\component\imgcut.py", line 324, in findrefresh
    img = cv2.cvtColor(sc, cv2.COLOR_BGR2GRAY)  # 转灰度图
cv2.error: C:\projects\opencv-python\opencv\modules\imgproc\src\color.cpp:10600: error: (-215) depth == CV_8U || depth == CV_16U || depth == CV_32F in function cv::cvtColor

Mon, 26 Mar 2018 17:03:41 imgcut.py[line:309] ERROR cut_img 这里出错
Mon, 26 Mar 2018 17:03:41 imgcut.py[line:310] ERROR this is an exception message
Traceback (most recent call last):
  File "F:/BestAssistant\component\imgcut.py", line 302, in cut_img
    set_val('imgpos_lowestprice', img[use_area[0][1]:use_area[0][3], use_area[0][0]:use_area[0][2]])  # ok
IndexError: list index out of range
Mon, 26 Mar 2018 17:03:41 app_thread.py[line:113] ERROR 刷新失败
Mon, 26 Mar 2018 17:03:41 app_thread.py[line:114] ERROR this is an exception message
Traceback (most recent call last):
  File "F:/BestAssistant\component\app_thread.py", line 111, in run
    findrefresh()
  File "F:/BestAssistant\component\imgcut.py", line 324, in findrefresh
    img = cv2.cvtColor(sc, cv2.COLOR_BGR2GRAY)  # 转灰度图
cv2.error: C:\projects\opencv-python\opencv\modules\imgproc\src\color.cpp:10600: error: (-215) depth == CV_8U || depth == CV_16U || depth == CV_32F in function cv::cvtColor

Mon, 26 Mar 2018 17:03:41 imgcut.py[line:309] ERROR cut_img 这里出错
Mon, 26 Mar 2018 17:03:41 imgcut.py[line:310] ERROR this is an exception message
Traceback (most recent call last):
  File "F:/BestAssistant\component\imgcut.py", line 302, in cut_img
    set_val('imgpos_lowestprice', img[use_area[0][1]:use_area[0][3], use_area[0][0]:use_area[0][2]])  # ok
IndexError: list index out of range
Mon, 26 Mar 2018 17:03:41 app_thread.py[line:113] ERROR 刷新失败
Mon, 26 Mar 2018 17:03:41 app_thread.py[line:114] ERROR this is an exception message
Traceback (most recent call last):
  File "F:/BestAssistant\component\app_thread.py", line 111, in run
    findrefresh()
  File "F:/BestAssistant\component\imgcut.py", line 324, in findrefresh
    img = cv2.cvtColor(sc, cv2.COLOR_BGR2GRAY)  # 转灰度图
cv2.error: C:\projects\opencv-python\opencv\modules\imgproc\src\color.cpp:10600: error: (-215) depth == CV_8U || depth == CV_16U || depth == CV_32F in function cv::cvtColor

Mon, 26 Mar 2018 17:03:41 app_thread.py[line:113] ERROR 刷新失败
Mon, 26 Mar 2018 17:03:41 app_thread.py[line:114] ERROR this is an exception message
Traceback (most recent call last):
  File "F:/BestAssistant\component\app_thread.py", line 111, in run
    findrefresh()
  File "F:/BestAssistant\component\imgcut.py", line 324, in findrefresh
    img = cv2.cvtColor(sc, cv2.COLOR_BGR2GRAY)  # 转灰度图
cv2.error: C:\projects\opencv-python\opencv\modules\imgproc\src\color.cpp:10600: error: (-215) depth == CV_8U || depth == CV_16U || depth == CV_32F in function cv::cvtColor

Mon, 26 Mar 2018 17:03:41 imgcut.py[line:309] ERROR cut_img 这里出错
Mon, 26 Mar 2018 17:03:41 imgcut.py[line:310] ERROR this is an exception message
Traceback (most recent call last):
  File "F:/BestAssistant\component\imgcut.py", line 302, in cut_img
    set_val('imgpos_lowestprice', img[use_area[0][1]:use_area[0][3], use_area[0][0]:use_area[0][2]])  # ok
IndexError: list index out of range
Mon, 26 Mar 2018 17:03:41 imgcut.py[line:309] ERROR cut_img 这里出错
Mon, 26 Mar 2018 17:03:41 imgcut.py[line:310] ERROR this is an exception message
Traceback (most recent call last):
  File "F:/BestAssistant\component\imgcut.py", line 302, in cut_img
    set_val('imgpos_lowestprice', img[use_area[0][1]:use_area[0][3], use_area[0][0]:use_area[0][2]])  # ok
IndexError: list index out of range
Mon, 26 Mar 2018 17:03:41 app_thread.py[line:113] ERROR 刷新失败
Mon, 26 Mar 2018 17:03:41 app_thread.py[line:114] ERROR this is an exception message
Traceback (most recent call last):
  File "F:/BestAssistant\component\app_thread.py", line 111, in run
    findrefresh()
  File "F:/BestAssistant\component\imgcut.py", line 324, in findrefresh
    img = cv2.cvtColor(sc, cv2.COLOR_BGR2GRAY)  # 转灰度图
cv2.error: C:\projects\opencv-python\opencv\modules\imgproc\src\color.cpp:10600: error: (-215) depth == CV_8U || depth == CV_16U || depth == CV_32F in function cv::cvtColor

Mon, 26 Mar 2018 17:03:41 imgcut.py[line:309] ERROR cut_img 这里出错
Mon, 26 Mar 2018 17:03:41 imgcut.py[line:310] ERROR this is an exception message
Traceback (most recent call last):
  File "F:/BestAssistant\component\imgcut.py", line 302, in cut_img
    set_val('imgpos_lowestprice', img[use_area[0][1]:use_area[0][3], use_area[0][0]:use_area[0][2]])  # ok
IndexError: list index out of range
Mon, 26 Mar 2018 17:03:41 app_thread.py[line:113] ERROR 刷新失败
Mon, 26 Mar 2018 17:03:41 app_thread.py[line:114] ERROR this is an exception message
Traceback (most recent call last):
  File "F:/BestAssistant\component\app_thread.py", line 111, in run
    findrefresh()
  File "F:/BestAssistant\component\imgcut.py", line 324, in findrefresh
    img = cv2.cvtColor(sc, cv2.COLOR_BGR2GRAY)  # 转灰度图
cv2.error: C:\projects\opencv-python\opencv\modules\imgproc\src\color.cpp:10600: error: (-215) depth == CV_8U || depth == CV_16U || depth == CV_32F in function cv::cvtColor

Mon, 26 Mar 2018 17:03:41 app_thread.py[line:113] ERROR 刷新失败
Mon, 26 Mar 2018 17:03:41 app_thread.py[line:114] ERROR this is an exception message
Traceback (most recent call last):
  File "F:/BestAssistant\component\app_thread.py", line 111, in run
    findrefresh()
  File "F:/BestAssistant\component\imgcut.py", line 324, in findrefresh
    img = cv2.cvtColor(sc, cv2.COLOR_BGR2GRAY)  # 转灰度图
cv2.error: C:\projects\opencv-python\opencv\modules\imgproc\src\color.cpp:10600: error: (-215) depth == CV_8U || depth == CV_16U || depth == CV_32F in function cv::cvtColor

Mon, 26 Mar 2018 17:03:41 imgcut.py[line:309] ERROR cut_img 这里出错
Mon, 26 Mar 2018 17:03:41 imgcut.py[line:310] ERROR this is an exception message
Traceback (most recent call last):
  File "F:/BestAssistant\component\imgcut.py", line 302, in cut_img
    set_val('imgpos_lowestprice', img[use_area[0][1]:use_area[0][3], use_area[0][0]:use_area[0][2]])  # ok
IndexError: list index out of range
Mon, 26 Mar 2018 17:03:42 app_thread.py[line:113] ERROR 刷新失败
Mon, 26 Mar 2018 17:03:42 app_thread.py[line:114] ERROR this is an exception message
Traceback (most recent call last):
  File "F:/BestAssistant\component\app_thread.py", line 111, in run
    findrefresh()
  File "F:/BestAssistant\component\imgcut.py", line 324, in findrefresh
    img = cv2.cvtColor(sc, cv2.COLOR_BGR2GRAY)  # 转灰度图
cv2.error: C:\projects\opencv-python\opencv\modules\imgproc\src\color.cpp:10600: error: (-215) depth == CV_8U || depth == CV_16U || depth == CV_32F in function cv::cvtColor

Mon, 26 Mar 2018 17:03:42 imgcut.py[line:309] ERROR cut_img 这里出错
Mon, 26 Mar 2018 17:03:42 imgcut.py[line:310] ERROR this is an exception message
Traceback (most recent call last):
  File "F:/BestAssistant\component\imgcut.py", line 302, in cut_img
    set_val('imgpos_lowestprice', img[use_area[0][1]:use_area[0][3], use_area[0][0]:use_area[0][2]])  # ok
IndexError: list index out of range
Mon, 26 Mar 2018 17:03:42 app_thread.py[line:113] ERROR 刷新失败
Mon, 26 Mar 2018 17:03:42 app_thread.py[line:114] ERROR this is an exception message
Traceback (most recent call last):
  File "F:/BestAssistant\component\app_thread.py", line 111, in run
    findrefresh()
  File "F:/BestAssistant\component\imgcut.py", line 324, in findrefresh
    img = cv2.cvtColor(sc, cv2.COLOR_BGR2GRAY)  # 转灰度图
cv2.error: C:\projects\opencv-python\opencv\modules\imgproc\src\color.cpp:10600: error: (-215) depth == CV_8U || depth == CV_16U || depth == CV_32F in function cv::cvtColor

Mon, 26 Mar 2018 17:03:42 imgcut.py[line:309] ERROR cut_img 这里出错
Mon, 26 Mar 2018 17:03:42 imgcut.py[line:310] ERROR this is an exception message
Traceback (most recent call last):
  File "F:/BestAssistant\component\imgcut.py", line 302, in cut_img
    set_val('imgpos_lowestprice', img[use_area[0][1]:use_area[0][3], use_area[0][0]:use_area[0][2]])  # ok
IndexError: list index out of range
Mon, 26 Mar 2018 17:03:42 app_thread.py[line:113] ERROR 刷新失败
Mon, 26 Mar 2018 17:03:42 app_thread.py[line:114] ERROR this is an exception message
Traceback (most recent call last):
  File "F:/BestAssistant\component\app_thread.py", line 111, in run
    findrefresh()
  File "F:/BestAssistant\component\imgcut.py", line 324, in findrefresh
    img = cv2.cvtColor(sc, cv2.COLOR_BGR2GRAY)  # 转灰度图
cv2.error: C:\projects\opencv-python\opencv\modules\imgproc\src\color.cpp:10600: error: (-215) depth == CV_8U || depth == CV_16U || depth == CV_32F in function cv::cvtColor

Mon, 26 Mar 2018 17:03:42 imgcut.py[line:309] ERROR cut_img 这里出错
Mon, 26 Mar 2018 17:03:42 imgcut.py[line:310] ERROR this is an exception message
Traceback (most recent call last):
  File "F:/BestAssistant\component\imgcut.py", line 302, in cut_img
    set_val('imgpos_lowestprice', img[use_area[0][1]:use_area[0][3], use_area[0][0]:use_area[0][2]])  # ok
IndexError: list index out of range
Mon, 26 Mar 2018 17:03:42 imgcut.py[line:309] ERROR cut_img 这里出错
Mon, 26 Mar 2018 17:03:42 app_thread.py[line:113] ERROR 刷新失败
Mon, 26 Mar 2018 17:03:42 imgcut.py[line:310] ERROR this is an exception message
Traceback (most recent call last):
  File "F:/BestAssistant\component\imgcut.py", line 302, in cut_img
    set_val('imgpos_lowestprice', img[use_area[0][1]:use_area[0][3], use_area[0][0]:use_area[0][2]])  # ok
IndexError: list index out of range
Mon, 26 Mar 2018 17:03:42 app_thread.py[line:114] ERROR this is an exception message
Traceback (most recent call last):
  File "F:/BestAssistant\component\app_thread.py", line 111, in run
    findrefresh()
  File "F:/BestAssistant\component\imgcut.py", line 324, in findrefresh
    img = cv2.cvtColor(sc, cv2.COLOR_BGR2GRAY)  # 转灰度图
cv2.error: C:\projects\opencv-python\opencv\modules\imgproc\src\color.cpp:10600: error: (-215) depth == CV_8U || depth == CV_16U || depth == CV_32F in function cv::cvtColor

Mon, 26 Mar 2018 17:03:42 imgcut.py[line:309] ERROR cut_img 这里出错
Mon, 26 Mar 2018 17:03:42 imgcut.py[line:310] ERROR this is an exception message
Traceback (most recent call last):
  File "F:/BestAssistant\component\imgcut.py", line 302, in cut_img
    set_val('imgpos_lowestprice', img[use_area[0][1]:use_area[0][3], use_area[0][0]:use_area[0][2]])  # ok
IndexError: list index out of range
Mon, 26 Mar 2018 17:03:42 app_thread.py[line:113] ERROR 刷新失败
Mon, 26 Mar 2018 17:03:42 app_thread.py[line:114] ERROR this is an exception message
Traceback (most recent call last):
  File "F:/BestAssistant\component\app_thread.py", line 111, in run
    findrefresh()
  File "F:/BestAssistant\component\imgcut.py", line 324, in findrefresh
    img = cv2.cvtColor(sc, cv2.COLOR_BGR2GRAY)  # 转灰度图
cv2.error: C:\projects\opencv-python\opencv\modules\imgproc\src\color.cpp:10600: error: (-215) depth == CV_8U || depth == CV_16U || depth == CV_32F in function cv::cvtColor

Mon, 26 Mar 2018 17:03:42 imgcut.py[line:309] ERROR cut_img 这里出错
Mon, 26 Mar 2018 17:03:42 imgcut.py[line:310] ERROR this is an exception message
Traceback (most recent call last):
  File "F:/BestAssistant\component\imgcut.py", line 302, in cut_img
    set_val('imgpos_lowestprice', img[use_area[0][1]:use_area[0][3], use_area[0][0]:use_area[0][2]])  # ok
IndexError: list index out of range
Mon, 26 Mar 2018 17:03:42 app_thread.py[line:113] ERROR 刷新失败
Mon, 26 Mar 2018 17:03:42 app_thread.py[line:114] ERROR this is an exception message
Traceback (most recent call last):
  File "F:/BestAssistant\component\app_thread.py", line 111, in run
    findrefresh()
  File "F:/BestAssistant\component\imgcut.py", line 324, in findrefresh
    img = cv2.cvtColor(sc, cv2.COLOR_BGR2GRAY)  # 转灰度图
cv2.error: C:\projects\opencv-python\opencv\modules\imgproc\src\color.cpp:10600: error: (-215) depth == CV_8U || depth == CV_16U || depth == CV_32F in function cv::cvtColor

Mon, 26 Mar 2018 17:03:42 imgcut.py[line:309] ERROR cut_img 这里出错
Mon, 26 Mar 2018 17:03:42 imgcut.py[line:310] ERROR this is an exception message
Traceback (most recent call last):
  File "F:/BestAssistant\component\imgcut.py", line 302, in cut_img
    set_val('imgpos_lowestprice', img[use_area[0][1]:use_area[0][3], use_area[0][0]:use_area[0][2]])  # ok
IndexError: list index out of range
Mon, 26 Mar 2018 17:03:42 app_thread.py[line:113] ERROR 刷新失败
Mon, 26 Mar 2018 17:03:42 app_thread.py[line:114] ERROR this is an exception message
Traceback (most recent call last):
  File "F:/BestAssistant\component\app_thread.py", line 111, in run
    findrefresh()
  File "F:/BestAssistant\component\imgcut.py", line 324, in findrefresh
    img = cv2.cvtColor(sc, cv2.COLOR_BGR2GRAY)  # 转灰度图
cv2.error: C:\projects\opencv-python\opencv\modules\imgproc\src\color.cpp:10600: error: (-215) depth == CV_8U || depth == CV_16U || depth == CV_32F in function cv::cvtColor

Mon, 26 Mar 2018 17:03:42 imgcut.py[line:309] ERROR cut_img 这里出错
Mon, 26 Mar 2018 17:03:42 imgcut.py[line:310] ERROR this is an exception message
Traceback (most recent call last):
  File "F:/BestAssistant\component\imgcut.py", line 302, in cut_img
    set_val('imgpos_lowestprice', img[use_area[0][1]:use_area[0][3], use_area[0][0]:use_area[0][2]])  # ok
IndexError: list index out of range
Mon, 26 Mar 2018 17:03:42 app_thread.py[line:113] ERROR 刷新失败
Mon, 26 Mar 2018 17:03:42 app_thread.py[line:114] ERROR this is an exception message
Traceback (most recent call last):
  File "F:/BestAssistant\component\app_thread.py", line 111, in run
    findrefresh()
  File "F:/BestAssistant\component\imgcut.py", line 324, in findrefresh
    img = cv2.cvtColor(sc, cv2.COLOR_BGR2GRAY)  # 转灰度图
cv2.error: C:\projects\opencv-python\opencv\modules\imgproc\src\color.cpp:10600: error: (-215) depth == CV_8U || depth == CV_16U || depth == CV_32F in function cv::cvtColor

Mon, 26 Mar 2018 17:03:42 imgcut.py[line:309] ERROR cut_img 这里出错
Mon, 26 Mar 2018 17:03:42 imgcut.py[line:310] ERROR this is an exception message
Traceback (most recent call last):
  File "F:/BestAssistant\component\imgcut.py", line 302, in cut_img
    set_val('imgpos_lowestprice', img[use_area[0][1]:use_area[0][3], use_area[0][0]:use_area[0][2]])  # ok
IndexError: list index out of range
Mon, 26 Mar 2018 17:03:42 app_thread.py[line:113] ERROR 刷新失败
Mon, 26 Mar 2018 17:03:42 app_thread.py[line:114] ERROR this is an exception message
Traceback (most recent call last):
  File "F:/BestAssistant\component\app_thread.py", line 111, in run
    findrefresh()
  File "F:/BestAssistant\component\imgcut.py", line 324, in findrefresh
    img = cv2.cvtColor(sc, cv2.COLOR_BGR2GRAY)  # 转灰度图
cv2.error: C:\projects\opencv-python\opencv\modules\imgproc\src\color.cpp:10600: error: (-215) depth == CV_8U || depth == CV_16U || depth == CV_32F in function cv::cvtColor

Mon, 26 Mar 2018 17:03:42 imgcut.py[line:309] ERROR cut_img 这里出错
Mon, 26 Mar 2018 17:03:42 imgcut.py[line:310] ERROR this is an exception message
Traceback (most recent call last):
  File "F:/BestAssistant\component\imgcut.py", line 302, in cut_img
    set_val('imgpos_lowestprice', img[use_area[0][1]:use_area[0][3], use_area[0][0]:use_area[0][2]])  # ok
IndexError: list index out of range
Mon, 26 Mar 2018 17:03:42 app_thread.py[line:113] ERROR 刷新失败
Mon, 26 Mar 2018 17:03:42 app_thread.py[line:114] ERROR this is an exception message
Traceback (most recent call last):
  File "F:/BestAssistant\component\app_thread.py", line 111, in run
    findrefresh()
  File "F:/BestAssistant\component\imgcut.py", line 324, in findrefresh
    img = cv2.cvtColor(sc, cv2.COLOR_BGR2GRAY)  # 转灰度图
cv2.error: C:\projects\opencv-python\opencv\modules\imgproc\src\color.cpp:10600: error: (-215) depth == CV_8U || depth == CV_16U || depth == CV_32F in function cv::cvtColor

Mon, 26 Mar 2018 17:03:42 imgcut.py[line:309] ERROR cut_img 这里出错
Mon, 26 Mar 2018 17:03:42 imgcut.py[line:310] ERROR this is an exception message
Traceback (most recent call last):
  File "F:/BestAssistant\component\imgcut.py", line 302, in cut_img
    set_val('imgpos_lowestprice', img[use_area[0][1]:use_area[0][3], use_area[0][0]:use_area[0][2]])  # ok
IndexError: list index out of range
Mon, 26 Mar 2018 17:03:42 app_thread.py[line:113] ERROR 刷新失败
Mon, 26 Mar 2018 17:03:42 app_thread.py[line:114] ERROR this is an exception message
Traceback (most recent call last):
  File "F:/BestAssistant\component\app_thread.py", line 111, in run
    findrefresh()
  File "F:/BestAssistant\component\imgcut.py", line 324, in findrefresh
    img = cv2.cvtColor(sc, cv2.COLOR_BGR2GRAY)  # 转灰度图
cv2.error: C:\projects\opencv-python\opencv\modules\imgproc\src\color.cpp:10600: error: (-215) depth == CV_8U || depth == CV_16U || depth == CV_32F in function cv::cvtColor

Mon, 26 Mar 2018 17:03:42 imgcut.py[line:309] ERROR cut_img 这里出错
Mon, 26 Mar 2018 17:03:42 app_thread.py[line:113] ERROR 刷新失败
Mon, 26 Mar 2018 17:03:42 imgcut.py[line:310] ERROR this is an exception message
Traceback (most recent call last):
  File "F:/BestAssistant\component\imgcut.py", line 302, in cut_img
    set_val('imgpos_lowestprice', img[use_area[0][1]:use_area[0][3], use_area[0][0]:use_area[0][2]])  # ok
IndexError: list index out of range
Mon, 26 Mar 2018 17:03:42 app_thread.py[line:114] ERROR this is an exception message
Traceback (most recent call last):
  File "F:/BestAssistant\component\app_thread.py", line 111, in run
    findrefresh()
  File "F:/BestAssistant\component\imgcut.py", line 324, in findrefresh
    img = cv2.cvtColor(sc, cv2.COLOR_BGR2GRAY)  # 转灰度图
cv2.error: C:\projects\opencv-python\opencv\modules\imgproc\src\color.cpp:10600: error: (-215) depth == CV_8U || depth == CV_16U || depth == CV_32F in function cv::cvtColor

Mon, 26 Mar 2018 17:03:42 imgcut.py[line:309] ERROR cut_img 这里出错
Mon, 26 Mar 2018 17:03:42 imgcut.py[line:310] ERROR this is an exception message
Traceback (most recent call last):
  File "F:/BestAssistant\component\imgcut.py", line 302, in cut_img
    set_val('imgpos_lowestprice', img[use_area[0][1]:use_area[0][3], use_area[0][0]:use_area[0][2]])  # ok
IndexError: list index out of range
Mon, 26 Mar 2018 17:03:42 app_thread.py[line:113] ERROR 刷新失败
Mon, 26 Mar 2018 17:03:42 app_thread.py[line:114] ERROR this is an exception message
Traceback (most recent call last):
  File "F:/BestAssistant\component\app_thread.py", line 111, in run
    findrefresh()
  File "F:/BestAssistant\component\imgcut.py", line 324, in findrefresh
    img = cv2.cvtColor(sc, cv2.COLOR_BGR2GRAY)  # 转灰度图
cv2.error: C:\projects\opencv-python\opencv\modules\imgproc\src\color.cpp:10600: error: (-215) depth == CV_8U || depth == CV_16U || depth == CV_32F in function cv::cvtColor

Mon, 26 Mar 2018 17:03:42 app_thread.py[line:113] ERROR 刷新失败
Mon, 26 Mar 2018 17:03:42 app_thread.py[line:114] ERROR this is an exception message
Traceback (most recent call last):
  File "F:/BestAssistant\component\app_thread.py", line 111, in run
    findrefresh()
  File "F:/BestAssistant\component\imgcut.py", line 324, in findrefresh
    img = cv2.cvtColor(sc, cv2.COLOR_BGR2GRAY)  # 转灰度图
cv2.error: C:\projects\opencv-python\opencv\modules\imgproc\src\color.cpp:10600: error: (-215) depth == CV_8U || depth == CV_16U || depth == CV_32F in function cv::cvtColor

Mon, 26 Mar 2018 17:03:42 imgcut.py[line:309] ERROR cut_img 这里出错
Mon, 26 Mar 2018 17:03:42 imgcut.py[line:310] ERROR this is an exception message
Traceback (most recent call last):
  File "F:/BestAssistant\component\imgcut.py", line 302, in cut_img
    set_val('imgpos_lowestprice', img[use_area[0][1]:use_area[0][3], use_area[0][0]:use_area[0][2]])  # ok
IndexError: list index out of range
Mon, 26 Mar 2018 17:03:42 app_thread.py[line:113] ERROR 刷新失败
Mon, 26 Mar 2018 17:03:42 app_thread.py[line:114] ERROR this is an exception message
Traceback (most recent call last):
  File "F:/BestAssistant\component\app_thread.py", line 111, in run
    findrefresh()
  File "F:/BestAssistant\component\imgcut.py", line 324, in findrefresh
    img = cv2.cvtColor(sc, cv2.COLOR_BGR2GRAY)  # 转灰度图
cv2.error: C:\projects\opencv-python\opencv\modules\imgproc\src\color.cpp:10600: error: (-215) depth == CV_8U || depth == CV_16U || depth == CV_32F in function cv::cvtColor

Mon, 26 Mar 2018 17:03:43 app_thread.py[line:113] ERROR 刷新失败
Mon, 26 Mar 2018 17:03:43 app_thread.py[line:114] ERROR this is an exception message
Traceback (most recent call last):
  File "F:/BestAssistant\component\app_thread.py", line 111, in run
    findrefresh()
  File "F:/BestAssistant\component\imgcut.py", line 324, in findrefresh
    img = cv2.cvtColor(sc, cv2.COLOR_BGR2GRAY)  # 转灰度图
cv2.error: C:\projects\opencv-python\opencv\modules\imgproc\src\color.cpp:10600: error: (-215) depth == CV_8U || depth == CV_16U || depth == CV_32F in function cv::cvtColor

Mon, 26 Mar 2018 17:03:43 imgcut.py[line:309] ERROR cut_img 这里出错
Mon, 26 Mar 2018 17:03:43 imgcut.py[line:310] ERROR this is an exception message
Traceback (most recent call last):
  File "F:/BestAssistant\component\imgcut.py", line 302, in cut_img
    set_val('imgpos_lowestprice', img[use_area[0][1]:use_area[0][3], use_area[0][0]:use_area[0][2]])  # ok
IndexError: list index out of range
Mon, 26 Mar 2018 17:03:43 imgcut.py[line:309] ERROR cut_img 这里出错
Mon, 26 Mar 2018 17:03:43 imgcut.py[line:310] ERROR this is an exception message
Traceback (most recent call last):
  File "F:/BestAssistant\component\imgcut.py", line 302, in cut_img
    set_val('imgpos_lowestprice', img[use_area[0][1]:use_area[0][3], use_area[0][0]:use_area[0][2]])  # ok
IndexError: list index out of range
Mon, 26 Mar 2018 17:03:43 app_thread.py[line:113] ERROR 刷新失败
Mon, 26 Mar 2018 17:03:43 app_thread.py[line:114] ERROR this is an exception message
Traceback (most recent call last):
  File "F:/BestAssistant\component\app_thread.py", line 111, in run
    findrefresh()
  File "F:/BestAssistant\component\imgcut.py", line 324, in findrefresh
    img = cv2.cvtColor(sc, cv2.COLOR_BGR2GRAY)  # 转灰度图
cv2.error: C:\projects\opencv-python\opencv\modules\imgproc\src\color.cpp:10600: error: (-215) depth == CV_8U || depth == CV_16U || depth == CV_32F in function cv::cvtColor

Mon, 26 Mar 2018 17:03:43 app_thread.py[line:113] ERROR 刷新失败
Mon, 26 Mar 2018 17:03:43 app_thread.py[line:114] ERROR this is an exception message
Traceback (most recent call last):
  File "F:/BestAssistant\component\app_thread.py", line 111, in run
    findrefresh()
  File "F:/BestAssistant\component\imgcut.py", line 324, in findrefresh
    img = cv2.cvtColor(sc, cv2.COLOR_BGR2GRAY)  # 转灰度图
cv2.error: C:\projects\opencv-python\opencv\modules\imgproc\src\color.cpp:10600: error: (-215) depth == CV_8U || depth == CV_16U || depth == CV_32F in function cv::cvtColor

Mon, 26 Mar 2018 17:03:43 app_thread.py[line:113] ERROR 刷新失败
Mon, 26 Mar 2018 17:03:43 app_thread.py[line:114] ERROR this is an exception message
Traceback (most recent call last):
  File "F:/BestAssistant\component\app_thread.py", line 111, in run
    findrefresh()
  File "F:/BestAssistant\component\imgcut.py", line 324, in findrefresh
    img = cv2.cvtColor(sc, cv2.COLOR_BGR2GRAY)  # 转灰度图
cv2.error: C:\projects\opencv-python\opencv\modules\imgproc\src\color.cpp:10600: error: (-215) depth == CV_8U || depth == CV_16U || depth == CV_32F in function cv::cvtColor

Mon, 26 Mar 2018 17:03:43 imgcut.py[line:309] ERROR cut_img 这里出错
Mon, 26 Mar 2018 17:03:43 imgcut.py[line:310] ERROR this is an exception message
Traceback (most recent call last):
  File "F:/BestAssistant\component\imgcut.py", line 302, in cut_img
    set_val('imgpos_lowestprice', img[use_area[0][1]:use_area[0][3], use_area[0][0]:use_area[0][2]])  # ok
IndexError: list index out of range
Mon, 26 Mar 2018 17:03:43 app_thread.py[line:113] ERROR 刷新失败
Mon, 26 Mar 2018 17:03:43 app_thread.py[line:114] ERROR this is an exception message
Traceback (most recent call last):
  File "F:/BestAssistant\component\app_thread.py", line 111, in run
    findrefresh()
  File "F:/BestAssistant\component\imgcut.py", line 324, in findrefresh
    img = cv2.cvtColor(sc, cv2.COLOR_BGR2GRAY)  # 转灰度图
cv2.error: C:\projects\opencv-python\opencv\modules\imgproc\src\color.cpp:10600: error: (-215) depth == CV_8U || depth == CV_16U || depth == CV_32F in function cv::cvtColor

Mon, 26 Mar 2018 17:03:43 imgcut.py[line:309] ERROR cut_img 这里出错
Mon, 26 Mar 2018 17:03:43 imgcut.py[line:310] ERROR this is an exception message
Traceback (most recent call last):
  File "F:/BestAssistant\component\imgcut.py", line 302, in cut_img
    set_val('imgpos_lowestprice', img[use_area[0][1]:use_area[0][3], use_area[0][0]:use_area[0][2]])  # ok
IndexError: list index out of range
