Tue, 10 Jul 2018 11:48:33 connectionpool.py[line:824] DEBUG Starting new HTTPS connection (1): hupai.pro
Tue, 10 Jul 2018 11:48:34 connectionpool.py[line:396] DEBUG https://hupai.pro:443 "GET /api/bid/get_guopaiurl/?format=json&type=identify_code&debug=True&version=5.2&identify_code=h99999902&diskid=dca984ffb6ff32225862a03946345c2c073097c1 HTTP/1.1" 200 None
Tue, 10 Jul 2018 11:48:34 connectionpool.py[line:208] DEBUG Starting new HTTP connection (1): ip.taobao.com
Tue, 10 Jul 2018 11:48:34 connectionpool.py[line:396] DEBUG http://ip.taobao.com:80 "GET /service/getIpInfo.php?ip=101.87.250.19 HTTP/1.1" 200 None
Tue, 10 Jul 2018 11:48:34 app_thread.py[line:256] ERROR 识别价格失败
Tue, 10 Jul 2018 11:48:34 app_thread.py[line:257] ERROR this is an exception message
Traceback (most recent call last):
  File "E:\hupai\component\app_thread.py", line 236, in read_lowest_price
    str_price = Price_read()
  File "E:\hupai\component\imgcut.py", line 360, in Price_read
    price = readpic(lowest_price_img)
  File "E:\hupai\component\read_pic.py", line 268, in readpic
    testData = cut(img)
  File "E:\hupai\component\read_pic.py", line 246, in cut
    imgn[i] = cv2.resize(imgn[i], (8, 8))
cv2.error: C:\projects\opencv-python\opencv\modules\imgproc\src\resize.cpp:4044: error: (-215) ssize.width > 0 && ssize.height > 0 in function cv::resize

Tue, 10 Jul 2018 11:48:34 app_thread.py[line:256] ERROR 识别价格失败
Tue, 10 Jul 2018 11:48:34 app_thread.py[line:257] ERROR this is an exception message
Traceback (most recent call last):
  File "E:\hupai\component\app_thread.py", line 236, in read_lowest_price
    str_price = Price_read()
  File "E:\hupai\component\imgcut.py", line 360, in Price_read
    price = readpic(lowest_price_img)
  File "E:\hupai\component\read_pic.py", line 268, in readpic
    testData = cut(img)
  File "E:\hupai\component\read_pic.py", line 246, in cut
    imgn[i] = cv2.resize(imgn[i], (8, 8))
cv2.error: C:\projects\opencv-python\opencv\modules\imgproc\src\resize.cpp:4044: error: (-215) ssize.width > 0 && ssize.height > 0 in function cv::resize

Tue, 10 Jul 2018 11:48:34 app_thread.py[line:256] ERROR 识别价格失败
Tue, 10 Jul 2018 11:48:34 app_thread.py[line:257] ERROR this is an exception message
Traceback (most recent call last):
  File "E:\hupai\component\app_thread.py", line 236, in read_lowest_price
    str_price = Price_read()
  File "E:\hupai\component\imgcut.py", line 360, in Price_read
    price = readpic(lowest_price_img)
  File "E:\hupai\component\read_pic.py", line 268, in readpic
    testData = cut(img)
  File "E:\hupai\component\read_pic.py", line 246, in cut
    imgn[i] = cv2.resize(imgn[i], (8, 8))
cv2.error: C:\projects\opencv-python\opencv\modules\imgproc\src\resize.cpp:4044: error: (-215) ssize.width > 0 && ssize.height > 0 in function cv::resize

Tue, 10 Jul 2018 11:48:35 app_thread.py[line:256] ERROR 识别价格失败
Tue, 10 Jul 2018 11:48:35 app_thread.py[line:257] ERROR this is an exception message
Traceback (most recent call last):
  File "E:\hupai\component\app_thread.py", line 236, in read_lowest_price
    str_price = Price_read()
  File "E:\hupai\component\imgcut.py", line 360, in Price_read
    price = readpic(lowest_price_img)
  File "E:\hupai\component\read_pic.py", line 268, in readpic
    testData = cut(img)
  File "E:\hupai\component\read_pic.py", line 100, in cut
    diff = xy[-1][2]  # 最后一个 图像块
IndexError: list index out of range
Tue, 10 Jul 2018 11:48:35 app_thread.py[line:256] ERROR 识别价格失败
Tue, 10 Jul 2018 11:48:35 app_thread.py[line:257] ERROR this is an exception message
Traceback (most recent call last):
  File "E:\hupai\component\app_thread.py", line 236, in read_lowest_price
    str_price = Price_read()
  File "E:\hupai\component\imgcut.py", line 360, in Price_read
    price = readpic(lowest_price_img)
  File "E:\hupai\component\read_pic.py", line 268, in readpic
    testData = cut(img)
  File "E:\hupai\component\read_pic.py", line 100, in cut
    diff = xy[-1][2]  # 最后一个 图像块
IndexError: list index out of range
Tue, 10 Jul 2018 11:48:35 app_thread.py[line:256] ERROR 识别价格失败
Tue, 10 Jul 2018 11:48:35 app_thread.py[line:257] ERROR this is an exception message
Traceback (most recent call last):
  File "E:\hupai\component\app_thread.py", line 236, in read_lowest_price
    str_price = Price_read()
  File "E:\hupai\component\imgcut.py", line 360, in Price_read
    price = readpic(lowest_price_img)
  File "E:\hupai\component\read_pic.py", line 268, in readpic
    testData = cut(img)
  File "E:\hupai\component\read_pic.py", line 100, in cut
    diff = xy[-1][2]  # 最后一个 图像块
IndexError: list index out of range
Tue, 10 Jul 2018 11:48:36 app_thread.py[line:256] ERROR 识别价格失败
Tue, 10 Jul 2018 11:48:36 app_thread.py[line:257] ERROR this is an exception message
Traceback (most recent call last):
  File "E:\hupai\component\app_thread.py", line 236, in read_lowest_price
    str_price = Price_read()
  File "E:\hupai\component\imgcut.py", line 360, in Price_read
    price = readpic(lowest_price_img)
  File "E:\hupai\component\read_pic.py", line 268, in readpic
    testData = cut(img)
  File "E:\hupai\component\read_pic.py", line 100, in cut
    diff = xy[-1][2]  # 最后一个 图像块
IndexError: list index out of range
Tue, 10 Jul 2018 11:48:36 app_thread.py[line:256] ERROR 识别价格失败
Tue, 10 Jul 2018 11:48:36 app_thread.py[line:257] ERROR this is an exception message
Traceback (most recent call last):
  File "E:\hupai\component\app_thread.py", line 236, in read_lowest_price
    str_price = Price_read()
  File "E:\hupai\component\imgcut.py", line 360, in Price_read
    price = readpic(lowest_price_img)
  File "E:\hupai\component\read_pic.py", line 268, in readpic
    testData = cut(img)
  File "E:\hupai\component\read_pic.py", line 100, in cut
    diff = xy[-1][2]  # 最后一个 图像块
IndexError: list index out of range
Tue, 10 Jul 2018 11:48:36 app_thread.py[line:256] ERROR 识别价格失败
Tue, 10 Jul 2018 11:48:36 app_thread.py[line:257] ERROR this is an exception message
Traceback (most recent call last):
  File "E:\hupai\component\app_thread.py", line 236, in read_lowest_price
    str_price = Price_read()
  File "E:\hupai\component\imgcut.py", line 360, in Price_read
    price = readpic(lowest_price_img)
  File "E:\hupai\component\read_pic.py", line 268, in readpic
    testData = cut(img)
  File "E:\hupai\component\read_pic.py", line 100, in cut
    diff = xy[-1][2]  # 最后一个 图像块
IndexError: list index out of range
Tue, 10 Jul 2018 11:48:36 app_thread.py[line:256] ERROR 识别价格失败
Tue, 10 Jul 2018 11:48:36 app_thread.py[line:257] ERROR this is an exception message
Traceback (most recent call last):
  File "E:\hupai\component\app_thread.py", line 236, in read_lowest_price
    str_price = Price_read()
  File "E:\hupai\component\imgcut.py", line 360, in Price_read
    price = readpic(lowest_price_img)
  File "E:\hupai\component\read_pic.py", line 268, in readpic
    testData = cut(img)
  File "E:\hupai\component\read_pic.py", line 100, in cut
    diff = xy[-1][2]  # 最后一个 图像块
IndexError: list index out of range
Tue, 10 Jul 2018 11:48:36 app_thread.py[line:256] ERROR 识别价格失败
Tue, 10 Jul 2018 11:48:36 app_thread.py[line:257] ERROR this is an exception message
Traceback (most recent call last):
  File "E:\hupai\component\app_thread.py", line 236, in read_lowest_price
    str_price = Price_read()
  File "E:\hupai\component\imgcut.py", line 360, in Price_read
    price = readpic(lowest_price_img)
  File "E:\hupai\component\read_pic.py", line 268, in readpic
    testData = cut(img)
  File "E:\hupai\component\read_pic.py", line 100, in cut
    diff = xy[-1][2]  # 最后一个 图像块
IndexError: list index out of range
Tue, 10 Jul 2018 11:48:36 app_thread.py[line:256] ERROR 识别价格失败
Tue, 10 Jul 2018 11:48:36 app_thread.py[line:257] ERROR this is an exception message
Traceback (most recent call last):
  File "E:\hupai\component\app_thread.py", line 236, in read_lowest_price
    str_price = Price_read()
  File "E:\hupai\component\imgcut.py", line 360, in Price_read
    price = readpic(lowest_price_img)
  File "E:\hupai\component\read_pic.py", line 268, in readpic
    testData = cut(img)
  File "E:\hupai\component\read_pic.py", line 100, in cut
    diff = xy[-1][2]  # 最后一个 图像块
IndexError: list index out of range
Tue, 10 Jul 2018 11:48:36 app_thread.py[line:256] ERROR 识别价格失败
Tue, 10 Jul 2018 11:48:36 app_thread.py[line:257] ERROR this is an exception message
Traceback (most recent call last):
  File "E:\hupai\component\app_thread.py", line 236, in read_lowest_price
    str_price = Price_read()
  File "E:\hupai\component\imgcut.py", line 360, in Price_read
    price = readpic(lowest_price_img)
  File "E:\hupai\component\read_pic.py", line 268, in readpic
    testData = cut(img)
  File "E:\hupai\component\read_pic.py", line 100, in cut
    diff = xy[-1][2]  # 最后一个 图像块
IndexError: list index out of range
Tue, 10 Jul 2018 11:48:36 app_thread.py[line:256] ERROR 识别价格失败
Tue, 10 Jul 2018 11:48:36 app_thread.py[line:257] ERROR this is an exception message
Traceback (most recent call last):
  File "E:\hupai\component\app_thread.py", line 236, in read_lowest_price
    str_price = Price_read()
  File "E:\hupai\component\imgcut.py", line 360, in Price_read
    price = readpic(lowest_price_img)
  File "E:\hupai\component\read_pic.py", line 268, in readpic
    testData = cut(img)
  File "E:\hupai\component\read_pic.py", line 100, in cut
    diff = xy[-1][2]  # 最后一个 图像块
IndexError: list index out of range
Tue, 10 Jul 2018 11:48:37 app_thread.py[line:256] ERROR 识别价格失败
Tue, 10 Jul 2018 11:48:37 app_thread.py[line:257] ERROR this is an exception message
Traceback (most recent call last):
  File "E:\hupai\component\app_thread.py", line 236, in read_lowest_price
    str_price = Price_read()
  File "E:\hupai\component\imgcut.py", line 360, in Price_read
    price = readpic(lowest_price_img)
  File "E:\hupai\component\read_pic.py", line 268, in readpic
    testData = cut(img)
  File "E:\hupai\component\read_pic.py", line 100, in cut
    diff = xy[-1][2]  # 最后一个 图像块
IndexError: list index out of range
