Sun, 22 Apr 2018 11:57:18 PngImagePlugin.py[line:137] DEBUG STREAM b'IHDR' 16 13
Sun, 22 Apr 2018 11:57:18 PngImagePlugin.py[line:137] DEBUG STREAM b'IDAT' 41 65536
Sun, 22 Apr 2018 11:57:18 PngImagePlugin.py[line:137] DEBUG STREAM b'IHDR' 16 13
Sun, 22 Apr 2018 11:57:18 PngImagePlugin.py[line:137] DEBUG STREAM b'IDAT' 41 65536
Sun, 22 Apr 2018 11:57:19 connectionpool.py[line:824] DEBUG Starting new HTTPS connection (1): hupai.pro
Sun, 22 Apr 2018 11:57:21 connectionpool.py[line:396] DEBUG https://hupai.pro:443 "GET /api/bid/get_guopaiurl/?type=identify_code&debug=True&version=2.2&identify_code=123456&diskid=dca984ffb6ff32225862a03946345c2c073097c1 HTTP/1.1" 200 167
Sun, 22 Apr 2018 11:57:21 app_thread.py[line:145] ERROR 刷新失败
Sun, 22 Apr 2018 11:57:21 app_thread.py[line:146] ERROR this is an exception message
Traceback (most recent call last):
  File "E:\hupai\component\app_thread.py", line 143, in run
    findrefresh()
  File "E:\hupai\component\imgcut.py", line 387, in findrefresh
    img = cv2.cvtColor(sc, cv2.COLOR_BGR2GRAY)  # 转灰度图
cv2.error: C:\projects\opencv-python\opencv\modules\imgproc\src\color.cpp:11073: error: (-215) depth == 0 || depth == 2 || depth == 5 in function cv::cvtColor

Sun, 22 Apr 2018 11:57:21 imgcut.py[line:372] ERROR cut_img 这里出错
Sun, 22 Apr 2018 11:57:21 imgcut.py[line:373] ERROR this is an exception message
Traceback (most recent call last):
  File "E:\hupai\component\imgcut.py", line 365, in cut_img
    set_val('imgpos_lowestprice', img[use_area[0][1]:use_area[0][3], use_area[0][0]:use_area[0][2]])  # ok
IndexError: list index out of range
Sun, 22 Apr 2018 11:57:21 app_thread.py[line:145] ERROR 刷新失败
Sun, 22 Apr 2018 11:57:21 app_thread.py[line:146] ERROR this is an exception message
Traceback (most recent call last):
  File "E:\hupai\component\app_thread.py", line 143, in run
    findrefresh()
  File "E:\hupai\component\imgcut.py", line 387, in findrefresh
    img = cv2.cvtColor(sc, cv2.COLOR_BGR2GRAY)  # 转灰度图
cv2.error: C:\projects\opencv-python\opencv\modules\imgproc\src\color.cpp:11073: error: (-215) depth == 0 || depth == 2 || depth == 5 in function cv::cvtColor

Sun, 22 Apr 2018 11:57:21 imgcut.py[line:372] ERROR cut_img 这里出错
Sun, 22 Apr 2018 11:57:21 imgcut.py[line:373] ERROR this is an exception message
Traceback (most recent call last):
  File "E:\hupai\component\imgcut.py", line 365, in cut_img
    set_val('imgpos_lowestprice', img[use_area[0][1]:use_area[0][3], use_area[0][0]:use_area[0][2]])  # ok
IndexError: list index out of range
Sun, 22 Apr 2018 11:57:21 app_thread.py[line:145] ERROR 刷新失败
Sun, 22 Apr 2018 11:57:21 app_thread.py[line:146] ERROR this is an exception message
Traceback (most recent call last):
  File "E:\hupai\component\app_thread.py", line 143, in run
    findrefresh()
  File "E:\hupai\component\imgcut.py", line 387, in findrefresh
    img = cv2.cvtColor(sc, cv2.COLOR_BGR2GRAY)  # 转灰度图
cv2.error: C:\projects\opencv-python\opencv\modules\imgproc\src\color.cpp:11073: error: (-215) depth == 0 || depth == 2 || depth == 5 in function cv::cvtColor

Sun, 22 Apr 2018 11:57:21 app_thread.py[line:145] ERROR 刷新失败
Sun, 22 Apr 2018 11:57:21 app_thread.py[line:146] ERROR this is an exception message
Traceback (most recent call last):
  File "E:\hupai\component\app_thread.py", line 143, in run
    findrefresh()
  File "E:\hupai\component\imgcut.py", line 387, in findrefresh
    img = cv2.cvtColor(sc, cv2.COLOR_BGR2GRAY)  # 转灰度图
cv2.error: C:\projects\opencv-python\opencv\modules\imgproc\src\color.cpp:11073: error: (-215) depth == 0 || depth == 2 || depth == 5 in function cv::cvtColor

Sun, 22 Apr 2018 11:57:21 imgcut.py[line:372] ERROR cut_img 这里出错
Sun, 22 Apr 2018 11:57:21 imgcut.py[line:373] ERROR this is an exception message
Traceback (most recent call last):
  File "E:\hupai\component\imgcut.py", line 365, in cut_img
    set_val('imgpos_lowestprice', img[use_area[0][1]:use_area[0][3], use_area[0][0]:use_area[0][2]])  # ok
IndexError: list index out of range
Sun, 22 Apr 2018 11:57:21 app_thread.py[line:145] ERROR 刷新失败
Sun, 22 Apr 2018 11:57:21 app_thread.py[line:146] ERROR this is an exception message
Traceback (most recent call last):
  File "E:\hupai\component\app_thread.py", line 143, in run
    findrefresh()
  File "E:\hupai\component\imgcut.py", line 387, in findrefresh
    img = cv2.cvtColor(sc, cv2.COLOR_BGR2GRAY)  # 转灰度图
cv2.error: C:\projects\opencv-python\opencv\modules\imgproc\src\color.cpp:11073: error: (-215) depth == 0 || depth == 2 || depth == 5 in function cv::cvtColor

Sun, 22 Apr 2018 11:57:21 imgcut.py[line:372] ERROR cut_img 这里出错
Sun, 22 Apr 2018 11:57:21 imgcut.py[line:373] ERROR this is an exception message
Traceback (most recent call last):
  File "E:\hupai\component\imgcut.py", line 365, in cut_img
    set_val('imgpos_lowestprice', img[use_area[0][1]:use_area[0][3], use_area[0][0]:use_area[0][2]])  # ok
IndexError: list index out of range
Sun, 22 Apr 2018 11:57:21 app_thread.py[line:145] ERROR 刷新失败
Sun, 22 Apr 2018 11:57:21 app_thread.py[line:146] ERROR this is an exception message
Traceback (most recent call last):
  File "E:\hupai\component\app_thread.py", line 143, in run
    findrefresh()
  File "E:\hupai\component\imgcut.py", line 387, in findrefresh
    img = cv2.cvtColor(sc, cv2.COLOR_BGR2GRAY)  # 转灰度图
cv2.error: C:\projects\opencv-python\opencv\modules\imgproc\src\color.cpp:11073: error: (-215) depth == 0 || depth == 2 || depth == 5 in function cv::cvtColor

Sun, 22 Apr 2018 11:57:21 imgcut.py[line:372] ERROR cut_img 这里出错
Sun, 22 Apr 2018 11:57:21 imgcut.py[line:373] ERROR this is an exception message
Traceback (most recent call last):
  File "E:\hupai\component\imgcut.py", line 365, in cut_img
    set_val('imgpos_lowestprice', img[use_area[0][1]:use_area[0][3], use_area[0][0]:use_area[0][2]])  # ok
IndexError: list index out of range
Sun, 22 Apr 2018 11:57:21 app_thread.py[line:145] ERROR 刷新失败
Sun, 22 Apr 2018 11:57:21 app_thread.py[line:146] ERROR this is an exception message
Traceback (most recent call last):
  File "E:\hupai\component\app_thread.py", line 143, in run
    findrefresh()
  File "E:\hupai\component\imgcut.py", line 387, in findrefresh
    img = cv2.cvtColor(sc, cv2.COLOR_BGR2GRAY)  # 转灰度图
cv2.error: C:\projects\opencv-python\opencv\modules\imgproc\src\color.cpp:11073: error: (-215) depth == 0 || depth == 2 || depth == 5 in function cv::cvtColor

Sun, 22 Apr 2018 11:57:21 app_thread.py[line:145] ERROR 刷新失败
Sun, 22 Apr 2018 11:57:21 imgcut.py[line:372] ERROR cut_img 这里出错
Sun, 22 Apr 2018 11:57:21 app_thread.py[line:146] ERROR this is an exception message
Traceback (most recent call last):
  File "E:\hupai\component\app_thread.py", line 143, in run
    findrefresh()
  File "E:\hupai\component\imgcut.py", line 387, in findrefresh
    img = cv2.cvtColor(sc, cv2.COLOR_BGR2GRAY)  # 转灰度图
cv2.error: C:\projects\opencv-python\opencv\modules\imgproc\src\color.cpp:11073: error: (-215) depth == 0 || depth == 2 || depth == 5 in function cv::cvtColor

Sun, 22 Apr 2018 11:57:21 imgcut.py[line:373] ERROR this is an exception message
Traceback (most recent call last):
  File "E:\hupai\component\imgcut.py", line 365, in cut_img
    set_val('imgpos_lowestprice', img[use_area[0][1]:use_area[0][3], use_area[0][0]:use_area[0][2]])  # ok
IndexError: list index out of range
Sun, 22 Apr 2018 11:57:21 app_thread.py[line:145] ERROR 刷新失败
Sun, 22 Apr 2018 11:57:21 app_thread.py[line:146] ERROR this is an exception message
Traceback (most recent call last):
  File "E:\hupai\component\app_thread.py", line 143, in run
    findrefresh()
  File "E:\hupai\component\imgcut.py", line 387, in findrefresh
    img = cv2.cvtColor(sc, cv2.COLOR_BGR2GRAY)  # 转灰度图
cv2.error: C:\projects\opencv-python\opencv\modules\imgproc\src\color.cpp:11073: error: (-215) depth == 0 || depth == 2 || depth == 5 in function cv::cvtColor

Sun, 22 Apr 2018 11:57:21 imgcut.py[line:372] ERROR cut_img 这里出错
Sun, 22 Apr 2018 11:57:21 imgcut.py[line:373] ERROR this is an exception message
Traceback (most recent call last):
  File "E:\hupai\component\imgcut.py", line 365, in cut_img
    set_val('imgpos_lowestprice', img[use_area[0][1]:use_area[0][3], use_area[0][0]:use_area[0][2]])  # ok
IndexError: list index out of range
Sun, 22 Apr 2018 11:57:21 app_thread.py[line:145] ERROR 刷新失败
Sun, 22 Apr 2018 11:57:21 app_thread.py[line:146] ERROR this is an exception message
Traceback (most recent call last):
  File "E:\hupai\component\app_thread.py", line 143, in run
    findrefresh()
  File "E:\hupai\component\imgcut.py", line 387, in findrefresh
    img = cv2.cvtColor(sc, cv2.COLOR_BGR2GRAY)  # 转灰度图
cv2.error: C:\projects\opencv-python\opencv\modules\imgproc\src\color.cpp:11073: error: (-215) depth == 0 || depth == 2 || depth == 5 in function cv::cvtColor

Sun, 22 Apr 2018 11:57:21 imgcut.py[line:372] ERROR cut_img 这里出错
Sun, 22 Apr 2018 11:57:21 imgcut.py[line:373] ERROR this is an exception message
Traceback (most recent call last):
  File "E:\hupai\component\imgcut.py", line 365, in cut_img
    set_val('imgpos_lowestprice', img[use_area[0][1]:use_area[0][3], use_area[0][0]:use_area[0][2]])  # ok
IndexError: list index out of range
Sun, 22 Apr 2018 11:57:21 app_thread.py[line:145] ERROR 刷新失败
Sun, 22 Apr 2018 11:57:21 app_thread.py[line:146] ERROR this is an exception message
Traceback (most recent call last):
  File "E:\hupai\component\app_thread.py", line 143, in run
    findrefresh()
  File "E:\hupai\component\imgcut.py", line 387, in findrefresh
    img = cv2.cvtColor(sc, cv2.COLOR_BGR2GRAY)  # 转灰度图
cv2.error: C:\projects\opencv-python\opencv\modules\imgproc\src\color.cpp:11073: error: (-215) depth == 0 || depth == 2 || depth == 5 in function cv::cvtColor

Sun, 22 Apr 2018 11:57:21 imgcut.py[line:372] ERROR cut_img 这里出错
Sun, 22 Apr 2018 11:57:21 imgcut.py[line:373] ERROR this is an exception message
Traceback (most recent call last):
  File "E:\hupai\component\imgcut.py", line 365, in cut_img
    set_val('imgpos_lowestprice', img[use_area[0][1]:use_area[0][3], use_area[0][0]:use_area[0][2]])  # ok
IndexError: list index out of range
