Wed, 25 Apr 2018 21:24:40 PngImagePlugin.py[line:137] DEBUG STREAM b'IHDR' 16 13
Wed, 25 Apr 2018 21:24:40 PngImagePlugin.py[line:137] DEBUG STREAM b'IDAT' 41 65536
Wed, 25 Apr 2018 21:24:40 PngImagePlugin.py[line:137] DEBUG STREAM b'IHDR' 16 13
Wed, 25 Apr 2018 21:24:40 PngImagePlugin.py[line:137] DEBUG STREAM b'IDAT' 41 65536
Wed, 25 Apr 2018 21:24:42 app_thread.py[line:147] ERROR 刷新失败
Wed, 25 Apr 2018 21:24:42 app_thread.py[line:148] ERROR this is an exception message
Traceback (most recent call last):
  File "E:\hupai\component\app_thread.py", line 145, in run
    findrefresh()
  File "E:\hupai\component\imgcut.py", line 396, in findrefresh
    img = cv2.cvtColor(sc, cv2.COLOR_BGR2GRAY)  # 转灰度图
cv2.error: C:\projects\opencv-python\opencv\modules\imgproc\src\color.cpp:11073: error: (-215) depth == 0 || depth == 2 || depth == 5 in function cv::cvtColor

Wed, 25 Apr 2018 21:24:42 imgcut.py[line:381] ERROR cut_img 这里出错
Wed, 25 Apr 2018 21:24:42 imgcut.py[line:382] ERROR this is an exception message
Traceback (most recent call last):
  File "E:\hupai\component\imgcut.py", line 374, in cut_img
    set_val('imgpos_lowestprice', img[use_area[0][1]:use_area[0][3], use_area[0][0]:use_area[0][2]])  # ok
IndexError: list index out of range
Wed, 25 Apr 2018 21:24:42 app_thread.py[line:147] ERROR 刷新失败
Wed, 25 Apr 2018 21:24:42 app_thread.py[line:148] ERROR this is an exception message
Traceback (most recent call last):
  File "E:\hupai\component\app_thread.py", line 145, in run
    findrefresh()
  File "E:\hupai\component\imgcut.py", line 396, in findrefresh
    img = cv2.cvtColor(sc, cv2.COLOR_BGR2GRAY)  # 转灰度图
cv2.error: C:\projects\opencv-python\opencv\modules\imgproc\src\color.cpp:11073: error: (-215) depth == 0 || depth == 2 || depth == 5 in function cv::cvtColor

Wed, 25 Apr 2018 21:24:42 imgcut.py[line:381] ERROR cut_img 这里出错
Wed, 25 Apr 2018 21:24:42 imgcut.py[line:382] ERROR this is an exception message
Traceback (most recent call last):
  File "E:\hupai\component\imgcut.py", line 374, in cut_img
    set_val('imgpos_lowestprice', img[use_area[0][1]:use_area[0][3], use_area[0][0]:use_area[0][2]])  # ok
IndexError: list index out of range
Wed, 25 Apr 2018 21:24:42 app_thread.py[line:147] ERROR 刷新失败
Wed, 25 Apr 2018 21:24:42 app_thread.py[line:148] ERROR this is an exception message
Traceback (most recent call last):
  File "E:\hupai\component\app_thread.py", line 145, in run
    findrefresh()
  File "E:\hupai\component\imgcut.py", line 396, in findrefresh
    img = cv2.cvtColor(sc, cv2.COLOR_BGR2GRAY)  # 转灰度图
cv2.error: C:\projects\opencv-python\opencv\modules\imgproc\src\color.cpp:11073: error: (-215) depth == 0 || depth == 2 || depth == 5 in function cv::cvtColor

Wed, 25 Apr 2018 21:24:43 app_thread.py[line:147] ERROR 刷新失败
Wed, 25 Apr 2018 21:24:43 app_thread.py[line:148] ERROR this is an exception message
Traceback (most recent call last):
  File "E:\hupai\component\app_thread.py", line 145, in run
    findrefresh()
  File "E:\hupai\component\imgcut.py", line 396, in findrefresh
    img = cv2.cvtColor(sc, cv2.COLOR_BGR2GRAY)  # 转灰度图
cv2.error: C:\projects\opencv-python\opencv\modules\imgproc\src\color.cpp:11073: error: (-215) depth == 0 || depth == 2 || depth == 5 in function cv::cvtColor

Wed, 25 Apr 2018 21:24:43 imgcut.py[line:381] ERROR cut_img 这里出错
Wed, 25 Apr 2018 21:24:43 imgcut.py[line:382] ERROR this is an exception message
Traceback (most recent call last):
  File "E:\hupai\component\imgcut.py", line 374, in cut_img
    set_val('imgpos_lowestprice', img[use_area[0][1]:use_area[0][3], use_area[0][0]:use_area[0][2]])  # ok
IndexError: list index out of range
Wed, 25 Apr 2018 21:24:43 app_thread.py[line:147] ERROR 刷新失败
Wed, 25 Apr 2018 21:24:43 app_thread.py[line:148] ERROR this is an exception message
Traceback (most recent call last):
  File "E:\hupai\component\app_thread.py", line 145, in run
    findrefresh()
  File "E:\hupai\component\imgcut.py", line 396, in findrefresh
    img = cv2.cvtColor(sc, cv2.COLOR_BGR2GRAY)  # 转灰度图
cv2.error: C:\projects\opencv-python\opencv\modules\imgproc\src\color.cpp:11073: error: (-215) depth == 0 || depth == 2 || depth == 5 in function cv::cvtColor

Wed, 25 Apr 2018 21:24:43 app_thread.py[line:147] ERROR 刷新失败
Wed, 25 Apr 2018 21:24:43 app_thread.py[line:148] ERROR this is an exception message
Traceback (most recent call last):
  File "E:\hupai\component\app_thread.py", line 145, in run
    findrefresh()
  File "E:\hupai\component\imgcut.py", line 396, in findrefresh
    img = cv2.cvtColor(sc, cv2.COLOR_BGR2GRAY)  # 转灰度图
cv2.error: C:\projects\opencv-python\opencv\modules\imgproc\src\color.cpp:11073: error: (-215) depth == 0 || depth == 2 || depth == 5 in function cv::cvtColor

Wed, 25 Apr 2018 21:24:43 imgcut.py[line:381] ERROR cut_img 这里出错
Wed, 25 Apr 2018 21:24:43 imgcut.py[line:382] ERROR this is an exception message
Traceback (most recent call last):
  File "E:\hupai\component\imgcut.py", line 374, in cut_img
    set_val('imgpos_lowestprice', img[use_area[0][1]:use_area[0][3], use_area[0][0]:use_area[0][2]])  # ok
IndexError: list index out of range
Wed, 25 Apr 2018 21:24:43 app_thread.py[line:147] ERROR 刷新失败
Wed, 25 Apr 2018 21:24:43 app_thread.py[line:148] ERROR this is an exception message
Traceback (most recent call last):
  File "E:\hupai\component\app_thread.py", line 145, in run
    findrefresh()
  File "E:\hupai\component\imgcut.py", line 396, in findrefresh
    img = cv2.cvtColor(sc, cv2.COLOR_BGR2GRAY)  # 转灰度图
cv2.error: C:\projects\opencv-python\opencv\modules\imgproc\src\color.cpp:11073: error: (-215) depth == 0 || depth == 2 || depth == 5 in function cv::cvtColor

Wed, 25 Apr 2018 21:24:43 imgcut.py[line:381] ERROR cut_img 这里出错
Wed, 25 Apr 2018 21:24:43 imgcut.py[line:382] ERROR this is an exception message
Traceback (most recent call last):
  File "E:\hupai\component\imgcut.py", line 374, in cut_img
    set_val('imgpos_lowestprice', img[use_area[0][1]:use_area[0][3], use_area[0][0]:use_area[0][2]])  # ok
IndexError: list index out of range
Wed, 25 Apr 2018 21:24:43 app_thread.py[line:147] ERROR 刷新失败
Wed, 25 Apr 2018 21:24:43 app_thread.py[line:148] ERROR this is an exception message
Traceback (most recent call last):
  File "E:\hupai\component\app_thread.py", line 145, in run
    findrefresh()
  File "E:\hupai\component\imgcut.py", line 396, in findrefresh
    img = cv2.cvtColor(sc, cv2.COLOR_BGR2GRAY)  # 转灰度图
cv2.error: C:\projects\opencv-python\opencv\modules\imgproc\src\color.cpp:11073: error: (-215) depth == 0 || depth == 2 || depth == 5 in function cv::cvtColor

Wed, 25 Apr 2018 21:24:43 imgcut.py[line:381] ERROR cut_img 这里出错
Wed, 25 Apr 2018 21:24:43 imgcut.py[line:382] ERROR this is an exception message
Traceback (most recent call last):
  File "E:\hupai\component\imgcut.py", line 374, in cut_img
    set_val('imgpos_lowestprice', img[use_area[0][1]:use_area[0][3], use_area[0][0]:use_area[0][2]])  # ok
IndexError: list index out of range
Wed, 25 Apr 2018 21:24:43 app_thread.py[line:147] ERROR 刷新失败
Wed, 25 Apr 2018 21:24:43 app_thread.py[line:148] ERROR this is an exception message
Traceback (most recent call last):
  File "E:\hupai\component\app_thread.py", line 145, in run
    findrefresh()
  File "E:\hupai\component\imgcut.py", line 396, in findrefresh
    img = cv2.cvtColor(sc, cv2.COLOR_BGR2GRAY)  # 转灰度图
cv2.error: C:\projects\opencv-python\opencv\modules\imgproc\src\color.cpp:11073: error: (-215) depth == 0 || depth == 2 || depth == 5 in function cv::cvtColor

Wed, 25 Apr 2018 21:24:43 imgcut.py[line:381] ERROR cut_img 这里出错
Wed, 25 Apr 2018 21:24:43 imgcut.py[line:382] ERROR this is an exception message
Traceback (most recent call last):
  File "E:\hupai\component\imgcut.py", line 374, in cut_img
    set_val('imgpos_lowestprice', img[use_area[0][1]:use_area[0][3], use_area[0][0]:use_area[0][2]])  # ok
IndexError: list index out of range
Wed, 25 Apr 2018 21:24:43 app_thread.py[line:147] ERROR 刷新失败
Wed, 25 Apr 2018 21:24:43 app_thread.py[line:148] ERROR this is an exception message
Traceback (most recent call last):
  File "E:\hupai\component\app_thread.py", line 145, in run
    findrefresh()
  File "E:\hupai\component\imgcut.py", line 396, in findrefresh
    img = cv2.cvtColor(sc, cv2.COLOR_BGR2GRAY)  # 转灰度图
cv2.error: C:\projects\opencv-python\opencv\modules\imgproc\src\color.cpp:11073: error: (-215) depth == 0 || depth == 2 || depth == 5 in function cv::cvtColor

Wed, 25 Apr 2018 21:24:43 app_thread.py[line:147] ERROR 刷新失败
Wed, 25 Apr 2018 21:24:43 app_thread.py[line:148] ERROR this is an exception message
Traceback (most recent call last):
  File "E:\hupai\component\app_thread.py", line 145, in run
    findrefresh()
  File "E:\hupai\component\imgcut.py", line 396, in findrefresh
    img = cv2.cvtColor(sc, cv2.COLOR_BGR2GRAY)  # 转灰度图
cv2.error: C:\projects\opencv-python\opencv\modules\imgproc\src\color.cpp:11073: error: (-215) depth == 0 || depth == 2 || depth == 5 in function cv::cvtColor

Wed, 25 Apr 2018 21:24:43 imgcut.py[line:381] ERROR cut_img 这里出错
Wed, 25 Apr 2018 21:24:43 imgcut.py[line:382] ERROR this is an exception message
Traceback (most recent call last):
  File "E:\hupai\component\imgcut.py", line 374, in cut_img
    set_val('imgpos_lowestprice', img[use_area[0][1]:use_area[0][3], use_area[0][0]:use_area[0][2]])  # ok
IndexError: list index out of range
Wed, 25 Apr 2018 21:24:43 app_thread.py[line:147] ERROR 刷新失败
Wed, 25 Apr 2018 21:24:43 app_thread.py[line:148] ERROR this is an exception message
Traceback (most recent call last):
  File "E:\hupai\component\app_thread.py", line 145, in run
    findrefresh()
  File "E:\hupai\component\imgcut.py", line 396, in findrefresh
    img = cv2.cvtColor(sc, cv2.COLOR_BGR2GRAY)  # 转灰度图
cv2.error: C:\projects\opencv-python\opencv\modules\imgproc\src\color.cpp:11073: error: (-215) depth == 0 || depth == 2 || depth == 5 in function cv::cvtColor

Wed, 25 Apr 2018 21:24:43 imgcut.py[line:381] ERROR cut_img 这里出错
Wed, 25 Apr 2018 21:24:43 imgcut.py[line:382] ERROR this is an exception message
Traceback (most recent call last):
  File "E:\hupai\component\imgcut.py", line 374, in cut_img
    set_val('imgpos_lowestprice', img[use_area[0][1]:use_area[0][3], use_area[0][0]:use_area[0][2]])  # ok
IndexError: list index out of range
Wed, 25 Apr 2018 21:24:43 app_thread.py[line:147] ERROR 刷新失败
Wed, 25 Apr 2018 21:24:43 app_thread.py[line:148] ERROR this is an exception message
Traceback (most recent call last):
  File "E:\hupai\component\app_thread.py", line 145, in run
    findrefresh()
  File "E:\hupai\component\imgcut.py", line 396, in findrefresh
    img = cv2.cvtColor(sc, cv2.COLOR_BGR2GRAY)  # 转灰度图
cv2.error: C:\projects\opencv-python\opencv\modules\imgproc\src\color.cpp:11073: error: (-215) depth == 0 || depth == 2 || depth == 5 in function cv::cvtColor

Wed, 25 Apr 2018 21:24:43 imgcut.py[line:381] ERROR cut_img 这里出错
Wed, 25 Apr 2018 21:24:43 imgcut.py[line:382] ERROR this is an exception message
Traceback (most recent call last):
  File "E:\hupai\component\imgcut.py", line 374, in cut_img
    set_val('imgpos_lowestprice', img[use_area[0][1]:use_area[0][3], use_area[0][0]:use_area[0][2]])  # ok
IndexError: list index out of range
Wed, 25 Apr 2018 21:24:43 app_thread.py[line:147] ERROR 刷新失败
Wed, 25 Apr 2018 21:24:43 app_thread.py[line:148] ERROR this is an exception message
Traceback (most recent call last):
  File "E:\hupai\component\app_thread.py", line 145, in run
    findrefresh()
  File "E:\hupai\component\imgcut.py", line 396, in findrefresh
    img = cv2.cvtColor(sc, cv2.COLOR_BGR2GRAY)  # 转灰度图
cv2.error: C:\projects\opencv-python\opencv\modules\imgproc\src\color.cpp:11073: error: (-215) depth == 0 || depth == 2 || depth == 5 in function cv::cvtColor

Wed, 25 Apr 2018 21:24:43 app_thread.py[line:147] ERROR 刷新失败
Wed, 25 Apr 2018 21:24:43 app_thread.py[line:148] ERROR this is an exception message
Traceback (most recent call last):
  File "E:\hupai\component\app_thread.py", line 145, in run
    findrefresh()
  File "E:\hupai\component\imgcut.py", line 396, in findrefresh
    img = cv2.cvtColor(sc, cv2.COLOR_BGR2GRAY)  # 转灰度图
cv2.error: C:\projects\opencv-python\opencv\modules\imgproc\src\color.cpp:11073: error: (-215) depth == 0 || depth == 2 || depth == 5 in function cv::cvtColor

Wed, 25 Apr 2018 21:24:43 imgcut.py[line:381] ERROR cut_img 这里出错
Wed, 25 Apr 2018 21:24:43 imgcut.py[line:382] ERROR this is an exception message
Traceback (most recent call last):
  File "E:\hupai\component\imgcut.py", line 374, in cut_img
    set_val('imgpos_lowestprice', img[use_area[0][1]:use_area[0][3], use_area[0][0]:use_area[0][2]])  # ok
IndexError: list index out of range
Wed, 25 Apr 2018 21:24:43 app_thread.py[line:147] ERROR 刷新失败
Wed, 25 Apr 2018 21:24:43 app_thread.py[line:148] ERROR this is an exception message
Traceback (most recent call last):
  File "E:\hupai\component\app_thread.py", line 145, in run
    findrefresh()
  File "E:\hupai\component\imgcut.py", line 396, in findrefresh
    img = cv2.cvtColor(sc, cv2.COLOR_BGR2GRAY)  # 转灰度图
cv2.error: C:\projects\opencv-python\opencv\modules\imgproc\src\color.cpp:11073: error: (-215) depth == 0 || depth == 2 || depth == 5 in function cv::cvtColor

Wed, 25 Apr 2018 21:24:43 imgcut.py[line:381] ERROR cut_img 这里出错
Wed, 25 Apr 2018 21:24:43 imgcut.py[line:382] ERROR this is an exception message
Traceback (most recent call last):
  File "E:\hupai\component\imgcut.py", line 374, in cut_img
    set_val('imgpos_lowestprice', img[use_area[0][1]:use_area[0][3], use_area[0][0]:use_area[0][2]])  # ok
IndexError: list index out of range
Wed, 25 Apr 2018 21:24:43 app_thread.py[line:147] ERROR 刷新失败
Wed, 25 Apr 2018 21:24:43 app_thread.py[line:148] ERROR this is an exception message
Traceback (most recent call last):
  File "E:\hupai\component\app_thread.py", line 145, in run
    findrefresh()
  File "E:\hupai\component\imgcut.py", line 396, in findrefresh
    img = cv2.cvtColor(sc, cv2.COLOR_BGR2GRAY)  # 转灰度图
cv2.error: C:\projects\opencv-python\opencv\modules\imgproc\src\color.cpp:11073: error: (-215) depth == 0 || depth == 2 || depth == 5 in function cv::cvtColor

Wed, 25 Apr 2018 21:24:43 imgcut.py[line:381] ERROR cut_img 这里出错
Wed, 25 Apr 2018 21:24:43 imgcut.py[line:382] ERROR this is an exception message
Traceback (most recent call last):
  File "E:\hupai\component\imgcut.py", line 374, in cut_img
    set_val('imgpos_lowestprice', img[use_area[0][1]:use_area[0][3], use_area[0][0]:use_area[0][2]])  # ok
IndexError: list index out of range
Wed, 25 Apr 2018 21:24:43 app_thread.py[line:147] ERROR 刷新失败
Wed, 25 Apr 2018 21:24:43 app_thread.py[line:148] ERROR this is an exception message
Traceback (most recent call last):
  File "E:\hupai\component\app_thread.py", line 145, in run
    findrefresh()
  File "E:\hupai\component\imgcut.py", line 396, in findrefresh
    img = cv2.cvtColor(sc, cv2.COLOR_BGR2GRAY)  # 转灰度图
cv2.error: C:\projects\opencv-python\opencv\modules\imgproc\src\color.cpp:11073: error: (-215) depth == 0 || depth == 2 || depth == 5 in function cv::cvtColor

Wed, 25 Apr 2018 21:24:43 imgcut.py[line:381] ERROR cut_img 这里出错
Wed, 25 Apr 2018 21:24:43 imgcut.py[line:382] ERROR this is an exception message
Traceback (most recent call last):
  File "E:\hupai\component\imgcut.py", line 374, in cut_img
    set_val('imgpos_lowestprice', img[use_area[0][1]:use_area[0][3], use_area[0][0]:use_area[0][2]])  # ok
IndexError: list index out of range
Wed, 25 Apr 2018 21:24:43 app_thread.py[line:147] ERROR 刷新失败
Wed, 25 Apr 2018 21:24:43 app_thread.py[line:148] ERROR this is an exception message
Traceback (most recent call last):
  File "E:\hupai\component\app_thread.py", line 145, in run
    findrefresh()
  File "E:\hupai\component\imgcut.py", line 396, in findrefresh
    img = cv2.cvtColor(sc, cv2.COLOR_BGR2GRAY)  # 转灰度图
cv2.error: C:\projects\opencv-python\opencv\modules\imgproc\src\color.cpp:11073: error: (-215) depth == 0 || depth == 2 || depth == 5 in function cv::cvtColor

Wed, 25 Apr 2018 21:24:43 imgcut.py[line:381] ERROR cut_img 这里出错
Wed, 25 Apr 2018 21:24:43 imgcut.py[line:382] ERROR this is an exception message
Traceback (most recent call last):
  File "E:\hupai\component\imgcut.py", line 374, in cut_img
    set_val('imgpos_lowestprice', img[use_area[0][1]:use_area[0][3], use_area[0][0]:use_area[0][2]])  # ok
IndexError: list index out of range
Wed, 25 Apr 2018 21:24:44 app_thread.py[line:147] ERROR 刷新失败
Wed, 25 Apr 2018 21:24:44 app_thread.py[line:148] ERROR this is an exception message
Traceback (most recent call last):
  File "E:\hupai\component\app_thread.py", line 145, in run
    findrefresh()
  File "E:\hupai\component\imgcut.py", line 396, in findrefresh
    img = cv2.cvtColor(sc, cv2.COLOR_BGR2GRAY)  # 转灰度图
cv2.error: C:\projects\opencv-python\opencv\modules\imgproc\src\color.cpp:11073: error: (-215) depth == 0 || depth == 2 || depth == 5 in function cv::cvtColor

Wed, 25 Apr 2018 21:24:44 app_thread.py[line:147] ERROR 刷新失败
Wed, 25 Apr 2018 21:24:44 app_thread.py[line:148] ERROR this is an exception message
Traceback (most recent call last):
  File "E:\hupai\component\app_thread.py", line 145, in run
    findrefresh()
  File "E:\hupai\component\imgcut.py", line 396, in findrefresh
    img = cv2.cvtColor(sc, cv2.COLOR_BGR2GRAY)  # 转灰度图
cv2.error: C:\projects\opencv-python\opencv\modules\imgproc\src\color.cpp:11073: error: (-215) depth == 0 || depth == 2 || depth == 5 in function cv::cvtColor

Wed, 25 Apr 2018 21:24:44 imgcut.py[line:381] ERROR cut_img 这里出错
Wed, 25 Apr 2018 21:24:44 imgcut.py[line:382] ERROR this is an exception message
Traceback (most recent call last):
  File "E:\hupai\component\imgcut.py", line 374, in cut_img
    set_val('imgpos_lowestprice', img[use_area[0][1]:use_area[0][3], use_area[0][0]:use_area[0][2]])  # ok
IndexError: list index out of range
Wed, 25 Apr 2018 21:24:44 app_thread.py[line:147] ERROR 刷新失败
Wed, 25 Apr 2018 21:24:44 app_thread.py[line:148] ERROR this is an exception message
Traceback (most recent call last):
  File "E:\hupai\component\app_thread.py", line 145, in run
    findrefresh()
  File "E:\hupai\component\imgcut.py", line 396, in findrefresh
    img = cv2.cvtColor(sc, cv2.COLOR_BGR2GRAY)  # 转灰度图
cv2.error: C:\projects\opencv-python\opencv\modules\imgproc\src\color.cpp:11073: error: (-215) depth == 0 || depth == 2 || depth == 5 in function cv::cvtColor

Wed, 25 Apr 2018 21:24:44 imgcut.py[line:381] ERROR cut_img 这里出错
Wed, 25 Apr 2018 21:24:44 imgcut.py[line:382] ERROR this is an exception message
Traceback (most recent call last):
  File "E:\hupai\component\imgcut.py", line 374, in cut_img
    set_val('imgpos_lowestprice', img[use_area[0][1]:use_area[0][3], use_area[0][0]:use_area[0][2]])  # ok
IndexError: list index out of range
Wed, 25 Apr 2018 21:24:44 app_thread.py[line:147] ERROR 刷新失败
Wed, 25 Apr 2018 21:24:44 app_thread.py[line:148] ERROR this is an exception message
Traceback (most recent call last):
  File "E:\hupai\component\app_thread.py", line 145, in run
    findrefresh()
  File "E:\hupai\component\imgcut.py", line 396, in findrefresh
    img = cv2.cvtColor(sc, cv2.COLOR_BGR2GRAY)  # 转灰度图
cv2.error: C:\projects\opencv-python\opencv\modules\imgproc\src\color.cpp:11073: error: (-215) depth == 0 || depth == 2 || depth == 5 in function cv::cvtColor

Wed, 25 Apr 2018 21:24:44 imgcut.py[line:381] ERROR cut_img 这里出错
Wed, 25 Apr 2018 21:24:44 imgcut.py[line:382] ERROR this is an exception message
Traceback (most recent call last):
  File "E:\hupai\component\imgcut.py", line 374, in cut_img
    set_val('imgpos_lowestprice', img[use_area[0][1]:use_area[0][3], use_area[0][0]:use_area[0][2]])  # ok
IndexError: list index out of range
Wed, 25 Apr 2018 21:24:44 app_thread.py[line:147] ERROR 刷新失败
Wed, 25 Apr 2018 21:24:44 app_thread.py[line:148] ERROR this is an exception message
Traceback (most recent call last):
  File "E:\hupai\component\app_thread.py", line 145, in run
    findrefresh()
  File "E:\hupai\component\imgcut.py", line 396, in findrefresh
    img = cv2.cvtColor(sc, cv2.COLOR_BGR2GRAY)  # 转灰度图
cv2.error: C:\projects\opencv-python\opencv\modules\imgproc\src\color.cpp:11073: error: (-215) depth == 0 || depth == 2 || depth == 5 in function cv::cvtColor

Wed, 25 Apr 2018 21:24:44 imgcut.py[line:381] ERROR cut_img 这里出错
Wed, 25 Apr 2018 21:24:44 imgcut.py[line:382] ERROR this is an exception message
Traceback (most recent call last):
  File "E:\hupai\component\imgcut.py", line 374, in cut_img
    set_val('imgpos_lowestprice', img[use_area[0][1]:use_area[0][3], use_area[0][0]:use_area[0][2]])  # ok
IndexError: list index out of range
Wed, 25 Apr 2018 21:24:44 app_thread.py[line:147] ERROR 刷新失败
Wed, 25 Apr 2018 21:24:44 app_thread.py[line:148] ERROR this is an exception message
Traceback (most recent call last):
  File "E:\hupai\component\app_thread.py", line 145, in run
    findrefresh()
  File "E:\hupai\component\imgcut.py", line 396, in findrefresh
    img = cv2.cvtColor(sc, cv2.COLOR_BGR2GRAY)  # 转灰度图
cv2.error: C:\projects\opencv-python\opencv\modules\imgproc\src\color.cpp:11073: error: (-215) depth == 0 || depth == 2 || depth == 5 in function cv::cvtColor

Wed, 25 Apr 2018 21:24:44 app_thread.py[line:147] ERROR 刷新失败
Wed, 25 Apr 2018 21:24:44 app_thread.py[line:148] ERROR this is an exception message
Traceback (most recent call last):
  File "E:\hupai\component\app_thread.py", line 145, in run
    findrefresh()
  File "E:\hupai\component\imgcut.py", line 396, in findrefresh
    img = cv2.cvtColor(sc, cv2.COLOR_BGR2GRAY)  # 转灰度图
cv2.error: C:\projects\opencv-python\opencv\modules\imgproc\src\color.cpp:11073: error: (-215) depth == 0 || depth == 2 || depth == 5 in function cv::cvtColor

Wed, 25 Apr 2018 21:24:44 imgcut.py[line:381] ERROR cut_img 这里出错
Wed, 25 Apr 2018 21:24:44 imgcut.py[line:382] ERROR this is an exception message
Traceback (most recent call last):
  File "E:\hupai\component\imgcut.py", line 374, in cut_img
    set_val('imgpos_lowestprice', img[use_area[0][1]:use_area[0][3], use_area[0][0]:use_area[0][2]])  # ok
IndexError: list index out of range
Wed, 25 Apr 2018 21:24:44 app_thread.py[line:147] ERROR 刷新失败
Wed, 25 Apr 2018 21:24:44 app_thread.py[line:148] ERROR this is an exception message
Traceback (most recent call last):
  File "E:\hupai\component\app_thread.py", line 145, in run
    findrefresh()
  File "E:\hupai\component\imgcut.py", line 396, in findrefresh
    img = cv2.cvtColor(sc, cv2.COLOR_BGR2GRAY)  # 转灰度图
cv2.error: C:\projects\opencv-python\opencv\modules\imgproc\src\color.cpp:11073: error: (-215) depth == 0 || depth == 2 || depth == 5 in function cv::cvtColor

Wed, 25 Apr 2018 21:24:44 imgcut.py[line:381] ERROR cut_img 这里出错
Wed, 25 Apr 2018 21:24:44 app_thread.py[line:147] ERROR 刷新失败
Wed, 25 Apr 2018 21:24:44 imgcut.py[line:382] ERROR this is an exception message
Traceback (most recent call last):
  File "E:\hupai\component\imgcut.py", line 374, in cut_img
    set_val('imgpos_lowestprice', img[use_area[0][1]:use_area[0][3], use_area[0][0]:use_area[0][2]])  # ok
IndexError: list index out of range
Wed, 25 Apr 2018 21:24:44 app_thread.py[line:148] ERROR this is an exception message
Traceback (most recent call last):
  File "E:\hupai\component\app_thread.py", line 145, in run
    findrefresh()
  File "E:\hupai\component\imgcut.py", line 396, in findrefresh
    img = cv2.cvtColor(sc, cv2.COLOR_BGR2GRAY)  # 转灰度图
cv2.error: C:\projects\opencv-python\opencv\modules\imgproc\src\color.cpp:11073: error: (-215) depth == 0 || depth == 2 || depth == 5 in function cv::cvtColor

Wed, 25 Apr 2018 21:24:44 app_thread.py[line:147] ERROR 刷新失败
Wed, 25 Apr 2018 21:24:44 app_thread.py[line:148] ERROR this is an exception message
Traceback (most recent call last):
  File "E:\hupai\component\app_thread.py", line 145, in run
    findrefresh()
  File "E:\hupai\component\imgcut.py", line 396, in findrefresh
    img = cv2.cvtColor(sc, cv2.COLOR_BGR2GRAY)  # 转灰度图
cv2.error: C:\projects\opencv-python\opencv\modules\imgproc\src\color.cpp:11073: error: (-215) depth == 0 || depth == 2 || depth == 5 in function cv::cvtColor

Wed, 25 Apr 2018 21:24:44 imgcut.py[line:381] ERROR cut_img 这里出错
Wed, 25 Apr 2018 21:24:44 imgcut.py[line:382] ERROR this is an exception message
Traceback (most recent call last):
  File "E:\hupai\component\imgcut.py", line 374, in cut_img
    set_val('imgpos_lowestprice', img[use_area[0][1]:use_area[0][3], use_area[0][0]:use_area[0][2]])  # ok
IndexError: list index out of range
Wed, 25 Apr 2018 21:24:44 app_thread.py[line:147] ERROR 刷新失败
Wed, 25 Apr 2018 21:24:44 app_thread.py[line:148] ERROR this is an exception message
Traceback (most recent call last):
  File "E:\hupai\component\app_thread.py", line 145, in run
    findrefresh()
  File "E:\hupai\component\imgcut.py", line 396, in findrefresh
    img = cv2.cvtColor(sc, cv2.COLOR_BGR2GRAY)  # 转灰度图
cv2.error: C:\projects\opencv-python\opencv\modules\imgproc\src\color.cpp:11073: error: (-215) depth == 0 || depth == 2 || depth == 5 in function cv::cvtColor

Wed, 25 Apr 2018 21:24:44 imgcut.py[line:381] ERROR cut_img 这里出错
Wed, 25 Apr 2018 21:24:44 imgcut.py[line:382] ERROR this is an exception message
Traceback (most recent call last):
  File "E:\hupai\component\imgcut.py", line 374, in cut_img
    set_val('imgpos_lowestprice', img[use_area[0][1]:use_area[0][3], use_area[0][0]:use_area[0][2]])  # ok
IndexError: list index out of range
Wed, 25 Apr 2018 21:24:44 app_thread.py[line:147] ERROR 刷新失败
Wed, 25 Apr 2018 21:24:44 app_thread.py[line:148] ERROR this is an exception message
Traceback (most recent call last):
  File "E:\hupai\component\app_thread.py", line 145, in run
    findrefresh()
  File "E:\hupai\component\imgcut.py", line 396, in findrefresh
    img = cv2.cvtColor(sc, cv2.COLOR_BGR2GRAY)  # 转灰度图
cv2.error: C:\projects\opencv-python\opencv\modules\imgproc\src\color.cpp:11073: error: (-215) depth == 0 || depth == 2 || depth == 5 in function cv::cvtColor

Wed, 25 Apr 2018 21:24:44 app_thread.py[line:147] ERROR 刷新失败
Wed, 25 Apr 2018 21:24:44 app_thread.py[line:148] ERROR this is an exception message
Traceback (most recent call last):
  File "E:\hupai\component\app_thread.py", line 145, in run
    findrefresh()
  File "E:\hupai\component\imgcut.py", line 396, in findrefresh
    img = cv2.cvtColor(sc, cv2.COLOR_BGR2GRAY)  # 转灰度图
cv2.error: C:\projects\opencv-python\opencv\modules\imgproc\src\color.cpp:11073: error: (-215) depth == 0 || depth == 2 || depth == 5 in function cv::cvtColor

Wed, 25 Apr 2018 21:24:44 imgcut.py[line:381] ERROR cut_img 这里出错
Wed, 25 Apr 2018 21:24:44 imgcut.py[line:382] ERROR this is an exception message
Traceback (most recent call last):
  File "E:\hupai\component\imgcut.py", line 374, in cut_img
    set_val('imgpos_lowestprice', img[use_area[0][1]:use_area[0][3], use_area[0][0]:use_area[0][2]])  # ok
IndexError: list index out of range
Wed, 25 Apr 2018 21:24:44 app_thread.py[line:147] ERROR 刷新失败
Wed, 25 Apr 2018 21:24:44 app_thread.py[line:148] ERROR this is an exception message
Traceback (most recent call last):
  File "E:\hupai\component\app_thread.py", line 145, in run
    findrefresh()
  File "E:\hupai\component\imgcut.py", line 396, in findrefresh
    img = cv2.cvtColor(sc, cv2.COLOR_BGR2GRAY)  # 转灰度图
cv2.error: C:\projects\opencv-python\opencv\modules\imgproc\src\color.cpp:11073: error: (-215) depth == 0 || depth == 2 || depth == 5 in function cv::cvtColor

Wed, 25 Apr 2018 21:24:44 imgcut.py[line:381] ERROR cut_img 这里出错
Wed, 25 Apr 2018 21:24:44 app_thread.py[line:147] ERROR 刷新失败
Wed, 25 Apr 2018 21:24:44 imgcut.py[line:382] ERROR this is an exception message
Traceback (most recent call last):
  File "E:\hupai\component\imgcut.py", line 374, in cut_img
    set_val('imgpos_lowestprice', img[use_area[0][1]:use_area[0][3], use_area[0][0]:use_area[0][2]])  # ok
IndexError: list index out of range
Wed, 25 Apr 2018 21:24:44 app_thread.py[line:148] ERROR this is an exception message
Traceback (most recent call last):
  File "E:\hupai\component\app_thread.py", line 145, in run
    findrefresh()
  File "E:\hupai\component\imgcut.py", line 396, in findrefresh
    img = cv2.cvtColor(sc, cv2.COLOR_BGR2GRAY)  # 转灰度图
cv2.error: C:\projects\opencv-python\opencv\modules\imgproc\src\color.cpp:11073: error: (-215) depth == 0 || depth == 2 || depth == 5 in function cv::cvtColor

Wed, 25 Apr 2018 21:24:44 app_thread.py[line:147] ERROR 刷新失败
Wed, 25 Apr 2018 21:24:44 app_thread.py[line:148] ERROR this is an exception message
Traceback (most recent call last):
  File "E:\hupai\component\app_thread.py", line 145, in run
    findrefresh()
  File "E:\hupai\component\imgcut.py", line 396, in findrefresh
    img = cv2.cvtColor(sc, cv2.COLOR_BGR2GRAY)  # 转灰度图
cv2.error: C:\projects\opencv-python\opencv\modules\imgproc\src\color.cpp:11073: error: (-215) depth == 0 || depth == 2 || depth == 5 in function cv::cvtColor

Wed, 25 Apr 2018 21:24:44 imgcut.py[line:381] ERROR cut_img 这里出错
Wed, 25 Apr 2018 21:24:44 imgcut.py[line:382] ERROR this is an exception message
Traceback (most recent call last):
  File "E:\hupai\component\imgcut.py", line 374, in cut_img
    set_val('imgpos_lowestprice', img[use_area[0][1]:use_area[0][3], use_area[0][0]:use_area[0][2]])  # ok
IndexError: list index out of range
Wed, 25 Apr 2018 21:24:44 app_thread.py[line:147] ERROR 刷新失败
Wed, 25 Apr 2018 21:24:44 app_thread.py[line:148] ERROR this is an exception message
Traceback (most recent call last):
  File "E:\hupai\component\app_thread.py", line 145, in run
    findrefresh()
  File "E:\hupai\component\imgcut.py", line 396, in findrefresh
    img = cv2.cvtColor(sc, cv2.COLOR_BGR2GRAY)  # 转灰度图
cv2.error: C:\projects\opencv-python\opencv\modules\imgproc\src\color.cpp:11073: error: (-215) depth == 0 || depth == 2 || depth == 5 in function cv::cvtColor

Wed, 25 Apr 2018 21:24:44 imgcut.py[line:381] ERROR cut_img 这里出错
Wed, 25 Apr 2018 21:24:44 imgcut.py[line:382] ERROR this is an exception message
Traceback (most recent call last):
  File "E:\hupai\component\imgcut.py", line 374, in cut_img
    set_val('imgpos_lowestprice', img[use_area[0][1]:use_area[0][3], use_area[0][0]:use_area[0][2]])  # ok
IndexError: list index out of range
Wed, 25 Apr 2018 21:24:45 app_thread.py[line:147] ERROR 刷新失败
Wed, 25 Apr 2018 21:24:45 app_thread.py[line:148] ERROR this is an exception message
Traceback (most recent call last):
  File "E:\hupai\component\app_thread.py", line 145, in run
    findrefresh()
  File "E:\hupai\component\imgcut.py", line 396, in findrefresh
    img = cv2.cvtColor(sc, cv2.COLOR_BGR2GRAY)  # 转灰度图
cv2.error: C:\projects\opencv-python\opencv\modules\imgproc\src\color.cpp:11073: error: (-215) depth == 0 || depth == 2 || depth == 5 in function cv::cvtColor

Wed, 25 Apr 2018 21:24:45 app_thread.py[line:147] ERROR 刷新失败
Wed, 25 Apr 2018 21:24:45 imgcut.py[line:381] ERROR cut_img 这里出错
Wed, 25 Apr 2018 21:24:45 app_thread.py[line:148] ERROR this is an exception message
Traceback (most recent call last):
  File "E:\hupai\component\app_thread.py", line 145, in run
    findrefresh()
  File "E:\hupai\component\imgcut.py", line 396, in findrefresh
    img = cv2.cvtColor(sc, cv2.COLOR_BGR2GRAY)  # 转灰度图
cv2.error: C:\projects\opencv-python\opencv\modules\imgproc\src\color.cpp:11073: error: (-215) depth == 0 || depth == 2 || depth == 5 in function cv::cvtColor

Wed, 25 Apr 2018 21:24:45 imgcut.py[line:382] ERROR this is an exception message
Traceback (most recent call last):
  File "E:\hupai\component\imgcut.py", line 374, in cut_img
    set_val('imgpos_lowestprice', img[use_area[0][1]:use_area[0][3], use_area[0][0]:use_area[0][2]])  # ok
IndexError: list index out of range
Wed, 25 Apr 2018 21:24:45 app_thread.py[line:147] ERROR 刷新失败
Wed, 25 Apr 2018 21:24:45 app_thread.py[line:148] ERROR this is an exception message
Traceback (most recent call last):
  File "E:\hupai\component\app_thread.py", line 145, in run
    findrefresh()
  File "E:\hupai\component\imgcut.py", line 396, in findrefresh
    img = cv2.cvtColor(sc, cv2.COLOR_BGR2GRAY)  # 转灰度图
cv2.error: C:\projects\opencv-python\opencv\modules\imgproc\src\color.cpp:11073: error: (-215) depth == 0 || depth == 2 || depth == 5 in function cv::cvtColor

Wed, 25 Apr 2018 21:24:45 imgcut.py[line:381] ERROR cut_img 这里出错
Wed, 25 Apr 2018 21:24:45 imgcut.py[line:382] ERROR this is an exception message
Traceback (most recent call last):
  File "E:\hupai\component\imgcut.py", line 374, in cut_img
    set_val('imgpos_lowestprice', img[use_area[0][1]:use_area[0][3], use_area[0][0]:use_area[0][2]])  # ok
IndexError: list index out of range
Wed, 25 Apr 2018 21:24:45 app_thread.py[line:147] ERROR 刷新失败
Wed, 25 Apr 2018 21:24:45 app_thread.py[line:148] ERROR this is an exception message
Traceback (most recent call last):
  File "E:\hupai\component\app_thread.py", line 145, in run
    findrefresh()
  File "E:\hupai\component\imgcut.py", line 396, in findrefresh
    img = cv2.cvtColor(sc, cv2.COLOR_BGR2GRAY)  # 转灰度图
cv2.error: C:\projects\opencv-python\opencv\modules\imgproc\src\color.cpp:11073: error: (-215) depth == 0 || depth == 2 || depth == 5 in function cv::cvtColor

Wed, 25 Apr 2018 21:24:45 imgcut.py[line:381] ERROR cut_img 这里出错
Wed, 25 Apr 2018 21:24:45 imgcut.py[line:382] ERROR this is an exception message
Traceback (most recent call last):
  File "E:\hupai\component\imgcut.py", line 374, in cut_img
    set_val('imgpos_lowestprice', img[use_area[0][1]:use_area[0][3], use_area[0][0]:use_area[0][2]])  # ok
IndexError: list index out of range
Wed, 25 Apr 2018 21:24:45 app_thread.py[line:147] ERROR 刷新失败
Wed, 25 Apr 2018 21:24:45 app_thread.py[line:148] ERROR this is an exception message
Traceback (most recent call last):
  File "E:\hupai\component\app_thread.py", line 145, in run
    findrefresh()
  File "E:\hupai\component\imgcut.py", line 396, in findrefresh
    img = cv2.cvtColor(sc, cv2.COLOR_BGR2GRAY)  # 转灰度图
cv2.error: C:\projects\opencv-python\opencv\modules\imgproc\src\color.cpp:11073: error: (-215) depth == 0 || depth == 2 || depth == 5 in function cv::cvtColor

Wed, 25 Apr 2018 21:24:45 imgcut.py[line:381] ERROR cut_img 这里出错
Wed, 25 Apr 2018 21:24:45 imgcut.py[line:382] ERROR this is an exception message
Traceback (most recent call last):
  File "E:\hupai\component\imgcut.py", line 374, in cut_img
    set_val('imgpos_lowestprice', img[use_area[0][1]:use_area[0][3], use_area[0][0]:use_area[0][2]])  # ok
IndexError: list index out of range
Wed, 25 Apr 2018 21:24:45 app_thread.py[line:147] ERROR 刷新失败
Wed, 25 Apr 2018 21:24:45 app_thread.py[line:148] ERROR this is an exception message
Traceback (most recent call last):
  File "E:\hupai\component\app_thread.py", line 145, in run
    findrefresh()
  File "E:\hupai\component\imgcut.py", line 396, in findrefresh
    img = cv2.cvtColor(sc, cv2.COLOR_BGR2GRAY)  # 转灰度图
cv2.error: C:\projects\opencv-python\opencv\modules\imgproc\src\color.cpp:11073: error: (-215) depth == 0 || depth == 2 || depth == 5 in function cv::cvtColor

Wed, 25 Apr 2018 21:24:45 app_thread.py[line:147] ERROR 刷新失败
Wed, 25 Apr 2018 21:24:45 app_thread.py[line:148] ERROR this is an exception message
Traceback (most recent call last):
  File "E:\hupai\component\app_thread.py", line 145, in run
    findrefresh()
  File "E:\hupai\component\imgcut.py", line 396, in findrefresh
    img = cv2.cvtColor(sc, cv2.COLOR_BGR2GRAY)  # 转灰度图
cv2.error: C:\projects\opencv-python\opencv\modules\imgproc\src\color.cpp:11073: error: (-215) depth == 0 || depth == 2 || depth == 5 in function cv::cvtColor

Wed, 25 Apr 2018 21:24:45 imgcut.py[line:381] ERROR cut_img 这里出错
Wed, 25 Apr 2018 21:24:45 imgcut.py[line:382] ERROR this is an exception message
Traceback (most recent call last):
  File "E:\hupai\component\imgcut.py", line 374, in cut_img
    set_val('imgpos_lowestprice', img[use_area[0][1]:use_area[0][3], use_area[0][0]:use_area[0][2]])  # ok
IndexError: list index out of range
Wed, 25 Apr 2018 21:24:45 app_thread.py[line:147] ERROR 刷新失败
Wed, 25 Apr 2018 21:24:45 app_thread.py[line:148] ERROR this is an exception message
Traceback (most recent call last):
  File "E:\hupai\component\app_thread.py", line 145, in run
    findrefresh()
  File "E:\hupai\component\imgcut.py", line 396, in findrefresh
    img = cv2.cvtColor(sc, cv2.COLOR_BGR2GRAY)  # 转灰度图
cv2.error: C:\projects\opencv-python\opencv\modules\imgproc\src\color.cpp:11073: error: (-215) depth == 0 || depth == 2 || depth == 5 in function cv::cvtColor

Wed, 25 Apr 2018 21:24:45 imgcut.py[line:381] ERROR cut_img 这里出错
Wed, 25 Apr 2018 21:24:45 imgcut.py[line:382] ERROR this is an exception message
Traceback (most recent call last):
  File "E:\hupai\component\imgcut.py", line 374, in cut_img
    set_val('imgpos_lowestprice', img[use_area[0][1]:use_area[0][3], use_area[0][0]:use_area[0][2]])  # ok
IndexError: list index out of range
Wed, 25 Apr 2018 21:24:45 app_thread.py[line:147] ERROR 刷新失败
Wed, 25 Apr 2018 21:24:45 app_thread.py[line:148] ERROR this is an exception message
Traceback (most recent call last):
  File "E:\hupai\component\app_thread.py", line 145, in run
    findrefresh()
  File "E:\hupai\component\imgcut.py", line 396, in findrefresh
    img = cv2.cvtColor(sc, cv2.COLOR_BGR2GRAY)  # 转灰度图
cv2.error: C:\projects\opencv-python\opencv\modules\imgproc\src\color.cpp:11073: error: (-215) depth == 0 || depth == 2 || depth == 5 in function cv::cvtColor

Wed, 25 Apr 2018 21:24:45 app_thread.py[line:147] ERROR 刷新失败
Wed, 25 Apr 2018 21:24:45 app_thread.py[line:148] ERROR this is an exception message
Traceback (most recent call last):
  File "E:\hupai\component\app_thread.py", line 145, in run
    findrefresh()
  File "E:\hupai\component\imgcut.py", line 396, in findrefresh
    img = cv2.cvtColor(sc, cv2.COLOR_BGR2GRAY)  # 转灰度图
cv2.error: C:\projects\opencv-python\opencv\modules\imgproc\src\color.cpp:11073: error: (-215) depth == 0 || depth == 2 || depth == 5 in function cv::cvtColor

Wed, 25 Apr 2018 21:24:45 app_thread.py[line:147] ERROR 刷新失败
Wed, 25 Apr 2018 21:24:45 app_thread.py[line:148] ERROR this is an exception message
Traceback (most recent call last):
  File "E:\hupai\component\app_thread.py", line 145, in run
    findrefresh()
  File "E:\hupai\component\imgcut.py", line 396, in findrefresh
    img = cv2.cvtColor(sc, cv2.COLOR_BGR2GRAY)  # 转灰度图
cv2.error: C:\projects\opencv-python\opencv\modules\imgproc\src\color.cpp:11073: error: (-215) depth == 0 || depth == 2 || depth == 5 in function cv::cvtColor

Wed, 25 Apr 2018 21:24:45 imgcut.py[line:381] ERROR cut_img 这里出错
Wed, 25 Apr 2018 21:24:45 imgcut.py[line:382] ERROR this is an exception message
Traceback (most recent call last):
  File "E:\hupai\component\imgcut.py", line 374, in cut_img
    set_val('imgpos_lowestprice', img[use_area[0][1]:use_area[0][3], use_area[0][0]:use_area[0][2]])  # ok
IndexError: list index out of range
Wed, 25 Apr 2018 21:24:45 app_thread.py[line:147] ERROR 刷新失败
Wed, 25 Apr 2018 21:24:45 app_thread.py[line:148] ERROR this is an exception message
Traceback (most recent call last):
  File "E:\hupai\component\app_thread.py", line 145, in run
    findrefresh()
  File "E:\hupai\component\imgcut.py", line 396, in findrefresh
    img = cv2.cvtColor(sc, cv2.COLOR_BGR2GRAY)  # 转灰度图
cv2.error: C:\projects\opencv-python\opencv\modules\imgproc\src\color.cpp:11073: error: (-215) depth == 0 || depth == 2 || depth == 5 in function cv::cvtColor

Wed, 25 Apr 2018 21:24:45 imgcut.py[line:381] ERROR cut_img 这里出错
Wed, 25 Apr 2018 21:24:45 imgcut.py[line:382] ERROR this is an exception message
Traceback (most recent call last):
  File "E:\hupai\component\imgcut.py", line 374, in cut_img
    set_val('imgpos_lowestprice', img[use_area[0][1]:use_area[0][3], use_area[0][0]:use_area[0][2]])  # ok
IndexError: list index out of range
Wed, 25 Apr 2018 21:24:45 app_thread.py[line:147] ERROR 刷新失败
Wed, 25 Apr 2018 21:24:45 app_thread.py[line:148] ERROR this is an exception message
Traceback (most recent call last):
  File "E:\hupai\component\app_thread.py", line 145, in run
    findrefresh()
  File "E:\hupai\component\imgcut.py", line 396, in findrefresh
    img = cv2.cvtColor(sc, cv2.COLOR_BGR2GRAY)  # 转灰度图
cv2.error: C:\projects\opencv-python\opencv\modules\imgproc\src\color.cpp:11073: error: (-215) depth == 0 || depth == 2 || depth == 5 in function cv::cvtColor

Wed, 25 Apr 2018 21:24:45 app_thread.py[line:147] ERROR 刷新失败
Wed, 25 Apr 2018 21:24:45 app_thread.py[line:148] ERROR this is an exception message
Traceback (most recent call last):
  File "E:\hupai\component\app_thread.py", line 145, in run
    findrefresh()
  File "E:\hupai\component\imgcut.py", line 396, in findrefresh
    img = cv2.cvtColor(sc, cv2.COLOR_BGR2GRAY)  # 转灰度图
cv2.error: C:\projects\opencv-python\opencv\modules\imgproc\src\color.cpp:11073: error: (-215) depth == 0 || depth == 2 || depth == 5 in function cv::cvtColor

Wed, 25 Apr 2018 21:24:45 imgcut.py[line:381] ERROR cut_img 这里出错
Wed, 25 Apr 2018 21:24:45 imgcut.py[line:382] ERROR this is an exception message
Traceback (most recent call last):
  File "E:\hupai\component\imgcut.py", line 374, in cut_img
    set_val('imgpos_lowestprice', img[use_area[0][1]:use_area[0][3], use_area[0][0]:use_area[0][2]])  # ok
IndexError: list index out of range
Wed, 25 Apr 2018 21:24:45 app_thread.py[line:147] ERROR 刷新失败
Wed, 25 Apr 2018 21:24:45 app_thread.py[line:148] ERROR this is an exception message
Traceback (most recent call last):
  File "E:\hupai\component\app_thread.py", line 145, in run
    findrefresh()
  File "E:\hupai\component\imgcut.py", line 396, in findrefresh
    img = cv2.cvtColor(sc, cv2.COLOR_BGR2GRAY)  # 转灰度图
cv2.error: C:\projects\opencv-python\opencv\modules\imgproc\src\color.cpp:11073: error: (-215) depth == 0 || depth == 2 || depth == 5 in function cv::cvtColor

Wed, 25 Apr 2018 21:24:45 imgcut.py[line:381] ERROR cut_img 这里出错
Wed, 25 Apr 2018 21:24:45 app_thread.py[line:147] ERROR 刷新失败
Wed, 25 Apr 2018 21:24:45 imgcut.py[line:382] ERROR this is an exception message
Traceback (most recent call last):
  File "E:\hupai\component\imgcut.py", line 374, in cut_img
    set_val('imgpos_lowestprice', img[use_area[0][1]:use_area[0][3], use_area[0][0]:use_area[0][2]])  # ok
IndexError: list index out of range
Wed, 25 Apr 2018 21:24:45 app_thread.py[line:148] ERROR this is an exception message
Traceback (most recent call last):
  File "E:\hupai\component\app_thread.py", line 145, in run
    findrefresh()
  File "E:\hupai\component\imgcut.py", line 396, in findrefresh
    img = cv2.cvtColor(sc, cv2.COLOR_BGR2GRAY)  # 转灰度图
cv2.error: C:\projects\opencv-python\opencv\modules\imgproc\src\color.cpp:11073: error: (-215) depth == 0 || depth == 2 || depth == 5 in function cv::cvtColor

Wed, 25 Apr 2018 21:24:45 app_thread.py[line:147] ERROR 刷新失败
Wed, 25 Apr 2018 21:24:45 app_thread.py[line:148] ERROR this is an exception message
Traceback (most recent call last):
  File "E:\hupai\component\app_thread.py", line 145, in run
    findrefresh()
  File "E:\hupai\component\imgcut.py", line 396, in findrefresh
    img = cv2.cvtColor(sc, cv2.COLOR_BGR2GRAY)  # 转灰度图
cv2.error: C:\projects\opencv-python\opencv\modules\imgproc\src\color.cpp:11073: error: (-215) depth == 0 || depth == 2 || depth == 5 in function cv::cvtColor

Wed, 25 Apr 2018 21:24:45 imgcut.py[line:381] ERROR cut_img 这里出错
Wed, 25 Apr 2018 21:24:45 imgcut.py[line:382] ERROR this is an exception message
Traceback (most recent call last):
  File "E:\hupai\component\imgcut.py", line 374, in cut_img
    set_val('imgpos_lowestprice', img[use_area[0][1]:use_area[0][3], use_area[0][0]:use_area[0][2]])  # ok
IndexError: list index out of range
Wed, 25 Apr 2018 21:24:46 app_thread.py[line:147] ERROR 刷新失败
Wed, 25 Apr 2018 21:24:46 app_thread.py[line:148] ERROR this is an exception message
Traceback (most recent call last):
  File "E:\hupai\component\app_thread.py", line 145, in run
    findrefresh()
  File "E:\hupai\component\imgcut.py", line 396, in findrefresh
    img = cv2.cvtColor(sc, cv2.COLOR_BGR2GRAY)  # 转灰度图
cv2.error: C:\projects\opencv-python\opencv\modules\imgproc\src\color.cpp:11073: error: (-215) depth == 0 || depth == 2 || depth == 5 in function cv::cvtColor

Wed, 25 Apr 2018 21:24:46 imgcut.py[line:381] ERROR cut_img 这里出错
Wed, 25 Apr 2018 21:24:46 imgcut.py[line:382] ERROR this is an exception message
Traceback (most recent call last):
  File "E:\hupai\component\imgcut.py", line 374, in cut_img
    set_val('imgpos_lowestprice', img[use_area[0][1]:use_area[0][3], use_area[0][0]:use_area[0][2]])  # ok
IndexError: list index out of range
Wed, 25 Apr 2018 21:24:46 app_thread.py[line:147] ERROR 刷新失败
Wed, 25 Apr 2018 21:24:46 app_thread.py[line:148] ERROR this is an exception message
Traceback (most recent call last):
  File "E:\hupai\component\app_thread.py", line 145, in run
    findrefresh()
  File "E:\hupai\component\imgcut.py", line 396, in findrefresh
    img = cv2.cvtColor(sc, cv2.COLOR_BGR2GRAY)  # 转灰度图
cv2.error: C:\projects\opencv-python\opencv\modules\imgproc\src\color.cpp:11073: error: (-215) depth == 0 || depth == 2 || depth == 5 in function cv::cvtColor

Wed, 25 Apr 2018 21:24:46 app_thread.py[line:147] ERROR 刷新失败
Wed, 25 Apr 2018 21:24:46 app_thread.py[line:148] ERROR this is an exception message
Traceback (most recent call last):
  File "E:\hupai\component\app_thread.py", line 145, in run
    findrefresh()
  File "E:\hupai\component\imgcut.py", line 396, in findrefresh
    img = cv2.cvtColor(sc, cv2.COLOR_BGR2GRAY)  # 转灰度图
cv2.error: C:\projects\opencv-python\opencv\modules\imgproc\src\color.cpp:11073: error: (-215) depth == 0 || depth == 2 || depth == 5 in function cv::cvtColor

Wed, 25 Apr 2018 21:24:46 imgcut.py[line:381] ERROR cut_img 这里出错
Wed, 25 Apr 2018 21:24:46 imgcut.py[line:382] ERROR this is an exception message
Traceback (most recent call last):
  File "E:\hupai\component\imgcut.py", line 374, in cut_img
    set_val('imgpos_lowestprice', img[use_area[0][1]:use_area[0][3], use_area[0][0]:use_area[0][2]])  # ok
IndexError: list index out of range
Wed, 25 Apr 2018 21:24:46 imgcut.py[line:269] ERROR this is an exception message
Traceback (most recent call last):
  File "E:\hupai\component\imgcut.py", line 239, in timeset
    currenttime = cv2.cvtColor(imgpos_currenttime, cv2.COLOR_BGR2GRAY)
cv2.error: C:\projects\opencv-python\opencv\modules\imgproc\src\color.cpp:11073: error: (-215) depth == 0 || depth == 2 || depth == 5 in function cv::cvtColor

Wed, 25 Apr 2018 21:24:46 app_thread.py[line:147] ERROR 刷新失败
Wed, 25 Apr 2018 21:24:46 app_thread.py[line:148] ERROR this is an exception message
Traceback (most recent call last):
  File "E:\hupai\component\app_thread.py", line 145, in run
    findrefresh()
  File "E:\hupai\component\imgcut.py", line 396, in findrefresh
    img = cv2.cvtColor(sc, cv2.COLOR_BGR2GRAY)  # 转灰度图
cv2.error: C:\projects\opencv-python\opencv\modules\imgproc\src\color.cpp:11073: error: (-215) depth == 0 || depth == 2 || depth == 5 in function cv::cvtColor

Wed, 25 Apr 2018 21:24:46 imgcut.py[line:381] ERROR cut_img 这里出错
Wed, 25 Apr 2018 21:24:46 imgcut.py[line:382] ERROR this is an exception message
Traceback (most recent call last):
  File "E:\hupai\component\imgcut.py", line 374, in cut_img
    set_val('imgpos_lowestprice', img[use_area[0][1]:use_area[0][3], use_area[0][0]:use_area[0][2]])  # ok
IndexError: list index out of range
Wed, 25 Apr 2018 21:24:46 app_thread.py[line:147] ERROR 刷新失败
Wed, 25 Apr 2018 21:24:46 app_thread.py[line:148] ERROR this is an exception message
Traceback (most recent call last):
  File "E:\hupai\component\app_thread.py", line 145, in run
    findrefresh()
  File "E:\hupai\component\imgcut.py", line 396, in findrefresh
    img = cv2.cvtColor(sc, cv2.COLOR_BGR2GRAY)  # 转灰度图
cv2.error: C:\projects\opencv-python\opencv\modules\imgproc\src\color.cpp:11073: error: (-215) depth == 0 || depth == 2 || depth == 5 in function cv::cvtColor

Wed, 25 Apr 2018 21:24:46 app_thread.py[line:147] ERROR 刷新失败
Wed, 25 Apr 2018 21:24:46 app_thread.py[line:148] ERROR this is an exception message
Traceback (most recent call last):
  File "E:\hupai\component\app_thread.py", line 145, in run
    findrefresh()
  File "E:\hupai\component\imgcut.py", line 396, in findrefresh
    img = cv2.cvtColor(sc, cv2.COLOR_BGR2GRAY)  # 转灰度图
cv2.error: C:\projects\opencv-python\opencv\modules\imgproc\src\color.cpp:11073: error: (-215) depth == 0 || depth == 2 || depth == 5 in function cv::cvtColor

Wed, 25 Apr 2018 21:24:47 imgcut.py[line:269] ERROR this is an exception message
Traceback (most recent call last):
  File "E:\hupai\component\imgcut.py", line 241, in timeset
    currenttime = readpic(currenttime, maindata)  # 识别出来的时间
  File "E:\hupai\component\imgcut.py", line 225, in readpic
    testData = cut(img)
  File "E:\hupai\component\imgcut.py", line 165, in cut
    diff = xy[-1][2]  # 最后一个 图像块
IndexError: list index out of range
Wed, 25 Apr 2018 21:24:48 imgcut.py[line:269] ERROR this is an exception message
Traceback (most recent call last):
  File "E:\hupai\component\imgcut.py", line 241, in timeset
    currenttime = readpic(currenttime, maindata)  # 识别出来的时间
  File "E:\hupai\component\imgcut.py", line 225, in readpic
    testData = cut(img)
  File "E:\hupai\component\imgcut.py", line 165, in cut
    diff = xy[-1][2]  # 最后一个 图像块
IndexError: list index out of range
Wed, 25 Apr 2018 21:24:48 imgcut.py[line:269] ERROR this is an exception message
Traceback (most recent call last):
  File "E:\hupai\component\imgcut.py", line 241, in timeset
    currenttime = readpic(currenttime, maindata)  # 识别出来的时间
  File "E:\hupai\component\imgcut.py", line 225, in readpic
    testData = cut(img)
  File "E:\hupai\component\imgcut.py", line 165, in cut
    diff = xy[-1][2]  # 最后一个 图像块
IndexError: list index out of range
Wed, 25 Apr 2018 21:24:48 imgcut.py[line:269] ERROR this is an exception message
Traceback (most recent call last):
  File "E:\hupai\component\imgcut.py", line 241, in timeset
    currenttime = readpic(currenttime, maindata)  # 识别出来的时间
  File "E:\hupai\component\imgcut.py", line 225, in readpic
    testData = cut(img)
  File "E:\hupai\component\imgcut.py", line 165, in cut
    diff = xy[-1][2]  # 最后一个 图像块
IndexError: list index out of range
Wed, 25 Apr 2018 21:24:48 imgcut.py[line:269] ERROR this is an exception message
Traceback (most recent call last):
  File "E:\hupai\component\imgcut.py", line 241, in timeset
    currenttime = readpic(currenttime, maindata)  # 识别出来的时间
  File "E:\hupai\component\imgcut.py", line 225, in readpic
    testData = cut(img)
  File "E:\hupai\component\imgcut.py", line 165, in cut
    diff = xy[-1][2]  # 最后一个 图像块
IndexError: list index out of range
Wed, 25 Apr 2018 21:24:48 imgcut.py[line:269] ERROR this is an exception message
Traceback (most recent call last):
  File "E:\hupai\component\imgcut.py", line 241, in timeset
    currenttime = readpic(currenttime, maindata)  # 识别出来的时间
  File "E:\hupai\component\imgcut.py", line 225, in readpic
    testData = cut(img)
  File "E:\hupai\component\imgcut.py", line 165, in cut
    diff = xy[-1][2]  # 最后一个 图像块
IndexError: list index out of range
Wed, 25 Apr 2018 21:24:49 imgcut.py[line:269] ERROR this is an exception message
Traceback (most recent call last):
  File "E:\hupai\component\imgcut.py", line 241, in timeset
    currenttime = readpic(currenttime, maindata)  # 识别出来的时间
  File "E:\hupai\component\imgcut.py", line 225, in readpic
    testData = cut(img)
  File "E:\hupai\component\imgcut.py", line 165, in cut
    diff = xy[-1][2]  # 最后一个 图像块
IndexError: list index out of range
Wed, 25 Apr 2018 21:24:50 imgcut.py[line:269] ERROR this is an exception message
Traceback (most recent call last):
  File "E:\hupai\component\imgcut.py", line 253, in timeset
    a_time_temp = time.mktime(time.strptime(b, '%Y-%m-%d %H:%M:%S')) + 0.6  # 转时间戳   补个平均时差
  File "C:\Users\Administrator\Python\Python36\Lib\_strptime.py", line 559, in _strptime_time
    tt = _strptime(data_string, format)[0]
  File "C:\Users\Administrator\Python\Python36\Lib\_strptime.py", line 362, in _strptime
    (data_string, format))
ValueError: time data '2018-04-25 44444' does not match format '%Y-%m-%d %H:%M:%S'
Wed, 25 Apr 2018 21:24:50 imgcut.py[line:269] ERROR this is an exception message
Traceback (most recent call last):
  File "E:\hupai\component\imgcut.py", line 253, in timeset
    a_time_temp = time.mktime(time.strptime(b, '%Y-%m-%d %H:%M:%S')) + 0.6  # 转时间戳   补个平均时差
  File "C:\Users\Administrator\Python\Python36\Lib\_strptime.py", line 559, in _strptime_time
    tt = _strptime(data_string, format)[0]
  File "C:\Users\Administrator\Python\Python36\Lib\_strptime.py", line 362, in _strptime
    (data_string, format))
ValueError: time data '2018-04-25 44444' does not match format '%Y-%m-%d %H:%M:%S'
Wed, 25 Apr 2018 21:24:50 imgcut.py[line:269] ERROR this is an exception message
Traceback (most recent call last):
  File "E:\hupai\component\imgcut.py", line 253, in timeset
    a_time_temp = time.mktime(time.strptime(b, '%Y-%m-%d %H:%M:%S')) + 0.6  # 转时间戳   补个平均时差
  File "C:\Users\Administrator\Python\Python36\Lib\_strptime.py", line 559, in _strptime_time
    tt = _strptime(data_string, format)[0]
  File "C:\Users\Administrator\Python\Python36\Lib\_strptime.py", line 362, in _strptime
    (data_string, format))
ValueError: time data '2018-04-25 44444' does not match format '%Y-%m-%d %H:%M:%S'
Wed, 25 Apr 2018 21:24:51 imgcut.py[line:269] ERROR this is an exception message
Traceback (most recent call last):
  File "E:\hupai\component\imgcut.py", line 253, in timeset
    a_time_temp = time.mktime(time.strptime(b, '%Y-%m-%d %H:%M:%S')) + 0.6  # 转时间戳   补个平均时差
  File "C:\Users\Administrator\Python\Python36\Lib\_strptime.py", line 559, in _strptime_time
    tt = _strptime(data_string, format)[0]
  File "C:\Users\Administrator\Python\Python36\Lib\_strptime.py", line 362, in _strptime
    (data_string, format))
ValueError: time data '2018-04-25 44444' does not match format '%Y-%m-%d %H:%M:%S'
Wed, 25 Apr 2018 21:24:51 imgcut.py[line:269] ERROR this is an exception message
Traceback (most recent call last):
  File "E:\hupai\component\imgcut.py", line 253, in timeset
    a_time_temp = time.mktime(time.strptime(b, '%Y-%m-%d %H:%M:%S')) + 0.6  # 转时间戳   补个平均时差
  File "C:\Users\Administrator\Python\Python36\Lib\_strptime.py", line 559, in _strptime_time
    tt = _strptime(data_string, format)[0]
  File "C:\Users\Administrator\Python\Python36\Lib\_strptime.py", line 362, in _strptime
    (data_string, format))
ValueError: time data '2018-04-25 44444' does not match format '%Y-%m-%d %H:%M:%S'
Wed, 25 Apr 2018 21:24:51 imgcut.py[line:269] ERROR this is an exception message
Traceback (most recent call last):
  File "E:\hupai\component\imgcut.py", line 253, in timeset
    a_time_temp = time.mktime(time.strptime(b, '%Y-%m-%d %H:%M:%S')) + 0.6  # 转时间戳   补个平均时差
  File "C:\Users\Administrator\Python\Python36\Lib\_strptime.py", line 559, in _strptime_time
    tt = _strptime(data_string, format)[0]
  File "C:\Users\Administrator\Python\Python36\Lib\_strptime.py", line 362, in _strptime
    (data_string, format))
ValueError: time data '2018-04-25 44444' does not match format '%Y-%m-%d %H:%M:%S'
Wed, 25 Apr 2018 21:24:51 imgcut.py[line:269] ERROR this is an exception message
Traceback (most recent call last):
  File "E:\hupai\component\imgcut.py", line 241, in timeset
    currenttime = readpic(currenttime, maindata)  # 识别出来的时间
  File "E:\hupai\component\imgcut.py", line 225, in readpic
    testData = cut(img)
  File "E:\hupai\component\imgcut.py", line 165, in cut
    diff = xy[-1][2]  # 最后一个 图像块
IndexError: list index out of range
Wed, 25 Apr 2018 21:24:51 imgcut.py[line:269] ERROR this is an exception message
Traceback (most recent call last):
  File "E:\hupai\component\imgcut.py", line 241, in timeset
    currenttime = readpic(currenttime, maindata)  # 识别出来的时间
  File "E:\hupai\component\imgcut.py", line 225, in readpic
    testData = cut(img)
  File "E:\hupai\component\imgcut.py", line 165, in cut
    diff = xy[-1][2]  # 最后一个 图像块
IndexError: list index out of range
Wed, 25 Apr 2018 21:24:52 imgcut.py[line:269] ERROR this is an exception message
Traceback (most recent call last):
  File "E:\hupai\component\imgcut.py", line 241, in timeset
    currenttime = readpic(currenttime, maindata)  # 识别出来的时间
  File "E:\hupai\component\imgcut.py", line 225, in readpic
    testData = cut(img)
  File "E:\hupai\component\imgcut.py", line 165, in cut
    diff = xy[-1][2]  # 最后一个 图像块
IndexError: list index out of range
